Workbook
Name LIST_YES_NO: 'Reference lists'!$C$5:$C$6
Name LIST_BU_REVIEW: 'Reference lists'!$C$7:$C$9
Name LIST_R03_RECORD_TYPE: 'Reference lists'!$C$10:$C$13
Name LIST_R06_QUALIFIER: 'Reference lists'!$C$14:$C$16
Name LIST_R06_ACTION: 'Reference lists'!$C$17:$C$18
Name LIST_R08_ACCOUNT_TYPE: 'Reference lists'!$C$19:$C$23
Name LIST_R08_NORMAL_BALANCE: 'Reference lists'!$C$24:$C$25
Name LIST_R08_LEGACY_CONTROL_TYPE: 'Reference lists'!$C$26:$C$33
Name LIST_R09_DEFAULT_MODE: 'Reference lists'!$C$34:$C$40
Name LIST_R11_KIND: 'Reference lists'!$C$41:$C$42
Name LIST_C01_CLIENT_TYPE: 'Reference lists'!$C$43:$C$44
Name LIST_C02_RECORD_TYPE: 'Reference lists'!$C$45:$C$46
Name LIST_C02_ADDRESS_TYPE: 'Reference lists'!$C$47:$C$50
Name LIST_C03_MODE: 'Reference lists'!$C$51:$C$52
Name LIST_P01_BUSINESS_TYPE: 'Reference lists'!$C$53:$C$54
Name LIST_P01_PAYMENT_ARRANGEMENT: 'Reference lists'!$C$55:$C$56
Name LIST_P03_RA_CHANNEL: 'Reference lists'!$C$57:$C$60
Name LIST_F01_INVOICE_KIND: 'Reference lists'!$C$61:$C$64
Name LIST_F01C_COMPONENT: 'Reference lists'!$C$65:$C$75
Name LIST_F02_CHANNEL: 'Reference lists'!$C$76:$C$82
Name LIST_F02_DISPOSITION_STATUS: 'Reference lists'!$C$83:$C$85
Name LIST_F03_RECORD_TYPE: 'Reference lists'!$C$86:$C$89
Name LIST_F04_RECORD_TYPE: 'Reference lists'!$C$90:$C$92
Name LIST_F06_RECORD_TYPE: 'Reference lists'!$C$93:$C$95
Name LIST_G01_TB_VERSION: 'Reference lists'!$C$96:$C$100
Name LIST_G03_TRUEUP_NO: 'Reference lists'!$C$101:$C$104
Name LIST_G03_ADJUSTMENT_KIND: 'Reference lists'!$C$105:$C$106
Name LIST_G03D_TRUEUP_NO: 'Reference lists'!$C$107:$C$110
Name LIST_G03D_ITEM_KIND: 'Reference lists'!$C$111:$C$112
Name LIST_G03D_COMPONENT: 'Reference lists'!$C$113:$C$126
Name LIST_G03D_MOVEMENT: 'Reference lists'!$C$127:$C$128
Name LIST_H01_RECORD_TYPE: 'Reference lists'!$C$129:$C$139
Name LIST_STATUS: 'Reference lists'!$C$140:$C$143

Sheet Cover
B6: MIGRATION WORKBOOK
B7: Migration Workbook BRD-13 Data Migration
B8: BRD-13 Data Migration – objects and decisions, load templates, code maps, validation rules, data owners, cut-over plan, reconciliation sign-off and the screens, for BU review
B9: BIBS – BDOI Broker System
B11: Client | C11: BDO Insurance and Reinsurance Brokers, Inc.
B12: BRD | C12: BRD-13
B13: Version | C13: 2.1
B14: Date | C14: 8 October 2026
B15: Classification | C15: Confidential
B16: Prepared by | C16: iorta TechNXT
B18: Sheets
B19: Sheet | C19: Content | D19: Rows
B20: README | C20: What each column of each sheet means, with the allowed values
B21: How to review | C21: How the business unit reviews this workbook | D21: 7
B22: Object catalogue | C22: One row per legacy data object with the proposed decision and the four criteria of the BRD (BRID_MIG 1.1) | D22: 32
B23: Data owners | C23: Business owner and data steward of every object; BDOI names the people (DMQ01) | D23: 30
B24: Extract planning | C24: What BDOI extracts per object, how much, how far back and by when | D24: 26
B25: Milestones | C25: Milestones used in the Due and Needed-by columns | D25: 7
B26: File rules | C26: Rules of every extract and control file: the delivery rules of the console workbook, then the rules of the migration | D26: 11
B27: Load templates | C27: Who provides what, the steps and the templates in the order they are filled in | D27: 29
B28: R01 Lists of values and MIS val | C28: R01 Lists of values and MIS values: One row per record of Lists of values and MIS values as extracted from QPS, EBIX. Key list_type, code. Sent as the file R01_template.csv (CSV, header row as below) with its control file (row count, count of … | D28: 1
B29: R02 Branches and invoicing bran | C29: R02 Branches and invoicing branches: One row per record of Branches and invoicing branches as extracted from EBIX. Key branch_code. Sent as the file R02_template.csv (CSV, header row as below) with its control file (row count, count of distinct … | D29: 1
B30: R03 Sales organisation (units a | C30: R03 Sales organisation (units and account officers): One row per record of Sales organisation (regions, departments, teams, unit heads, account officers) as extracted from QPS, EBIX. Key record_type, unit_code, ao_user_id. Sent as the file … | D30: 1
B31: R04 Insurers | C31: R04 Insurers: One row per record of Insurers and insurer branches as extracted from QPS, EBIX. Key insurer_code. Sent as the file R04_template.csv (CSV, header row as below) with its control file (row count, count of distinct keys). | D31: 1
B32: R04B Insurer branches | C32: R04B Insurer branches: One row per record of Insurers and insurer branches as extracted from QPS, EBIX. Key insurer_code, branch_code. Sent as the file R04B_template.csv (CSV, header row as below) with its control file (row count, count of distinct … | D32: 1
... B89: Sign-off certificate | C89: By signing, the signatories confirm the BRD-13 Data Migration – Business Sign-off Pack v2.1: its content, screens and navigation are frozen; the screenshots use fictitious seed data; later changes go through the Change Management Register | D89: 17
B91: Legend
B92: Accept | C92: The row is correct as specified
B93: Change requested | C93: The row must change: describe the change in BU comment
B94: Comment | C94: A remark that does not change the row
B96: Issued on 08-Oct-2026 with the Data Migration Handbook v2.1, re-based on the Data Migration BRD V0.03. The load template sheets are the layouts of the Migration Console column for column, each with its guide above the header row; the sheet Load templates lists them in load order. The console exports the same templates (Layouts and Rules).
B97: Fill in the BU review columns (on a load template sheet, the BU review rows above each column) and, on the Proposed rules sheet, the BDOI decision. After sign-off the objects, decisions, layouts, screens and rules are frozen; later changes go through the Change Management Register.
B99: Prepared by iorta TechNXT for BDOI. Confidential – BDOI.

Sheet README
A1: README – columns of each sheet
A2: Migration Workbook BRD-13 Data Migration, version 2.1. Drop-down columns accept only the listed values.
A4: Sheet | B4: Column | C4: Meaning | D4: Allowed values
A5: How to review | B5: Step | C5: Step number
A6: How to review | B6: How to review | C6: Instruction
A7: Object catalogue | B7: Object | C7: Data object code
A8: Object catalogue | B8: Data object | C8: What the object holds
A9: Object catalogue | B9: Category | C9: Reference, Client, Policy, Open item, GL, History
A10: Object catalogue | B10: Decision (proposed) | C10: Migrate, Carry forward, Conditional, Archive or Excluded; the business owner confirms at gate G1 | D10: Migrate, Carry forward, Conditional, Archive, Excluded
A11: Object catalogue | B11: Rationale | C11: Why this decision
A12: Object catalogue | B12: Day-1 need | C12: Needed in BIBS on the first business day
A13: Object catalogue | B13: Compliance need | C13: Must be kept for compliance or audit
A14: Object catalogue | B14: Archive option | C14: Read-only legacy or the BIBS archive is enough
A15: Object catalogue | B15: Data trust | C15: High, Medium or Low, before cleansing
A16: Object catalogue | B16: Condition | C16: Condition of a conditional object
A17: Object catalogue | B17: Source system | C17: Legacy system(s) that hold the object
A18: Object catalogue | B18: Templates | C18: Load templates of the object (sheets of this workbook)
A19: Object catalogue | B19: Where it lands in BIBS | C19: The BIBS records the object becomes
A20: Object catalogue | B20: Load order | C20: Lower loads first
A21: Object catalogue | B21: Loads after | C21: Objects that must be accepted first
A22: Object catalogue | B22: BRD | C22: BRD requirement
A23: Object catalogue | B23: Open decisions | C23: Decisions that affect the object
A24: Object catalogue | B24: BU review | C24: Business unit decision on the row | D24: Accept, Change requested, Comment
A25: Object catalogue | B25: BU comment | C25: What should change, or the comment
A26: Object catalogue | B26: Reviewer | C26: Name of the BU reviewer
A27: Object catalogue | B27: Review date | C27: Date of the review (dd-mmm-yyyy)
A28: Data owners | B28: Object | C28: Data object code
A29: Data owners | B29: Data object | C29: What the object holds
A30: Data owners | B30: Business owner (proposed) | C30: Signs the decision (G1), the code maps (G2) and the acceptance (G6)
A31: Data owners | B31: Data steward (proposed) | C31: Prepares the code maps, resolves data-quality issues, fixes records at source
A32: Data owners | B32: Named business owner | C32: Name given by BDOI
A33: Data owners | B33: Named data steward | C33: Name given by BDOI
A34: Data owners | B34: BU review | C34: Business unit decision on the row | D34: Accept, Change requested, Comment
A35: Data owners | B35: BU comment | C35: What should change, or the comment
A36: Data owners | B36: Reviewer | C36: Name of the BU reviewer
A37: Data owners | B37: Review date | C37: Date of the review (dd-mmm-yyyy)
A38: Extract planning | B38: Object | C38: Data object code
A39: Extract planning | B39: Data object | C39: What the object holds
A40: Extract planning | B40: Volume (BDOI to fill) | C40: Row count per source system at the last extract
A41: Extract planning | B41: Planning bound | C41: Known bound from the BRDs
...

Sheet How to review
A1: How to review
A2: How the business unit reviews this workbook
A4: Step | B4: How to review
A5: 1 | B5: Read the Handbook part of your role with the screenshots, or walk through the Migration Console on the SIT environment during the sessions of the Start Here guide.
A6: 2 | B6: On the sheets of your objects (Object catalogue, Data owners, Extract planning, Code maps, Validation rules, Reconciliation sign-off) and on the screen sheets, set BU review to Accept, Change requested or Comment for each row you review, and write the change in BU comment. On a load template sheet the BU review and BU comment rows sit above each column.
A7: 3 | B7: On the Proposed rules sheet, record the BDOI decision (Agree, Agree with change, Disagree, Need more information), the change asked for, who decided and the date.
A8: 4 | B8: Put your name in Reviewer and the date in Review date. Leave the other columns unchanged.
A9: 5 | B9: The sheet Load templates lists the load templates in load order with a link to each. A load template sheet is the layout of the Migration Console column for column, with the guide of each column (Mandatory, Format, Allowed values, What to enter, the check when loaded) directly above the header row; the console exports the same templates (Layouts and Rules, Load Templates Workbook).
A10: 6 | B10: Return the workbook to the iorta TechNXT project team by the date of the Start Here guide. Every Change requested row is answered in the Comments log before sign-off.
A11: 7 | B11: Questions and change requests go to the Comments log, with the load template and the column when they concern one; the project team answers each one there. On the Sign-off certificate sheet, each signatory records the decision and the date. The screenshots use fictitious seed data.

Sheet Object catalogue
A1: Object catalogue
A2: One row per legacy data object with the proposed decision and the four criteria of the BRD (BRID_MIG 1.1)
A4: Object | B4: Data object | C4: Category | D4: Decision (proposed) | E4: Rationale | F4: Day-1 need | G4: Compliance need | H4: Archive option | I4: Data trust | J4: Condition | K4: Source system | L4: Templates | M4: Where it lands in BIBS | N4: Load order | O4: Loads after | P4: BRD | Q4: Open decisions | R4: BU review | S4: BU comment | T4: Reviewer | U4: Review date
A5: R01 | B5: Lists of values and MIS values | C5: Reference | D5: Migrate | E5: Every coded field of clients, policies and open items needs its BIBS value on Day 1 (BRID_MIG 3.1). Legacy values are mapped to BIBS values; missing values are created through the LOV master with maker-checker. | F5: Yes | G5: No | H5: No | I5: Medium | K5: QPS, EBIX | L5: R01 | M5: Lists of Values (maker-checker); MIS field catalogue | N5: 1 | O5: - | P5: BRID_MIG 3.1 | Q5: DMQ08
A6: R02 | B6: Branches and invoicing branches | C6: Reference | D6: Migrate | E6: Branch codes are mapped only; BIBS branches are configured by Comptrollership before the load. | F6: Yes | G6: No | H6: No | I6: Medium | K6: EBIX | L6: R02 | M6: Branches (check only, code map BRANCH) | N6: 1 | O6: - | P6: BRID_MIG 3.1 | Q6: DMQ08
A7: R03 | B7: Sales organisation (regions, departments, teams, unit heads, account officers) | C7: Reference | D7: Migrate | E7: Clients, policies and open items carry the AO and unit; MIS reporting and Collections assignment need them on Day 1. | F7: Yes | G7: No | H7: No | I7: Medium | K7: QPS, EBIX | L7: R03 | M7: Sales organisation: sales units and account officers | N7: 2 | O7: R02 | P7: BRID_MIG 3.1 | Q7: DMQ08
A8: R04 | B8: Insurers and insurer branches | C8: Reference | D8: Migrate | E8: Every open invoice, header and remittance position is owed to or by an insurer. | F8: Yes | G8: No | H8: No | I8: Medium | K8: QPS, EBIX | L8: R04, R04B | M8: Insurers and insurer branches (insurer and party records) | N8: 2 | O8: - | P8: BRID_MIG 3.1 | Q8: DMQ08
A9: R05 | B9: Product lines, cover types, products and risk codes | C9: Reference | D9: Migrate | E9: The risk code decides the premium components, taxes and commission of every open invoice and header. | F9: Yes | G9: No | H9: No | I9: Medium | K9: QPS, EBIX | L9: R05 | M9: Product catalogue: product lines, cover types and products | N9: 3 | O9: - | P9: BRID_MIG 3.1 | Q9: DMQ08
A10: R06 | B10: Package code map (legacy package and version to BIBS package version) | C10: Reference | D10: Migrate | E10: Packages are remapped at sanitation in Renewal, not at migration intake (DMQ36, answered 26-Sep-2026). The migration loads the package code map as reference data only; the Renewal package check uses it and sends unmapped packages to the Exception bucket, worked by the Renewal processing team. The BIBS packages themselves are maintained by TSU in Product Maintenance (BRD-3) and are not migrated. | F10: Yes | G10: No | H10: No | I10: Medium | K10: QPS (legacy packages); TSU (BIBS package versions) | L10: R06 | M10: Renewal package map, used by the package check of the Renewal sanitation | N10: 3 | O10: - | P10: BRID_MIG 3.1, 12.1 | Q10: DMQ08, DMQ36
A11: R07 | B11: Commission rates by insurer and product | C11: Reference | D11: Migrate | E11: Endorsements and renewals of legacy policies compute commission from the rate table. | F11: Yes | G11: No | H11: No | I11: Medium | K11: QPS, EBIX | L11: R07 | M11: Commission rates of the product catalogue | N11: 3 | O11: R04 | P11: BRID_MIG 3.1 | Q11: DMQ30
A12: R08 | B12: Chart of accounts mapping (legacy GL account to BIBS account) | C12: Reference | D12: Migrate | E12: The GL opening trial balance (G01) is loaded through this map; legacy control accounts are mapped to Migration Clearing. | F12: Yes | G12: No | H12: No | I12: Medium | K12: EBIX, ISYS GL | L12: R08 | M12: GL account code map to the BIBS chart of accounts (chart configured by Comptrollership) | N12: 3 | O12: - | P12: BRID_MIG 5.1-8.1; AQ01 | Q12: DMQ18
A13: R09 | B13: Payees | C13: Reference | D13: Conditional | E13: Payees are loaded through the payee migration upload of Disbursement; in scope if BDOI confirms (AQ11, DMQ30). | F13: Yes | G13: No | H13: No | I13: Medium | J13: Loaded through the payee registration of Disbursement if BDOI confirms (DMQ30). | K13: EBIX, Disbursement files | L13: R09 | M13: Payees (party and payee records, loaded by the payee migration) | N13: 4 | O13: - | P13: BRID_MIG 3.1; AQ11 | Q13: DMQ30, CLR-DM-06
A14: R10 | B14: Users and roles | C14: Reference | D14: Excluded | E14: Users are created through User Access requests and approvals (BRD-11); legacy user IDs are only mapped (user code map) so that the AO, handler and collector fields resolve. | F14: No | G14: No | H14: Yes | I14: Medium | K14: QPS, EBIX | L14: - | M14: None (code map USER only) | N14: - | O14: - | P14: BRD-11 | Q14: DMQ30
A15: R11 | B15: Receipt series in use (AR and OR, ATP and next number) | C15: Reference | D15: Carry forward | E15: Receipts issued in BIBS after go-live must continue the BIR-authorised series without gap or overlap. | F15: Yes | G15: No | H15: No | I15: Medium | K15: EBIX | L15: R11 | M15: Receipt series of Cashiering | N15: 4 | O15: R02 | P15: BRID_MIG 6.1 | Q15: DMQ14
A16: C01 | B16: Client master (individual and corporate) | C16: Client | D16: Migrate | E16: Marketing, Operations and Renewal must find and use clients on Day 1 without re-encoding (BRID_MIG 2.1); clients are deduplicated before load. Umbrella BRD p.43 asks for clients "2020 to present" and daily client batches (DCR-173). | F16: Yes | G16: No | H16: No | I16: Medium | K16: QPS, EBIX, CMS | L16: C01, C02 | M16: Client master, registered as migrated clients | N16: 5 | O16: R01,R02,R03 | P16: BRID_MIG 1.3, 2.1 | Q16: DMQ04, DMQ05, DMQ06, DCR-173, CLR-DM-10, CLR-DM-11
A17: C03 | B17: Client payout accounts (for refunds) | C17: Client | D17: Migrate | E17: Refunds of legacy UPP (BRID_MIG 5.4) need the client's payout account. | F17: Yes | G17: No | H17: No | I17: Medium | K17: EBIX | L17: C03 | M17: Client payout accounts | N17: 6 | O17: C01 | P17: BRID_MIG 5.4 | Q17: DMQ17
A18: C04 | B18: KYC documents and IDs | C18: Client | D18: Archive | E18: Documents stay retrievable for audit; BIBS keeps the KYC status and review date on the client (DMQ07 may change this to MIGRATE). | F18: No | G18: Yes | H18: Yes | I18: Medium | K18: QPS, file shares | L18: H02 | M18: BIBS archive (legacy document attachments) | N18: 16 | O18: - | P18: BRID_MIG 11.1 | Q18: DMQ07, DMQ24
A19: C05 | B19: Screening results and risk ratings | C19: Client | D19: Excluded | E19: One full screening run after the client load gives current results (BRD-10); legacy results are archived with the client history. | F19: No | G19: No | H19: Yes | I19: Medium | K19: Excel, Compliance | L19: - | M19: None (a full periodic screening run after C01) | N19: - | O19: - | P19: BRID_MIG 2.1 | Q19: DMQ06
A20: P01 | B20: In-force policy headers | C20: Policy | D20: Conditional | E20: Needed to locate active coverage, to endorse legacy invoices (BRID_MIG 9) and to renew in BIBS (BRID_MIG 12.1); the scope condition is decided by BDOI (DMQ09). Whatever it is, every policy expiring from T to 31-May-2028 and every renewal term booked in legacy that starts on or after T are in scope, because the go-live renewal extraction works only from the headers (DMQ37). The legacy package is kept as given; it is remapped at Renewal sanitation (DMQ36). | F20: Yes | G20: No | H20: No | I20: Medium | J20: Needed to locate active coverage, to endorse legacy invoices and to renew in BIBS; the scope condition is decided by BDOI. Whatever it is, every policy expiring from T to 31-May-2028 and every renewal term booked in legacy that starts on or after T are in scope, because the go-live renewal extraction works only from the headers. The legacy package is kept as given; it is remapped at Renewal sanitation. | K20: QPS, EBIX | L20: P01, P01S | M20: Accounts, imported as legacy policy headers | N20: 7 | O20: C01,R04,R05 | P20: BRID_MIG 1.3, 4.1 | Q20: DMQ09, DMQ22, DMQ36, DMQ37
A21: P02 | B21: Expired policies and policy history | C21: Policy | D21: Archive | E21: History is not converted (BRD p.3); kept for inquiry. | F21: No | G21: Yes | H21: Yes | I21: Medium | K21: QPS, EBIX | L21: H01 | M21: BIBS archive, record type POLICY | N21: 16 | O21: - | P21: BRID_MIG 11.1 | Q21: DMQ24
A22: P03 | B22: Renewal advices already sent before go-live (RA-sent file) | C22: Policy | D22: Migrate | E22: The January-May 2028 expiries are processed in BIBS after go-live from a go-live extraction of the migrated headers (DMQ37, answered 26-Sep-2026); no renewal candidate is carried. The RAs already sent by hand before go-live, kept in the Excel trackers of the Renewal processing team (DMQ38), are loaded as a small reference file so that BIBS does not send them again. | F22: Yes | G22: No | H22: No | I22: Medium | K22: Excel RA trackers of the Renewal processing team | L22: P03 | M22: Renewal Advices already sent, given to Renewal with the policy header in the go-live extraction | N22: 13 | O22: P01 | P22: BRID_MIG 12.1, 12.2 | Q22: DMQ26, DMQ37, DMQ38, CLR-DM-07
A23: P04 | B23: Submitted-policy masterlists | C23: Policy | D23: Conditional | E23: Loaded through the masterlist upload of Submitted Policies if BDOI confirms (SP SQ16, DMQ30); the layout is issued with that module. | F23: Yes | G23: No | H23: No | I23: Medium | J23: Loaded through the policy registration of Submitted Policies if BDOI confirms (DMQ30); the layout is issued with the Submitted Policies set. | K23: Excel | L23: - | M23: Submitted Policies masterlist (migration upload) | N23: 14 | O23: - | P23: BRID_MIG 1.3; BRIDSP-33 | Q23: DMQ30, CLR-DM-05
A24: P05 | B24: Employee Benefits programmes | C24: Policy | D24: Conditional | E24: Loaded through the programme upload of Employee Benefits if BDOI confirms (DMQ30); the layout is issued with that module. | F24: Yes | G24: No | H24: No | I24: Medium | J24: Loaded through the programme set-up of Employee Benefits if BDOI confirms (DMQ30); the layout is issued with the Employee Benefits set. | K24: EBIX | L24: - | M24: Employee Benefits programmes (programme load) | N24: 14 | O24: - | P24: BRD-8 | Q24: DMQ30
A25: F01 | B25: Open legacy invoices (premium receivable, paid not remitted, commission receivable, PR2307), with components and insurer shares | C25: Open item | D25: Carry forward | E25: Receivables and payables open at cutover must be collected, remitted, reversed and endorsed in BIBS (BRID_MIG 5.1-10.1). | F25: Yes | G25: No | H25: No | I25: Medium | K25: EBIX, QPS | L25: F01, F01S, F01C | M25: Operations invoice ledger (invoices, insurer shares, components) with an opening accounting entry on the legacy sub-ledgers | N25: 8 | O25: C01,R04,R05,P01 | P25: BRID_MIG 5.2, 6.1-6.4, 7.1, 7.2, 8.1, 9.1-9.3, 10.1, 13.1 | Q25: DMQ10, DMQ11, DMQ12, DMQ13, DMQ35, CLR-DM-14, CLR-DM-18
A26: F02 | B26: Unapplied premium payments (UPP) with disposition in progress | C26: Open item | D26: Carry forward | E26: Unapplied cash must not be lost after cutover (BRID_MIG 5.1); it is applied, refunded or reclassified in BIBS. | F26: Yes | G26: No | H26: No | I26: Medium | K26: EBIX, CMS | L26: F02 | M26: Cashiering unapplied payments, as migrated items, with an opening accounting entry | N26: 9 | O26: C01 | P26: BRID_MIG 5.1-5.5, 6.3, 6.4, 13.1 | Q26: DMQ14, DMQ15, DMQ16
A27: F03 | B27: Open collection state (dispositions, promises to pay, installment plans, collector assignments) | C27: Open item | D27: Carry forward | E27: Collectors continue their follow-up without re-keying (CQ07); only the open state is carried, history is archived (DMQ34). | F27: Yes | G27: No | H27: No | I27: Medium | K27: CMS | L27: F03 | M27: Legacy follow-up of the Collections worklist items | N27: 10 | O27: F01 | P27: CQ07 | Q27: DMQ34
A28: F04 | B28: Remittance in flight (batches not yet paid, holds, special remittances) | C28: Open item | D28: Conditional | E28: Proposal - complete legacy batches before the freeze; carry only holds and special remittances that cannot complete (DMQ21). | F28: Yes | G28: No | H28: No | I28: Medium | J28: Proposal - complete legacy batches before the freeze; carry only holds and special remittances that cannot complete. | K28: EBIX | L28: F04 | M28: Remittance holds and special remittances | N28: 11 | O28: F01 | P28: BRID_MIG 8.1 | Q28: DMQ21
A29: F05 | B29: DP billing in process and DP commission receivable | C29: Open item | D29: Carry forward | E29: Carried inside F01 (dp_flag and the COMMISSION components of direct-payment invoices); no separate file. | F29: Yes | G29: No | H29: No | I29: Medium | K29: EBIX, Operations files | L29: - | M29: Part of F01; Commission DP list | N29: 8 | O29: - | P29: BRID_MIG 7.1 | Q29: DMQ19, CLR-DM-15
A30: F06 | B30: PDCs in the warehouse, check pick-ups and refunds in process | C30: Open item | D30: Conditional | E30: Proposal - carry PDCs in the warehouse; complete pick-ups and refunds in legacy before the freeze where possible (DMQ33). | F30: Yes | G30: No | H30: No | I30: Medium | J30: Proposal - carry PDCs in the warehouse; complete pick-ups and refunds in legacy before the freeze where possible. | K30: EBIX | L30: F06 | M30: Cashiering PDC warehouse and check pick-up | N30: 11 | O30: C01 | P30: BRID_MIG 5.1 | Q30: DMQ33
A31: F07 | B31: Open claims | C31: Open item | D31: Conditional | E31: Loaded through the Claims migration if BDOI decides (CLQ14, DMQ30); closed claims are archived. | F31: Yes | G31: No | H31: No | I31: Medium | J31: Loaded through the claim registration of Claims if BDOI decides (DMQ30); closed claims are archived. | K31: EBIX, ISYS | L31: - | M31: Claims, through the claims migration | N31: 14 | O31: - | P31: BRID_MIG 1.3, 14.1; CLQ14 | Q31: DMQ30, CLR-DM-08
A32: G01 | B32: GL trial balance per account, branch and currency (provisional opening; legacy TB at each true-up) | C32: GL | D32: Migrate | E32: At the year-end go-live (DMQ39, option A recommended) the BIBS GL opens from the preliminary December 2027 TB - balance-sheet accounts only, the FY2027 net result to retained earnings, legacy control-account lines to Migration Clearing, which the F01 and F02 opening entries clear to 0.00. The opening is provisional; at each true-up the legacy TB after the adjustments is sent again as reconciliation input (G03). | F32: Yes | G32: No | H32: No | I32: Medium | K32: EBIX GL, ISYS GL | L32: G01 | M32: General ledger journals of type OPENING (value date 1-Jan-2028); at a true-up, reconciliation input only | N32: 12 | O32: R08,F01,F02 | P32: BRID_MIG 1.2, 5.1-8.1, 13.1 | Q32: DMQ18, DMQ25, DMQ35, DMQ39
A33: G02 | B33: GL history (journals and balances before cutover) | C33: History | D33: Archive | E33: Kept for audit; BIBS starts from the opening trial balance. | F33: No | G33: Yes | H33: Yes | I33: Medium | K33: EBIX GL, ISYS GL | L33: H01 | M33: BIBS archive, record type GL journal | N33: 16 | O33: - | P33: BRID_MIG 11.1 | Q33: DMQ24
A34: G03 | B34: FY2027 opening-balance true-ups (legacy adjustment journals after the freeze and their open-item detail) | C34: GL | D34: Migrate | E34: The legacy GL stays open after the freeze only for the FY2027 closing and audit adjustments of Comptrollership (DMQ39). Each adjustment reaches BIBS as a controlled opening-balance adjustment journal in the opening period - after the legacy year-end close and after the audited FS - with approvals, cut-off controls and a reconciliation to the legacy TB. | F34: Yes | G34: No | H34: No | I34: Medium | K34: EBIX GL, ISYS GL; FY2027 adjustment register of Comptrollership | L34: G03, G03D | M34: General ledger journals of type OPENING (reference MIG-TU-<n>); opening adjustments of the legacy open items and unapplied payments | N34: 17 | O34: G01 | P34: BRID_MIG 1.2, 5.1-8.1, 13.1 | Q34: DMQ18, DMQ39
A35: H01 | B35: Closed transactions (paid and remitted invoices, receipts, remittances, endorsements, claims, renewal advices, letters) | C35: History | D35: Archive | E35: History stays in read-only legacy or the BIBS archive with logged access (BRID_MIG 11.1). | F35: No | G35: Yes | H35: Yes | I35: Medium | K35: EBIX, QPS, ISYS | L35: H01 | M35: BIBS archive (Legacy Inquiry) | N35: 16 | O35: - | P35: BRID_MIG 11.1 | Q35: DMQ24, DMQ27
A36: H02 | B36: Legacy documents (policies, SOAs, ORs, certificates, letters) | C36: History | D36: Archive | E36: Documents are kept with their archive record and a checksum. | F36: No | G36: Yes | H36: Yes | I36: Medium | K36: File shares, EBIX | L36: H02 | M36: Legacy documents attached to the archive records | N36: 16 | O36: - | P36: BRID_MIG 11.1 | Q36: DMQ24

Sheet Data owners
A1: Data owners
A2: Business owner and data steward of every object; BDOI names the people (DMQ01)
A4: Object | B4: Data object | C4: Business owner (proposed) | D4: Data steward (proposed) | E4: Named business owner | F4: Named data steward | G4: BU review | H4: BU comment | I4: Reviewer | J4: Review date
A5: R01 | B5: Lists of values and MIS values | C5: Product Owner, Marketing Business System (MBS) | D5: MBS data steward (to name)
A6: R02 | B6: Branches and invoicing branches | C6: Head, Comptrollership | D6: Comptrollership data steward (to name)
A7: R03 | B7: Sales organisation (regions, departments, teams, unit heads, account officers) | C7: Heads, Retail and Corporate Marketing | D7: Marketing data steward (to name)
A8: R04 | B8: Insurers and insurer branches | C8: Head, Operations | D8: Operations data steward (to name)
A9: R05 | B9: Product lines, cover types, products and risk codes | C9: Product Owner, MBS | D9: MBS data steward (to name)
A10: R06 | B10: Package code map (legacy package and version to BIBS package version) | C10: Product Owner, MBS (approves); TSU (prepares) | D10: TSU (to name)
A11: R07 | B11: Commission rates by insurer and product | C11: Head, Operations | D11: Operations data steward (to name)
A12: R08 | B12: Chart of accounts mapping (legacy GL account to BIBS account) | C12: Head, Comptrollership; Product Owner FRBS and ACSL | D12: Comptrollership data steward (to name)
A13: R09 | B13: Payees | C13: Product Owner, Comptrollership - Disbursement | D13: Disbursement data steward (to name)
A14: R11 | B14: Receipt series in use (AR and OR, ATP and next number) | C14: Operations - Financial Transactions | D14: Cashiering data steward (to name)
A15: C01 | B15: Client master (individual and corporate) | C15: Product Owner, MBS; Heads, Retail and Corporate Marketing | D15: Marketing data steward (to name)
A16: C03 | B16: Client payout accounts (for refunds) | C16: Product Owner, Comptrollership - Disbursement | D16: Disbursement data steward (to name)
... A34: H02 | B34: Legacy documents (policies, SOAs, ORs, certificates, letters) | C34: Audit / Compliance | D34: Compliance data steward (to name)

Sheet Extract planning
A1: Extract planning
A2: What BDOI extracts per object, how much, how far back and by when
A4: Object | B4: Data object | C4: Volume (BDOI to fill) | D4: Planning bound | E4: History depth | F4: Delta frequency | G4: Format | H4: Control totals | I4: Due | J4: BU review | K4: BU comment | L4: Reviewer | M4: Review date
A5: R01 | B5: Lists of values and MIS values | D5: A few thousand values | E5: Current values and values used by any migrated record | F5: None after the map freeze (T-7 days); changes by change request and a new map version | G5: CSV | H5: Row count; count of distinct (list_type, code) | I5: M3 (29 Jan 2027)
A6: R02 | B6: Branches and invoicing branches | D6: Under 100 | E6: Current | F6: None | G6: CSV | H6: Row count | I6: M3 (29 Jan 2027)
A7: R03 | B7: Sales organisation (regions, departments, teams, unit heads, account officers) | D7: About 600 AOs (485 Marketing users, BRD-3) | E7: Current, plus inactive AOs referenced by open items | F7: Weekly until the freeze | G7: CSV | H7: Row count per record type | I7: M3 (29 Jan 2027)
A8: R04 | B8: Insurers and insurer branches | D8: Under 100 insurers | E8: Active insurers, and inactive insurers with open items | F8: None | G8: CSV | H8: Row count per file | I8: M3 (29 Jan 2027)
A9: R05 | B9: Product lines, cover types, products and risk codes | D9: A few hundred codes | E9: Current, plus codes used by in-force policies and open items | F9: None | G9: CSV | H9: Row count | I9: M3 (29 Jan 2027)
A10: R06 | B10: Package code map (legacy package and version to BIBS package version) | D10: Under 200 legacy packages | E10: Legacy packages of in-force policies | F10: New map versions until the map freeze (T-7 days) | G10: XLSX or CSV | H10: Row count; count of distinct (legacy_package_code, legacy_package_version) | I10: M5 (18 Jun 2027); final at T-7
A11: R07 | B11: Commission rates by insurer and product | D11: Insurers x products | E11: Rates effective at cutover and later | F11: None | G11: CSV | H11: Row count | I11: M3 (29 Jan 2027)
A12: R08 | B12: Chart of accounts mapping (legacy GL account to BIBS account) | D12: A few thousand accounts | E12: Current chart | F12: None | G12: XLSX or CSV | H12: Row count | I12: M3 (29 Jan 2027)
A13: R09 | B13: Payees | D13: To supply | E13: Active payees | F13: None | G13: CSV | H13: Row count | I13: M3 (29 Jan 2027)
A14: R11 | B14: Receipt series in use (AR and OR, ATP and next number) | D14: One per branch and kind | E14: Series in use at the freeze | F14: Final values at the freeze (T-3) | G14: CSV | H14: Row count | I14: M3 (29 Jan 2027); final at T-3
A15: C01 | B15: Client master (individual and corporate) | D15: Loaders sized for 1,000,000 rows | E15: Clients from 2020 to present (umbrella p.43); filter per DMQ05 | F15: Daily new and changed clients from T-14 days until the freeze | G15: CSV | H15: Row count; count of distinct legacy_client_no | I15: M3 (29 Jan 2027); deltas daily from T-14 days
A16: C03 | B16: Client payout accounts (for refunds) | D16: To supply | E16: Active accounts | F16: None | G16: CSV | H16: Row count | I16: M3 (29 Jan 2027)
... A30: H02 | B30: Legacy documents (policies, SOAs, ORs, certificates, letters) | D30: To supply | E30: Per retention | F30: None | G30: CSV index plus files | H30: Row count; SHA-256 per file | I30: Before decommissioning

Sheet Milestones
A1: Milestones
A2: Milestones used in the Due and Needed-by columns
A4: Milestone | B4: What is due | C4: When
A5: M0 | B5: Business sign-off set issued to BDOI (release set v2.0, with the BDOI answers to DMQ36-DMQ39) | C5: 5 Oct 2026
A6: M1 | B6: Scope-shaping decisions (answers that change the migration functions) | C6: 16 Oct 2026
A7: M2 | B7: Owners, stewards, keys and remaining business rules; object decisions signed (gate G1); layouts frozen, version 1 (G2 part 1) - end of requirements and mapping | C7: 30 Oct 2026
A8: M3 | B8: First full extracts in the templates, with control files and volumes (profiling, performance sizing) | C8: 29 Jan 2027
A9: M4 | B9: Extracts for Trial migration 1 (SIT migration starts); reference data and clients first | C9: 9 Apr 2027
A10: M5 | B10: Code maps approved for Trial migration 2 (G2), including the package code map | C10: 18 Jun 2027
A11: M6 | B11: Cut-over date and window, fallback and decommissioning criteria agreed; Comptrollership confirms the year-end option A (DMQ39) | C11: 1 Oct 2027

Sheet File rules
A1: File rules
A2: Rules of every extract and control file: the delivery rules of the console workbook, then the rules of the migration
A4: Topic | B4: Rule | C4: BU review | D4: BU comment | E4: Reviewer | F4: Review date
A5: File name | B5: <LAYOUT>_<SOURCE>_<yyyyMMdd>_<nn>.xlsx or .csv, for example F01C_EBIX_20271231_01.xlsx: the layout code, the source system, the as-of date and the sequence of the day
A6: One file per | B6: Layout, source system and extract; an object with several layouts sends one file per layout with the same as-of date
A7: Excel | B7: The load template of the console, uploaded as it is: its guide rows and example row are skipped and the sheet of the layout is read; a workbook of several layouts is uploaded once per layout, named after that layout. A plain workbook has the header in row 1 of its first sheet, no merged cells, no formulas
A8: CSV | B8: For large extracts: UTF-8 without byte order mark, comma separator, double quotes around values that hold a comma, a quote or a line break, one header row with the column names exactly as in the template
A9: Values | B9: Dates as Excel dates or yyyy-MM-dd; timestamps yyyy-MM-dd HH:mm:ss (Philippine time); amounts with a dot decimal, 2 decimals, no thousands separator, minus sign for negatives; currency ISO 4217; codes exactly as stored in the legacy system; blank means no value
A10: Control file | B10: <data file name>.ctl.xlsx or .ctl.csv in the control layout: the row count, the hash total of the key column, the total of each amount column per currency and the SHA-256 of the data file, one row per measure
A11: Delivery | B11: Upload the data file and its control file together on the Extracts screen of the Migration Console; never by e-mail
A12: Checks | B12: A file whose checksum, header, row count, amount totals or hash total does not agree with its control file is rejected with the reason; nothing of it is loaded
A13: Personal data | B13: Production extracts are loaded only in production. Every other environment receives masked data: names, addresses, TIN, ID, account and phone numbers, e-mail addresses and birth dates are masked when the file is received. Staged rows and files are deleted within 5 days of the batch sign-off
A14: Layout changes | B14: A layout is frozen at gate G2. A file whose header does not match the layout in force is rejected. A change of layout is a new layout version agreed with the Data Migration Lead
A15: Load template workbook of P03 | B15: The Renewal processing team may send the RA-sent file in the load template workbook of layout P03 exported by the Migration Console (the template sheet with the guide rows Mandatory, Format, Allowed values and What to enter directly above the header row, and the Lists sheet with the allowed values); the CSV template is also accepted

Sheet Load templates
A3: Load templates – start here
A4: The extract layouts in force, in load order, each with its sheet
A6: Client | C6: BDO Insurance and Reinsurance Brokers, Inc.
A7: Release set | C7: BRD-13 Data Migration (Drop 0, Setup and Data Migration)
A8: Version and date | C8: Version 2.1, 8 October 2026
A9: Owner | C9: Program Manager, Business Project Services (Data Migration)
A10: Due | C10: Per object: the Due of the index (milestones on the sheet Milestones)
A12: How to fill in this workbook
A13: 1 | B13: The index below lists the load templates in load order: reference data first, then clients, policies, open items, the general ledger and the archive. Each template has a sheet of its own, named as in the workbook the Migration Console exports (Layouts and Rules); the extracts are sent as CSV files with their control file (sheets File rules and Control file).
A14: 2 | B14: On a template sheet, the header block says what one row holds, who provides it, when it is due and how it is loaded; above each column the guide gives Mandatory, Format (type and length), Allowed values or the code map, What to enter and the check applied when the file is loaded. The header row is the header row of the file; * marks a mandatory column.
A15: 3 | B15: Review each column: set BU review (Accept, Change requested or Comment) and write the change in BU comment, in the two rows above the guide; record your name and the date in Reviewed by and Review date.
A16: 4 | B16: The grey example row is made up. Test rows may be entered under it for the review: the drop-downs offer the allowed values (sheet Reference lists) and a mandatory cell left empty turns red.
A17: 5 | B17: Set the Status of each template in the index. Questions go to the Comments log with the template and the column.
A19: Load templates in load order
A20: Step | B20: Layout | C20: Object | D20: Content | E20: Provided by | F20: Due | G20: Decision | H20: Loads after | I20: Columns | J20: Mandatory | K20: Key | L20: File | M20: Rows entered | N20: Mandatory cells missing | O20: Status | P20: Open
A21: 1 | B21: R01 | C21: R01 | D21: Lists of values and MIS values | E21: MBS data steward (to name); approved by Product Owner, Marketing Business System (MBS); extracted by BDOI IT | F21: M3 (29 Jan 2027) | G21: Migrate | H21: - | I21: 8 | J21: 4 | K21: list_type, code | L21: R01_template.csv | M21: ='R01 Lists of values and MIS val'!$C$9 | N21: ='R01 Lists of values and MIS val'!$E$9 | O21: Not started | P21: Open →
A22: 2 | B22: R02 | C22: R02 | D22: Branches and invoicing branches | E22: Comptrollership data steward (to name); approved by Head, Comptrollership; extracted by BDOI IT | F22: M3 (29 Jan 2027) | G22: Migrate | H22: - | I22: 5 | J22: 4 | K22: branch_code | L22: R02_template.csv | M22: ='R02 Branches and invoicing bran'!$C$9 | N22: ='R02 Branches and invoicing bran'!$E$9 | O22: Not started | P22: Open →
A23: 3 | B23: R03 | C23: R03 | D23: Sales organisation (units and account officers) | E23: Marketing data steward (to name); approved by Heads, Retail and Corporate Marketing; extracted by BDOI IT | F23: M3 (29 Jan 2027) | G23: Migrate | H23: R02 | I23: 11 | J23: 3 | K23: record_type, unit_code, ao_user_id | L23: R03_template.csv | M23: ='R03 Sales organisation (units a'!$C$9 | N23: ='R03 Sales organisation (units a'!$E$9 | O23: Not started | P23: Open →
A24: 4 | B24: R04 | C24: R04 | D24: Insurers | E24: Operations data steward (to name); approved by Head, Operations; extracted by BDOI IT | F24: M3 (29 Jan 2027) | G24: Migrate | H24: - | I24: 10 | J24: 3 | K24: insurer_code | L24: R04_template.csv | M24: ='R04 Insurers'!$C$9 | N24: ='R04 Insurers'!$E$9 | O24: Not started | P24: Open →
A25: 5 | B25: R04B | C25: R04 | D25: Insurer branches | E25: Operations data steward (to name); approved by Head, Operations; extracted by BDOI IT | F25: M3 (29 Jan 2027) | G25: Migrate | H25: R04 | I25: 7 | J25: 4 | K25: insurer_code, branch_code | L25: R04B_template.csv | M25: ='R04B Insurer branches'!$C$9 | N25: ='R04B Insurer branches'!$E$9 | O25: Not started | P25: Open →
A26: 6 | B26: R05 | C26: R05 | D26: Product lines, cover types, products and risk codes | E26: MBS data steward (to name); approved by Product Owner, MBS; extracted by BDOI IT | F26: M3 (29 Jan 2027) | G26: Migrate | H26: - | I26: 9 | J26: 4 | K26: risk_code | L26: R05_template.csv | M26: ='R05 Product lines, cover types,'!$C$9 | N26: ='R05 Product lines, cover types,'!$E$9 | O26: Not started | P26: Open →
A27: 7 | B27: R06 | C27: R06 | D27: Package code map (legacy package to BIBS package version) | E27: TSU (to name); approved by Product Owner, MBS (approves); TSU (prepares); extracted by BDOI IT | F27: M5 (18 Jun 2027); final at T-7 | G27: Migrate | H27: - | I27: 8 | J27: 4 | K27: legacy_package_code, legacy_package_version, qualifier, qualifier_value | L27: R06_template.csv | M27: ='R06 Package code map (legacy pa'!$C$9 | N27: ='R06 Package code map (legacy pa'!$E$9 | O27: Not started | P27: Open →
A28: 8 | B28: R07 | C28: R07 | D28: Commission rates by insurer and product | E28: Operations data steward (to name); approved by Head, Operations; extracted by BDOI IT | F28: M3 (29 Jan 2027) | G28: Migrate | H28: R04, R04B | I28: 5 | J28: 4 | K28: insurer_code, risk_code, effective_from | L28: R07_template.csv | M28: ='R07 Commission rates by insurer'!$C$9 | N28: ='R07 Commission rates by insurer'!$E$9 | O28: Not started | P28: Open →
A29: 9 | B29: R08 | C29: R08 | D29: Chart of accounts mapping | E29: Comptrollership data steward (to name); approved by Head, Comptrollership; Product Owner FRBS and ACSL; extracted by BDOI IT | F29: M3 (29 Jan 2027) | G29: Migrate | H29: - | I29: 8 | J29: 4 | K29: legacy_account_code | L29: R08_template.csv | M29: ='R08 Chart of accounts mapping'!$C$9 | N29: ='R08 Chart of accounts mapping'!$E$9 | O29: Not started | P29: Open →
A30: 10 | B30: R09 | C30: R09 | D30: Payees | E30: Disbursement data steward (to name); approved by Product Owner, Comptrollership - Disbursement; extracted by BDOI IT | F30: M3 (29 Jan 2027) | G30: Conditional | H30: - | I30: 11 | J30: 6 | K30: payee_code | L30: R09_template.csv | M30: ='R09 Payees'!$C$9 | N30: ='R09 Payees'!$E$9 | O30: Not started | P30: Open →
A31: 11 | B31: R11 | C31: R11 | D31: Receipt series in use | E31: Cashiering data steward (to name); approved by Operations - Financial Transactions; extracted by BDOI IT | F31: M3 (29 Jan 2027); final at T-3 | G31: Carry forward | H31: R02 | I31: 8 | J31: 7 | K31: branch_code, kind, prefix | L31: R11_template.csv | M31: ='R11 Receipt series in use'!$C$9 | N31: ='R11 Receipt series in use'!$E$9 | O31: Not started | P31: Open →
A32: 12 | B32: C01 | C32: C01 | D32: Client master | E32: Marketing data steward (to name); approved by Product Owner, MBS; Heads, Retail and Corporate Marketing; extracted by BDOI IT | F32: M3 (29 Jan 2027); deltas daily from T-14 days | G32: Migrate | H32: R01, R02, R03 | I32: 36 | J32: 6 | K32: legacy_client_no | L32: C01_template.csv | M32: ='C01 Client master'!$C$9 | N32: ='C01 Client master'!$E$9 | O32: Not started | P32: Open →
A33: 13 | B33: C02 | C33: C01 | D33: Client addresses and contacts | E33: Marketing data steward (to name); approved by Product Owner, MBS; Heads, Retail and Corporate Marketing; extracted by BDOI IT | F33: M3 (29 Jan 2027); deltas daily from T-14 days | G33: Migrate | H33: C01, R01, R02, R03 | I33: 13 | J33: 4 | K33: legacy_client_no, record_type, seq_no | L33: C02_template.csv | M33: ='C02 Client addresses and contac'!$C$9 | N33: ='C02 Client addresses and contac'!$E$9 | O33: Not started | P33: Open →
A34: 14 | B34: C03 | C34: C03 | D34: Client payout accounts | E34: Disbursement data steward (to name); approved by Product Owner, Comptrollership - Disbursement; extracted by BDOI IT | F34: M3 (29 Jan 2027) | G34: Migrate | H34: C01, C02 | I34: 6 | J34: 4 | K34: legacy_client_no, account_no | L34: C03_template.csv | M34: ='C03 Client payout accounts'!$C$9 | N34: ='C03 Client payout accounts'!$E$9 | O34: Not started | P34: Open →
A35: 15 | B35: P01 | C35: P01 | D35: In-force policy headers | E35: Operations data steward (to name); approved by Head, Operations; extracted by BDOI IT | F35: M3 (29 Jan 2027); final at T-2 | G35: Conditional | H35: C01, C02, R04, R04B, R05 | I35: 31 | J35: 20 | K35: legacy_policy_ref | L35: P01_template.csv | M35: ='P01 In-force policy headers'!$C$9 | N35: ='P01 In-force policy headers'!$E$9 | O35: Not started | P35: Open →
A36: 16 | B36: P01S | C36: P01 | D36: Policy insurer shares | E36: Operations data steward (to name); approved by Head, Operations; extracted by BDOI IT | F36: M3 (29 Jan 2027); final at T-2 | G36: Conditional | H36: P01, C01, C02, R04, R04B, R05 | I36: 6 | J36: 5 | K36: legacy_policy_ref, share_seq | L36: P01S_template.csv | M36: ='P01S Policy insurer shares'!$C$9 | N36: ='P01S Policy insurer shares'!$E$9 | O36: Not started | P36: Open →
A37: 17 | B37: F01 | C37: F01 | D37: Open legacy invoices - header | E37: Operations data steward (to name); approved by Operations - Financial Transactions; Head, Comptrollership; extracted by BDOI IT | F37: M3 (29 Jan 2027); final at T-2 | G37: Carry forward | H37: C01, C02, R04, R04B, R05, P01, P01S | I37: 38 | J37: 24 | K37: legacy_invoice_no | L37: F01_template.csv | M37: ='F01 Open legacy invoices - head'!$C$9 | N37: ='F01 Open legacy invoices - head'!$E$9 | O37: Not started | P37: Open →
A38: 18 | B38: F01C | C38: F01 | D38: Open legacy invoices - components and positions | E38: Operations data steward (to name); approved by Operations - Financial Transactions; Head, Comptrollership; extracted by BDOI IT | F38: M3 (29 Jan 2027); final at T-2 | G38: Carry forward | H38: F01, C01, C02, R04, R04B, R05, P01, P01S | I38: 8 | J38: 8 | K38: legacy_invoice_no, component | L38: F01C_template.csv | M38: ='F01C Open legacy invoices - com'!$C$9 | N38: ='F01C Open legacy invoices - com'!$E$9 | O38: Not started | P38: Open →
A39: 19 | B39: F01S | C39: F01 | D39: Open legacy invoices - insurer shares | E39: Operations data steward (to name); approved by Operations - Financial Transactions; Head, Comptrollership; extracted by BDOI IT | F39: M3 (29 Jan 2027); final at T-2 | G39: Carry forward | H39: F01, C01, C02, R04, R04B, R05, P01, P01S | I39: 5 | J39: 5 | K39: legacy_invoice_no, share_seq | L39: F01S_template.csv | M39: ='F01S Open legacy invoices - ins'!$C$9 | N39: ='F01S Open legacy invoices - ins'!$E$9 | O39: Not started | P39: Open →
A40: 20 | B40: F02 | C40: F02 | D40: Unapplied premium payments (UPP) | E40: Cashiering data steward (to name); approved by Operations - Financial Transactions; extracted by BDOI IT | F40: M3 (29 Jan 2027); final at T-2 | G40: Carry forward | H40: C01, C02 | I40: 21 | J40: 11 | K40: legacy_upp_ref | L40: F02_template.csv | M40: ='F02 Unapplied premium payments'!$C$9 | N40: ='F02 Unapplied premium payments'!$E$9 | O40: Not started | P40: Open →
A41: 21 | B41: F03 | C41: F03 | D41: Open collection state | E41: Collections data steward (to name); approved by Head, Operations (Collections); extracted by BDOI IT | F41: M3 (29 Jan 2027); final at T-2 | G41: Carry forward | H41: F01, F01S, F01C | I41: 12 | J41: 3 | K41: legacy_invoice_no, record_type, seq_no | L41: F03_template.csv | M41: ='F03 Open collection state'!$C$9 | N41: ='F03 Open collection state'!$E$9 | O41: Not started | P41: Open →
A42: 22 | B42: F04 | C42: F04 | D42: Remittance in flight | E42: Remittance data steward (to name); approved by Operations - Remittance; extracted by BDOI IT | F42: M3 (29 Jan 2027); final at T-2 | G42: Conditional | H42: F01, F01S, F01C | I42: 10 | J42: 6 | K42: legacy_batch_no, legacy_invoice_no | L42: F04_template.csv | M42: ='F04 Remittance in flight'!$C$9 | N42: ='F04 Remittance in flight'!$E$9 | O42: Not started | P42: Open →
A43: 23 | B43: F06 | C43: F06 | D43: PDCs, check pick-ups and refunds in process | E43: Cashiering data steward (to name); approved by Operations - Cashiering; extracted by BDOI IT | F43: M3 (29 Jan 2027); final at T-2 | G43: Conditional | H43: C01, C02 | I43: 14 | J43: 6 | K43: record_type, reference | L43: F06_template.csv | M43: ='F06 PDCs, check pick-ups and re'!$C$9 | N43: ='F06 PDCs, check pick-ups and re'!$E$9 | O43: Not started | P43: Open →
A44: 24 | B44: G01 | C44: G01 | D44: GL opening trial balance | E44: Comptrollership data steward (to name); approved by Head, Comptrollership; extracted by BDOI IT | F44: M3 (29 Jan 2027); final at T-2; at each true-up | G44: Migrate | H44: R08, F01, F01S, F01C, F02 | I44: 11 | J44: 9 | K44: tb_version, branch_code, currency, legacy_account_code, cost_center | L44: G01_template.csv | M44: ='G01 GL opening trial balance'!$C$9 | N44: ='G01 GL opening trial balance'!$E$9 | O44: Not started | P44: Open →
A45: 25 | B45: P03 | C45: P03 | D45: Renewal advices already sent before go-live (RA-sent file) | E45: Renewal processing team - makers (corrections) and checkers (resubmission approval); approved by Head of the Renewal processing team; extracted by BDOI IT | F45: M4 (9 Apr 2027) (Trial migration 1); final at T-5 | G45: Migrate | H45: P01, P01S | I45: 13 | J45: 6 | K45: legacy_policy_ref | L45: P03_template.csv | M45: ='P03 Renewal advices already sen'!$C$9 | N45: ='P03 Renewal advices already sen'!$E$9 | O45: Not started | P45: Open →
...

Sheet R01 Lists of values and MIS val
A1: R01 Lists of values and MIS values | I1: Step 1 of 29
A2: ← Back to Load templates | B2: Step 1 of 29. Fill in one row per record below the column headers; the guide above each column says what to enter. | I2: Ask a question →
A3: Purpose | B3: One row per record of Lists of values and MIS values as extracted from QPS, EBIX. Key list_type, code. Sent as the file R01_template.csv (CSV, header row as below) with its control file (row count, count of distinct keys).
A4: Provided by | B4: MBS data steward (to name); approved by Product Owner, Marketing Business System (MBS); extracted by BDOI IT
A5: Due | B5: M3 (29 Jan 2027)
A6: How it is loaded | B6: Data migration object R01 (Migrate), layout R01 version 1, through the Migration Console; lands in: Lists of Values (maker-checker); MIS field catalogue
A7: Source | B7: QPS, EBIX
A8: Depends on | B8: Nothing: this template can be filled in first
A9: Progress | B9: Rows entered | C9: =SUMPRODUCT(((ROW($B$20:$B$220)>20)+($B$20<>"MARKET_SEGMENT")>0)*(LEN($B$20:$B$220&$C$20:$C$220&$D$20:$D$220&$E$20:$E$220&$F$20:$F$220&$G$20:$G$220&$H$20:$H$220&$I$20:$I$220)>0)) | D9: Mandatory cells missing | E9: =SUMPRODUCT(((ROW($B$20:$B$220)>20)+($B$20<>"MARKET_SEGMENT")>0)*(LEN($B$20:$B$220&$C$20:$C$220&$D$20:$D$220&$E$20:$E$220&$F$20:$F$220&$G$20:$G$220&$H$20:$H$220&$I$20:$I$220)>0)*(($B$20:$B$220="")+($C$20:$C$220="")+($D$20:$D$220="")+($F$20:$F$220="")))
A10: Reviewed by (BU reviewer) | D10: Review date
A12: BU review
A13: BU comment
A14: Check when loaded | B14: Known list name | C14: Unique per list_type | D14: Not blank | E14: Parent exists in the file | F14: Y or N | G14: Valid date | H14: Not before effective_from | I14: 0 or more
A15: Mandatory | B15: Yes | C15: Yes | D15: Yes | E15: No | F15: Yes | G15: No | H15: No | I15: No
A16: Format | B16: Code, up to 40; Upper case | C16: Code, up to 40; As stored in legacy | D16: Text, up to 200; Free text | E16: Code, up to 40 | F16: Flag, up to 1; Y or N | G16: Date, up to 10; yyyy-MM-dd | H16: Date, up to 10; yyyy-MM-dd | I16: Integer, up to 9; Digits
A17: Allowed values | B17: Legacy list names; one code map set LOV:<list> or MIS:<field> per list | C17: Free entry, up to 40 characters | D17: Free entry, up to 200 characters | E17: Codes of the same file | F17: Y or N | G17: Free entry | H17: Free entry | I17: A whole number
A18: What to enter | B18: Legacy name of the list (for example MARKET_SEGMENT, BUSINESS_ORIGIN, CUSTOMER_SEGMENT, REGION, AREA, DEPARTMENT, ACCOUNT_TYPE, ID_TYPE, NATIONALITY) | C18: Legacy value code | D18: Legacy value description | E18: Code of the parent value for hierarchical lists (area under region) | F18: Value in use in legacy | G18: First day the value is valid | H18: Last day the value is valid | I18: Number of legacy records that use the value (helps the mapping)
A19: Row | B19: list_type * | C19: code * | D19: description * | E19: parent_code | F19: active_flag * | G19: effective_from | H19: effective_to | I19: used_count
A20: Example – overwrite or delete | B20: MARKET_SEGMENT | C20: CBG | D20: Consumer Banking Group | E20: NCR | F20: Y | G20: 2020-01-01 | I20: 1520

Sheet R02 Branches and invoicing bran
A1: R02 Branches and invoicing branches | G1: Step 2 of 29
A2: ← Back to Load templates | B2: Step 2 of 29. Fill in one row per record below the column headers; the guide above each column says what to enter. | G2: Ask a question →
A3: Purpose | B3: One row per record of Branches and invoicing branches as extracted from EBIX. Key branch_code. Sent as the file R02_template.csv (CSV, header row as below) with its control file (row count, count of distinct keys).
A4: Provided by | B4: Comptrollership data steward (to name); approved by Head, Comptrollership; extracted by BDOI IT
A5: Due | B5: M3 (29 Jan 2027)
A6: How it is loaded | B6: Data migration object R02 (Migrate), layout R02 version 1, through the Migration Console; lands in: Branches (check only, code map BRANCH)
A7: Source | B7: EBIX
A8: Depends on | B8: Nothing: this template can be filled in first
A9: Progress | B9: Rows entered | C9: =SUMPRODUCT(((ROW($B$20:$B$220)>20)+($B$20<>"MKT01")>0)*(LEN($B$20:$B$220&$C$20:$C$220&$D$20:$D$220&$E$20:$E$220&$F$20:$F$220)>0)) | D9: Mandatory cells missing | E9: =SUMPRODUCT(((ROW($B$20:$B$220)>20)+($B$20<>"MKT01")>0)*(LEN($B$20:$B$220&$C$20:$C$220&$D$20:$D$220&$E$20:$E$220&$F$20:$F$220)>0)*(($B$20:$B$220="")+($C$20:$C$220="")+($D$20:$D$220="")+($F$20:$F$220="")))
A10: Reviewed by (BU reviewer) | D10: Review date
A12: BU review
A13: BU comment
A14: Check when loaded | B14: Unique | C14: Not blank | D14: Y or N | E14: - | F14: Y or N
A15: Mandatory | B15: Yes | C15: Yes | D15: Yes | E15: No | F15: Yes
A16: Format | B16: Code, up to 20; As stored in legacy | C16: Text, up to 120; Free text | D16: Flag, up to 1; Y or N | E16: Text, up to 80; Free text | F16: Flag, up to 1; Y or N
A17: Allowed values | B17: Free entry, up to 20 characters | C17: Free entry, up to 120 characters | D17: Y or N | E17: Free entry, up to 80 characters | F17: Y or N
A18: What to enter | B18: Legacy branch code | C18: Branch name | D18: Branch issues invoices and receipts | E18: City of the branch | F18: Branch active in legacy
A19: Row | B19: branch_code * | C19: branch_name * | D19: invoicing_branch_flag * | E19: city | F19: active_flag *
A20: Example – overwrite or delete | B20: MKT01 | C20: Makati Head Office | D20: Y | E20: Makati City | F20: Y

Sheet R03 Sales organisation (units a
A1: R03 Sales organisation (units and account officers) | L1: Step 3 of 29
A2: ← Back to Load templates | B2: Step 3 of 29. Fill in one row per record below the column headers; the guide above each column says what to enter. | L2: Ask a question →
A3: Purpose | B3: One row per record of Sales organisation (regions, departments, teams, unit heads, account officers) as extracted from QPS, EBIX. Key record_type, unit_code, ao_user_id. Sent as the file R03_template.csv (CSV, header row as below) with its control file (row count, row count).
A4: Provided by | B4: Marketing data steward (to name); approved by Heads, Retail and Corporate Marketing; extracted by BDOI IT
A5: Due | B5: M3 (29 Jan 2027)
A6: How it is loaded | B6: Data migration object R03 (Migrate), layout R03 version 1, through the Migration Console; lands in: Sales organisation: sales units and account officers
A7: Source | B7: QPS, EBIX
A8: Depends on | B8: R02 Branches and invoicing branches →
A9: Progress | B9: Rows entered | C9: =SUMPRODUCT(((ROW($B$20:$B$220)>20)+($B$20<>"TEAM")>0)*(LEN($B$20:$B$220&$C$20:$C$220&$D$20:$D$220&$E$20:$E$220&$F$20:$F$220&$G$20:$G$220&$H$20:$H$220&$I$20:$I$220&$J$20:$J$220&$K$20:$K$220&$L$20:$L$220)>0)) | D9: Mandatory cells missing | E9: =SUMPRODUCT(((ROW($B$20:$B$220)>20)+($B$20<>"TEAM")>0)*(LEN($B$20:$B$220&$C$20:$C$220&$D$20:$D$220&$E$20:$E$220&$F$20:$F$220&$G$20:$G$220&$H$20:$H$220&$I$20:$I$220&$J$20:$J$220&$K$20:$K$220&$L$20:$L$220)>0)*(($B$20:$B$220="")+($C$20:$C$220="")+($L$20:$L$220="")))
A10: Reviewed by (BU reviewer) | D10: Review date
A12: BU review
A13: BU comment
A14: Check when loaded | B14: In the list | C14: Exists as a TEAM row for AO rows | D14: Mandatory for REGION, DEPARTMENT, TEAM | E14: Mandatory for DEPARTMENT and TEAM; parent exists | F14: Mapped in USER | G14: Mapped | H14: Mandatory for AO rows; mapped in USER | I14: Unique | J14: Mandatory for AO rows | K14: Mapped | L14: Y or N
A15: Mandatory | B15: Yes | C15: Yes | D15: Conditional: Mandatory for REGION, DEPARTMENT, TEAM | E15: Conditional: Mandatory for DEPARTMENT and TEAM; parent exists | F15: No | G15: No | H15: Conditional: Mandatory for AO rows; mapped in USER | I15: No | J15: Conditional: Mandatory for AO rows | K15: No | L15: Yes
A16: Format | B16: Code, up to 12; Upper case | C16: Code, up to 20; As stored in legacy | D16: Text, up to 120; Free text | E16: Code, up to 20; As stored in legacy | F16: Code, up to 50; As stored in legacy | G16: Code, up to 20; As stored in legacy | H16: Code, up to 50; As stored in legacy | I16: Code, up to 20; As stored in legacy | J16: Text, up to 120; Free text | K16: Code, up to 20; As stored in legacy | L16: Flag, up to 1; Y or N
A17: Allowed values | B17: REGION, DEPARTMENT, TEAM, AO (list R03 record_type) | C17: Free entry, up to 20 characters | D17: Free entry, up to 120 characters | E17: unit_code values of the file | F17: The legacy code; mapped by the code map USER (sheet Code maps) | G17: The legacy code; mapped by the code map COST_CENTER (sheet Code maps) | H17: The legacy code; mapped by the code map USER (sheet Code maps) | I17: The legacy code; mapped by the code map AO (sheet Code maps) | J17: Free entry, up to 120 characters | K17: The legacy code; mapped by the code map BRANCH (sheet Code maps) | L17: Y or N
A18: What to enter | B18: Kind of row | C18: Legacy code of the unit (for an AO row, the team of the AO) | D18: Unit name | E18: Code of the parent unit (department of a team, region of a department) | F18: Legacy user ID of the unit head | G18: Cost centre of the unit | H18: Legacy user ID of the account officer | I18: Legacy AO code if different from the user ID | J18: AO full name | K18: Branch of the unit or AO | L18: Unit or AO active
