Workbook

Sheet Cover
B6: REGISTER
B7: BRD Discrepancy and Clarification Register
B8: Discrepancies, conflicts, gaps and points for clarification in the BRDs (BRD-00 to BRD-13) and the Report List
B9: BIBS – BDOI Broker System
B11: Client | C11: BDO Insurance and Reinsurance Brokers, Inc.
B12: BRD | C12: BRD-00
B13: Version | C13: 1.2
B14: Date | C14: 26 September 2026
B15: Classification | C15: Confidential
B16: Prepared by | C16: iorta TechNXT
B18: Sheets
B19: Sheet | C19: Content | D19: Rows
B20: README | C20: What each column of each sheet means, with the allowed values
B21: Summary | C21: Counts by BRD, type and severity; status pivot; items to resolve first
B22: Register | C22: One row per discrepancy, conflict, gap or clarification. Filter on BRD, drop, type, severity or status. | D22: 239
B23: Open questions | C23: Every open question of the specs, with its status, the consolidated question and the register items. | D23: 453
B24: NFR comparison | C24: Every NFR theme against each BRD's value. Conflicting rows are highlighted; grey cells: not stated or 'follow QPS'. | D24: 18
B26: Legend
B27: Open | C27: Waiting for a BDOI answer
B28: Answered | C28: A signed BDOI document answers the item; BDOI confirms to close
B29: Closed | C29: BDOI confirmed the resolution
B31: Severity rule, types and status values: see the README sheet.
B32: Page numbers are PDF pages of the source files in docs/source-documents.
B33: The CSF pack holds meeting credentials in an attached e-mail (DCR-098); they are not copied here.
B35: Prepared by iorta TechNXT for BDOI. Confidential – BDOI.

Sheet README
A1: README – columns of each sheet
A2: BRD Discrepancy and Clarification Register, version 1.2. Drop-down columns accept only the listed values.
A4: Sheet | B4: Column | C4: Meaning | D4: Allowed values
A5: Register | B5: Ref | C5: Register reference DCR-nnn. Stable: a new item gets the next number.
A6: Register | B6: BRD(s) involved | C6: BRDs the item involves (BRD-n and short name; Report List where relevant). Several BRDs are separated by semicolons.
A7: Register | B7: Drop | C7: BDOI drop in which the item is resolved: Drop 0 (setup and data migration), Drop 1 (transactional), Drop 2 (independent), Programme (platform-wide) or Phase 2 (outside the January 2028 scope). Default: the earliest drop of the BRDs involved. | D7: Drop 0, Drop 1, Drop 2, Programme, Phase 2
A8: Register | B8: BRD ID / section / page | C8: Requirement ID, section and PDF page of the source file in docs/source-documents, for each BRD involved.
A9: Register | B9: Type | C9: Kind of issue (definitions below). | D9: Contradiction within BRD, Conflict between BRDs, Gap / missing detail, Ambiguity, BRD vs platform, NFR inconsistency, Data / numbering issue, Document quality
A10: Register | B10: Description | C10: What the BRD says, with the conflicting statements quoted briefly.
A11: Register | B11: Impact (business / build / test) | C11: Effect on the business process, on what is built, and on testing.
A12: Register | B12: Severity | C12: High, Medium or Low (rule below). | D12: High, Medium, Low
A13: Register | B13: Affected modules | C13: BIBS modules affected.
A14: Register | B14: Proposed resolution / recommendation | C14: What the project proposes, and builds as the default until BDOI answers.
A15: Register | B15: Clarification question to BDOI | C15: The question BDOI is asked to answer.
A16: Register | B16: Owner (BDOI) | C16: BDOI business unit that owns the answer, from the BRD approval sheets. Items involving several BRDs go to the BIBS Product Owner with the owners involved.
A17: Register | B17: Raised on | C17: Date the item was raised.
A18: Register | B18: Status | C18: Open, Answered or Closed (rule below). | D18: Open, Answered, Closed
A19: Register | B19: BDOI response | C19: BDOI's answer, or the signed BDOI document that answers the item.
A20: Register | B20: Resolution date | C20: Date the item was Closed.
A21: Register | B21: Related question IDs | C21: Open-question IDs of the specs (CRQ, Q, OQ, PQ, CQ, AQ, RQ, CLQ, EBQ, CSQ, SP-SQ, SANC-SQ, UQ, DMQ, IQ, DSQ, XQ; see the Open questions sheet) and related register items (DCR).
A22: Open questions | B22: Question ID | C22: Original ID of the question. SQ is used by two specs, so it is written SP-SQnn (Submitted Policies) and SANC-SQnn (Sanction Screening).
A23: Open questions | B23: BRD | C23: Spec that raised the question (Cross-BRD: BDOI_CROSS_BRD_DECISIONS.md).
A24: Open questions | B24: Topic | C24: Topic of the question.
A25: Open questions | B25: Question | C25: Question as asked in the spec.
A26: Open questions | B26: Source reference | C26: Requirement IDs and earlier questions the question refers to.
A27: Open questions | B27: Status | C27: Open, Partially answered (a later BRD answers part of it) or Answered. | D27: Open, Partially answered, Answered
A28: Open questions | B28: Answer so far (source) | C28: Short answer from a later BRD, with the answering document and ID.
A29: Open questions | B29: Consolidated under | C29: Primary question of the topic when several specs ask the same thing. Answer the primary question; the others follow.
A30: Open questions | B30: Same topic as | C30: For a primary question: the questions consolidated under it.
A31: Open questions | B31: Register items | C31: Register items (DCR) that cite the question.
A32: NFR comparison | B32: NFR theme | C32: Non-functional theme compared across the BRDs.
A33: NFR comparison | B33: BRD-0 CORE | C33: Value in BRD-0 CORE BDOI Core Replacement (umbrella), with the page.
A34: NFR comparison | B34: BRD-1 NB | C34: Value in BRD-1 NB New Business (NB), with the page.
A35: NFR comparison | B35: BRD-2 OPS | C35: Value in BRD-2 OPS Operations, with the page.
A36: NFR comparison | B36: BRD-3 PM | C36: Value in BRD-3 PM Product Maintenance, with the page.
A37: NFR comparison | B37: BRD-4 CLXN | C37: Value in BRD-4 CLXN Collections (CLXN), with the page.
A38: NFR comparison | B38: BRD-5 ACCT | C38: Value in BRD-5 ACCT Accounting, Disbursement and ACSL, with the page.
A39: NFR comparison | B39: BRD-6 RN | C39: Value in BRD-6 RN Renewal (RN), with the page.
... A49: NFR comparison | B49: Register items | C49: Register items on the theme.
A51: Severity rule
...

Sheet Summary
B1: Summary
B2: BRD Discrepancy and Clarification Register, version 1.2, 26 September 2026. 239 register items; 453 open questions from the BRD specs, the programme alignment, the document storage decision and the cross-BRD decisions.
B5: Items by severity and status
B6: Status pivot. Counts follow the Status column of the Register.
B7: Severity | C7: Open | D7: Answered | E7: Closed | F7: Total
B8: High | C8: =COUNTIFS('Register'!$H$5:$H$743,"High",'Register'!$N$5:$N$743,"Open") | D8: =COUNTIFS('Register'!$H$5:$H$743,"High",'Register'!$N$5:$N$743,"Answered") | E8: =COUNTIFS('Register'!$H$5:$H$743,"High",'Register'!$N$5:$N$743,"Closed") | F8: =SUM(C8:E8)
B9: Medium | C9: =COUNTIFS('Register'!$H$5:$H$743,"Medium",'Register'!$N$5:$N$743,"Open") | D9: =COUNTIFS('Register'!$H$5:$H$743,"Medium",'Register'!$N$5:$N$743,"Answered") | E9: =COUNTIFS('Register'!$H$5:$H$743,"Medium",'Register'!$N$5:$N$743,"Closed") | F9: =SUM(C9:E9)
B10: Low | C10: =COUNTIFS('Register'!$H$5:$H$743,"Low",'Register'!$N$5:$N$743,"Open") | D10: =COUNTIFS('Register'!$H$5:$H$743,"Low",'Register'!$N$5:$N$743,"Answered") | E10: =COUNTIFS('Register'!$H$5:$H$743,"Low",'Register'!$N$5:$N$743,"Closed") | F10: =SUM(C10:E10)
B11: Total | C11: =SUM(C8:C10) | D11: =SUM(D8:D10) | E11: =SUM(E8:E10) | F11: =SUM(F8:F10)
B13: Items by BRD
B14: An item that involves several BRDs is counted once for each BRD involved.
B15: BRD | C15: High | D15: Medium | E15: Low | F15: Total | G15: Open
B16: BRD-0 CORE - BDOI Core Replacement (umbrella) | C16: =COUNTIFS('Register'!$B$5:$B$743,"*BRD-0 CORE*",'Register'!$H$5:$H$743,"High") | D16: =COUNTIFS('Register'!$B$5:$B$743,"*BRD-0 CORE*",'Register'!$H$5:$H$743,"Medium") | E16: =COUNTIFS('Register'!$B$5:$B$743,"*BRD-0 CORE*",'Register'!$H$5:$H$743,"Low") | F16: =SUM(C16:E16) | G16: =COUNTIFS('Register'!$B$5:$B$743,"*BRD-0 CORE*",'Register'!$N$5:$N$743,"Open")
B17: BRD-1 NB - New Business (NB) | C17: =COUNTIFS('Register'!$B$5:$B$743,"*BRD-1 NB*",'Register'!$H$5:$H$743,"High") | D17: =COUNTIFS('Register'!$B$5:$B$743,"*BRD-1 NB*",'Register'!$H$5:$H$743,"Medium") | E17: =COUNTIFS('Register'!$B$5:$B$743,"*BRD-1 NB*",'Register'!$H$5:$H$743,"Low") | F17: =SUM(C17:E17) | G17: =COUNTIFS('Register'!$B$5:$B$743,"*BRD-1 NB*",'Register'!$N$5:$N$743,"Open")
B18: BRD-2 OPS - Operations | C18: =COUNTIFS('Register'!$B$5:$B$743,"*BRD-2 OPS*",'Register'!$H$5:$H$743,"High") | D18: =COUNTIFS('Register'!$B$5:$B$743,"*BRD-2 OPS*",'Register'!$H$5:$H$743,"Medium") | E18: =COUNTIFS('Register'!$B$5:$B$743,"*BRD-2 OPS*",'Register'!$H$5:$H$743,"Low") | F18: =SUM(C18:E18) | G18: =COUNTIFS('Register'!$B$5:$B$743,"*BRD-2 OPS*",'Register'!$N$5:$N$743,"Open")
B19: BRD-3 PM - Product Maintenance | C19: =COUNTIFS('Register'!$B$5:$B$743,"*BRD-3 PM*",'Register'!$H$5:$H$743,"High") | D19: =COUNTIFS('Register'!$B$5:$B$743,"*BRD-3 PM*",'Register'!$H$5:$H$743,"Medium") | E19: =COUNTIFS('Register'!$B$5:$B$743,"*BRD-3 PM*",'Register'!$H$5:$H$743,"Low") | F19: =SUM(C19:E19) | G19: =COUNTIFS('Register'!$B$5:$B$743,"*BRD-3 PM*",'Register'!$N$5:$N$743,"Open")
B20: BRD-4 CLXN - Collections (CLXN) | C20: =COUNTIFS('Register'!$B$5:$B$743,"*BRD-4 CLXN*",'Register'!$H$5:$H$743,"High") | D20: =COUNTIFS('Register'!$B$5:$B$743,"*BRD-4 CLXN*",'Register'!$H$5:$H$743,"Medium") | E20: =COUNTIFS('Register'!$B$5:$B$743,"*BRD-4 CLXN*",'Register'!$H$5:$H$743,"Low") | F20: =SUM(C20:E20) | G20: =COUNTIFS('Register'!$B$5:$B$743,"*BRD-4 CLXN*",'Register'!$N$5:$N$743,"Open")
B21: BRD-5 ACCT - Accounting, Disbursement and ACSL | C21: =COUNTIFS('Register'!$B$5:$B$743,"*BRD-5 ACCT*",'Register'!$H$5:$H$743,"High") | D21: =COUNTIFS('Register'!$B$5:$B$743,"*BRD-5 ACCT*",'Register'!$H$5:$H$743,"Medium") | E21: =COUNTIFS('Register'!$B$5:$B$743,"*BRD-5 ACCT*",'Register'!$H$5:$H$743,"Low") | F21: =SUM(C21:E21) | G21: =COUNTIFS('Register'!$B$5:$B$743,"*BRD-5 ACCT*",'Register'!$N$5:$N$743,"Open")
B22: BRD-6 RN - Renewal (RN) | C22: =COUNTIFS('Register'!$B$5:$B$743,"*BRD-6 RN*",'Register'!$H$5:$H$743,"High") | D22: =COUNTIFS('Register'!$B$5:$B$743,"*BRD-6 RN*",'Register'!$H$5:$H$743,"Medium") | E22: =COUNTIFS('Register'!$B$5:$B$743,"*BRD-6 RN*",'Register'!$H$5:$H$743,"Low") | F22: =SUM(C22:E22) | G22: =COUNTIFS('Register'!$B$5:$B$743,"*BRD-6 RN*",'Register'!$N$5:$N$743,"Open")
B23: BRD-7 CLM - Claims (CLM) | C23: =COUNTIFS('Register'!$B$5:$B$743,"*BRD-7 CLM*",'Register'!$H$5:$H$743,"High") | D23: =COUNTIFS('Register'!$B$5:$B$743,"*BRD-7 CLM*",'Register'!$H$5:$H$743,"Medium") | E23: =COUNTIFS('Register'!$B$5:$B$743,"*BRD-7 CLM*",'Register'!$H$5:$H$743,"Low") | F23: =SUM(C23:E23) | G23: =COUNTIFS('Register'!$B$5:$B$743,"*BRD-7 CLM*",'Register'!$N$5:$N$743,"Open")
B24: BRD-8 EB - Employee Benefits (EB) | C24: =COUNTIFS('Register'!$B$5:$B$743,"*BRD-8 EB*",'Register'!$H$5:$H$743,"High") | D24: =COUNTIFS('Register'!$B$5:$B$743,"*BRD-8 EB*",'Register'!$H$5:$H$743,"Medium") | E24: =COUNTIFS('Register'!$B$5:$B$743,"*BRD-8 EB*",'Register'!$H$5:$H$743,"Low") | F24: =SUM(C24:E24) | G24: =COUNTIFS('Register'!$B$5:$B$743,"*BRD-8 EB*",'Register'!$N$5:$N$743,"Open")
B25: BRD-9 CSF - Customer Servicing Facility (CSF) | C25: =COUNTIFS('Register'!$B$5:$B$743,"*BRD-9 CSF*",'Register'!$H$5:$H$743,"High") | D25: =COUNTIFS('Register'!$B$5:$B$743,"*BRD-9 CSF*",'Register'!$H$5:$H$743,"Medium") | E25: =COUNTIFS('Register'!$B$5:$B$743,"*BRD-9 CSF*",'Register'!$H$5:$H$743,"Low") | F25: =SUM(C25:E25) | G25: =COUNTIFS('Register'!$B$5:$B$743,"*BRD-9 CSF*",'Register'!$N$5:$N$743,"Open")
B26: BRD-10 SANC - Sanction Screening and Risk Profiling | C26: =COUNTIFS('Register'!$B$5:$B$743,"*BRD-10 SANC*",'Register'!$H$5:$H$743,"High") | D26: =COUNTIFS('Register'!$B$5:$B$743,"*BRD-10 SANC*",'Register'!$H$5:$H$743,"Medium") | E26: =COUNTIFS('Register'!$B$5:$B$743,"*BRD-10 SANC*",'Register'!$H$5:$H$743,"Low") | F26: =SUM(C26:E26) | G26: =COUNTIFS('Register'!$B$5:$B$743,"*BRD-10 SANC*",'Register'!$N$5:$N$743,"Open")
B27: BRD-11 UAM - User Access Maintenance (UAM) | C27: =COUNTIFS('Register'!$B$5:$B$743,"*BRD-11 UAM*",'Register'!$H$5:$H$743,"High") | D27: =COUNTIFS('Register'!$B$5:$B$743,"*BRD-11 UAM*",'Register'!$H$5:$H$743,"Medium") | E27: =COUNTIFS('Register'!$B$5:$B$743,"*BRD-11 UAM*",'Register'!$H$5:$H$743,"Low") | F27: =SUM(C27:E27) | G27: =COUNTIFS('Register'!$B$5:$B$743,"*BRD-11 UAM*",'Register'!$N$5:$N$743,"Open")
B28: BRD-12 SP - Submitted Policies (SP) | C28: =COUNTIFS('Register'!$B$5:$B$743,"*BRD-12 SP*",'Register'!$H$5:$H$743,"High") | D28: =COUNTIFS('Register'!$B$5:$B$743,"*BRD-12 SP*",'Register'!$H$5:$H$743,"Medium") | E28: =COUNTIFS('Register'!$B$5:$B$743,"*BRD-12 SP*",'Register'!$H$5:$H$743,"Low") | F28: =SUM(C28:E28) | G28: =COUNTIFS('Register'!$B$5:$B$743,"*BRD-12 SP*",'Register'!$N$5:$N$743,"Open")
B29: BRD-13 DM - Data Migration (draft v0.01) | C29: =COUNTIFS('Register'!$B$5:$B$743,"*BRD-13 DM*",'Register'!$H$5:$H$743,"High") | D29: =COUNTIFS('Register'!$B$5:$B$743,"*BRD-13 DM*",'Register'!$H$5:$H$743,"Medium") | E29: =COUNTIFS('Register'!$B$5:$B$743,"*BRD-13 DM*",'Register'!$H$5:$H$743,"Low") | F29: =SUM(C29:E29) | G29: =COUNTIFS('Register'!$B$5:$B$743,"*BRD-13 DM*",'Register'!$N$5:$N$743,"Open")
B30: Report List as of 27-Apr-2026 | C30: =COUNTIFS('Register'!$B$5:$B$743,"*Report List*",'Register'!$H$5:$H$743,"High") | D30: =COUNTIFS('Register'!$B$5:$B$743,"*Report List*",'Register'!$H$5:$H$743,"Medium") | E30: =COUNTIFS('Register'!$B$5:$B$743,"*Report List*",'Register'!$H$5:$H$743,"Low") | F30: =SUM(C30:E30) | G30: =COUNTIFS('Register'!$B$5:$B$743,"*Report List*",'Register'!$N$5:$N$743,"Open")
B31: Items involving two or more BRDs | C31: =COUNTIFS('Register'!$B$5:$B$743,"*;*",'Register'!$H$5:$H$743,"High") | D31: =COUNTIFS('Register'!$B$5:$B$743,"*;*",'Register'!$H$5:$H$743,"Medium") | E31: =COUNTIFS('Register'!$B$5:$B$743,"*;*",'Register'!$H$5:$H$743,"Low") | F31: =SUM(C31:E31) | G31: =COUNTIFS('Register'!$B$5:$B$743,"*;*",'Register'!$N$5:$N$743,"Open")
B33: Items by drop
B34: Drop in which the item is resolved (column Drop of the Register).
B35: Drop | C35: High | D35: Medium | E35: Low | F35: Total | G35: Open
B36: Drop 0 - Setup and Data Migration | C36: =COUNTIFS('Register'!$C$5:$C$743,"Drop 0",'Register'!$H$5:$H$743,"High") | D36: =COUNTIFS('Register'!$C$5:$C$743,"Drop 0",'Register'!$H$5:$H$743,"Medium") | E36: =COUNTIFS('Register'!$C$5:$C$743,"Drop 0",'Register'!$H$5:$H$743,"Low") | F36: =SUM(C36:E36) | G36: =COUNTIFS('Register'!$C$5:$C$743,"Drop 0",'Register'!$N$5:$N$743,"Open")
B37: Drop 1 - Transactional (upstream and downstream) | C37: =COUNTIFS('Register'!$C$5:$C$743,"Drop 1",'Register'!$H$5:$H$743,"High") | D37: =COUNTIFS('Register'!$C$5:$C$743,"Drop 1",'Register'!$H$5:$H$743,"Medium") | E37: =COUNTIFS('Register'!$C$5:$C$743,"Drop 1",'Register'!$H$5:$H$743,"Low") | F37: =SUM(C37:E37) | G37: =COUNTIFS('Register'!$C$5:$C$743,"Drop 1",'Register'!$N$5:$N$743,"Open")
B38: Drop 2 - Independent | C38: =COUNTIFS('Register'!$C$5:$C$743,"Drop 2",'Register'!$H$5:$H$743,"High") | D38: =COUNTIFS('Register'!$C$5:$C$743,"Drop 2",'Register'!$H$5:$H$743,"Medium") | E38: =COUNTIFS('Register'!$C$5:$C$743,"Drop 2",'Register'!$H$5:$H$743,"Low") | F38: =SUM(C38:E38) | G38: =COUNTIFS('Register'!$C$5:$C$743,"Drop 2",'Register'!$N$5:$N$743,"Open")
B39: Programme (cross-drop) | C39: =COUNTIFS('Register'!$C$5:$C$743,"Programme",'Register'!$H$5:$H$743,"High") | D39: =COUNTIFS('Register'!$C$5:$C$743,"Programme",'Register'!$H$5:$H$743,"Medium") | E39: =COUNTIFS('Register'!$C$5:$C$743,"Programme",'Register'!$H$5:$H$743,"Low") | F39: =SUM(C39:E39) | G39: =COUNTIFS('Register'!$C$5:$C$743,"Programme",'Register'!$N$5:$N$743,"Open")
B40: Phase 2 (outside the January 2028 scope) | C40: =COUNTIFS('Register'!$C$5:$C$743,"Phase 2",'Register'!$H$5:$H$743,"High") | D40: =COUNTIFS('Register'!$C$5:$C$743,"Phase 2",'Register'!$H$5:$H$743,"Medium") | E40: =COUNTIFS('Register'!$C$5:$C$743,"Phase 2",'Register'!$H$5:$H$743,"Low") | F40: =SUM(C40:E40) | G40: =COUNTIFS('Register'!$C$5:$C$743,"Phase 2",'Register'!$N$5:$N$743,"Open")
B42: Items by type
B43: Type | C43: High | D43: Medium | E43: Low | F43: Total | G43: Open
B44: Contradiction within BRD | C44: =COUNTIFS('Register'!$E$5:$E$743,"Contradiction within BRD",'Register'!$H$5:$H$743,"High") | D44: =COUNTIFS('Register'!$E$5:$E$743,"Contradiction within BRD",'Register'!$H$5:$H$743,"Medium") | E44: =COUNTIFS('Register'!$E$5:$E$743,"Contradiction within BRD",'Register'!$H$5:$H$743,"Low") | F44: =SUM(C44:E44) | G44: =COUNTIFS('Register'!$E$5:$E$743,"Contradiction within BRD",'Register'!$N$5:$N$743,"Open")
B45: Conflict between BRDs | C45: =COUNTIFS('Register'!$E$5:$E$743,"Conflict between BRDs",'Register'!$H$5:$H$743,"High") | D45: =COUNTIFS('Register'!$E$5:$E$743,"Conflict between BRDs",'Register'!$H$5:$H$743,"Medium") | E45: =COUNTIFS('Register'!$E$5:$E$743,"Conflict between BRDs",'Register'!$H$5:$H$743,"Low") | F45: =SUM(C45:E45) | G45: =COUNTIFS('Register'!$E$5:$E$743,"Conflict between BRDs",'Register'!$N$5:$N$743,"Open")
...

Sheet Register
A1: Register
A2: One row per discrepancy, conflict, gap or clarification. Filter on BRD, drop, type, severity or status.
A4: Ref | B4: BRD(s) involved | C4: Drop | D4: BRD ID / section / page | E4: Type | F4: Description | G4: Impact (business / build / test) | H4: Severity | I4: Affected modules | J4: Proposed resolution / recommendation | K4: Clarification question to BDOI | L4: Owner (BDOI) | M4: Raised on | N4: Status | O4: BDOI response | P4: Resolution date | Q4: Related question IDs
A5: DCR-001 | B5: BRD-1 NB | C5: Drop 1 | D5: BRNB.029 / BRD 1.3.1.1.3 (p.68); BRNB.063 / BRD 1.3.1 (p.109-110, p.153) | E5: Contradiction within BRD | F5: BRNB.029: "Quotation/Proposal creation must require a client code." BRNB.063: "Generate a quotation/proposal reference number creation without client code." | G5: Business: walk-in and bank-referred prospects may not be quotable. Build: decides whether a prospect client code is created at quotation. Test: one of the two rows fails whichever rule is built. | H5: High | I5: Quotation; Client (CRM) | J5: Allow a quotation without a confirmed client, and create a prospect client code automatically at quotation (BRNB.029 then holds for the prospect code). | K5: Can a quotation be created before the client exists? If yes, may BIBS create a prospect client code automatically at that point? | L5: Marketing and Processing - New Business (Product Owner) | M5: 46290 | N5: Open | Q5: Q13, Q20
A6: DCR-002 | B6: BRD-1 NB | C6: Drop 1 | D6: Role matrix item 35 / 42 (p.124, p.127); BRD 2.1.16 (p.180) | E6: Data / numbering issue | F6: "Reactivate cancelled placed accounts" is in the role matrix and in legacy BRD 2.1.16, but no BRNB ID carries it, so it is missing from the BRNB consolidation. | G6: Build: the function is not traced to a governing requirement. Test: no acceptance criteria in the BRNB set. | H6: Medium | I6: Placement | J6: Add a BRNB ID for reactivation of cancelled placements, or confirm it is dropped. | K6: Is reactivation of a cancelled placement in scope? If yes, please confirm the BRNB ID and who may reactivate. | L6: Marketing and Processing - New Business (Product Owner) | M6: 46290 | N6: Open | Q6: Q25
A7: DCR-003 | B7: BRD-1 NB | C7: Drop 1 | D7: Workshop addendum (p.1-44): row "send generated service invoice" without ID | E7: Data / numbering issue | F7: The workshop addendum has an unnumbered row "send generated service invoice". It is traced as BRNB.100b in the baseline. | G7: Test: acceptance cannot cite an official ID. | H7: Low | I7: Booking | J7: Assign an ID in the next addendum revision; BRNB.100b is used until then. | K7: Please confirm the ID for "send generated service invoice" (proposed BRNB.100b). | L7: Marketing and Processing - New Business (Product Owner) | M7: 46290 | N7: Open | Q7: Q32
A8: DCR-004 | B8: BRD-1 NB | C8: Drop 1 | D8: BRNB.089 / BRD 3.4.3.1 (p.127) | E8: Document quality | F8: Under "a. Generate audit log report", criterion 1 reads "User should be able to assign cancel placement function", copied from the row above. | G8: Test: the criterion does not describe the audit log report. | H8: Low | I8: User Access; Reports | J8: Read criterion 1 as "generate the audit log report". | K8: Please confirm criterion 1 of BRNB.089 is "generate the audit log report". | L8: Marketing and Processing - New Business (Product Owner) | M8: 46290 | N8: Open
A9: DCR-005 | B9: BRD-1 NB | C9: Drop 1 | D9: Appendix A, Fire computation (p.216) | E9: Ambiguity | F9: Appendix A gives "PTX (Premium Tax) 12% of the Net Premium" for Fire, next to FST 2% and LGT. 12% is the VAT rate; the premium tax rate and base are not stated elsewhere. | G9: Business: gross premium on quotations and invoices is wrong if the rate is wrong. Build: premium calculator and tax table. Test: expected premiums in test cases. | H9: High | I9: Quotation; Product Maintenance (rates and taxes); Booking | J9: Keep tax rates and bases in the Rates and Taxes master; seed them only after Comptrollership confirms. | K9: For Fire, which taxes apply (VAT or premium tax, DST, FST, LGT), at what rate and on which base? Does BDOI compute them or copy the insurer's figures? | L9: Marketing and Processing - New Business (Product Owner) | M9: 46290 | N9: Open | Q9: Q43, PQ10
A10: DCR-006 | B10: BRD-1 NB | C10: Drop 1 | D10: Appendix A, Motor computation (p.216) | E10: Ambiguity | F10: OD / Theft cover formula gives two bases on one line: "81% of TSI" and "90% of TSI", without saying which applies when (new vs used vehicle, year of cover, multi-year). | G10: Business: Motor premium differs by 9 points of TSI. Build: motor rating rule. Test: expected premiums. | H10: High | I10: Quotation; Product Maintenance | J10: Model the OD / Theft base as a parameter per product and policy year until confirmed. | K10: When does the OD / Theft base use 81% of TSI and when 90%? Is it tied to multi-year policies (year 2 onwards)? | L10: Marketing and Processing - New Business (Product Owner) | M10: 46290 | N10: Open | Q10: Q35
A11: DCR-007 | B11: BRD-1 NB | C11: Drop 1 | D11: Addendum data retention (p.82); main BRD usage requirements (p.212) | E11: NFR inconsistency | F11: The addendum sets 5 years online, 15 years offline, backup every 4 hours, backup retention 5 years (p.82). The main BRD says "Follow existing QPS set up" (p.212). | G11: Build: retention and archive rules. The baseline applies the addendum (later document). | H11: Medium | I11: Platform (retention and archive) | J11: Apply the addendum values (5 / 15 years, 4-hour backup, 5-year backup retention). | K11: Please confirm that the addendum retention values replace "Follow existing QPS set up" for New Business. | L11: Marketing and Processing - New Business (Product Owner) | M11: 46290 | N11: Open | Q11: Q39, XQ08
A12: DCR-008 | B12: BRD-1 NB; BRD-11 UAM | C12: Drop 0 | D12: BRD-1 BRD 1.4.1.1 (p.93), 1.1.1.2-1.1.1.3 (p.137); BRD-11 BRD 1.001.1.2-1.001.1.3 (p.8), NFR 5 (p.17) | E12: Ambiguity | F12: BRD-1: "Receive warning 30 minutes prior to system triggered log out" after an inactivity warning at 15 minutes; it is unclear whether 30 minutes is an absolute session length. BRD-11 states "inactivity warning (15 minutes)" and "warning prior to system triggered log out (30 minutes)". | G12: Build: session timer. Test: logout timing cases. | H12: Medium | I12: Security (sessions) | J12: Inactivity log-out at 30 minutes with a warning at 15 minutes (SESSION_TIMEOUT_MINUTES = 30, SESSION_IDLE_WARNING_MINUTES = 15). | K12: Confirm that the 30 minutes is inactivity, not a maximum session length. | L12: UAM process owner (Product Owner) with ITIO | M12: 46290 | N12: Answered | O12: BRD-11 p.17 NFR 5: inactivity warning after 15 minutes, warning prior to system-triggered log out after 30 minutes. | Q12: Q42
A13: DCR-009 | B13: BRD-1 NB; BRD-6 RN; BRD-12 SP; Report List | C13: Drop 1 | D13: BRD-1 BRNB.018 (p.57); Report List #182 (p.57); BRD-6 reports 1.009.2-1.009.3 | E13: Conflict between BRDs | F13: BRNB.018 asks for a "Late Renewal Requests Report" in New Business. The Renewal BRD has no such report, and Report List #182 "Late Renewal" is a TSU package report ("This should be under a separate TSU module"). | G13: Build: no owner for the report. Test: BRNB.018 cannot be accepted. | H13: Medium | I13: Renewal; Reports | J13: Build it in Renewal as a variant of the renewal listing (renewals booked after expiry). | K13: Is the Late Renewal Requests Report still needed? If yes, is it the renewal listing filtered on late requests, and who uses it? | L13: Marketing and Processing - Renewal (RMEL) | M13: 46290 | N13: Open | Q13: Q09, RQ29, XQ09
A14: DCR-010 | B14: BRD-1 NB; BRD-6 RN; BRD-8 EB; BRD-12 SP | C14: Drop 1 | D14: BRNB.097 (BRD-1); BRRN.033 (BRD-6, p.4-15); BRID-022.01 (BRD-8 Add. p.10); BRIDSP-26 / 27 (BRD-12 p.11) | E14: BRD vs platform | F14: Four BRDs require New Business / Renewal classification from creation to the invoice and as a report filter. BIBS booking sets every invoice to NEW_BUSINESS (booking InvoiceBuilder, line 129). | G14: Business: renewal production cannot be reported apart from new business. Build: shared change BT0 (account business type, invoice, report filters). Test: every booking and production report test. | H14: High | I14: Account; Booking; Reports; Renewal; Employee Benefits; Submitted Policies | J14: Build work item BT0 once for all three BRDs: business type on the account, carried to the invoice and used as a report filter. | K14: Confirm the two values (New Business, Renewal) and that a renewal with changed terms stays a Renewal (BRRN.033). | L14: BIBS Product Owner, with the owners of the BRDs involved | M14: 46290 | N14: Answered | O14: BRRN.033 (BRD-6), BRID-022.01 (BRD-8) and BRIDSP-26 / 27 (BRD-12) require the classification at creation and as a report filter.
A15: DCR-011 | B15: BRD-2 OPS | C15: Drop 1 | D15: RMTID.002: main BRD (p.50) and Addendum 1 (p.3-4) | E15: Contradiction within BRD | F15: Main BRD: "Facility to allow User to edit the extracted file" and push it "with or without edit". Addendum 1: users "mark specific record or row for exclusion"; only non-excluded data is pushed; no editing of financial data. | G15: Build: remittance extraction screen. The addendum governs. | H15: Medium | I15: Remittance | J15: Build exclusion only (no edit of financial fields), per Addendum 1. | K15: None; recorded for traceability. BDOI to confirm the main-BRD wording is superseded. | L15: Operations - Financial Transactions and Processing | M15: 46290 | N15: Answered | O15: Operations Addendum 1 (p.3-4): exclusion instead of edit; "When the file is pushed to Disbursement, only non-excluded data" is sent.
A16: DCR-012 | B16: BRD-2 OPS | C16: Drop 1 | D16: ADJID.015 (p.96); MKTID.008 (Adjustment section) | E16: Data / numbering issue | F16: ADJID.015 (persona "User", "Note: This is a Marketing activity") and MKTID.008 describe the same Endorsement Slip. | G16: Build: one function, two IDs. Test: two rows cite one screen. | H16: Medium | I16: Adjustment | J16: Build the Endorsement Slip once, available to Marketing and Adjustment users. | K16: Who prepares the Endorsement Slip: Marketing, the Adjustment unit, or both? | L16: Operations - Financial Transactions and Processing | M16: 46290 | N16: Open | Q16: OQ32
A17: DCR-013 | B17: BRD-2 OPS | C17: Drop 1 | D17: RMTID.023 (p.62); PRCID.028 (p.85) | E17: Contradiction within BRD | F17: RMTID.023 (Remittance) and PRCID.028 (Production Reconciliation) both automate the early-remittance incentive. PRCID.028 limits it to CLG / CBG motor and fire; RMTID.023 does not. | G17: Business: incentive income may be computed twice or on the wrong lines. Build: one computation owner. Test: incentive amounts. | H17: High | I17: Remittance; Production Reconciliation; Commission | J17: One computation in Remittance, with eligible lines as data (CLG / CBG motor and fire at go-live). | K17: Is the early-remittance incentive one programme? Which lines and rates apply, and does the window start at inception or booking? | L17: Operations - Financial Transactions and Processing | M17: 46290 | N17: Open | Q17: OQ23, CQ24, AQ25
A18: DCR-014 | B18: BRD-2 OPS | C18: Drop 1 | D18: Summary 5.f (p.22); CSHID.016 (p.37-38); ADJID.026 (p.101) | E18: Contradiction within BRD | F18: Three minimal-balance rules: summary 5.f "Auto-reverse records with minimal balances (Php 10.00 and below) to AP overages"; CSHID.016 balances "<= Php 10.00" compared with PR2307; ADJID.026 "balances between 10.00 and 100.00 ... may be written off or credited". 10.00 is in both ranges. | G18: Business: small balances post to different GL accounts. Build: cashiering and adjustment rules. Test: boundary cases at 10.00. | H18: High | I18: Cashiering; Adjustment; FRBS / GL | J18: Up to 9.99 auto-reversed to AP overages; 10.00-100.00 write-off or credit through an adjustment. Thresholds as parameters. | K18: Please give one rule for small balances: the boundary at exactly 10.00, GL accounts, and who approves a write-off. | L18: Operations - Financial Transactions and Processing | M18: 46290 | N18: Open | Q18: OQ11, CQ03, OQ26
A19: DCR-015 | B19: BRD-2 OPS | C19: Drop 1 | D19: RMTID.014 (p.56-57) | E19: Contradiction within BRD | F19: RMTID.014 "Validate that paid AR is not more than" the DTIP balance: the expected result remits only the DTIP balance, while the acceptance criteria flag and exclude the account. | G19: Business: remittance to insurers is capped or withheld. Build: remittance validation. Test: expected result differs. | H19: High | I19: Remittance | J19: Flag and exclude the account from the batch until resolved (acceptance criteria). | K19: When paid AR is more than the DTIP balance, should BIBS remit the DTIP balance or exclude the account? | L19: Operations - Financial Transactions and Processing | M19: 46290 | N19: Open | Q19: OQ19
A20: DCR-016 | B20: BRD-2 OPS | C20: Drop 1 | D20: RMTID.019 (p.59) | E20: Ambiguity | F20: RMTID.019 "Validate remittance status upon submission" lists payment states (Unapplied Payment, With Outstanding Balance) together with remittance states. | G20: Build: remittance status model. Test: status transitions. | H20: Medium | I20: Remittance | J20: Keep payment state and remittance state as two separate fields. | K20: Please confirm the remittance status list and who approves a remittance batch (TL / TH). | L20: Operations - Financial Transactions and Processing | M20: 46290 | N20: Open | Q20: OQ21
A21: DCR-017 | B21: BRD-2 OPS | C21: Drop 1 | D21: Key capability f (p.21); CSHID.007 (p.29) | E21: Contradiction within BRD | F21: CSHID.007: "One OR per Remittance Batch number" and "OR is issued per individual payment unless consolidation" criteria are met. Key capability f: "one OR per settlement batch per Insurer". | G21: Business: number of ORs issued for commission. Build: OR generation. Test: OR count. | H21: Medium | I21: Cashiering; Commission | J21: One OR per remittance batch per insurer by default; individual OR as an option. | K21: For commission received from insurers, which prevails: one OR per remittance batch, or one per payment? | L21: Operations - Financial Transactions and Processing | M21: 46290 | N21: Open | Q21: OQ49
A22: DCR-018 | B22: BRD-2 OPS | C22: Drop 1 | D22: ADJID.002e (p.90), ADJID.010 (p.94); ADJID.004 item 4 (p.91) | E22: Contradiction within BRD | F22: "Extension of Cover" is a financial endorsement with additional premium and approval (ADJID.002e, ADJID.010) and a non-financial endorsement (ADJID.004: "extensions of cover/clauses/warranties/deductibles are added"). | G22: Business: approval and premium may be skipped. Build: endorsement type list. Test: endorsement cases. | H22: Medium | I22: Adjustment | J22: Two types: "Extension of cover (period, with premium)" and "Additional clause / warranty (no premium)". | K22: Please confirm the endorsement type list and who approves additional premium. | L22: Operations - Financial Transactions and Processing | M22: 46290 | N22: Open | Q22: OQ35
A23: DCR-019 | B23: BRD-2 OPS | C23: Drop 1 | D23: RMTID.001 (p.49); PRCID.004 (p.79); PRCID.016 (p.82); PRCID.024 / 025; ADJID.025 (p.100) | E23: Gap / missing detail | F23: Values left open in the signed BRD: "Batch Run: TDB" (RMTID.001); "Standard naming convention: TBD" (PRCID.004); company-concerned list "to be provided" (PRCID.016); automatch frequency blank (PRCID.024 / 025); supporting document list blank (ADJID.025). | G23: Build: defaults must be assumed. Test: no expected values. | H23: Medium | I23: Remittance; Production Reconciliation; Adjustment | J23: Build each as a parameter or list with a documented default. | K23: Please give the remittance extraction schedule, the production register naming, the company-concerned list, the automatch frequency and the endorsement document list. | L23: Operations - Financial Transactions and Processing | M23: 46290 | N23: Open | Q23: OQ17, OQ29, OQ30, OQ31, OQ32
A24: DCR-020 | B24: BRD-2 OPS | C24: Drop 1 | D24: CSHID.008 (p.30-31) | E24: Ambiguity | F24: Trade, Direct Credit and CLPC files are "manually prepared by BU, send to IT, IT to run batch process - FS04", while Operations users upload payment files. The PDC list is an Excel upload and also "PDC from PMS". | G24: Build: upload screen vs batch intake. Test: file intake cases. | H24: Medium | I24: Cashiering | J24: Operations users upload all files in BIBS; a scheduled pick-up from FS04 can be added later. | K24: Who loads each payment file (Operations or IT batch)? What is PMS? Please share sample files and layouts. | L24: Operations - Financial Transactions and Processing | M24: 46290 | N24: Open | Q24: OQ03, OQ04
A25: DCR-021 | B25: BRD-2 OPS | C25: Drop 1 | D25: CSHID.026 / 027, RMTID.038 / 040, ADJID.026-028, CMRID.015, MKTID.010-013 | E25: Data / numbering issue | F25: Several IDs have no key-capability number. MKTID numbering does not follow document order (MKTID.013 is in Cashiering, MKTID.008 comes last, in Adjustment). | G25: Traceability only. | H25: Low | I25: Operations (all) | J25: Trace by ID; key capability inferred from the section. | K25: None; correct in the next revision. | L25: Operations - Financial Transactions and Processing | M25: 46290 | N25: Open
A26: DCR-022 | B26: BRD-2 OPS; BRD-4 CLXN; BRD-5 ACCT; BRD-7 CLM | C26: Drop 1 | D26: BRD-2 BRQID.004-005 (p.16-20); BRD-4 p.37-39; BRD-5 DIS 3.25.0, FRBS 2.5.0; BRD-7 p.23 | E26: Conflict between BRDs | F26: BRD-2 treats Collection, Accounting, Disbursement, Marketing and Claims as other systems that Operations integrates with. BRD-4, BRD-5 and BRD-7 describe Collections, Accounting, Disbursement and Claims as functions inside the target system. | G26: Build: in-app interfaces instead of external integrations. | H26: Medium | I26: Cashiering; Remittance; Collections; Disbursement; FRBS / GL; Claims | J26: Collections, Disbursement, FRBS and Claims are BIBS modules; Operations uses in-app ports. | K26: Confirm that the Marketing (ISYS) link is the only external system left in BRQID.004. | L26: BIBS Product Owner, with the owners of the BRDs involved | M26: 46290 | N26: Answered | O26: BRD-4 p.37-39 (Collection Management System); BRD-5 DIS 3.25.0 and FRBS 2.5.0 (Disbursement and GL in the target system); BRD-7 p.23 (claims module). | Q26: OQ01, OQ02, OQ46
A27: DCR-023 | B27: BRD-2 OPS; BRD-4 CLXN | C27: Drop 1 | D27: BRD-2 MKTID.001-013; BRD-4 BRCLXN.016, p.41 | E27: Ambiguity | F27: MKTID (Marketing) and DBMID (Disbursement) rows are requirements on other units. BRD-4 covers only the 2307 and DP tagging dispositions; holds, special remittance, send-schedule and DP tagging at quotation (MKTID.001-009, 011) have no other BRD. | G27: Build: the Marketing screens stay in the Operations build. | H27: Medium | I27: Remittance; Collections; Adjustment | J27: MKTID.001-009 and 011 stay in Operations; MKTID.010 / 013 tagging moves to Collections dispositions. | K27: Confirm that Marketing performs holds, special remittance requests and the schedule request inside BIBS. | L27: Operations - Financial Transactions and Processing | M27: 46290 | N27: Open | Q27: OQ45
A28: DCR-024 | B28: BRD-2 OPS | C28: Drop 1 | D28: Annex I acronyms (p.124) | E28: Document quality | F28: The acronym table gives "DTIP - Due To Insurer Provider" and "BDOI - BDO Insurance Brokers, Inc." | G28: Glossary only. | H28: Low | I28: - | J28: Glossary uses "Due to Insurance Provider" and the registered company name. | K28: Please confirm the expansion of DTIP. | L28: Operations - Financial Transactions and Processing | M28: 46290 | N28: Open
A29: DCR-025 | B29: BRD-2 OPS | C29: Drop 1 | D29: Usage requirements, Commission Receivables (p.118-119) | E29: Gap / missing detail | F29: The Commission Receivables volume table is headed "Volume and Performance - Adjustment / Endorsement" (copy error). Transaction volumes and growth rates are blank for every area. | G29: Build: sizing assumed from BRD-1. Test: no volume targets for performance tests. | H29: Medium | I29: Platform (sizing) | J29: Size with the BRD-1 volumes plus Operations users. | K29: Please give monthly transaction volumes and growth per Operations area. | L29: Operations - Financial Transactions and Processing | M29: 46290 | N29: Open | Q29: OQ44
A30: DCR-026 | B30: BRD-2 OPS | C30: Drop 1 | D30: Addendum 1 approval (p.6) | E30: Document quality | F30: A reviewer date on the addendum approval page is written "1/6/2025"; the addendum is dated 18-Dec-2025, so it is probably 1/6/2026. | G30: Approval record only. | H30: Low | I30: - | J30: None. | K30: Please confirm the date. | L30: Operations - Financial Transactions and Processing | M30: 46290 | N30: Open
A31: DCR-027 | B31: BRD-1 NB; BRD-2 OPS | C31: Drop 1 | D31: BRD-1 BRNB.067 (p.114), BRNB.076 (p.118), BRNB.114; BRD-2 CSHID.008 (p.30), ADJID.001 / 003 / 011, MKTID.011 | E31: Conflict between BRDs | F31: The same functions are specified twice: CLPC payment matching before placement (BRNB.067 / 068) and CLPC payment upload (CSHID.008); endorsements and cancellation in booking (BRNB.076 / 081 / 094) and in Adjustment (ADJID.001 / 003 / 011); DP tagging (BRNB.114, MKTID.011). | G31: Business: two owners for one process. Build: risk of two payment intakes and two endorsement paths. Test: duplicated cases. | H31: High | I31: Placement; Booking; Cashiering; Adjustment | J31: Cashiering is the single payment intake and placement reads its result; Adjustment owns endorsements and cancellations after booking; Marketing raises the request. | K31: Confirm Cashiering as the single payment intake, and who raises (Marketing) and processes (Adjustment) endorsements. | L31: BIBS Product Owner, with the owners of the BRDs involved | M31: 46290 | N31: Open | Q31: OQ12, OQ32, OQ38
A32: DCR-028 | B32: BRD-2 OPS | C32: Drop 1 | D32: CSHID.026 (p.44); CSHID.027 / DBMID.001 | E32: Gap / missing detail | F32: For 2307 cash payments CSHID.026 says only "Premium is reversed" and the remittance is processed, with no accounting entries. CSHID.027 / DBMID.001 give Dr PR2307 / Cr PR and Dr DTIP / Cr PR2307. | G32: Business: GL entries for CWT unclear. Build: posting rules. Test: GL expected entries. | H32: High | I32: Cashiering; Remittance; FRBS / GL | J32: Post Dr PR2307 / Cr PR on application and Dr DTIP / Cr PR2307 when the 2307 batch is released with the remittance. | K32: Please give the entries for CSHID.026 and the moment Dr DTIP / Cr PR2307 is posted. | L32: Operations - Financial Transactions and Processing | M32: 46290 | N32: Open | Q32: OQ10, OQ16, AQ16
A33: DCR-029 | B33: BRD-3 PM | C33: Drop 0 | D33: BRPM.022 / BRPM.024 (p.31); earlier version BRQID.022 / 024 (p.36-61) | E33: Data / numbering issue | F33: BRPM.023 does not exist: BRPM.022 is followed by BRPM.024. The earlier signed version also skips BRQID.023. | G33: Traceability: a requirement may be missing. | H33: Low | I33: Product Maintenance | J33: Treat the gap as numbering only. | K33: Confirm that no requirement is missing at BRPM.023. | L33: Marketing Business Services (MBS) and TSU | M33: 46290 | N33: Open | Q33: PQ20
A34: DCR-030 | B34: BRD-3 PM | C34: Drop 0 | D34: Earlier signed version BRQID.008 (p.36-61); final BRPM.007 (p.17) | E34: Gap / missing detail | F34: The pack holds an earlier signed version (pp.36-61). Its BRQID.008 required documented client negotiation before a new rate scheme applies to a renewal already advised. The final version drops it without a revision-log entry and keeps only "old packages locked for new business but accessible for renewals". | G34: Business: a renewal could be repriced after the RA without client evidence. Build: renewal acceptance evidence. | H34: Medium | I34: Product Maintenance; Renewal | J34: BRRN.038 AC 3 (acceptance evidence when a renewal has a financial impact) covers the dropped rule; no separate Product Maintenance control. | K34: Confirm that BRQID.008 was dropped on purpose and that BRRN.038 now governs. | L34: Marketing Business Services (MBS) and TSU | M34: 46290 | N34: Open | Q34: PQ10
A35: DCR-031 | B35: BRD-3 PM | C35: Drop 0 | D35: Addendum p.2, p.3, p.4, p.8; main BRD approval p.34, p.59 | E35: Document quality | F35: Copied headings: the addendum is titled "Business Requirements for New Business" (p.3) and "Table of New Business Requirements" (p.4); its approval says "New Business Fire and Motor" (p.8); the main BRD approval says "for the OPERATIONS request" (p.34, p.59). Revision log: "Added BRID PMADD07 and PMADD07" (p.2); preparer date "11/06/205" (p.34). | G35: Approval record: the signatures refer to another BRD title. | H35: Low | I35: - | J35: None for the build. | K35: Please confirm the approvals apply to Product Maintenance, and correct the headings in the next revision. | L35: Marketing Business Services (MBS) and TSU | M35: 46290 | N35: Open
A36: DCR-032 | B36: BRD-3 PM | C36: Drop 0 | D36: Addendum table, column "Source BRD ID" (p.4-7) | E36: Gap / missing detail | F36: The "Source BRD ID" column is empty for every PMADD row, so the addendum does not say which main-BRD rows it refines. Read against the main BRD: PMADD06 details BRPM.015, PMADD04 details BRPM.010 / 013, PMADD03 details BRPM.014, PMADD05 details BRPM.002. | G36: Test: acceptance may be run against the superseded wording. | H36: Medium | I36: Product Maintenance | J36: Use the mapping above. | K36: Please confirm the PMADD to BRPM mapping. | L36: Marketing Business Services (MBS) and TSU | M36: 46290 | N36: Open
A37: DCR-033 | B37: BRD-3 PM | C37: Drop 0 | D37: BRPM.003 (p.16); BRPM.013 (p.23) | E37: Data / numbering issue | F37: BRPM.003 has no priority level. BRPM.013 names the keying of insurer terms, but its acceptance criteria describe comparative tables and a monitoring sheet. | G37: Test: BRPM.013 criteria do not test the requirement. | H37: Low | I37: Product Maintenance | J37: Treat BRPM.003 as Must have; test BRPM.013 on the capture of insurer terms. | K37: Confirm the priority of BRPM.003 and the acceptance criteria of BRPM.013. | L37: Marketing Business Services (MBS) and TSU | M37: 46290 | N37: Open | Q37: PQ06
A38: DCR-034 | B38: BRD-3 PM; BRD-1 NB | C38: Drop 0 | D38: BRD-3 BRPM.018 (p.28); BRD-1 BRNB.011 | E38: Contradiction within BRD | F38: BRPM.018 is titled "Placement Update Reports" but its result speaks of "Package Status Update Reports" of package creation. BRD-1 already has a Placement Update Report (BRNB.011). | G38: Build: two reports with one name. Test: wrong report tested. | H38: Medium | I38: Product Maintenance; Reports | J38: Name it "Package Status Update Report", separate from the BRD-1 Placement Update Report. | K38: Confirm BRPM.018 is a package status report and give its columns. | L38: Marketing Business Services (MBS) and TSU | M38: 46290 | N38: Open | Q38: PQ15
A39: DCR-035 | B39: BRD-3 PM | C39: Drop 0 | D39: Addendum footnote 2 (p.4); approval p.8; earlier version p.49 | E39: Ambiguity | F39: Persona "User": "User could be but not limited to Marketing AO, TSU, Processing. User roles and authorization will be further defined in succeeding documentations." MBS and ManCom are not defined in the final version. | G39: Build: role-to-action matrix (PMADD05) has no agreed content. Test: access tests. | H39: Medium | I39: Product Maintenance; User Access | J39: Seed roles from the design persona list; BDOI confirms the matrix. | K39: Please provide the Product Maintenance role-to-action matrix and the ManCom membership and decision rule. | L39: Marketing Business Services (MBS) and TSU | M39: 46290 | N39: Open | Q39: PQ07, PQ17, OQ48
A40: DCR-036 | B40: BRD-3 PM | C40: Drop 0 | D40: Revision log (p.11); PMADD01 (p.4) | E40: Gap / missing detail | F40: The revision log of 27-Oct-2025 says "Exclude Non-Package and include this as part of an addendum". The April 2026 addendum does not add it; PMADD01 mentions "non-package items if/when added". | G40: Build: scope of product maintenance for non-package products is undefined. | H40: Medium | I40: Product Maintenance | J40: Non-package product maintenance out of this phase; non-package placement stays in New Business. | K40: Confirm that maintenance of non-package products is out of scope for this phase. | L40: Marketing Business Services (MBS) and TSU | M40: 46290 | N40: Open | Q40: PQ19
A41: DCR-037 | B41: BRD-3 PM; BRD-5 ACCT; BRD-2 OPS; BRD-4 CLXN | C41: Drop 0 | D41: BRD-3 PMADD07 / 08 (p.6-7); BRD-5 DIS 3.29.0-3.29.2 (Workshop addendum p.1-15); BRD-2 CMRID.003-006; BRD-4 BRCLXN.061-062 (draft) | E41: Conflict between BRDs | F41: Incentives are specified in four BRDs: criteria on the products matrix "(i.e. CPC2)" (BRD-3, no definition); CPC2 as package Fire / Motor incentive computed per remittance, and early incentive with service invoice and 2% withholding (BRD-5); No Touch, Top Up and Motor Mania schemes (BRD-2); incentive campaigns (BRD-4 draft rows). No BRD gives rates, tiers or targets. | G41: Business: incentive income and pass-on to branches. Build: one incentive model across modules. Test: no expected values. | H41: High | I41: Product Maintenance; Remittance; Commission; Collections; FRBS / GL | J41: Criteria kept once in Product Maintenance; CPC2 and early incentive computed in Remittance; schemes in Commission reference the criteria. | K41: Please list the incentive programmes (CPC2, early remittance, No Touch, Top Up, Motor Mania, campaigns) with rates, base, period, payer and whether each is billed by service invoice. | L41: BIBS Product Owner, with the owners of the BRDs involved | M41: 46290 | N41: Open | Q41: PQ04, OQ39, Q33, AQ24, CQ24, SP-SQ14
...

Sheet Open questions
A1: Open questions
A2: Every open question of the specs, with its status, the consolidated question and the register items.
A4: Question ID | B4: BRD | C4: Topic | D4: Question | E4: Source reference | F4: Status | G4: Answer so far (source) | H4: Consolidated under | I4: Same topic as | J4: Register items
A5: CRQ01 | B5: BRD-0 CORE | C5: BRD set and ownership | D5: The umbrella lists ten BRDs (p.3) and cites a "User & Data Management" BRD (pp.38-41). Is it the umbrella over all twelve BRDs, the Data Migration BRD and the ReInsurance BRD? Who owns Data Management (capability 17)? | E5: CF-07, CORE-17 | F5: Open | J5: DCR-169, DCR-201
A6: CRQ02 | B6: BRD-0 CORE | C6: Non-Package Management | D6: Capability 4 (added 20-Nov-2025) has no BR ID and no traceability row. Please confirm it is the non-package placement of New Business (PRF, quotation slip, comparative table, proposal slip) and not the maintenance of non-package products (PQ19). | E6: CORE-04 | F6: Open | H6: PQ19 | J6: DCR-181
A7: CRQ03 | B7: BRD-0 CORE | C7: Claims cheques | D7: BR-146 to BR-148 ask for safekeeping of unclaimed cheques and hand-over to / retrieval from Cashiering. BRD-7 has no claim money through BDOI (CLQ10). Does BDOI hold settlement cheques? If yes, which unit keeps them, and what is recorded at hand-over and release? | E7: CORE-14.08-14.10 | F7: Open | H7: XQ13 | J7: DCR-164
A8: CRQ04 | B8: BRD-0 CORE | C8: CSF case management | D8: BR-165 asks for case resolution; BRD-9 e-mail item 10 keeps case logging in SharePoint. Which applies in phase 1? | E8: CORE-16.06 | F8: Open | H8: XQ12 | J8: DCR-163
A9: CRQ05 | B9: BRD-0 CORE | C9: Delete of prospect | D9: Is deactivation with a reason, followed by the retention purge, acceptable for "delete of prospect / record" (BR-008), or must a prospect be erased on request (for example under the Data Privacy Act)? | E9: CORE-01.04 | F9: Open | J9: DCR-182
A10: CRQ06 | B10: BRD-0 CORE | C10: Role dashboards | D10: Which figures does each role see on its home page (BR-125, 152, 160 say "to be defined")? Is one landing page per role expected, or the existing section homes? | E10: XC-02 | F10: Open | J10: DCR-178
A11: CRQ07 | B11: BRD-0 CORE | C11: Master data change log | D11: Which master data is in scope (users, products, insurers, LOVs, others)? Must the log show old and new values per field and the approver? Who views it? | E11: CORE-17.01 | F11: Open | J11: DCR-174
A12: CRQ08 | B12: BRD-0 CORE | C12: Insurer management | D12: What are "risk participation", "payment terms" and "remittance schedules" on the insurer record (BR-171)? Which unit maintains insurer records, and do changes need approval? | E12: CORE-17.02 | F12: Open | J12: DCR-176
A13: CRQ09 | B13: BRD-0 CORE | C13: MIS field definition | D13: Is BR-173 a fixed list of MIS fields per entity (as in its example) or a facility for users to add fields? Who maintains it? | E13: CORE-17.04 | F13: Open | J13: DCR-175, DCR-214
A14: CRQ10 | B14: BRD-0 CORE | C14: Emerging capabilities | D14: Capability 18 and BR-176 ("any other / additional system capabilities") cannot be tested. Please list the capabilities or withdraw the row. | E14: CORE-18.01 | F14: Open | J14: DCR-180
A15: CRQ11 | B15: BRD-0 CORE | C15: Report customisation and scheduling | D15: Which reports need user-chosen fields, charts and summaries? Who may schedule a report, how often, in which formats, and how is it delivered (e-mail, folder)? Is Word needed for all reports (EBQ21)? | E15: CORE-21.04, 21.05 | F15: Open | H15: Q40 | J15: DCR-177
A16: CRQ12 | B16: BRD-0 CORE | C16: SOA at booking | D16: Which SOA is generated with the placement report and Insurance Advice (BR-039) and with the insurer's service invoice at booking (BR-043): the client billing SOA or an insurer SOA? | E16: XC-10 | F16: Open | J16: DCR-171
A17: CRQ13 | B17: BRD-0 CORE | C17: Invoice Master List | D17: Is the Invoice Master List (BR-175) the Operations invoice ledger? Please confirm the columns (cover number, version number, assignees, placement status, approval dates) and the owner. | E17: XC-13 | F17: Open | J17: DCR-179
A18: CRQ14 | B18: BRD-0 CORE | C18: Letter names | D18: The umbrella writes "Non-Renewal Letter (NRL)", BRD-6 "Not for Renewal Letter (NFR)". Which name is printed on the letter? | E18: CORE-06.07 | F18: Open | J18: DCR-168
A19: CRQ15 | B19: BRD-0 CORE | C19: Bank account operations | D19: What does "Bank Account Operations" (p.9) cover beyond the account funding and bank instruments of BRD-5? | E19: CORE-08.21 | F19: Open
A20: CRQ16 | B20: BRD-0 CORE | C20: CSF resend | D20: Must CSF agents also resend e-policies (BR-164), or only RAs (BRCSF-006)? | E20: CORE-16.04 | F20: Open | J20: DCR-172
A21: CRQ17 | B21: BRD-0 CORE | C21: BDO design assets | D21: Please supply the BDO icon and illustration set and the design system or Figma files (BR-179, 180, 183). | E21: XC-14 | F21: Open | J21: DCR-187
A22: CRQ18 | B22: BRD-0 CORE | C22: Insurer invoice delivery | D22: For "Invoice Batch Printing" (p.43): what is the batch file (one PDF per insurer, a ZIP, a manifest), the SFTP endpoint per insurer, and does it replace the e-mail of each service invoice? | E22: XC-19 | F22: Open | J22: DCR-184
A23: CRQ19 | B23: BRD-0 CORE | C23: Client migration and feeds | D23: "One-time migration from Broker and source, 2020 to present" and the daily midday and EOD client batches (p.43): which source system, and for how long do the daily batches run? How does this fit the selective migration of the Data Migration BRD? | E23: XC-20, CF-11 | F23: Open | H23: DMQ05 | J23: DCR-173
A24: CRQ20 | B24: BRD-0 CORE | C24: ALeA | D24: What is ALeA, and what is "e-mail address encoding" (p.43)? | E24: XC-21 | F24: Open | J24: DCR-185
A25: CRQ21 | B25: BRD-0 CORE | C25: Response time and sizing | D25: Response under 5 seconds for every role (p.42) differs from nine BRDs; 429 concurrent users is the sum of the BRD rows. Which values govern the performance tests? | E25: CF-03, CF-04 | F25: Open | H25: XQ08 | J25: DCR-165, DCR-166
A26: CRQ22 | B26: BRD-0 CORE | C26: Retention and backup | D26: Do the umbrella values (5 / 15 years, backup every 4 hours kept 5 years) replace the BRD-specific ones (BRD-7 10 years online; BRD-5, 10, 12 five years archive; BRD-9 backup every 15 minutes; BRD-2 and BRD-8 backup kept 7 years)? | E26: CF-05 | F26: Open | H26: XQ08 | J26: DCR-167, DCR-209
A27: CRQ23 | B27: BRD-0 CORE | C27: Traceability workbook | D27: Please send "E2E BDOI Mapping.xlsx" (p.30) and confirm that the final IDs of each BRD (BRPM, BRRN, BRCLXN, BRCLM, BRCSF) govern where the umbrella cites earlier ones. | E27: CF-08, §10 | F27: Open | J27: DCR-170
A28: CRQ24 | B28: BRD-0 CORE | C28: User counts | D28: Employee Benefits 13 / 13 (umbrella) or 20 internal users (BRD-8)? Claims 67 / 26 or 47 / 25 (BRD-7)? Product Maintenance 13 / 13 or TSU 13 plus MBS 5? | E28: CF-04 | F28: Open | H28: XQ08 | J28: DCR-166
A29: CRQ25 | B29: BRD-0 CORE | C29: Approval of the umbrella | D29: The Product Owner for FRBS and ACSL is marked "On Mandatory Leave" without a signature; the Analytics and Risk Management head marks "sign-off not applicable"; four approvals are by e-mail only (pp.46-48). Is the document approved? | E29: §14 | F29: Open | J29: DCR-186
A30: Q01 | B30: BRD-1 NB | C30: Product master | D30: Please share the product matrix files (MTR08..MTR38, PAR01..PAR25, other risk codes) referenced in Appendix B; the SharePoint link is internal to BDO. | E30: BRNB.001-003, 093 | F30: Partially answered | G30: The products matrix is maintained in BIBS by MBS / TSU with the hierarchy LOB, subline / type / subtype, coverage / peril. The MTR / PAR matrix files are still not provided. (BRD-3 p.12, PMADD01-02)
A31: Q02 | B31: BRD-1 NB | C31: Product master | D31: Minimum mandatory fields per product line / cover type (Annex II: Property, Motor, Engineering, Liability, Crime, Floater, Marine, Hull, Aviation, PA, EEI, Misc.). | E31: BRNB.002, 003, 093 | F31: Open
A32: Q03 | B32: BRD-1 NB | C32: Templates | D32: Sample layouts for IDF, FFYMI quotation, Quotation Slip, Proposal Slip, Comparative Table, Placement Slip, Hold Cover request, Insurance Advice, Service Invoice. | E32: BRNB.004, 008, 017, 069, 070, 100 | F32: Open | I32: RQ26, EBQ08
A33: Q04 | B33: BRD-1 NB | C33: TSU routing | D33: Exact TSU involvement criteria: package vs non-package list, fleet threshold (no. of units), multi-location threshold, TSI threshold, endorsement types. | E33: BRNB.098 | F33: Open | J33: DCR-131
A34: Q05 | B34: BRD-1 NB | C34: Approvals | D34: Approval chain and limits for PRF (Marketing TL / TH / UH) and QS (TSU) - by amount, product or segment? | E34: BRNB.005, 014 | F34: Partially answered | G34: Package requests: approved by the Marketing TL, TH or UH; TSU TL recommends, TH approves; ManCom sign-off. No amount limits. (BRD-3 BRPM.008 / 009 / 012 / 015, PMADD06) | I34: PQ08
A35: Q06 | B35: BRD-1 NB | C35: Insurer channel | D35: How are insurers reached per insurer: e-mail only, SFTP, or insurer API? List of panel insurers and branch codes (LGT depends on insurer branch). | E35: BRNB.008, 071 | F35: Partially answered | G35: For EB, insurers use a secure portal or API. Other lines: still e-mail. (BRD-8 BRID-005, 005.01-005.02, 009) | I35: OQ29, Q31 | J35: DCR-096, DCR-211
A36: Q07 | B36: BRD-1 NB | C36: Encryption | D36: Password convention for outbound documents (standard vs generated syntax, e.g. surname + birth date); which documents to clients vs insurers. | E36: BRNB.013, 035, 077 | F36: Partially answered | G36: Standard assigned password or system-generated with a defined syntax, sent separately. The convention itself is still missing. (BRD-8 BRID-007) | I36: EBQ09, PQ21, CSQ06, RQ16 | J36: DCR-072, DCR-153
A37: Q08 | B37: BRD-1 NB | C37: Integration | D37: Which 'BDOI systems' must receive NB data (core/accounting, CRM, GRF/ARF, data warehouse) and preferred interface (file vs API). | E37: BRNB.015, 096 | F37: Partially answered | G37: QPS and EBIX receive client contact updates during coexistence (BRD-9); BRD-13 makes legacy read-only after cutover with no feed required (conflict DCR-202). Accounting is internal to BIBS. Other targets open. (BRD-9 p.3 footnote 3; BRD-5 FRBS 2.5.0; BRD-13 p.5) | I37: PQ16 | J37: DCR-104, DCR-202
A38: Q09 | B38: BRD-1 NB | C38: Renewals | D38: Late Renewal Requests Report is renewal-related - confirm it stays in NB scope or moves to the Renewal BRD. | E38: BRNB.018 | F38: Open | H38: XQ09 | J38: DCR-009
A39: Q10 | B39: BRD-1 NB | C39: Workflow | D39: Confirm the master list of stages and statuses and allowed transitions per transaction type (NB individual, NB bulk, non-package, direct booking, endorsement). | E39: BRNB.022, 115 | F39: Partially answered | G39: Renewal stages and statuses, and package negotiation outcomes. Counter mapping still to confirm. (BRD-6 personas, tabs, counters, BRRN.040; BRD-3 PMADD04) | I39: RQ10 | J39: DCR-070
A40: Q11 | B40: BRD-1 NB | C40: HLS | D40: HLS interface specification (format, fields, frequency, transport, source authentication) and other source systems for bulk (e.g. auto loans for FFYMI). | E40: BRNB.023, 028 | F40: Partially answered | G40: Sources named (LFS, HLS, CIU, SPI, LAMD, Loan Booking Report, IA masterlist), all Excel. Layouts and transport open. (BRD-12 p.4-5; Report List #138, #151) | I40: SP-SQ01 | J40: DCR-216
A41: Q12 | B41: BRD-1 NB | C41: E-mail intake | D41: Should the system read a shared mailbox for quotation requests automatically, or is manual capture with the e-mail attached sufficient? | E41: BRNB.041 | F41: Open
...

Sheet NFR comparison
A1: NFR comparison
A2: Every NFR theme against each BRD's value. Conflicting rows are highlighted; grey cells: not stated or 'follow QPS'.
A4: NFR theme | B4: BRD-0 CORE | C4: BRD-1 NB | D4: BRD-2 OPS | E4: BRD-3 PM | F4: BRD-4 CLXN | G4: BRD-5 ACCT | H4: BRD-6 RN | I4: BRD-7 CLM | J4: BRD-8 EB | K4: BRD-9 CSF | L4: BRD-10 SANC | M4: BRD-11 UAM | N4: BRD-12 SP | O4: BRD-13 DM | P4: Aligned? | Q4: Proposed BIBS-wide value | R4: Register items
A5: Availability target | B5: Refer to BRD (p.44) | C5: Follow existing QPS set up (p.212) | D5: 99.9% (p.115) | E5: 99.9% (p.33) | F5: Not stated; no downtime when scaling (p.54-55) | G5: Main BRD: follow QPS / EBIX (p.138). Addendum 1: 100% (p.37) | H5: Follow existing QPS set up (p.187) | I5: Not stated | J5: 99.99% (p.53) | K5: 99.9% (p.13) | L5: 99.9% (p.24) | M5: Follow existing QPS set up (p.11) | N5: 99.9% uptime (p.14) | O5: Not stated; refers to the consolidated NFR, not in the pack (p.13-14) | P5: CONFLICT | Q5: 99.9% within service hours | R5: DCR-134, DCR-057
