Workbook

Sheet Cover
B6: ESTIMATE
B7: Change Request Effort Estimate
B8: BRD-03 Product Maintenance – points beyond the BRD of the FRS v1.3: change requests with their effort
B9: BIBS – BDOI Broker System
B11: Client | C11: BDO Insurance and Reinsurance Brokers, Inc.
B12: BRD | C12: BRD-03
B13: Version | C13: 1.0
B14: Date | C14: 11 October 2026
B15: Classification | C15: Confidential
B16: Prepared by | C16: iorta TechNXT
B18: Sheets
B19: Sheet | C19: Content | D19: Rows
B20: README | C20: What each column of each sheet means, with the allowed values
B21: Summary | C21: Totals of the points beyond the BRD of the FRS v1.3 (Annex Y) | D21: 15
B22: CR Effort | C22: One row per orange point of the FRS v1.3 (Annex Y.2), effort in man-days | D22: 2
B23: Beyond the BRD - OOTB | C23: Points beyond the BRD that the iNXT BrokerVerse OOTB platform provides (green): no cost | D23: 1
B24: BRD covered - OOTB | C24: BRD requirements (black in the FRS, in scope) that the iNXT BrokerVerse OOTB platform provides: no change request, no effort | D24: 4
B25: Integration & DM scope | C25: Covered by the Integration scope or the Data Migration scope (BRD-13): no CR cost here | D25: 23
B26: Best practice (blue) | C26: Not in the BRD, the FRS or the OOTB platform: recommendations (Annex Y.6), not commitments | D26: 3
B27: BRD items to deliver | C27: BRD requirements not fully met by the OOTB platform: in-scope delivery work for planning, not CRs | D27: 20
B28: Assumptions | C28: Man-day, range and day rate used by the formulas | D28: 0
B31: Prepared by iorta TechNXT for BDOI. Confidential – BDOI.

Sheet README
A1: README – columns of each sheet
A2: Change Request Effort Estimate, version 1.0. Drop-down columns accept only the listed values.
A4: Sheet | B4: Column | C4: Meaning | D4: Allowed values
A5: Summary | B5: Item | C5: What is counted
A6: Summary | B6: Value | C6: Count, man-days or cost
A7: CR Effort | B7: CR No. | C7: Change request (FRS Annex Y.2 and the CR register)
A8: CR Effort | B8: Title | C8: The change
A9: CR Effort | B9: FRS reference | C9: FR item or annex row
A10: CR Effort | B10: BRD reference | C10: BRD ID it extends, or 'Not in BRD'
A11: CR Effort | B11: BRD relation | C11: Extends a BRD requirement / Not in any BRD | D11: Extends a BRD requirement, Not in any BRD
A12: CR Effort | B12: Where the point comes from | C12: Document and section
A13: CR Effort | B13: Why needed | C13: Business reason
A14: CR Effort | B14: Feature List ID / OOTB status | C14: Programme Feature List, column OOTB platform
A15: CR Effort | B15: OOTB evidence | C15: Screen or function of brokerverse-platform, or 'not found'
A16: CR Effort | B16: Effort covers | C16: For a Partial feature: the missing part only
A17: CR Effort | B17: Estimate basis | C17: Size of the platform parts the change touches
A18: CR Effort | B18: Analysis & design (md) | C18: Man-days
A19: CR Effort | B19: Backend (md) | C19: Man-days
A20: CR Effort | B20: Frontend (md) | C20: Man-days
A21: CR Effort | B21: Testing (md) | C21: Man-days
A22: CR Effort | B22: Documentation / UAT support (md) | C22: Man-days
A23: CR Effort | B23: Total (md) | C23: Sum of the activities
... A26: CR Effort | B26: Cost (PHP) | C26: Total x day rate (Assumptions)
A27: CR Effort | B27: Complexity | C27: Low / Medium / High | D27: Low, Medium, High
A28: CR Effort | B28: Priority | C28: High / Medium / Low | D28: High, Medium, Low
A29: CR Effort | B29: Dependencies | C29: What the change needs first
A30: CR Effort | B30: Assumptions | C30: Scope assumed by the estimate
A31: Beyond the BRD - OOTB | B31: No. | C31: Point (Annex Y.3)
A32: Beyond the BRD - OOTB | B32: Point | C32: The point of the FRS
A33: Beyond the BRD - OOTB | B33: FRS reference | C33: FR item or annex
A34: Beyond the BRD - OOTB | B34: Feature List ID / OOTB status | C34: Programme Feature List, column OOTB platform
A35: Beyond the BRD - OOTB | B35: OOTB evidence | C35: Screen or function of brokerverse-platform
A36: Beyond the BRD - OOTB | B36: BRD reference | C36: Not in the BRD
A37: Beyond the BRD - OOTB | B37: Cost (md) | C37: Zero
A38: BRD covered - OOTB | B38: No. | C38: Former green point
A39: BRD covered - OOTB | B39: Point | C39: The point of the FRS
A40: BRD covered - OOTB | B40: FRS reference | C40: FR item or annex
... A45: Integration & DM scope | B45: Item | C45: Interface or data load
A46: Integration & DM scope | B46: Scope | C46: Integration or Data Migration | D46: Integration scope, Data Migration scope
A47: Integration & DM scope | B47: What | C47: What is exchanged or loaded
...

Sheet Summary
A1: Summary
A2: Totals of the points beyond the BRD of the FRS v1.3 (Annex Y)
A4: Item | B4: Value
A5: Points beyond the BRD available OOTB (green, no cost) | B5: 1
A6: BRD requirements offered OOTB (black, in scope, no effort) | B6: 4
A7: Change requests (orange) | B7: 1
A8: Man-days: Analysis & design | B8: =SUM('CR Effort'!L5:L5)
A9: Man-days: Backend | B9: =SUM('CR Effort'!M5:M5)
A10: Man-days: Frontend | B10: =SUM('CR Effort'!N5:N5)
A11: Man-days: Testing | B11: =SUM('CR Effort'!O5:O5)
A12: Man-days: Documentation / UAT support | B12: =SUM('CR Effort'!P5:P5)
A13: Total change request man-days | B13: =SUM('CR Effort'!Q5:Q5)
A14: Range low (-20%) | B14: =SUM('CR Effort'!R5:R5)
A15: Range high (+20%) | B15: =SUM('CR Effort'!S5:S5)
A16: Cost in PHP at the day rate of the Assumptions sheet | B16: =SUM('CR Effort'!T5:T5)
A17: Items covered by the Integration or Data Migration scope (no CR cost) | B17: 23
A18: Best-practice recommendations (blue; indicative, not in the CR total) | B18: 3
A19: Best-practice indicative man-days (not in the CR total) | B19: 14

Sheet CR Effort
A1: CR Effort
A2: One row per orange point of the FRS v1.3 (Annex Y.2), effort in man-days
A4: CR No. | B4: Title | C4: FRS reference | D4: BRD reference | E4: BRD relation | F4: Where the point comes from | G4: Why needed | H4: Feature List ID / OOTB status | I4: OOTB evidence | J4: Effort covers | K4: Estimate basis | L4: Analysis & design (md) | M4: Backend (md) | N4: Frontend (md) | O4: Testing (md) | P4: Documentation / UAT support (md) | Q4: Total (md) | R4: Low (-20%) | S4: High (+20%) | T4: Cost (PHP) | U4: Complexity | V4: Priority | W4: Dependencies | X4: Assumptions
A5: CR-PM-101 | B5: Accessibility of the Product Maintenance screens (WCAG 2.2 level AA) | C5: Annex T, T-15 | D5: Not in BRD | E5: Not in any BRD | F5: Programme register of non-functional requirements (NFR-ACC-01, NFR-ACC-02), proposed in FRS v1.2 Annex T | G5: No BDOI BRD asks for an accessibility level; the programme register proposes WCAG 2.2 AA so that keyboard and screen-reader users can work in the module. | H5: NFR-021 Partial (contrast checked to WCAG AA in the theme; no accessibility statement or full WCAG audit) | I5: Branding: contrast check only; no WCAG audit | J5: Partial in BrokerVerse OOTB; the effort covers the missing part only: the WCAG 2.2 AA check and fixes of the module screens. | K5: Product Maintenance screens: 35 screen files, about 3,800 lines. | L5: 1.5 | M5: 0 | N5: 6 | O5: 3 | P5: 1 | Q5: =SUM(L5:P5) | R5: =ROUND(Q5*(1-Assumptions!$B$6),1) | S5: =ROUND(Q5*(1+Assumptions!$B$6),1) | T5: =Q5*Assumptions!$B$7 | U5: Medium | V5: Low | W5: BDOI's decision on the accessibility level (Annex V, PQ18) | X5: Check and fixes on the 35 Product Maintenance screen files (about 3,800 lines) and the product master screens; no redesign.
A6: Total | B6: 1 change requests | L6: =SUM(L5:L5) | M6: =SUM(M5:M5) | N6: =SUM(N5:N5) | O6: =SUM(O5:O5) | P6: =SUM(P5:P5) | Q6: =SUM(Q5:Q5) | R6: =SUM(R5:R5) | S6: =SUM(S5:S5) | T6: =SUM(T5:T5)

Sheet Beyond the BRD - OOTB
A1: Beyond the BRD - OOTB
A2: Points beyond the BRD that the iNXT BrokerVerse OOTB platform provides (green): no cost
A4: No. | B4: Point | C4: FRS reference | D4: Feature List ID / OOTB status | E4: OOTB evidence | F4: BRD reference | G4: Cost (md)
A5: G-02 | B5: Premium Calculator on the package rate scheme | C5: FRPM.002.01 | D5: PRD-005 Available | E5: Product Configurator > Rating Engine: premium calculation | F5: Not in BRD | G5: 0

Sheet BRD covered - OOTB
A1: BRD covered - OOTB
A2: BRD requirements (black in the FRS, in scope) that the iNXT BrokerVerse OOTB platform provides: no change request, no effort
A4: No. | B4: Point | C4: FRS reference | D4: BRD line | E4: Feature List ID / OOTB status | F4: OOTB evidence | G4: Effort (md)
A5: G-01 | B5: TSU Workbench with the TSU queues by stage (team worklist) | C5: FRPM.002.01 | D5: BRPM.011 "Facility to allow User to receive and view requests for product creation, amend, updating, or deletion" ("The system displays all incoming requests with relevant details"); BRPM.019 "Dashboard for real-time tracking and reporting" ("Dashboard displays request status") | E5: WFL-005 Available | F5: My Work: personal and team worklists | G5: 0
A6: G-03 | B6: Report exported to PDF, Excel and CSV, every run logged | C6: FRPM.019.01 | D6: BRPM.018 "Reports are exportable in standard formats (PDF, Excel) for sharing or archiving"; "All report generation actions are logged for audit and traceability" | E6: RPT-011 Available; RPT-003 Partial (PDF, Excel and CSV available; Word and text exports, not asked here, are the missing part) | F6: Reports: exports and history of produced files | G6: 0
A7: G-04 | B7: E-mail log with recipient, time, subject and attachment | C7: FRPM.021.01 | D7: BRPM.024 "Ensure audit trail for all actions and changes" ("System logs all actions (creation, edits, approvals, sharing) for traceability"); the advisory e-mails of the BRD are a sharing action | E7: WFL-011 Available | F7: E-mail outbox with the status of each e-mail | G7: 0
A8: G-05 | B8: Old and new field values of changed master records | C8: FRPM.021.01; Annex M.5 | D8: BRPM.024 "Ensure audit trail for all actions and changes" ("Users can review a complete audit trail for any request or document"); programme NFR 4.01 "account changes" and 4.03 "Access and updates of customer records" (Collections, Claims, ReInsurance addenda) | E8: ADM-012 Available | F8: Audit trail: before and after values of every change | G8: 0

Sheet Integration & DM scope
A1: Integration & DM scope
A2: Covered by the Integration scope or the Data Migration scope (BRD-13): no CR cost here
A4: Item | B4: Scope | C4: What | D4: Where in the FRS
A5: IN-01 New Business (BRD-01) | B5: Integration scope | C5: Products and their flags, the latest approved rate scheme of each package, rate exceptions, incentive indicators | D5: FRS Annex S
A6: IN-02 New Business (BRD-01): client master | B6: Integration scope | C6: Client look-up on client-specific package requests | D6: FRS Annex S
A7: IN-03 New Business (BRD-01): non-package requests | B7: Integration scope | C7: Quotation requests, Quotation Slips, proposals and client responses (BDOI's FRPM.005 to FRPM.010) | D7: FRS Annex S
A8: IN-04 Operations (BRD-02) | B8: Integration scope | C8: Package version for endorsement re-rating; incentive codes for commission | D8: FRS Annex S
A9: IN-05 Renewal (BRD-06) | B9: Integration scope | C9: Package version of the expiring account | D9: FRS Annex S
A10: IN-06 User Access Maintenance (BRD-11) | B10: Integration scope | C10: Users, roles, sign-in through BDO sign-in (Entra ID) | D10: FRS Annex S
A11: IN-07 Data Migration (BRD-13) | B11: Integration scope | C11: Go-live product masters, insurers, commission rates; package map of legacy packages | D11: FRS Annex S
A12: IN-08 E-mail channel of BDOI (Microsoft 365 or CCM) | B12: Integration scope | C12: Quotation Slips, advisories, ManCom notices, password e-mails | D12: FRS Annex S
A13: IN-09 Insurers | B13: Integration scope | C13: Protected Quotation Slips; replies received by e-mail and keyed in | D13: FRS Annex S
A14: IN-10 Document store (ECM) | B14: Integration scope | C14: Package documents and attachments | D14: FRS Annex S
A15: IN-11 Other BDOI systems (to be named) | B15: Integration scope | C15: Product master changes (package added, updated, deactivated or expired: product, version, effective date, request, status) in the file ProductMaster_yyyyMMddHHmmss.csv | D15: FRS Annex S
... A27: U-12 | B27: Data Migration scope | C27: Users and roles of the module; ManCom approver list | D27: FRS Annex U

Sheet Best practice (blue)
A1: Best practice (blue)
A2: Not in the BRD, the FRS or the OOTB platform: recommendations (Annex Y.6), not commitments
A4: ID | B4: Practice | C4: Why it matters for a broker | D4: Suggested priority | E4: Indicative man-days
A5: BP-PM-01 | B5: Periodic package performance review: take-up, premium, claims experience and loss ratio per package, with a recorded decision to keep, redesign or retire it before renewal | C5: Packages sold through the bank stay fair value for clients and viable for insurers; Insurance Commission conduct expectations for products sold through banks | D5: Medium | E5: 6
A6: BP-PM-02 | B6: Product disclosure sheet per package for the bank channel (key features, exclusions, insurer, BDOI's role as broker), produced from the released package version | C6: Bancassurance sales need clear pre-sale disclosure; one source avoids outdated brochures (Insurance Commission and BSP bancassurance rules) | D6: High | E6: 5
A7: BP-PM-03 | B7: Data-sharing record on client-specific packages: the basis for sharing with each insurer of the package and the client data sent in Quotation Slips | C7: Data Privacy Act: personal data shared with insurers needs a documented basis and only the minimum data | D7: Medium | E7: 3

Sheet BRD items to deliver
A1: BRD items to deliver
A2: BRD requirements not fully met by the OOTB platform: in-scope delivery work for planning, not CRs
A4: BRD ID | B4: BRD requirement | C4: Fit | D4: What iNXT BrokerVerse offers out of the box | E4: Planning man-days
A5: PMADD01 | B5: I want a standard reusable product structure hierarchy so that product data is consistent and scalable across packaged and non-packaged products. | C5: Configure | D5: PRD-001 Single product catalogue keyed by BDOI risk code: Available – Line of business, product and cover masters with product templates per line; BDOI codes loaded as master data. PRD-002 Standard product hierarchy enforced complete: Partial – Line, product, template and Coverage Builder exist; no subtype level and no completeness rule on the hierarchy.
A6: PMADD02 | B6: I want insurer-specific coverage, deductibles, and warranty mappings maintained without IT intervention so that insurer variability is supported in a controlled manner. | C6: Configure | D6: PRD-014 Clause, warranty and exclusion library: Not available – Clauses and warranties are free text on offers and documents; no maintained library. PRD-015 Insurer-specific coverage, deductible and warranty mapping: Partial – Insurer rate tables per product (rate basis, minimum premium, deductible, commission) and market mapping terms; no coverage-level terms per insurer. PRD-016 Insurer panel per product: Available – Insurer panel per template; market restricted when the setting is on. QPL-016 Co-insurance with lead and shares: Available – Shares must total exactly 100% with one lead; taxes, payables and commission split per participant.
A7: PMADD04 | B7: I want to have explicit exception states and iterative negotiation loop support so that non-linear insurer negotiations, revisions, and declines are handled as formal workflow outcomes rather than informal handling. | C7: Configure | D7: PRD-019 Package negotiation rounds with insurers: Partial – Request for Quotation to several insurers with offers, declines and terms, set up for one client risk; no rounds or outcome states for a programme.
A8: PMADD07 | B8: I want to define and maintain Incentive criteria based on the Maintained Products Matrix, so that incentives are accurately configured and applied only to eligible product combinations. | C8: Configure | D8: PRD-026 Incentive criteria on the products matrix: Partial – Incentive programmes by target metric for account executives; no product-level eligibility criteria.
A9: PMADD08 | B9: I must have a maintenance facility to define and update Incentives (i.e. CPC2) criteria based on the maintained products. | C9: Configure | D9: PRD-026 Incentive criteria on the products matrix: Partial – Incentive programmes by target metric for account executives; no product-level eligibility criteria.
A10: BRPM.003 | B10: There must be a capability to capture, store, and validate all mandatory, critical and product-specific fields. | C10: Configure | D10: PRD-003 Product-specific risk fields per line: Partial – Risk mappings with risk sections per product line; the quote wizard asks for the fields the rules test (require rule fields). No minimum-field matrix per product.
A11: BRPM.004 | B11: There must be a capability to apply validation rules based on product type. | C11: Configure | D11: PRD-004 Configurable validation rules per product: Partial – Acceptance rules accept, refer, decline or load on risk fields; acceptance limits on sum insured and ages. No general data-validation rule set.
A12: BRPM.005 | B12: There must be a capability to use shared templates with dynamic fields for product-specific data. | C12: Configure | D12: PRD-027 Document templates per product with merge fields: Available – Templates per product with merge fields and blocks, preview, printed on the letterhead; unknown merge fields refused.
A13: BRPM.008 | B13: Submit approved Package Request Form. | C13: Extend | D13: PRD-018 Package request with multi-level approval: Not available – Products are created directly in the configurator; no request or approval chain. ADM-013 Document numbering formats: Available – 85 series with prefix, pattern, width, reset rule and start number; counters only move forward.
A14: BRPM.011 | B14: Facility to allow User to receive and view requests for product creation, amend, updating, or deletion based on client or business needs. | C14: Recommend change | D14: PRD-018 Package request with multi-level approval: Not available – Products are created directly in the configurator; no request or approval chain.
A15: BRPM.015 | B15: Received product requirements from TSU. (i.e. computation and details that Marketing needed for their transactions). Product requirements and details from TSU are submitted via the system, triggering a ManCom review and signoff workflow. Only after ManCom’s in-system approval are requirements automatically forwarded to MBS for processing. MBS receives only validated, signed-off requirements and returns incomplete submissions. Marketing is notified by the system when the package is ready. While some manual steps (like physical signatures) may still occur, most information should flow through the system. | C15: Extend | D15: PRD-005 Rating engine with factors, minimum premium and test calculator: Available – Multiplicative, discount and additive factors, minimum premium, illustration per template; the server re-prices every quotation. PRD-017 Package products with negotiated rates per insurer: Available – Bundles and insurer rate tables with minimum premium, deductible and commission per insurer and product. PRD-021 ManCom sign-off and hand-off to set-up: Not available – No requirements pack, committee step or hand-off.
A16: BRPM.017 | B16: The system must enable the TSU Officer to monitor the expiry or anniversary date of each insurance package | C16: Extend | D16: PRD-023 Package expiry monitoring and renewal request: Partial – Template expiry dates and an expiring-templates list (warning period of 60 days); no renewal request.
... A21: BRPM.024 | B21: Ensure audit trail for all actions and changes. | C21: Extend | D21: Audit history of changes per record.
A22: D-PM-01 | B22: Quotation Slip decision notice to the preparer (FRPM.006.01, FRPM.012.01; Annex P NT-16). BRD line: BRPM.021 AC5: 'The system notifies users of pending validation or approval actions and tracks resolution within the SLA'; BRPM.012: 'Prepare and send quotation slip to Insurers' | C22: BRD point to deliver | D22: PRD-019 Partial (no negotiation rounds or slip approval for a programme); WFL-010 Available (in-app notices). Partial in BrokerVerse OOTB: notices are available, the package slip approval is not; effort for the notice of the slip decision only. | E22: 3.5
A23: D-PM-02 | B23: ManCom e-mails in BDOI's wording, with the President's text (FRPM.014.01; Annex P NT-13, NT-14). BRD line: BRPM.015: 'a ManCom review and signoff workflow with audit logging'; BRPM.022: 'Notification and integration for seamless data flow' | C23: BRD point to deliver | D23: PRD-021 Not available (no committee step or hand-off). Not available in BrokerVerse OOTB. The effort is for the routing and the two BDOI texts. | E23: 2.5
A24: D-PM-03 | B24: 'Due soon' marker at 80% of the stage service level (FRPM.001.01). BRD line: BRPM.021 ER3: 'Each approval step is completed by the designated authority ... within the defined SLA'; AC5 'tracks resolution within the SLA' | C24: BRD point to deliver | D24: WFL-007 Partial (deadlines and escalation for claims, complaints, leads and collections; no general turnaround engine). Partial in BrokerVerse OOTB; the planning effort covers the missing part only: the marker at a percentage of each stage's service level. | E24: 3.5

Sheet Assumptions
A1: Assumptions
A3: Item | B3: Value | C3: Note
A4: Hours in a man-day | B4: 8 | C4: One man-day (md) = 8 working hours
A5: Currency | B5: PHP | C5: Philippine peso
A6: Estimate range (plus or minus) | B6: 0.2 | C6: Each total is an estimate within plus or minus 20%
A7: DayRate (PHP per man-day) | C7: Enter the agreed day rate; the cost columns follow by formula
A8: OOTB baseline | B8: brokerverse-platform | C8: iNXT BrokerVerse OOTB platform (brokerverse-platform), with the programme Feature List (column OOTB platform) as a cross-check
A9: Basis | B9: Platform size | C9: Effort from the size of the platform parts each change touches and a similar existing function; for a Partial feature, the missing part only
A10: Not change requests | B10: - | C10: BRD requirements (in scope), Integration scope and Data Migration scope items, best-practice recommendations
A11: Excluded | B11: - | C11: BDOI decisions and inputs, BDOI testing time, infrastructure
A12: Validity | B12: 30 days | C12: Estimated again if the scope of a change request changes

Sheet Lists
A1: CR Effort: BRD relation | B1: CR Effort: Complexity | C1: CR Effort: Priority | D1: Integration & DM scope: Scope | E1: Best practice (blue): Suggested priority
A2: Extends a BRD requirement | B2: Low | C2: High | D2: Integration scope | E2: High
A3: Not in any BRD | B3: Medium | C3: Medium | D3: Data Migration scope | E3: Medium
B4: High | C4: Low | E4: Low
