Workbook

Sheet Cover
B6: BDOI INPUTS WORKBOOK
B7: BDOI Requirements and Inputs by BRD
B8: What the project needs from the BDOI business users, BRD by BRD
B9: BIBS – BDOI Broker System
B11: Client | C11: BDO Insurance and Reinsurance Brokers, Inc.
B12: BRD | C12: BRD-00 (all BRDs)
B13: Version | C13: 1.0
B14: Date | C14: 8 October 2026
B15: Classification | C15: Confidential
B16: Prepared by | C16: iorta TechNXT
B18: Sheets
B19: Sheet | C19: Content | D19: Rows
B20: README | C20: What each column of each sheet means, with the allowed values
B21: Instructions | C21: How to read and answer this workbook | D21: 0
B22: Summary | C22: Counts per BRD and type, status, owners and due dates | D22: 0
B23: BRD-00 Cross-cutting | C23: BRD-00 Core Replacement and cross-cutting points: what BDOI provides; owner BIBS Product Owner with the Program Manager, Business Project Services | D23: 144
B24: BRD-01 New Business | C24: BRD-01 New Business: what BDOI provides; owner Product Owner, New Business | D24: 76
B25: BRD-02 Operations | C25: BRD-02 Operations: what BDOI provides; owner Head, Operations Services | D25: 89
B26: BRD-03 Product Maintenance | C26: BRD-03 Product Maintenance: what BDOI provides; owner Product Owner, Marketing Business System (MBS) | D26: 79
B27: BRD-04 Collections | C27: BRD-04 Collections: what BDOI provides; owner VP and Head, BDOI Operations (Collections) | D27: 58
B28: BRD-05 Accounting and ACSL | C28: BRD-05 Accounting, Disbursement and ACSL: what BDOI provides; owner Head, Comptrollership | D28: 85
B29: BRD-06 Renewal | C29: BRD-06 Renewal: what BDOI provides; owner Product Owner, Renewal | D29: 64
B30: BRD-07 Claims | C30: BRD-07 Claims: what BDOI provides; owner Product Owner, Claims | D30: 38
B31: BRD-08 Employee Benefits | C31: BRD-08 Employee Benefits: what BDOI provides; owner Product Owner, Employee Benefits | D31: 34
B32: BRD-09 Customer Servicing | C32: BRD-09 Customer Servicing Facility: what BDOI provides; owner Product Owner, Customer Servicing Facility | D32: 26
... B37: RI Reinsurance (phase 2) | C37: Phase 2 ReInsurance (phase 2): what BDOI provides; owner BIBS Product Owner with the Head, Operations (Remittance) | D37: 5
B39: Legend
B40: Open | C40: Waiting for the BDOI answer
B41: Partly answered | C41: BDOI has answered in part; the rest of the point is open
B42: Answered | C42: BDOI has answered; the answer is applied and BDOI confirms it
B45: Prepared by iorta TechNXT for BDOI. Confidential – BDOI.

Sheet Instructions
A1: Instructions
A2: BDOI Requirements and Inputs by BRD, version 1.0, 8 October 2026
A4: Purpose | B4: This workbook lists, BRD by BRD, everything the project needs from the BDOI business users to complete the requirements, set BIBS up and test it: decisions, clarifications, confirmations of the proposed rules, configuration values, master data, sample documents, report layouts, integration details, test data and sign-offs. It answers the request of the BDOI product owner of 8 October 2026 for the BRD-specific requirements from the BDOI users.
A5: Where the rows come from | B5: The rows bring together the proposed business rules and clarifications (CLR) and the open questions of every FRS and of the Data Migration set, the discrepancy and clarification register, the earlier Drop 0 requirements list, the Drop 0 configuration register, the NFR targets and the dependencies, sign-offs and test windows of the project plan. A point raised in several documents is listed once; the Source column gives every ID under which it was raised, so an answer given against any of them is found here.
A6: One tab per BRD | B6: BRD-00 holds the cross-cutting points (several BRDs, programme, NFR targets, infrastructure and integrations). BRD-01 to BRD-13 hold the points of each BRD. The last tab holds the few points of ReInsurance, which is phase 2.
A7: How to answer | B7: Write the answer in BDOI response, set Status to Answered (or Partly answered) and send the workbook back to the iorta TechNXT project team. Where a proposal is given, an answer of 'Agree' is enough; otherwise give the decision, the value or attach the document and name it in the response. Do not change the Ref, so that the answer is traced back to the FRS, the register and the templates.
A8: Needed by and priority | B8: Needed by is the date of the project plan of 8 October 2026 by which the input is needed: the sign-off of the FRS or sign-off set of the BRD for decisions and clarifications, the configuration milestones (D1 to D7) for values and master data, the integration specifications for interface details and the UAT preparation for test data. High blocks a sign-off, the set-up or a test window; Medium is needed before UAT; Low can follow.
A9: Status | B9: The status is taken from the latest sources: Answered where BDOI has answered (the answer is in Remarks and BDOI confirms it), Partly answered where part of the point is answered, Open otherwise. Answered points stay in the list so that every answer is visible.
A10: Master data and configuration | B10: The rows of type Master data and Configuration value name the template to fill in. The templates are in the companion workbook BIBS_Templates_BRD-00_Master_Data_and_Configuration_Upload_Templates_v1.0, with its guide; fill the data there, not in this workbook.
A11: Proposals | B11: Until BDOI answers, the proposal of a row is the working assumption of the project team; the screens, tests and set-up follow it, and a different answer is applied by the change control of the programme.
A13: Types of input
A14: Type | B14: What BDOI provides
A15: Decision | B15: BDOI chooses between options or sets the scope; the choice changes what is delivered.
A16: Clarification | B16: The BRD text is unclear, incomplete or contradictory; BDOI explains what is meant.
A17: Business rule confirmation | B17: The project team proposes a rule; BDOI confirms it or gives its own.
A18: Configuration value | B18: A value BIBS is set up with: limits, days, rates, lists, numbering, parameters.
A19: Master data | B19: Records BIBS needs before go-live: organisation, users, products, insurers, accounts, clients.
A20: Sample document or template | B20: A letter, form, advice, slip or e-mail in the BDOI layout and wording.
A21: Report layout | B21: The columns, totals and filters of a report or an extract.
A22: Integration detail | B22: A file layout, interface, transport or contact of another system.
A23: Test data | B23: Testers, cases and business data for SIT and UAT.
A24: Sign-off | B24: A document or test result BDOI signs.

Sheet Summary
A1: Summary
A2: Counts per BRD, type and status follow the tabs as they are answered (formulas); owners and dates as issued.
A4: Items per BRD and type
A5: BRD | B5: Name | C5: Drop | D5: BDOI owner (role) | E5: Items | F5: Decision | G5: Clarification | H5: Business rule confirmation | I5: Configuration value | J5: Master data | K5: Sample document or template | L5: Report layout | M5: Integration detail | N5: Test data | O5: Sign-off | P5: Open | Q5: Partly answered | R5: Answered | S5: First needed by | T5: Last needed by
A6: BRD-00 | B6: Core Replacement and cross-cutting points | C6: Programme | D6: BIBS Product Owner with the Program Manager, Business Project Services | E6: =COUNTA('BRD-00 Cross-cutting'!A5:A649) | F6: =COUNTIF('BRD-00 Cross-cutting'!C5:C649,"Decision") | G6: =COUNTIF('BRD-00 Cross-cutting'!C5:C649,"Clarification") | H6: =COUNTIF('BRD-00 Cross-cutting'!C5:C649,"Business rule confirmation") | I6: =COUNTIF('BRD-00 Cross-cutting'!C5:C649,"Configuration value") | J6: =COUNTIF('BRD-00 Cross-cutting'!C5:C649,"Master data") | K6: =COUNTIF('BRD-00 Cross-cutting'!C5:C649,"Sample document or template") | L6: =COUNTIF('BRD-00 Cross-cutting'!C5:C649,"Report layout") | M6: =COUNTIF('BRD-00 Cross-cutting'!C5:C649,"Integration detail") | N6: =COUNTIF('BRD-00 Cross-cutting'!C5:C649,"Test data") | O6: =COUNTIF('BRD-00 Cross-cutting'!C5:C649,"Sign-off") | P6: =COUNTIF('BRD-00 Cross-cutting'!K5:K649,"Open") | Q6: =COUNTIF('BRD-00 Cross-cutting'!K5:K649,"Partly answered") | R6: =COUNTIF('BRD-00 Cross-cutting'!K5:K649,"Answered") | S6: =MIN('BRD-00 Cross-cutting'!I5:I649) | T6: =MAX('BRD-00 Cross-cutting'!I5:I649)
A7: BRD-01 | B7: New Business | C7: Drop 1 | D7: Product Owner, New Business | E7: =COUNTA('BRD-01 New Business'!A5:A581) | F7: =COUNTIF('BRD-01 New Business'!C5:C581,"Decision") | G7: =COUNTIF('BRD-01 New Business'!C5:C581,"Clarification") | H7: =COUNTIF('BRD-01 New Business'!C5:C581,"Business rule confirmation") | I7: =COUNTIF('BRD-01 New Business'!C5:C581,"Configuration value") | J7: =COUNTIF('BRD-01 New Business'!C5:C581,"Master data") | K7: =COUNTIF('BRD-01 New Business'!C5:C581,"Sample document or template") | L7: =COUNTIF('BRD-01 New Business'!C5:C581,"Report layout") | M7: =COUNTIF('BRD-01 New Business'!C5:C581,"Integration detail") | N7: =COUNTIF('BRD-01 New Business'!C5:C581,"Test data") | O7: =COUNTIF('BRD-01 New Business'!C5:C581,"Sign-off") | P7: =COUNTIF('BRD-01 New Business'!K5:K581,"Open") | Q7: =COUNTIF('BRD-01 New Business'!K5:K581,"Partly answered") | R7: =COUNTIF('BRD-01 New Business'!K5:K581,"Answered") | S7: =MIN('BRD-01 New Business'!I5:I581) | T7: =MAX('BRD-01 New Business'!I5:I581)
A8: BRD-02 | B8: Operations | C8: Drop 1 | D8: Head, Operations Services | E8: =COUNTA('BRD-02 Operations'!A5:A594) | F8: =COUNTIF('BRD-02 Operations'!C5:C594,"Decision") | G8: =COUNTIF('BRD-02 Operations'!C5:C594,"Clarification") | H8: =COUNTIF('BRD-02 Operations'!C5:C594,"Business rule confirmation") | I8: =COUNTIF('BRD-02 Operations'!C5:C594,"Configuration value") | J8: =COUNTIF('BRD-02 Operations'!C5:C594,"Master data") | K8: =COUNTIF('BRD-02 Operations'!C5:C594,"Sample document or template") | L8: =COUNTIF('BRD-02 Operations'!C5:C594,"Report layout") | M8: =COUNTIF('BRD-02 Operations'!C5:C594,"Integration detail") | N8: =COUNTIF('BRD-02 Operations'!C5:C594,"Test data") | O8: =COUNTIF('BRD-02 Operations'!C5:C594,"Sign-off") | P8: =COUNTIF('BRD-02 Operations'!K5:K594,"Open") | Q8: =COUNTIF('BRD-02 Operations'!K5:K594,"Partly answered") | R8: =COUNTIF('BRD-02 Operations'!K5:K594,"Answered") | S8: =MIN('BRD-02 Operations'!I5:I594) | T8: =MAX('BRD-02 Operations'!I5:I594)
A9: BRD-03 | B9: Product Maintenance | C9: Drop 0 | D9: Product Owner, Marketing Business System (MBS) | E9: =COUNTA('BRD-03 Product Maintenance'!A5:A584) | F9: =COUNTIF('BRD-03 Product Maintenance'!C5:C584,"Decision") | G9: =COUNTIF('BRD-03 Product Maintenance'!C5:C584,"Clarification") | H9: =COUNTIF('BRD-03 Product Maintenance'!C5:C584,"Business rule confirmation") | I9: =COUNTIF('BRD-03 Product Maintenance'!C5:C584,"Configuration value") | J9: =COUNTIF('BRD-03 Product Maintenance'!C5:C584,"Master data") | K9: =COUNTIF('BRD-03 Product Maintenance'!C5:C584,"Sample document or template") | L9: =COUNTIF('BRD-03 Product Maintenance'!C5:C584,"Report layout") | M9: =COUNTIF('BRD-03 Product Maintenance'!C5:C584,"Integration detail") | N9: =COUNTIF('BRD-03 Product Maintenance'!C5:C584,"Test data") | O9: =COUNTIF('BRD-03 Product Maintenance'!C5:C584,"Sign-off") | P9: =COUNTIF('BRD-03 Product Maintenance'!K5:K584,"Open") | Q9: =COUNTIF('BRD-03 Product Maintenance'!K5:K584,"Partly answered") | R9: =COUNTIF('BRD-03 Product Maintenance'!K5:K584,"Answered") | S9: =MIN('BRD-03 Product Maintenance'!I5:I584) | T9: =MAX('BRD-03 Product Maintenance'!I5:I584)
A10: BRD-04 | B10: Collections | C10: Drop 1 | D10: VP and Head, BDOI Operations (Collections) | E10: =COUNTA('BRD-04 Collections'!A5:A563) | F10: =COUNTIF('BRD-04 Collections'!C5:C563,"Decision") | G10: =COUNTIF('BRD-04 Collections'!C5:C563,"Clarification") | H10: =COUNTIF('BRD-04 Collections'!C5:C563,"Business rule confirmation") | I10: =COUNTIF('BRD-04 Collections'!C5:C563,"Configuration value") | J10: =COUNTIF('BRD-04 Collections'!C5:C563,"Master data") | K10: =COUNTIF('BRD-04 Collections'!C5:C563,"Sample document or template") | L10: =COUNTIF('BRD-04 Collections'!C5:C563,"Report layout") | M10: =COUNTIF('BRD-04 Collections'!C5:C563,"Integration detail") | N10: =COUNTIF('BRD-04 Collections'!C5:C563,"Test data") | O10: =COUNTIF('BRD-04 Collections'!C5:C563,"Sign-off") | P10: =COUNTIF('BRD-04 Collections'!K5:K563,"Open") | Q10: =COUNTIF('BRD-04 Collections'!K5:K563,"Partly answered") | R10: =COUNTIF('BRD-04 Collections'!K5:K563,"Answered") | S10: =MIN('BRD-04 Collections'!I5:I563) | T10: =MAX('BRD-04 Collections'!I5:I563)
A11: BRD-05 | B11: Accounting, Disbursement and ACSL | C11: Drop 1 | D11: Head, Comptrollership | E11: =COUNTA('BRD-05 Accounting and ACSL'!A5:A590) | F11: =COUNTIF('BRD-05 Accounting and ACSL'!C5:C590,"Decision") | G11: =COUNTIF('BRD-05 Accounting and ACSL'!C5:C590,"Clarification") | H11: =COUNTIF('BRD-05 Accounting and ACSL'!C5:C590,"Business rule confirmation") | I11: =COUNTIF('BRD-05 Accounting and ACSL'!C5:C590,"Configuration value") | J11: =COUNTIF('BRD-05 Accounting and ACSL'!C5:C590,"Master data") | K11: =COUNTIF('BRD-05 Accounting and ACSL'!C5:C590,"Sample document or template") | L11: =COUNTIF('BRD-05 Accounting and ACSL'!C5:C590,"Report layout") | M11: =COUNTIF('BRD-05 Accounting and ACSL'!C5:C590,"Integration detail") | N11: =COUNTIF('BRD-05 Accounting and ACSL'!C5:C590,"Test data") | O11: =COUNTIF('BRD-05 Accounting and ACSL'!C5:C590,"Sign-off") | P11: =COUNTIF('BRD-05 Accounting and ACSL'!K5:K590,"Open") | Q11: =COUNTIF('BRD-05 Accounting and ACSL'!K5:K590,"Partly answered") | R11: =COUNTIF('BRD-05 Accounting and ACSL'!K5:K590,"Answered") | S11: =MIN('BRD-05 Accounting and ACSL'!I5:I590) | T11: =MAX('BRD-05 Accounting and ACSL'!I5:I590)
A12: BRD-06 | B12: Renewal | C12: Drop 1 | D12: Product Owner, Renewal | E12: =COUNTA('BRD-06 Renewal'!A5:A569) | F12: =COUNTIF('BRD-06 Renewal'!C5:C569,"Decision") | G12: =COUNTIF('BRD-06 Renewal'!C5:C569,"Clarification") | H12: =COUNTIF('BRD-06 Renewal'!C5:C569,"Business rule confirmation") | I12: =COUNTIF('BRD-06 Renewal'!C5:C569,"Configuration value") | J12: =COUNTIF('BRD-06 Renewal'!C5:C569,"Master data") | K12: =COUNTIF('BRD-06 Renewal'!C5:C569,"Sample document or template") | L12: =COUNTIF('BRD-06 Renewal'!C5:C569,"Report layout") | M12: =COUNTIF('BRD-06 Renewal'!C5:C569,"Integration detail") | N12: =COUNTIF('BRD-06 Renewal'!C5:C569,"Test data") | O12: =COUNTIF('BRD-06 Renewal'!C5:C569,"Sign-off") | P12: =COUNTIF('BRD-06 Renewal'!K5:K569,"Open") | Q12: =COUNTIF('BRD-06 Renewal'!K5:K569,"Partly answered") | R12: =COUNTIF('BRD-06 Renewal'!K5:K569,"Answered") | S12: =MIN('BRD-06 Renewal'!I5:I569) | T12: =MAX('BRD-06 Renewal'!I5:I569)
A13: BRD-07 | B13: Claims | C13: Drop 2 | D13: Product Owner, Claims | E13: =COUNTA('BRD-07 Claims'!A5:A543) | F13: =COUNTIF('BRD-07 Claims'!C5:C543,"Decision") | G13: =COUNTIF('BRD-07 Claims'!C5:C543,"Clarification") | H13: =COUNTIF('BRD-07 Claims'!C5:C543,"Business rule confirmation") | I13: =COUNTIF('BRD-07 Claims'!C5:C543,"Configuration value") | J13: =COUNTIF('BRD-07 Claims'!C5:C543,"Master data") | K13: =COUNTIF('BRD-07 Claims'!C5:C543,"Sample document or template") | L13: =COUNTIF('BRD-07 Claims'!C5:C543,"Report layout") | M13: =COUNTIF('BRD-07 Claims'!C5:C543,"Integration detail") | N13: =COUNTIF('BRD-07 Claims'!C5:C543,"Test data") | O13: =COUNTIF('BRD-07 Claims'!C5:C543,"Sign-off") | P13: =COUNTIF('BRD-07 Claims'!K5:K543,"Open") | Q13: =COUNTIF('BRD-07 Claims'!K5:K543,"Partly answered") | R13: =COUNTIF('BRD-07 Claims'!K5:K543,"Answered") | S13: =MIN('BRD-07 Claims'!I5:I543) | T13: =MAX('BRD-07 Claims'!I5:I543)
A14: BRD-08 | B14: Employee Benefits | C14: Drop 2 | D14: Product Owner, Employee Benefits | E14: =COUNTA('BRD-08 Employee Benefits'!A5:A539) | F14: =COUNTIF('BRD-08 Employee Benefits'!C5:C539,"Decision") | G14: =COUNTIF('BRD-08 Employee Benefits'!C5:C539,"Clarification") | H14: =COUNTIF('BRD-08 Employee Benefits'!C5:C539,"Business rule confirmation") | I14: =COUNTIF('BRD-08 Employee Benefits'!C5:C539,"Configuration value") | J14: =COUNTIF('BRD-08 Employee Benefits'!C5:C539,"Master data") | K14: =COUNTIF('BRD-08 Employee Benefits'!C5:C539,"Sample document or template") | L14: =COUNTIF('BRD-08 Employee Benefits'!C5:C539,"Report layout") | M14: =COUNTIF('BRD-08 Employee Benefits'!C5:C539,"Integration detail") | N14: =COUNTIF('BRD-08 Employee Benefits'!C5:C539,"Test data") | O14: =COUNTIF('BRD-08 Employee Benefits'!C5:C539,"Sign-off") | P14: =COUNTIF('BRD-08 Employee Benefits'!K5:K539,"Open") | Q14: =COUNTIF('BRD-08 Employee Benefits'!K5:K539,"Partly answered") | R14: =COUNTIF('BRD-08 Employee Benefits'!K5:K539,"Answered") | S14: =MIN('BRD-08 Employee Benefits'!I5:I539) | T14: =MAX('BRD-08 Employee Benefits'!I5:I539)
A15: BRD-09 | B15: Customer Servicing Facility | C15: Drop 1 | D15: Product Owner, Customer Servicing Facility | E15: =COUNTA('BRD-09 Customer Servicing'!A5:A531) | F15: =COUNTIF('BRD-09 Customer Servicing'!C5:C531,"Decision") | G15: =COUNTIF('BRD-09 Customer Servicing'!C5:C531,"Clarification") | H15: =COUNTIF('BRD-09 Customer Servicing'!C5:C531,"Business rule confirmation") | I15: =COUNTIF('BRD-09 Customer Servicing'!C5:C531,"Configuration value") | J15: =COUNTIF('BRD-09 Customer Servicing'!C5:C531,"Master data") | K15: =COUNTIF('BRD-09 Customer Servicing'!C5:C531,"Sample document or template") | L15: =COUNTIF('BRD-09 Customer Servicing'!C5:C531,"Report layout") | M15: =COUNTIF('BRD-09 Customer Servicing'!C5:C531,"Integration detail") | N15: =COUNTIF('BRD-09 Customer Servicing'!C5:C531,"Test data") | O15: =COUNTIF('BRD-09 Customer Servicing'!C5:C531,"Sign-off") | P15: =COUNTIF('BRD-09 Customer Servicing'!K5:K531,"Open") | Q15: =COUNTIF('BRD-09 Customer Servicing'!K5:K531,"Partly answered") | R15: =COUNTIF('BRD-09 Customer Servicing'!K5:K531,"Answered") | S15: =MIN('BRD-09 Customer Servicing'!I5:I531) | T15: =MAX('BRD-09 Customer Servicing'!I5:I531)
A16: BRD-10 | B16: Sanction Screening and Risk Profiling | C16: Drop 1 | D16: Chief Compliance Officer (Compliance) | E16: =COUNTA('BRD-10 Sanction Screening'!A5:A530) | F16: =COUNTIF('BRD-10 Sanction Screening'!C5:C530,"Decision") | G16: =COUNTIF('BRD-10 Sanction Screening'!C5:C530,"Clarification") | H16: =COUNTIF('BRD-10 Sanction Screening'!C5:C530,"Business rule confirmation") | I16: =COUNTIF('BRD-10 Sanction Screening'!C5:C530,"Configuration value") | J16: =COUNTIF('BRD-10 Sanction Screening'!C5:C530,"Master data") | K16: =COUNTIF('BRD-10 Sanction Screening'!C5:C530,"Sample document or template") | L16: =COUNTIF('BRD-10 Sanction Screening'!C5:C530,"Report layout") | M16: =COUNTIF('BRD-10 Sanction Screening'!C5:C530,"Integration detail") | N16: =COUNTIF('BRD-10 Sanction Screening'!C5:C530,"Test data") | O16: =COUNTIF('BRD-10 Sanction Screening'!C5:C530,"Sign-off") | P16: =COUNTIF('BRD-10 Sanction Screening'!K5:K530,"Open") | Q16: =COUNTIF('BRD-10 Sanction Screening'!K5:K530,"Partly answered") | R16: =COUNTIF('BRD-10 Sanction Screening'!K5:K530,"Answered") | S16: =MIN('BRD-10 Sanction Screening'!I5:I530) | T16: =MAX('BRD-10 Sanction Screening'!I5:I530)
A17: BRD-11 | B17: User Access Maintenance | C17: Drop 0 | D17: Product Owner, MBS, with Business Administration (User Access) | E17: =COUNTA('BRD-11 User Access'!A5:A581) | F17: =COUNTIF('BRD-11 User Access'!C5:C581,"Decision") | G17: =COUNTIF('BRD-11 User Access'!C5:C581,"Clarification") | H17: =COUNTIF('BRD-11 User Access'!C5:C581,"Business rule confirmation") | I17: =COUNTIF('BRD-11 User Access'!C5:C581,"Configuration value") | J17: =COUNTIF('BRD-11 User Access'!C5:C581,"Master data") | K17: =COUNTIF('BRD-11 User Access'!C5:C581,"Sample document or template") | L17: =COUNTIF('BRD-11 User Access'!C5:C581,"Report layout") | M17: =COUNTIF('BRD-11 User Access'!C5:C581,"Integration detail") | N17: =COUNTIF('BRD-11 User Access'!C5:C581,"Test data") | O17: =COUNTIF('BRD-11 User Access'!C5:C581,"Sign-off") | P17: =COUNTIF('BRD-11 User Access'!K5:K581,"Open") | Q17: =COUNTIF('BRD-11 User Access'!K5:K581,"Partly answered") | R17: =COUNTIF('BRD-11 User Access'!K5:K581,"Answered") | S17: =MIN('BRD-11 User Access'!I5:I581) | T17: =MAX('BRD-11 User Access'!I5:I581)
A18: BRD-12 | B18: Submitted Policies | C18: Drop 1 | D18: Product Owner, Submitted Policies | E18: =COUNTA('BRD-12 Submitted Policies'!A5:A542) | F18: =COUNTIF('BRD-12 Submitted Policies'!C5:C542,"Decision") | G18: =COUNTIF('BRD-12 Submitted Policies'!C5:C542,"Clarification") | H18: =COUNTIF('BRD-12 Submitted Policies'!C5:C542,"Business rule confirmation") | I18: =COUNTIF('BRD-12 Submitted Policies'!C5:C542,"Configuration value") | J18: =COUNTIF('BRD-12 Submitted Policies'!C5:C542,"Master data") | K18: =COUNTIF('BRD-12 Submitted Policies'!C5:C542,"Sample document or template") | L18: =COUNTIF('BRD-12 Submitted Policies'!C5:C542,"Report layout") | M18: =COUNTIF('BRD-12 Submitted Policies'!C5:C542,"Integration detail") | N18: =COUNTIF('BRD-12 Submitted Policies'!C5:C542,"Test data") | O18: =COUNTIF('BRD-12 Submitted Policies'!C5:C542,"Sign-off") | P18: =COUNTIF('BRD-12 Submitted Policies'!K5:K542,"Open") | Q18: =COUNTIF('BRD-12 Submitted Policies'!K5:K542,"Partly answered") | R18: =COUNTIF('BRD-12 Submitted Policies'!K5:K542,"Answered") | S18: =MIN('BRD-12 Submitted Policies'!I5:I542) | T18: =MAX('BRD-12 Submitted Policies'!I5:I542)
A19: BRD-13 | B19: Data Migration | C19: Drop 0 | D19: Program Manager, Business Project Services (Data Migration) | E19: =COUNTA('BRD-13 Data Migration'!A5:A578) | F19: =COUNTIF('BRD-13 Data Migration'!C5:C578,"Decision") | G19: =COUNTIF('BRD-13 Data Migration'!C5:C578,"Clarification") | H19: =COUNTIF('BRD-13 Data Migration'!C5:C578,"Business rule confirmation") | I19: =COUNTIF('BRD-13 Data Migration'!C5:C578,"Configuration value") | J19: =COUNTIF('BRD-13 Data Migration'!C5:C578,"Master data") | K19: =COUNTIF('BRD-13 Data Migration'!C5:C578,"Sample document or template") | L19: =COUNTIF('BRD-13 Data Migration'!C5:C578,"Report layout") | M19: =COUNTIF('BRD-13 Data Migration'!C5:C578,"Integration detail") | N19: =COUNTIF('BRD-13 Data Migration'!C5:C578,"Test data") | O19: =COUNTIF('BRD-13 Data Migration'!C5:C578,"Sign-off") | P19: =COUNTIF('BRD-13 Data Migration'!K5:K578,"Open") | Q19: =COUNTIF('BRD-13 Data Migration'!K5:K578,"Partly answered") | R19: =COUNTIF('BRD-13 Data Migration'!K5:K578,"Answered") | S19: =MIN('BRD-13 Data Migration'!I5:I578) | T19: =MAX('BRD-13 Data Migration'!I5:I578)
A20: Phase 2 | B20: ReInsurance (phase 2) | C20: Phase 2 | D20: BIBS Product Owner with the Head, Operations (Remittance) | E20: =COUNTA('RI Reinsurance (phase 2)'!A5:A510) | F20: =COUNTIF('RI Reinsurance (phase 2)'!C5:C510,"Decision") | G20: =COUNTIF('RI Reinsurance (phase 2)'!C5:C510,"Clarification") | H20: =COUNTIF('RI Reinsurance (phase 2)'!C5:C510,"Business rule confirmation") | I20: =COUNTIF('RI Reinsurance (phase 2)'!C5:C510,"Configuration value") | J20: =COUNTIF('RI Reinsurance (phase 2)'!C5:C510,"Master data") | K20: =COUNTIF('RI Reinsurance (phase 2)'!C5:C510,"Sample document or template") | L20: =COUNTIF('RI Reinsurance (phase 2)'!C5:C510,"Report layout") | M20: =COUNTIF('RI Reinsurance (phase 2)'!C5:C510,"Integration detail") | N20: =COUNTIF('RI Reinsurance (phase 2)'!C5:C510,"Test data") | O20: =COUNTIF('RI Reinsurance (phase 2)'!C5:C510,"Sign-off") | P20: =COUNTIF('RI Reinsurance (phase 2)'!K5:K510,"Open") | Q20: =COUNTIF('RI Reinsurance (phase 2)'!K5:K510,"Partly answered") | R20: =COUNTIF('RI Reinsurance (phase 2)'!K5:K510,"Answered") | S20: =MIN('RI Reinsurance (phase 2)'!I5:I510) | T20: =MAX('RI Reinsurance (phase 2)'!I5:I510)
A21: Total | E21: =SUM(E6:E20) | F21: =SUM(F6:F20) | G21: =SUM(G6:G20) | H21: =SUM(H6:H20) | I21: =SUM(I6:I20) | J21: =SUM(J6:J20) | K21: =SUM(K6:K20) | L21: =SUM(L6:L20) | ... R21: =SUM(R6:R20) | S21: =MIN(S6:S20) | T21: =MAX(T6:T20)
A23: Items per BDOI owner (role), as issued (owners with five items or more)
A24: Owner (role) | E24: Items | F24: Open | G24: Partly answered | H24: Answered | I24: First needed by | J24: BRDs
A25: Head, Comptrollership | E25: 69 | F25: 67 | G25: 2 | H25: 0 | I25: 46311 | J25: BRD-00, BRD-05, BRD-11, BRD-13
A26: Head, Operations Services | E26: 69 | F26: 58 | G26: 9 | H26: 2 | I26: 46356 | J26: BRD-02
A27: Product Owner, New Business | E27: 50 | F27: 39 | G27: 11 | H27: 0 | I27: 46356 | J27: BRD-01
A28: Product Owner, Renewal | E28: 45 | F28: 39 | G28: 5 | H28: 1 | I28: 46356 | J28: BRD-06
A29: VP and Head, BDOI Operations (Collections) | E29: 43 | F29: 36 | G29: 6 | H29: 1 | I29: 46356 | J29: BRD-04
A30: Product Owner, Claims | E30: 29 | F30: 24 | G30: 4 | H30: 1 | I30: 46444 | J30: BRD-07
A31: Program Manager, Business Project Services (Data Migration) | E31: 26 | F31: 25 | G31: 1 | H31: 0 | I31: 46311 | J31: BRD-13
A32: Product Owner, Submitted Policies | E32: 24 | F32: 23 | G32: 0 | H32: 1 | I32: 46356 | J32: BRD-12
A33: BDOI IT | E33: 20 | F33: 20 | G33: 0 | H33: 0 | I33: 46311 | J33: BRD-00, BRD-03, BRD-13
A34: Marketing and Processing - Renewal (RMEL) | E34: 20 | F34: 16 | G34: 3 | H34: 1 | I34: 46356 | J34: BRD-00, BRD-04, BRD-06
A35: Head, BDOI Information Security | E35: 17 | F35: 16 | G35: 1 | H35: 0 | I35: 46357 | J35: BRD-11
A36: Process Owner, User Access Maintenance (Business Administration) | E36: 17 | F36: 17 | G36: 0 | H36: 0 | I36: 46357 | J36: BRD-11
... A68: Other owners (138 roles with fewer than 5 items each) | E68: 167 | F68: 150 | G68: 15 | H68: 2 | I68: 46311 | J68: BRD-00, BRD-01, BRD-02, BRD-03, BRD-04, BRD-05, BRD-06, BRD-07, BRD-08, BRD-09, BRD-10, BRD-11, BRD-12, BRD-13, RI
A70: Items by month needed, as issued
A71: Month | C71: Items | D71: High | E71: Medium | F71: Low
A72: Oct 2026 | C72: 59 | D72: 25 | E72: 33 | F72: 1
A73: Nov 2026 | C73: 523 | D73: 84 | E73: 410 | F73: 29
A74: Dec 2026 | C74: 62 | D74: 30 | E74: 26 | F74: 6
...

Sheet BRD-00 Cross-cutting
A1: BRD-00 Cross-cutting
A2: BRD-00 Core Replacement and cross-cutting points: what BDOI provides; owner BIBS Product Owner with the Program Manager, Business Project Services
A4: Ref | B4: BRD / module | C4: Type | D4: What we need from BDOI | E4: Why / impact if not provided | F4: Our proposal (if any) | G4: Source (FRS section / CLR / BRD page) | H4: BDOI owner (role) | I4: Needed by | J4: Priority | K4: Status | L4: BDOI response | M4: Remarks
A5: CLR-CR-02 | B5: BRD-00 Core Replacement and cross-cutting points | C5: Clarification | D5: Claims cheque safekeeping: Answer CRQ03. | E5: Whether BDOI holds claim cheques is open (CRQ03, CLQ10). | F5: No cheque custody in phase 1; if BDOI holds claim settlement cheques, a cheque custody register is added in Claims with hand-over to and from Cashiering. | G5: FRS BRD-00 v1.1, Proposed business rules and clarifications; CORE-14.08-14.10; also raised as CRQ03 (open question), DCR-164 (register item) | H5: Claims and Risk Management | I5: 46356 | J5: High | K5: Open | M5: Also affects BRD-07.
A6: CLR-CR-03 | B6: BRD-00 Core Replacement and cross-cutting points | C6: Decision | D6: CSF case resolution: Decide the delivery drop of the Case Management module (CLR-CSF-07); close DCR-163 and CR-0005 against it. | E6: The addendum answers CRQ04 and the cross-BRD conflict XQ12 (DCR-163); change request CR-0005 kept case resolution out of phase 1. | F6: Case resolution is BDOI scope: the signed CSF Addendum - Case Management (BRCSFCM.001-012) is specified in FRS BRD-9 (FR-CSF-050 to 061). Its delivery drop and plan follow the decision of BDOI and the Change Control Board (FRS BRD-9 CLR-CSF-07). | G6: FRS BRD-00 v1.1, Proposed business rules and clarifications; CORE-16.06; also raised as CRQ04 (open question), XQ12 (open question), CSQ09 (open question), DCR-163 (register item) | H6: Contact Center Management / Alternative Distribution | I6: 46356 | J6: High | K6: Partly answered | M6: Answer so far: in scope by the Case Management Addendum; drop open, CLR-CSF-07; Case Management Addendum; drop open, CLR-CSF-07. Also affects BRD-09.
A7: NFR-PRF-01 | B7: BRD-00 Core Replacement and cross-cutting points | C7: Decision | D7: Screen response time: decide the target; the BRDs give different values | E7: Every screen opens, and every single-record action (save, submit, approve) completes, within the target at the design load. | F7: p95 at most 2.0 seconds and p99 at most 4.0 seconds | G7: Non-functional requirements register v1.0, NFR-PRF-01; BRD-00 p.42 (under 5 s for every role); BRD-12 p.13 (2 s); BRD-9 p.13 (3 s); BRD-1 p.210 and BRD-6 p.186 (10 s); register DCR-137, DCR-165; CRQ21; also raised as CRQ21 (open question), XQ08 (open question), CQ25 (open question), AQ27 (open question), RQ28 (open question), EBQ25 (open question), SANC-SQ18 (open question), DCR-057 (register item), DCR-071 (register item), DCR-137 (register item), DCR-139 (register item), DCR-165 (register item), DCR-193 (register item) | H7: BIBS Product Owner | I7: 46356 | J7: High | K7: Partly answered | M7: Answer so far: Umbrella: retention 5 / 15, backup every 4 hours kept 5 years, response under 5 s, users per role (1,344 / 429). Availability, hours and maintenance still per BRD. BRD-13 refers to a consolidated NFR document not in the pack (DMQ29). (BRD-00 p.42-45; BRD-13 p. Also affects BRD-01, BRD-02, BRD-03, BRD-04, BRD-05, BRD-06, BRD-07, BRD-08, BRD-09, BRD-10, BRD-11, BRD-12, BRD-13.
A8: NFR-PRF-02 | B8: BRD-00 Core Replacement and cross-cutting points | C8: Configuration value | D8: Search and work-list response time: confirm the proposed target or give the BDOI value | E8: The first page of any search result or work list is shown within the target; lists are paged on the server. | F8: First page (up to 50 rows) p95 at most 3.0 seconds; each further page p95 at most 2.0 seconds | G8: Non-functional requirements register v1.0, NFR-PRF-02; BRD-9 p.13 (retrieval and search under 3 s); BRD-4 NFR 15 (5 s); BRD-10 p.22-24 (3 to 5 s) | H8: BIBS Product Owner | I8: 46356 | J8: High | K8: Open
A9: NFR-PRF-03 | B9: BRD-00 Core Replacement and cross-cutting points | C9: Decision | D9: Interactive reports: decide the target; the BRDs give different values | E9: An on-screen report or its export is produced within the target; larger reports run as background jobs (NFR-PRF-04). | F9: At most 20 seconds (p95) for a report of up to 30,000 rows | G9: Non-functional requirements register v1.0, NFR-PRF-03; BRD-6 p.186 and BRD-11 p.11 (20 s); BRD-5 p.133-137 (10 to 20 s first load); register DCR-137 | H9: BIBS Product Owner | I9: 46356 | J9: High | K9: Open
A10: NFR-PRF-07 | B10: BRD-00 Core Replacement and cross-cutting points | C10: Configuration value | D10: Night batch window: confirm the proposed target or give the BDOI value | E10: The scheduled jobs of the night (booking batch, remittance extraction, GL-SL reconciliation, Collections files, renewal extraction, screening, application file) finish before the service window opens. | F10: The chain from 20:00 to 05:30 PHT completes before 06:00 PHT at year-5 volumes; a failed job can be re-run within the window | G10: Non-functional requirements register v1.0, NFR-PRF-07; Register DCR-133 (service window from 06:00); programme alignment pack, section 6.5 (job times); also raised as DCR-133 (register item) | H10: Head, BDOI IT | I10: 46356 | J10: High | K10: Open | M10: Also affects BRD-01, BRD-02, BRD-03, BRD-04, BRD-05, BRD-06, BRD-07, BRD-08, BRD-09, BRD-10, BRD-12.
A11: NFR-CAP-01 | B11: BRD-00 Core Replacement and cross-cutting points | C11: Decision | D11: Users: decide the target; the BRDs give different values | E11: BIBS serves every named user of BDOI and the concurrent sessions of the peak. | F11: 1,344 named users; design load 150 concurrent users in year 1, growing 20% a year (311 in year 5); peak test at 429 concurrent sessions | G11: Non-functional requirements register v1.0, NFR-CAP-01; BRD-00 p.42 (1,344 named, 429 concurrent); BRD-1 p.210 (485 / 145, growth 20%); IER architecture sheet (about 1,200 internal users); register DCR-166, DCR-232; CRQ21, CRQ24; also raised as CRQ24 (open question), DCR-166 (register item), DCR-232 (register item) | H11: BIBS Product Owner | I11: 46356 | J11: High | K11: Open | M11: Also affects BRD-03, BRD-07, BRD-08.
A12: NFR-CAP-03 | B12: BRD-00 Core Replacement and cross-cutting points | C12: Configuration value | D12: Data and document volume: confirm the proposed target or give the BDOI value | E12: Storage is sized for five years of data and documents with headroom. | F12: Five years (60 months) at 20% growth a year with at least 30% free capacity at the end of year 5; migrated base up to 1,000,000 client rows and 500,000 open items | G12: Non-functional requirements register v1.0, NFR-CAP-03; IER HW & SW Requirements (60 months; 15% growth a year); Data Migration Handbook (1,000,000 clients, 500,000 open items); programme alignment pack 6.3 (data store re-sized without documents) | H12: Cloud and Digital Operations Engineering (IER owner) | I12: 46356 | J12: High | K12: Open
A13: NFR-CAP-05 | B13: BRD-00 Core Replacement and cross-cutting points | C13: Configuration value | D13: Peak periods: confirm the proposed target or give the BDOI value | E13: The month-end, mid-month and year-end peaks are carried without missing the response targets. | F13: 1.5 times the average daily volume on the 15th, the 30th, month-end and year-end, within NFR-PRF-01 and NFR-PRF-02 | G13: Non-functional requirements register v1.0, NFR-CAP-05; BRD-2 (15th and 30th); BRD-5 (month-end and year-end); BRD-9 (first quarter); BRD-1 and BRD-6 (08:00-10:00 and 15:00-17:00) | H13: Head, Comptrollership | I13: 46356 | J13: High | K13: Open
A14: NFR-AVL-01 | B14: BRD-00 Core Replacement and cross-cutting points | C14: Decision | D14: Availability in the service window: decide the target; the BRDs give different values | E14: BIBS is available to users throughout the service window. | F14: 99.9% of the service window each month (about 25 minutes of unplanned unavailability in a month of 26 service days) | G14: Non-functional requirements register v1.0, NFR-AVL-01; Register DCR-134 (99.9% in service hours); BRD-2, 3, 9, 10, 12 (99.9%); BRD-8 (99.99%); BRD-5 Add.1 (100%); also raised as DCR-134 (register item) | H14: Head, BDOI IT | I14: 46356 | J14: High | K14: Open | M14: Also affects BRD-01, BRD-02, BRD-03, BRD-05, BRD-06, BRD-08, BRD-09, BRD-10, BRD-11, BRD-12.
A15: NFR-AVL-02 | B15: BRD-00 Core Replacement and cross-cutting points | C15: Decision | D15: Service window: decide the target; the BRDs give different values | E15: One service window serves every module; production runs 24 x 7 so jobs and interfaces run outside it. | F15: 06:00 to 22:00 PHT Monday to Saturday, plus month-end weekends; production infrastructure 24 x 7 | G15: Non-functional requirements register v1.0, NFR-AVL-02; Register DCR-133; IER Assumptions 3 and 4 (non-production 12 x 5, production 24 x 7); BRD service hours from 06:00 (BRD-4, 7, 9) to 22:00 (BRD-1, 4, 6, 9) | H15: BIBS Product Owner | I15: 46356 | J15: High | K15: Open
A16: NFR-AVL-03 | B16: BRD-00 Core Replacement and cross-cutting points | C16: Decision | D16: Planned maintenance: decide the target; the BRDs give different values | E16: Planned work happens in one window outside every module's service hours. | F16: 00:00 to 04:00 PHT; at most 45 minutes of planned downtime a month; announced 5 business days ahead; releases without downtime where the change allows | G16: Non-functional requirements register v1.0, NFR-AVL-03; Register DCR-138 and DCR-134; BRD-10 p.25 and BRD-12 p.14 (00:00-04:00, 45 minutes a month); also raised as CSQ12 (open question), DCR-103 (register item), DCR-138 (register item) | H16: Head, BDOI IT | I16: 46356 | J16: High | K16: Open | M16: Also affects BRD-01, BRD-04, BRD-05, BRD-09, BRD-10, BRD-12.
A17: NFR-REC-03 | B17: BRD-00 Core Replacement and cross-cutting points | C17: Decision | D17: Backup: decide the target; the BRDs give different values | E17: Data and documents are backed up continuously and kept for the retention period. | F17: Continuous transaction-log archiving plus a base backup every 4 hours; backups encrypted and kept 7 years; document store versioned with cross-region replication | G17: Non-functional requirements register v1.0, NFR-REC-03; Register DCR-102, DCR-135, DCR-136; BRD-00 p.45 (every 4 hours, kept 5 years); BRD-2 and BRD-8 (kept 7 years); also raised as DCR-135 (register item), DCR-136 (register item) | H17: Cloud and Digital Operations Engineering (IER owner) | I17: 46356 | J17: High | K17: Partly answered | M17: Answer so far: The IER workbook v20 (BDOI IT, received 26-Sep-2026) states RPO 15 minutes and RTO 4 hours, the values proposed here. To be confirmed by the BRD owners. Also affects BRD-01, BRD-02, BRD-03, BRD-04, BRD-05, BRD-06, BRD-07, BRD-08, BRD-09, BRD-10, BRD-11, BRD-12.
A18: NFR-REC-04 | B18: BRD-00 Core Replacement and cross-cutting points | C18: Configuration value | D18: Restore and DR drills: confirm the proposed target or give the BDOI value | E18: Recovery is proven before go-live and kept proven afterwards. | F18: Point-in-time restore tested every quarter; DR failover drill before go-live (Dec 2027) and twice a year after; each with a written result | G18: Non-functional requirements register v1.0, NFR-REC-04; Operations runbook (quarterly restore test); IER DR environment | H18: Head, BDOI IT | I18: 46356 | J18: High | K18: Open
A19: NFR-REC-05 | B19: BRD-00 Core Replacement and cross-cutting points | C19: Decision | D19: DR region: decide the target; the BRDs give different values | E19: A second AWS region hosts the DR copy of BIBS once BDOI confirms data residency. | F19: Data store cross-region replica, document store cross-region replication, standby Kubernetes cluster scaled from 0 to 6 backend pods at failover | G19: Non-functional requirements register v1.0, NFR-REC-05; IER PROD DR (cross-region read replica) and diagram (warm standby); register DCR-225; programme alignment pack 6.4; IQ26; also raised as IQ26 (open question), DCR-225 (register item) | H19: Cloud and Digital Operations Engineering (IER owner) | I19: 46356 | J19: High | K19: Open
A20: NFR-SEC-02 | B20: BRD-00 Core Replacement and cross-cutting points | C20: Configuration value | D20: Second factor: confirm the proposed target or give the BDOI value | E20: Privileged users prove a second factor. | F20: TOTP second factor for every privileged role and every break-glass administrator; EIAM conditional access for single sign-on users | G20: Non-functional requirements register v1.0, NFR-SEC-02; Security controls (TOTP, policy PRIVILEGED as delivered); drop plan EIAM | H20: BDOI Information Security | I20: 46356 | J20: High | K20: Open
A21: NFR-SEC-03 | B21: BRD-00 Core Replacement and cross-cutting points | C21: Decision | D21: User provisioning and leavers: decide the target; the BRDs give different values | E21: Joiners, movers and leavers reach BIBS from UIDM-ISC; dormant accounts are disabled. | F21: SCIM 2.0 provisioning from UIDM-ISC (planned); a leaver disabled in BIBS within 1 hour of the UIDM-ISC change; accounts dormant for 90 days disabled by the daily job | G21: Non-functional requirements register v1.0, NFR-SEC-03; Drop plan integration UIDM-ISC (INT-02); BRD-11 UAM-NFR-09 (dormant users disabled); IQ05, DCR-229; also raised as IQ05 (open question), DCR-229 (register item) | H21: BDOI Information Security | I21: 46356 | J21: High | K21: Open | M21: Also affects BRD-11.
A22: NFR-SEC-05 | B22: BRD-00 Core Replacement and cross-cutting points | C22: Decision | D22: Session and lock-out: decide the target; the BRDs give different values | E22: Idle sessions end and repeated failures lock the account. | F22: Inactivity warning at 15 minutes and sign-out at 30 minutes; absolute session end 8 hours; lock-out after 3 consecutive failed attempts | G22: Non-functional requirements register v1.0, NFR-SEC-05; BRD-11 UAM-NFR-19, 34; BRD-1 p.93 and BRD-6 p.44 (warning 15, log-out 30); BRD-4 p.53 and BRD-7 p.35 (15 minutes); register DCR-140, DCR-142; also raised as DCR-140 (register item), DCR-142 (register item) | H22: BDOI Information Security | I22: 46356 | J22: High | K22: Partly answered | M22: Answer so far: BRD-11 p.14: "Users should be locked out to the system after 3 invalid attempts.". Also affects BRD-01, BRD-04, BRD-07, BRD-11.
A23: NFR-SEC-06 | B23: BRD-00 Core Replacement and cross-cutting points | C23: Configuration value | D23: Encryption in transit and at rest: confirm the proposed target or give the BDOI value | E23: Data is encrypted on every connection and in every store. | F23: TLS 1.2 or higher on every connection (browser, Gateway Interface, between workloads, to the managed services); data store, document store and backups encrypted with customer-managed keys per environment | G23: Non-functional requirements register v1.0, NFR-SEC-06; Security controls (TLS at the edge and to the pods); programme alignment pack 6.3 (KMS keys per environment); BRD-8 derived privacy requirement (encryption in transit and at rest) | H23: BDOI Information Security | I23: 46356 | J23: High | K23: Open
A24: NFR-SEC-08 | B24: BRD-00 Core Replacement and cross-cutting points | C24: Configuration value | D24: DAST and penetration test: confirm the proposed target or give the BDOI value | E24: The running application is tested from outside before go-live. | F24: DAST scan of each release candidate in SIT and Pre-Prod with no open high or critical finding; early scan in SIT in June 2027; independent penetration test 1 Nov to 15 Dec 2027; critical and high findings closed before go-live | G24: Non-functional requirements register v1.0, NFR-SEC-08; BDOI programme timeline (performance and penetration test Nov to Dec 2027); programme alignment pack (early security scan, IQ35); project plan DEP-19; also raised as IQ35 (open question) | H24: BDOI Information Security | I24: 46356 | J24: High | K24: Open
A25: NFR-SEC-12 | B25: BRD-00 Core Replacement and cross-cutting points | C25: Configuration value | D25: Vulnerability remediation: confirm the proposed target or give the BDOI value | E25: Security findings in production are fixed within set times. | F25: Critical within 7 days, high within 30 days, medium within 90 days; an accepted finding expires after at most 6 months | G25: Non-functional requirements register v1.0, NFR-SEC-12; Quality gates (accepted findings expire after at most six months) | H25: BDOI Information Security | I25: 46356 | J25: High | K25: Open
A26: NFR-PRV-02 | B26: BRD-00 Core Replacement and cross-cutting points | C26: Decision | D26: Data residency and support access: decide the target; the BRDs give different values | E26: Production data stays in the agreed region and is reached only by authorised personnel in the Philippines. | F26: Production in AWS ap-southeast-1; DR region confirmed by BDOI after the data-residency check; production access only by named personnel in the Philippines, each session logged | G26: Non-functional requirements register v1.0, NFR-PRV-02; FRS BRD-00 NFR table (hosting appendix: AWS ap-southeast-1, access from the Philippines); register DCR-225; IQ26 | H26: Data Protection Officer, BDOI | I26: 46356 | J26: High | K26: Open
A27: NFR-ACC-01 | B27: BRD-00 Core Replacement and cross-cutting points | C27: Configuration value | D27: WCAG 2.2 level AA: confirm the proposed target or give the BDOI value | E27: Every screen meets the success criteria of WCAG 2.2 at levels A and AA. | F27: 0 open level A or AA failures on the screens of each sign-off set; 0 serious or critical issues in the scan of every screen | G27: Non-functional requirements register v1.0, NFR-ACC-01; BRD-11 UAM-NFR-05 (options for impaired vision or colour blindness); BDO UX guidelines (AA contrast, keyboard use) | H27: BIBS Product Owner | I27: 46356 | J27: High | K27: Open
A28: NFR-USE-01 | B28: BRD-00 Core Replacement and cross-cutting points | C28: Configuration value | D28: Low-click navigation: confirm the proposed target or give the BDOI value | E28: Daily work starts from the role home page with few clicks. | F28: Any daily task reached in at most 2 clicks from the role home page or the menu; a record opened from a search result in 1 click; the main action of a record (submit, approve) at most 1 click away | G28: Non-functional requirements register v1.0, NFR-USE-01; BRD-00 p.5 (role-based self-service, centralised dashboards); FRS BRD-00 FR-CR-001 and FR-CR-010 (persona menus, role home) | H28: BIBS Product Owner | I28: 46356 | J28: High | K28: Open
A29: NFR-RSP-03 | B29: BRD-00 Core Replacement and cross-cutting points | C29: Configuration value | D29: Supported browsers: confirm the proposed target or give the BDOI value | E29: Users need only a browser. | F29: Current and previous major versions of Microsoft Edge and Google Chrome on Windows, Safari on iOS and Chrome on Android; no plug-in or local install | G29: Non-functional requirements register v1.0, NFR-RSP-03; BRD-11 UAM-NFR-28 (browser only on workstations) | H29: Head, BDOI IT | I29: 46356 | J29: High | K29: Open
A30: NFR-MNT-02 | B30: BRD-00 Core Replacement and cross-cutting points | C30: Configuration value | D30: Code coverage: confirm the proposed target or give the BDOI value | E30: New and changed code is covered by unit testing. | F30: Line coverage above 90% on new and changed code (new-code gate of SonarQube); overall line coverage at least 80% and branch coverage at least 65% | G30: Non-functional requirements register v1.0, NFR-MNT-02; Quality gates (overall gate 80% lines, 65% branches); programme target for new code | H30: Head, BDOI IT | I30: 46356 | J30: High | K30: Open
A31: NFR-MNT-05 | B31: BRD-00 Core Replacement and cross-cutting points | C31: Configuration value | D31: Releases and rollback: confirm the proposed target or give the BDOI value | E31: Releases do not stop users and can be rolled back. | F31: Rolling deployment with no pod unavailable; data changes compatible with the previous release; rollback by redeploying the previous release within 30 minutes | G31: Non-functional requirements register v1.0, NFR-MNT-05; Operations runbook (rolling update, expand-migrate-contract, rollback by previous image) | H31: Head, BDOI IT | I31: 46356 | J31: High | K31: Open
A32: NFR-OBS-01 | B32: BRD-00 Core Replacement and cross-cutting points | C32: Decision | D32: Metrics and dashboards: decide the target; the BRDs give different values | E32: Operations sees the health and load of every workload. | F32: Application, JVM, request, connection-pool and business metrics sent to the BDO monitoring platform; dashboards per workload (web, jobs, integration, web tier) and for the managed services | G32: Non-functional requirements register v1.0, NFR-OBS-01; Operations runbook (metrics on the management port); IER VDI and K8S sheets (Dynatrace); IQ30; also raised as IQ30 (open question), DCR-224 (register item) | H32: Head, BDOI IT | I32: 46356 | J32: High | K32: Open
A33: NFR-OBS-02 | B33: BRD-00 Core Replacement and cross-cutting points | C33: Configuration value | D33: Logs: confirm the proposed target or give the BDOI value | E33: Logs let support trace every event without exposing personal data. | F33: One line per event with time stamp, correlation ID, user and module; shipped to the BDO log platform within 1 minute; no passwords or full personal identifiers in logs | G33: Non-functional requirements register v1.0, NFR-OBS-02; Operations runbook (logs, correlation ID); security controls (no passwords in logs); BRD-11 UAM-NFR-21 (error log sent to a remote log server) | H33: BDOI Information Security | I33: 46356 | J33: High | K33: Open
A34: NFR-OBS-03 | B34: BRD-00 Core Replacement and cross-cutting points | C34: Configuration value | D34: Alerts: confirm the proposed target or give the BDOI value | E34: Faults raise alerts before users report them. | F34: Alerts for an error rate above 1% over 5 minutes, p95 above its NFR-PRF target for 10 minutes, a failed job, a new dead letter, a security-store failure and a certificate expiring within 30 days; the on-call person notified within 5 minutes | G34: Non-functional requirements register v1.0, NFR-OBS-03; Operations runbook (security-store alert, dead letters); BRD-11 UAM-NFR-25 (failed batch e-mail) | H34: Head, BDOI IT | I34: 46356 | J34: High | K34: Open
A35: NFR-SUP-02 | B35: BRD-00 Core Replacement and cross-cutting points | C35: Configuration value | D35: Incident handling within the agreed service levels: confirm the proposed target or give the BDOI value | E35: Production incidents are answered and resolved within the response and resolution times of their priority (P1 to P4) in the support service levels. | F35: At least 95% of incidents each month within the response and resolution times of their priority | G35: Non-functional requirements register v1.0, NFR-SUP-02; Production support approach and service levels (priorities P1 to P4) | H35: Head, BDOI IT | I35: 46356 | J35: High | K35: Open
A36: NFR-RET-01 | B36: BRD-00 Core Replacement and cross-cutting points | C36: Decision | D36: Retention per record type: decide the target; the BRDs give different values | E36: Each record type has its retention rule. | F36: Default 5 years online and 15 years archive; Claims 10 years online and 15 archive; Accounting vouchers and reports, Sanction Screening and Submitted Policies 5 years online and 5 archive | G36: Non-functional requirements register v1.0, NFR-RET-01; BRD-00 p.45 (5 / 15 years); BRD-7 p.41 (10 / 15); BRD-5 Add.1, BRD-10 p.25, BRD-12 p.14 (5 / 5); register DCR-136; CRQ22; also raised as CRQ22 (open question), DCR-167 (register item), DCR-209 (register item) | H36: BIBS Product Owner | I36: 46356 | J36: High | K36: Open | M36: Also affects BRD-05, BRD-07, BRD-09, BRD-10, BRD-12, BRD-13.
A37: NFR-RET-03 | B37: BRD-00 Core Replacement and cross-cutting points | C37: Decision | D37: Audit log retention: decide the target; the BRDs give different values | E37: Audit records outlive the records they describe. | F37: Audit records 5 years online and archived to 16 years | G37: Non-functional requirements register v1.0, NFR-RET-03; BRD-7 p.41 (audit logs archive 16 years); BRD-00 p.45 (5 / 15 years) | H37: Internal Audit, BDOI | I37: 46356 | J37: High | K37: Open
A38: NFR-INT-04 | B38: BRD-00 Core Replacement and cross-cutting points | C38: Configuration value | D38: File interfaces: confirm the proposed target or give the BDOI value | E38: Inbound files are validated, reconciled and reported. | F38: Every inbound file (PDC list, bills payment, bank and insurer files) validated against its layout; each run reconciled to its control totals; errors reported per row; a failed transfer retried up to 3 times | G38: Non-functional requirements register v1.0, NFR-INT-04; Programme alignment pack 5 (PMS, OBPCS, Old BOB, CMS / New BOB, insurer systems); FRS BRD-02 (payment files) | H38: Head, Operations | I38: 46356 | J38: High | K38: Open
A39: NFR-INT-05 | B39: BRD-00 Core Replacement and cross-cutting points | C39: Decision | D39: E-mail through CCM: decide the target; the BRDs give different values | E39: All outbound e-mail goes through the BDO communications service. | F39: 100% of outbound e-mail sent through CCM with its delivery status recorded | G39: Non-functional requirements register v1.0, NFR-INT-05; Drop plan integration CCM (INT-13); IQ11; also raised as IQ11 (open question) | H39: Head, BDOI IT | I39: 46356 | J39: High | K39: Open
A40: XQ04 | B40: BRD-00 Core Replacement and cross-cutting points | C40: Report layout | D40: Access classes of shared documents: Final confidentiality matrix per document type, including CSF (CSQ07, EBQ15) Background: The EB spec gives renewal advice the classes MARKETING and PROCESSING; CSF agents must view and resend RAs and claims reports; claims documents may be confidential | E40: Open point of the FRS (FR-CSF-033): the requirement cannot be finalised or tested as BDOI intends until it is answered. | F40: Treat master lists and utilization as sensitive personal information: need-to-know access classes, download logging, encryption. | G40: FRS BRD-09 v1.1, Open questions XQ04 (affects FR-CSF-033); Discrepancy and clarification register v1.2, open question XQ04; baseline Cross-BRD decisions section 5; also raised as EBQ15 (open question), CSQ07 (open question), DCR-094 (register item), DCR-148 (register item) | H40: Employee Benefits - Marketing, Processing and Collection | I40: 46356 | J40: High | K40: Open | M40: Also affects BRD-07, BRD-08, BRD-09.
A41: IQ01 | B41: BRD-00 Core Replacement and cross-cutting points | C41: Clarification | D41: Go-live date: (Priority 1) Which date in January 2028 is T? We propose Monday 3 January 2028, with the legacy freeze after the EOD of Wednesday 29 December 2027 and the legacy December / year-end close completed in legacy before the final extracts. If T is later in January, the migration rule "first business day of a month after a legacy month-end close" (DMQ25) no longer holds and the GL opening needs a short January period. | E41: Open point of the FRS: the requirement cannot be finalised or tested as BDOI intends until it is answered. | F41: T = Monday 3 January 2028; absolute trial-migration calendar Trial migration 1 Apr-May, Trial migration 2 Jun-Jul, Trial migration 3 Aug, re-load Oct, dress rehearsal Nov-Dec 2027. | G41: Discrepancy and clarification register v1.2, open question IQ01; baseline Timeline slide; answer A1; DMQ25, DMQ18; also raised as DCR-217 (register item) | H41: Enterprise Services Group - Business Project Services (Program Manager) with BDOI Comptrollership and Operations | I41: 46356 | J41: High | K41: Open | M41: Also affects BRD-13.
...

Sheet BRD-01 New Business
A1: BRD-01 New Business
A2: BRD-01 New Business: what BDOI provides; owner Product Owner, New Business
A4: Ref | B4: BRD / module | C4: Type | D4: What we need from BDOI | E4: Why / impact if not provided | F4: Our proposal (if any) | G4: Source (FRS section / CLR / BRD page) | H4: BDOI owner (role) | I4: Needed by | J4: Priority | K4: Status | L4: BDOI response | M4: Remarks
A5: CLR-NB-17 | B5: BRD-01 New Business | C5: Business rule confirmation | D5: Placement file to insurers: Specify the insurer channels or confirm e-mail only (Q06). | E5: The electronic channels to insurers (file transfer or system-to-system) are not specified (Q06). | F5: Slips are sent by e-mail when Processing clicks Send. An insurer set up for another channel is refused with a message until the electronic channels are specified. | G5: FRS BRD-01 v2.1, Proposed business rules and clarifications; BRNB.071; FR-NB-081; also raised as Q06 (open question), DCR-211 (register item) | H5: Employee Benefits - Marketing, Processing and Collection | I5: 46356 | J5: High | K5: Partly answered | M5: Answer so far: For EB, insurers use a secure portal or Interface. Other lines: still e-mail. (BRD-8 BRID-005, 005.01-005.02, 009). Also affects BRD-00, BRD-08.
A6: CLR-NB-23 | B6: BRD-01 New Business | C6: Clarification | D6: Tags and instructions: Name the tags that block and the final list of tags and instructions (Q18). | E6: Which tags block a process, and the final list, are not given (Q18). | F6: Tags and instructions show as a banner that warns; they do not block a process. BRD-10 sets PEP and watchlist review by rule. | G6: FRS BRD-01 v2.1, Proposed business rules and clarifications; BRNB.091; FR-NB-036; also raised as Q18 (open question), DCR-112 (register item) | H6: Compliance (Chief Compliance Officer) | I6: 46356 | J6: High | K6: Partly answered | M6: Answer so far: PEP and high-risk tags are set by rules and trigger reviews. Block vs warn still open (SANC-SQ07). (BRD-10 SNSRP-302 / 303). Also affects BRD-06, BRD-10.
A7: CLR-NB-31 | B7: BRD-01 New Business | C7: Clarification | D7: Multi-year policies: Give the multi-year basis (Q35). | E7: The basis (upfront or yearly) is not given (Q35). | F7: The premium and commission basis of a multi-year policy follows BDOI's answer; each year is invoiced separately until then. | G7: FRS BRD-01 v2.1, Proposed business rules and clarifications; FR-NB-114; also raised as Q35 (open question), DCR-006 (register item) | H7: Marketing and Processing - New Business (Product Owner) | I7: 46356 | J7: High | K7: Partly answered | M7: Answer so far: Multi-year policies are billed per billing cycle. Accounting per cycle open. (BRD-4 BRCLXN.058).
A8: CLR-NB-32 | B8: BRD-01 New Business | C8: Business rule confirmation | D8: Premium tax and Motor bases: Confirm the premium tax basis (Q43) and the multi-year basis (Q35). | E8: The premium tax basis is to be confirmed (Q43). | F8: The Fire premium tax of 12% of net premium and the Motor OD / Theft bases of 90% and 81% of TSI are applied as written, as rates in the catalogue. | G8: FRS BRD-01 v2.1, Proposed business rules and clarifications; Appendix A; also raised as Q43 (open question), DCR-005 (register item) | H8: Marketing and Processing - New Business (Product Owner) | I8: 46356 | J8: High | K8: Open
A9: Q13 | B9: BRD-01 New Business | C9: Business rule confirmation | D9: Client code: BRNB.029 requires a client code for every quotation; BRNB.063 allows quotation without client code. Confirm: auto-create prospect code at quotation? | E9: Open point of the FRS (FR-NB-041, 046): the requirement cannot be finalised or tested as BDOI intends until it is answered. | F9: Allow a quotation without a confirmed client, and create a prospect client code automatically at quotation (BRNB.029 then holds for the prospect code). | G9: FRS BRD-01 v2.1, Open questions Q13 (affects FR-NB-041, 046); Discrepancy and clarification register v1.2, open question Q13; baseline BRNB.029, 063; also raised as DCR-001 (register item) | H9: Marketing and Processing - New Business (Product Owner) | I9: 46356 | J9: High | K9: Open
A10: SO-01-1 | B10: BRD-01 New Business | C10: Sign-off | D10: Sign the FRS and sign-off set of BRD-01 New Business. | E10: The signed document fixes the scope for the next step of the plan; a late sign-off moves the dates that follow it. | G10: Project plan v1.0 (8-Oct-2026), sign-offs and milestones | H10: Product Owner, New Business; Business Project Services (traceability) | I10: 46356 | J10: High | K10: Open
A11: CLR-NB-01 | B11: BRD-01 New Business | C11: Master data | D11: Approval levels: Give the approval chain by amount, product or segment, or confirm one approval stage (Q05). | E11: The BRD asks for TL, then TH, then UH; the chain by amount, product or segment is not given (Q05). | F11: One approval stage per quotation and per PRF: any holder of the approval permission other than the maker approves. | G11: FRS BRD-01 v2.1, Proposed business rules and clarifications; BRNB.005, 014; FR-NB-014, 043, 051; also raised as Q05 (open question) | H11: Product Owner, New Business | I11: 46356 | J11: Medium | K11: Partly answered | M11: Answer so far: Package requests: approved by the Marketing TL, TH or UH; TSU TL recommends, TH approves; ManCom sign-off. No amount limits. (BRD-3 BRPM.008 / 009 / 012 / 015, PMADD06).
A12: CLR-NB-03 | B12: BRD-01 New Business | C12: Report layout | D12: Late Renewal Requests Report: Confirm the Renewal listing variant (Q09, RQ29). | E12: The report concerns renewals; Report List #182 is a package report. | F12: A variant of the Renewal listing (RNW-LISTING) of BRD-6, restricted by role, in place of a New Business report. | G12: FRS BRD-01 v2.1, Proposed business rules and clarifications; BRNB.018; FR-NB-126; also raised as Q09 (open question), RQ29 (open question) | H12: Product Owner, New Business | I12: 46356 | J12: Medium | K12: Open
