Workbook
Name CODES_D0_02_BRANCH_CODE: 'D0-02 Branches'!$B$18:$B$518
Name CODES_D0_04_CODE: 'D0-04 Dimensions'!$C$17:$C$517
Name CODES_D0_06_ACCOUNT_CODE: 'D0-06 Chart of accounts'!$C$17:$C$517
Name CODES_D0_07_CATEGORY_CODE: 'D0-07 Categories and numbering'!$C$17:$C$517
Name CODES_MD_02_CURRENCY_CODE: 'MD-02 Currencies'!$B$17:$B$317
Name CODES_PM_01_COVER_TYPE_CODE: 'PM-01 Product catalogue'!$E$17:$E$517
Name CODES_UA_01_USER_ID: 'UA-01 Users and roles'!$C$17:$C$517
Name CODES_PM_01_LINE_CODE: 'PM-01 Product catalogue'!$B$17:$B$517
Name CODES_D0_11_BANK_ACCOUNT_CODE: 'D0-11 Bank accounts'!$B$18:$B$518
Name CODES_D0_05_EMPLOYEE_NUMBER: 'D0-05 Employees'!$B$17:$B$517
Name CODES_PM_01_RISK_CODE: 'PM-01 Product catalogue'!$H$17:$H$517
Name LIST_YES_NO: 'Reference lists'!$C$5:$C$6
Name LIST_MARKET_SEGMENT: 'Reference lists'!$C$7:$C$11
Name LIST_PLACEMENT_GATE: 'Reference lists'!$C$12:$C$13
Name LIST_TSU_REVIEW: 'Reference lists'!$C$14:$C$16
Name LIST_CI02_RECORD: 'Reference lists'!$C$17:$C$19
Name LIST_DOCUMENT_TYPE: 'Reference lists'!$C$20:$C$80
Name LIST_CLAUSE_KIND: 'Reference lists'!$C$81:$C$84
Name LIST_RATE_TABLE: 'Reference lists'!$C$85:$C$87
Name LIST_MAP_ACTION: 'Reference lists'!$C$88:$C$89
Name LIST_PKG_DOCUMENT: 'Reference lists'!$C$90:$C$95
Name LIST_PM_LIST_OR_PARAMETER: 'Reference lists'!$C$96:$C$119
Name LIST_INCENTIVE_TYPE: 'Reference lists'!$C$120:$C$121
Name LIST_UA_ACTION: 'Reference lists'!$C$122:$C$125
Name LIST_PRIVILEGE_LEVEL: 'Reference lists'!$C$126:$C$129
Name LIST_KEEP_ADD_REMOVE: 'Reference lists'!$C$130:$C$132
Name LIST_UA_ROLE: 'Reference lists'!$C$133:$C$137
Name LIST_SOD_STATUS: 'Reference lists'!$C$138:$C$140
Name LIST_SOD_CONTROL: 'Reference lists'!$C$141:$C$143
Name LIST_REVIEW_FREQUENCY: 'Reference lists'!$C$144:$C$145
Name LIST_UA_PARAMETER: 'Reference lists'!$C$146:$C$162
Name LIST_UA_LIST: 'Reference lists'!$C$163:$C$165
Name LIST_DIMENSION: 'Reference lists'!$C$166:$C$167
Name LIST_ACCOUNT_CLASS: 'Reference lists'!$C$168:$C$172
Name LIST_ACCOUNT_CLASS_CHART: 'Reference lists'!$C$173:$C$178
Name LIST_ACCOUNT_LEVEL: 'Reference lists'!$C$179:$C$182
Name LIST_NEGATIVE_BALANCE: 'Reference lists'!$C$183:$C$185
Name LIST_CATEGORY_ROW: 'Reference lists'!$C$186:$C$187
Name LIST_ACCOUNTING_EVENT: 'Reference lists'!$C$188:$C$252
Name LIST_DEBIT_CREDIT: 'Reference lists'!$C$253:$C$254
Name LIST_LEGACY_ACCOUNT: 'Reference lists'!$C$255:$C$262
Name LIST_TAX_TYPE: 'Reference lists'!$C$263:$C$266
Name LIST_PAYEE_CLASS: 'Reference lists'!$C$267:$C$272
Name LIST_APPROVAL_MODULE: 'Reference lists'!$C$273:$C$276
Name LIST_D0_04_DIMENSION: 'Reference lists'!$C$277:$C$279
Name LIST_R03_RECORD_TYPE: 'Reference lists'!$C$280:$C$283
Name LIST_UA_06_LIST: 'Reference lists'!$C$284:$C$286
Name LIST_UA_02_PRIVILEGE_LEVEL: 'Reference lists'!$C$287:$C$290
Name LIST_UA_02_KEEP_ADD_REMOVE: 'Reference lists'!$C$291:$C$293
Name LIST_UA_03_ROLE_IN_USER_ACCESS: 'Reference lists'!$C$294:$C$298
Name LIST_UA_04_STATUS: 'Reference lists'!$C$299:$C$301
Name LIST_UA_04_CONTROL: 'Reference lists'!$C$302:$C$304
Name LIST_UA_04_REVIEW_FREQUENCY: 'Reference lists'!$C$305:$C$306
Name LIST_UA_05_PARAMETER: 'Reference lists'!$C$307:$C$323
Name LIST_D0_15_MODULE: 'Reference lists'!$C$324:$C$327
Name LIST_D0_07_ROW: 'Reference lists'!$C$328:$C$329
Name LIST_D0_07_ACCOUNT_CLASS: 'Reference lists'!$C$330:$C$335
Name LIST_D0_07_SEPARATOR: 'Reference lists'!$C$336:$C$337
Name LIST_R08_ACCOUNT_TYPE: 'Reference lists'!$C$338:$C$342
Name LIST_R08_NORMAL_BALANCE: 'Reference lists'!$C$343:$C$344

Sheet Start here
A3: Master Data and Configuration Upload Templates
A4: Every master, reference and configuration dataset BIBS needs before go-live, with the templates in the order the data is loaded
A6: Client | C6: BDO Insurance and Reinsurance Brokers, Inc.
A7: Scope | C7: Every master, reference and configuration dataset BIBS needs before go-live, all BRDs
A8: Version and date | C8: Version 1.2, 9 October 2026
A9: Go-live | C9: Go-live is proposed for Monday 3 January 2028 (T), at the year-end boundary (option A of the Data Migration set, for Comptrollership to confirm).
A10: Owner | C10: Program Manager, Business Project Services, with the BDOI owner of each dataset
A11: Prepared by | C11: iorta TechNXT
A12: Classification | C12: Confidential
A14: How to fill in this workbook
A15: 1 | B15: The index below lists every master, reference and configuration dataset BIBS needs before go-live, one template sheet each, in the order the data is loaded: a dataset whose codes others use comes first (Loads after names the templates it depends on). Each template has the column layout BIBS loads.
A16: 2 | B16: Load route: Configuration screen upload (28 templates) - the filled-in sheet is uploaded with Upload on the named configuration screen, in exactly this layout; every row is checked first and the rows are applied when a second user approves the upload; Screen upload (5) - the filled-in sheet is uploaded on the named screen, which checks every row; Migration Console (15) - the data is extracted from the legacy systems by BDOI IT in this layout and loaded by the Data Migration Console; Configuration screen (0) - no upload: the rows are keyed on the screen from the filled-in template (sheet Gaps). Every record is authorised by a second user.
A17: 3 | B17: On a template sheet, read the header block (purpose, who fills it in, how it is loaded, due, depends on) and the guide above each column (Mandatory, Format, Allowed values, What to enter; * marks a mandatory column). Overwrite or delete the grey example row and enter one row per record. Drop-downs offer the allowed values (sheet Reference lists) and the codes of the templates filled in before; a mandatory cell left empty turns red. For a large legacy dataset (clients, opening balances) BDOI IT sends the extract file in the layout instead of typing it.
A18: 4 | B18: The review sheets (lists of values, system parameters, SLA and turnaround, numbering prefixes, notification events, document templates, accounting events) list what the platform delivers; write the value wanted or the decision on each row you own. The sheet Configured on screens lists the set-up decided in working sessions and entered directly on the screens.
A19: 5 | B19: Set the Status of each template, follow Rows entered and Mandatory cells missing, raise questions on the sheet Questions and comments, and return the workbook to the iorta TechNXT project team by each due date. The owner confirms each template (Confirmed by and Date on the sheet) before it is loaded; the guide (BIBS_Templates_BRD-00_Master_Data_Upload_Guide_v1.2) explains the validation and the sign-off of the master data.
A21: Index of the datasets in load order (dependencies first)
A22: Step | B22: ID | C22: Dataset | D22: Group | E22: BRD | F22: Drop | G22: Provided by | H22: Load route | I22: Entered or loaded on | J22: Loads after | K22: Due | L22: Rows entered | M22: Mandatory cells missing | N22: Status | O22: Open
A23: 1 | B23: D0-02 | C23: Branches | D23: Organisation | E23: BRD-05 | F23: Drop 1 | G23: Head, Comptrollership | H23: Configuration screen upload | I23: Setup & Administration › Setup › Branches | J23: - | K23: 4-Jan-2027 – Platform set-up for Drop 1 SIT | L23: ='D0-02 Branches'!$C$10 | M23: ='D0-02 Branches'!$E$10 | N23: Not started | O23: D0-02 →
A24: 2 | B24: D0-04 | C24: Cost centres and business lines | D24: Organisation | E24: BRD-05 | F24: Drop 1 | G24: Head, Comptrollership | H24: Configuration screen upload | I24: Setup & Administration › Setup › Dimensions | J24: - | K24: 4-Jan-2027 – Platform set-up for Drop 1 SIT | L24: ='D0-04 Dimensions'!$C$9 | M24: ='D0-04 Dimensions'!$E$9 | N24: Not started | O24: D0-04 →
A25: 3 | B25: D0-07 | C25: Account categories and numbering | D25: Chart of accounts, tax and accounting | E25: BRD-05 | F25: Drop 1 | G25: Head, Comptrollership | H25: Configuration screen upload | I25: Finance › General Ledger › Chart Upload | J25: - | K25: 4-Jan-2027 – Platform set-up for Drop 1 SIT | L25: ='D0-07 Categories and numbering'!$C$9 | M25: ='D0-07 Categories and numbering'!$E$9 | N25: Not started | O25: D0-07 →
A26: 4 | B26: MD-02 | C26: Currencies | D26: Chart of accounts, tax and accounting | E26: BRD-05 | F26: Drop 1 | G26: Head, Comptrollership (Treasury) | H26: Configuration screen – no upload: BDOI fills in this template and the rows are keyed on the screen, each record authorised by a second user | I26: Setup & Administration › Setup › Currencies & Rates | J26: - | K26: 4-Jan-2027 – Platform set-up for Drop 1 SIT | L26: ='MD-02 Currencies'!$C$9 | M26: ='MD-02 Currencies'!$E$9 | N26: Not started | O26: MD-02 →
A27: 5 | B27: PM-09 | C27: Lists of values and parameters | D27: Products, packages and rates | E27: BRD-03 | F27: Drop 0 | G27: Product Owner, MBS; System Administrator (entry) | H27: Configuration screen upload | I27: Setup & Administration › Broking Setup › Lists of Values or Setup & Administration › Administration › System Parameters | J27: - | K27: 16-Jul-2027 – Values for UAT | L27: ='PM-09 Lists and parameters'!$C$9 | M27: ='PM-09 Lists and parameters'!$E$9 | N27: Not started | O27: PM-09 →
A28: 6 | B28: R01 | C28: Lists of values and MIS values | D28: Clients and KYC | E28: BRD-13 | F28: Drop 0 | G28: MBS data steward (to name); approved by Product Owner, Marketing Business System (MBS); extracted by BDOI IT | H28: Migration Console | I28: Data Migration › Data Migration › Extracts and Batches | J28: - | K28: M3 (29 Jan 2027) | L28: ='R01 Lists of values and MIS val'!$C$9 | M28: ='R01 Lists of values and MIS val'!$E$9 | N28: Not started | O28: R01 →
A29: 7 | B29: R04 | C29: Insurers | D29: Insurers, partners, intermediaries and payees | E29: BRD-03 | F29: Drop 0 | G29: Operations data steward (to name); approved by Head, Operations; extracted by BDOI IT | H29: Migration Console | I29: Data Migration › Data Migration › Extracts and Batches | J29: - | K29: M3 (29 Jan 2027) | L29: ='R04 Insurers'!$C$11 | M29: ='R04 Insurers'!$E$11 | N29: Not started | O29: R04 →
A30: 8 | B30: UA-02 | C30: Role-to-permission matrix | D30: Users, access and approvals | E30: BRD-11 | F30: Drop 0 | G30: Business Administration with the unit heads; reviewed and signed by BDOI Information Security | H30: Configuration screen upload | I30: Setup & Administration › Administration › Roles & Permissions | J30: - | K30: 9-Apr-2027 – Reference data for Trial migration 1 (M4) | L30: ='UA-02 Role matrix'!$C$9 | M30: ='UA-02 Role matrix'!$E$9 | N30: Not started | O30: UA-02 →
A31: 9 | B31: UA-06 | C31: Lists of values | D31: Users, access and approvals | E31: BRD-11 | F31: Drop 0 | G31: Business Administration | H31: Configuration screen upload | I31: Setup & Administration › Broking Setup › Lists of Values | J31: - | K31: 1-Nov-2027 – before the templates that use its codes | L31: ='UA-06 Lists of values'!$C$9 | M31: ='UA-06 Lists of values'!$E$9 | N31: Not started | O31: UA-06 →
A32: 10 | B32: D0-05 | C32: Employees | D32: Organisation | E32: BRD-05 | F32: Drop 1 | G32: Human Resources; Head, Comptrollership | H32: Configuration screen upload | I32: Setup & Administration › Setup › Employees | J32: D0-02, D0-04 | K32: 16-Jul-2027 – Values for UAT | L32: ='D0-05 Employees'!$C$9 | M32: ='D0-05 Employees'!$E$9 | N32: Not started | O32: D0-05 →
A33: 11 | B33: D0-06 | C33: Chart of accounts | D33: Chart of accounts, tax and accounting | E33: BRD-05 | F33: Drop 1 | G33: Head, Comptrollership | H33: Screen upload | I33: Finance › General Ledger › Chart Upload | J33: D0-07 | K33: 4-Jan-2027 – Platform set-up for Drop 1 SIT | L33: ='D0-06 Chart of accounts'!$C$9 | M33: ='D0-06 Chart of accounts'!$E$9 | N33: Not started | O33: D0-06 →
A34: 12 | B34: MD-01 | C34: Business partners (reinsurers, intermediaries, suppliers) | D34: Insurers, partners, intermediaries and payees | E34: BRD-05 | F34: Drop 1 | G34: Head, Comptrollership; Head, Operations for the reinsurers and intermediaries | H34: Configuration screen upload | I34: Setup & Administration › Setup › Business Partners | J34: D0-02 | K34: 9-Apr-2027 – Reference data for Trial migration 1 (M4) | L34: ='MD-01 Business partners'!$C$9 | M34: ='MD-01 Business partners'!$E$9 | N34: Not started | O34: MD-01 →
A35: 13 | B35: R03 | C35: Sales organisation (units and account officers) | D35: Organisation | E35: BRD-01 | F35: Drop 1 | G35: Marketing data steward (to name); approved by Heads, Retail and Corporate Marketing; extracted by BDOI IT | H35: Migration Console | I35: Data Migration › Data Migration › Extracts and Batches | J35: D0-02, D0-04 | K35: M3 (29 Jan 2027) | L35: ='R03 Sales organisation (units a'!$C$9 | M35: ='R03 Sales organisation (units a'!$E$9 | N35: Not started | O35: R03 →
A36: 14 | B36: R05 | C36: Product lines, cover types, products and risk codes | D36: Products, packages and rates | E36: BRD-03 | F36: Drop 0 | G36: MBS data steward (to name); approved by Product Owner, MBS; extracted by BDOI IT | H36: Migration Console | I36: Data Migration › Data Migration › Extracts and Batches | J36: PM-09 | K36: M3 (29 Jan 2027) | L36: ='R05 Product lines, cover types,'!$C$9 | M36: ='R05 Product lines, cover types,'!$E$9 | N36: Not started | O36: R05 →
A37: 15 | B37: UA-01 | C37: Users and roles load | D37: Users, access and approvals | E37: BRD-11 | F37: Drop 0 | G37: Business Administration, with the unit heads who name their users | H37: Screen upload | I37: Setup & Administration › User Access › Bulk Request | J37: UA-06, UA-02 | K37: 1-Nov-2027 – Production values before the dress rehearsal | L37: ='UA-01 Users and roles'!$C$9 | M37: ='UA-01 Users and roles'!$E$9 | N37: Not started | O37: UA-01 →
A38: 16 | B38: D0-03 | C38: Holiday calendar | D38: Organisation | E38: BRD-05 | F38: Drop 1 | G38: Head, Comptrollership; Human Resources | H38: Configuration screen upload | I38: Setup & Administration › Setup › Holiday Calendar | J38: D0-02 | K38: 4-Jan-2027 – Platform set-up for Drop 1 SIT | L38: ='D0-03 Holiday calendar'!$C$9 | M38: ='D0-03 Holiday calendar'!$E$9 | N38: Not started | O38: D0-03 →
A39: 17 | B39: MD-03 | C39: Exchange rates and their source | D39: Chart of accounts, tax and accounting | E39: BRD-05 | F39: Drop 1 | G39: Head, Comptrollership (Treasury) | H39: Configuration screen – no upload: BDOI fills in this template and the rows are keyed on the screen, each record authorised by a second user | I39: Setup & Administration › Setup › Currencies & Rates | J39: MD-02 | K39: 16-Jul-2027 – Values for UAT | L39: ='MD-03 Exchange rates'!$C$9 | M39: ='MD-03 Exchange rates'!$E$9 | N39: Not started | O39: MD-03 →
A40: 18 | B40: R02 | C40: Branches and invoicing branches | D40: Organisation | E40: BRD-05 | F40: Drop 1 | G40: Comptrollership data steward (to name); approved by Head, Comptrollership; extracted by BDOI IT | H40: Migration Console | I40: Data Migration › Data Migration › Extracts and Batches | J40: D0-02 | K40: M3 (29 Jan 2027) | L40: ='R02 Branches and invoicing bran'!$C$9 | M40: ='R02 Branches and invoicing bran'!$E$9 | N40: Not started | O40: R02 →
A41: 19 | B41: R04B | C41: Insurer branches | D41: Insurers, partners, intermediaries and payees | E41: BRD-03 | F41: Drop 0 | G41: Operations data steward (to name); approved by Head, Operations; extracted by BDOI IT | H41: Migration Console | I41: Data Migration › Data Migration › Extracts and Batches | J41: R04 | K41: M3 (29 Jan 2027) | L41: ='R04B Insurer branches'!$C$9 | M41: ='R04B Insurer branches'!$E$9 | N41: Not started | O41: R04B →
A42: 20 | B42: R11 | C42: Receipt series in use | D42: Banks, bank accounts and cheque books | E42: BRD-02 | F42: Drop 1 | G42: Cashiering data steward (to name); approved by Operations - Financial Transactions; extracted by BDOI IT | H42: Migration Console | I42: Data Migration › Data Migration › Extracts and Batches | J42: D0-02 | K42: M3 (29 Jan 2027); final at T-3 | L42: ='R11 Receipt series in use'!$C$9 | M42: ='R11 Receipt series in use'!$E$9 | N42: Not started | O42: R11 →
A43: 21 | B43: UA-04 | C43: Separation-of-duties rules | D43: Users, access and approvals | E43: BRD-11 | F43: Drop 0 | G43: BDOI Information Security | H43: Configuration screen upload | I43: Setup & Administration › User Access › Separation of Duties | J43: UA-02 | K43: 16-Jul-2027 – Values for UAT | L43: ='UA-04 SoD rules'!$C$10 | M43: ='UA-04 SoD rules'!$E$10 | N43: Not started | O43: UA-04 →
A44: 22 | B44: UP-01 | C44: Clients not held in the legacy systems | D44: Clients and KYC | E44: BRD-01 | F44: Drop 1 | G44: Heads, Retail and Corporate Marketing; Product Owner, MBS | H44: Screen upload | I44: Client & Policy › Clients › Clients | J44: R01 | K44: 16-Jul-2027 – Values for UAT | L44: ='UP-01 Clients (upload)'!$C$9 | M44: ='UP-01 Clients (upload)'!$E$9 | N44: Not started | O44: UP-01 →
A45: 23 | B45: C01 | C45: Client master | D45: Clients and KYC | E45: BRD-01 | F45: Drop 1 | G45: Marketing data steward (to name); approved by Product Owner, MBS; Heads, Retail and Corporate Marketing; extracted by BDOI IT | H45: Migration Console | I45: Data Migration › Data Migration › Extracts and Batches | J45: R01, R03, D0-02 | K45: M3 (29 Jan 2027); deltas daily from T-14 days | L45: ='C01 Client master'!$C$10 | M45: ='C01 Client master'!$E$10 | N45: Not started | O45: C01 →
...

Sheet D0-02 Branches
A1: D0-02 Branches | O1: Step 1 of 52
A2: ← Back to Start here | B2: Step 1 of 52. Fill in one row per record below the column headers; the guide above each column says what to enter. | O2: Ask a question →
A3: Purpose | B3: Every BDOI branch and invoicing branch
A4: Provided by | B4: Head, Comptrollership
A5: Due | B5: 4-Jan-2027 – Platform set-up for Drop 1 SIT
A6: How it is loaded | B6: Upload on the configuration screen Setup & Administration › Setup › Branches, approved by a second user
A7: Source | B7: Upload template of the configuration screen (the same columns, headers, mandatory flags and allowed values)
A8: Depends on | B8: Nothing: this template can be filled in first
A9: Tax registration | B9: The BIR branch code and the RDO code of each branch registered with the BIR (blank for a branch that is not a separate registration)
A10: Progress | B10: Rows entered | C10: =SUMPRODUCT(((ROW($B$18:$B$518)>18)+($B$18<>"HO")>0)*(LEN($B$18:$B$518&$C$18:$C$518&$D$18:$D$518&$E$18:$E$518&$F$18:$F$518&$G$18:$G$518&$H$18:$H$518&$I$18:$I$518&$J$18:$J$518&$K$18:$K$518&$L$18:$L$518&$M$18:$M$518&$N$18:$N$518&$O$18:$O$518)>0)) | D10: Mandatory cells missing | E10: =SUMPRODUCT(((ROW($B$18:$B$518)>18)+($B$18<>"HO")>0)*(LEN($B$18:$B$518&$C$18:$C$518&$D$18:$D$518&$E$18:$E$518&$F$18:$F$518&$G$18:$G$518&$H$18:$H$518&$I$18:$I$518&$J$18:$J$518&$K$18:$K$518&$L$18:$L$518&$M$18:$M$518&$N$18:$N$518&$O$18:$O$518)>0)*(($B$18:$B$518="")+($C$18:$C$518="")+($F$18:$F$518="")+($G$18:$G$518="")+($H$18:$H$518="")))
A11: Confirmed by (BDOI owner) | D11: Date
A13: Mandatory | B13: Yes | C13: Yes | D13: No | E13: No | F13: Yes | G13: Yes | H13: Yes | I13: No | J13: No | K13: No | L13: No | M13: No | N13: No | O13: No
A14: Format | B14: Up to 10 capitals | C14: Text | D14: Text | E14: Text | F14: Date dd-MMM-yyyy, e.g. 15-Jan-2026 | G14: Y or N | H14: Y or N | I14: Text | J14: Text | K14: Text | L14: SAT, SUN | M14: Codes separated by commas | N14: 3 to 5 digits | O14: Three digits, optionally a letter
A15: Allowed values | B15: Free entry | C15: Free entry | D15: Free entry | E15: Free entry | F15: A date, for example 15-Jan-2028 | G15: Y or N | H15: Y or N | I15: Free entry | J15: Free entry | K15: Free entry | L15: Free entry | M15: Free entry | N15: Free entry | O15: Free entry
A16: What to enter | B16: Code of the branch; unique | C16: Name shown on screens and documents | D16: Region of the branch | E16: Address printed on documents | F16: Date the branch opened | G16: Y for one branch only | H16: May receive and pay in foreign currency | I16: Branch telephone | J16: Branch mailbox | K16: Head of the branch | L16: Days the branch is closed each week | M16: Legacy branch codes for the code map BRANCH | N16: Branch code of the BIR registration | O16: Revenue District Office of the branch
A17: Row | B17: Branch code * | C17: Branch name * | D17: Region | E17: Address | F17: Opening date * | G17: Head office * | H17: Foreign currency authorised * | I17: Contact phone | J17: Contact e-mail | K17: Branch manager | L17: Weekly rest days | M17: Legacy branch codes | N17: BIR branch code | O17: RDO code
A18: Example – overwrite or delete | B18: HO | C18: Head Office | D18: NCR | E18: Makati City | F18: 40179 | G18: Y | H18: Y | I18: (02) 8888-0000 | J18: ho@company.example.ph | L18: SAT,SUN | M18: 001 | N18: 00000 | O18: 050

Sheet D0-04 Dimensions
A1: D0-04 Cost centres and business lines | G1: Step 2 of 52
A2: ← Back to Start here | B2: Step 2 of 52. Fill in one row per record below the column headers; the guide above each column says what to enter. | G2: Ask a question →
A3: Purpose | B3: The values of the dimensions of journal lines
A4: Provided by | B4: Head, Comptrollership
A5: Due | B5: 4-Jan-2027 – Platform set-up for Drop 1 SIT
A6: How it is loaded | B6: Upload on the configuration screen Setup & Administration › Setup › Dimensions, approved by a second user
A7: Source | B7: Upload template of the configuration screen (the same columns, headers, mandatory flags and allowed values)
A8: Depends on | B8: Nothing: this template can be filled in first
A9: Progress | B9: Rows entered | C9: =SUMPRODUCT(((ROW($B$17:$B$517)>17)+($B$17<>"COST_CENTER")>0)*(LEN($B$17:$B$517&$C$17:$C$517&$D$17:$D$517&$E$17:$E$517)>0)) | D9: Mandatory cells missing | E9: =SUMPRODUCT(((ROW($B$17:$B$517)>17)+($B$17<>"COST_CENTER")>0)*(LEN($B$17:$B$517&$C$17:$C$517&$D$17:$D$517&$E$17:$E$517)>0)*(($B$17:$B$517="")+($C$17:$C$517="")+($D$17:$D$517="")+($E$17:$E$517="")))
A10: Confirmed by (BDOI owner) | D10: Date
A12: Mandatory | B12: Yes | C12: Yes | D12: Yes | E12: Yes
A13: Format | B13: Code from the drop-down | C13: Up to 20 capitals or digits | D13: Text | E13: Y or N
A14: Allowed values | B14: COST_CENTER, BUSINESS_LINE, DEPARTMENT (list Dimension (D0-04)) | C14: Free entry | D14: Free entry | E14: Y or N
A15: What to enter | B15: Dimension of the value | C15: Code of the value | D15: Name shown on screens and reports | E15: N keeps the value for history only
A16: Row | B16: Dimension * | C16: Code * | D16: Name * | E16: Active *
A17: Example – overwrite or delete | B17: COST_CENTER | C17: FIN | D17: Finance and Accounting | E17: Y

Sheet D0-07 Categories and numbering
A1: D0-07 Account categories and numbering | I1: Step 3 of 52
A2: ← Back to Start here | B2: Step 3 of 52. Fill in one row per record below the column headers; the guide above each column says what to enter. | I2: Ask a question →
A3: Purpose | B3: The GL categories and the numbering scheme under each parent account
A4: Provided by | B4: Head, Comptrollership
A5: Due | B5: 4-Jan-2027 – Platform set-up for Drop 1 SIT
A6: How it is loaded | B6: Upload on the configuration screen Finance › General Ledger › Chart Upload, approved by a second user
A7: Source | B7: Upload template of the configuration screen (the same columns, headers, mandatory flags and allowed values)
A8: Depends on | B8: Nothing: this template can be filled in first
A9: Progress | B9: Rows entered | C9: =SUMPRODUCT(((ROW($B$17:$B$517)>17)+($B$17<>"CATEGORY")>0)*(LEN($B$17:$B$517&$C$17:$C$517&$D$17:$D$517&$E$17:$E$517&$F$17:$F$517&$G$17:$G$517&$H$17:$H$517&$I$17:$I$517)>0)) | D9: Mandatory cells missing | E9: =SUMPRODUCT(((ROW($B$17:$B$517)>17)+($B$17<>"CATEGORY")>0)*(LEN($B$17:$B$517&$C$17:$C$517&$D$17:$D$517&$E$17:$E$517&$F$17:$F$517&$G$17:$G$517&$H$17:$H$517&$I$17:$I$517)>0)*(($B$17:$B$517="")))
A10: Confirmed by (BDOI owner) | D10: Date
A12: Mandatory | B12: Yes | C12: Conditional: CATEGORY | D12: Conditional: CATEGORY | E12: Conditional: CATEGORY | F12: Conditional: CATEGORY | G12: Conditional: NUMBERING | H12: Conditional: NUMBERING | I12: Conditional: NUMBERING
A13: Format | B13: Code from the drop-down | C13: Text | D13: Text | E13: Code from the drop-down | F13: Y or N | G13: Text | H13: Code from the drop-down | I13: Number without thousands separators, e.g. 1500000.50
A14: Allowed values | B14: CATEGORY, NUMBERING (list Row (D0-07)) | C14: Free entry | D14: Free entry | E14: ASSET, LIABILITY, EQUITY, INCOME, EXPENSE, MEMORANDUM (list Account class (D0-07)) | F14: Y or N | G14: Code of an existing account of the chart of accounts | H14: ., - (list Separator (D0-07)) | I14: A whole number from 1 to 6
A15: What to enter | B15: What the row defines | C15: GL category | D15: Name of the category | E15: Class of the accounts of the category | F15: Y for the accounts of bank accounts | G15: Parent whose children are numbered | H15: Between the parent code and the running number | I15: Digits of the running number
A16: Row | B16: Row * | C16: Category code | D16: Category name | E16: Account class | F16: Bank category | G16: Parent account | H16: Separator | I16: Width
A17: Example – overwrite or delete | B17: CATEGORY | C17: CASH_IN_BANK | D17: Cash in bank | E17: ASSET | F17: Y | G17: 1110 | H17: . | I17: 2

Sheet MD-02 Currencies
A1: MD-02 Currencies | G1: Step 4 of 52
A2: ← Back to Start here | B2: Step 4 of 52. Fill in one row per record below the column headers; the guide above each column says what to enter. | G2: Ask a question →
A3: Purpose | B3: One row per currency BIBS accepts on transactions and bank accounts: the base currency PHP and each foreign currency BDOI deals in.
A4: Provided by | B4: Head, Comptrollership (Treasury)
A5: Due | B5: 4-Jan-2027 – Platform set-up for Drop 1 SIT
A6: How it is loaded | B6: Configuration screen: Setup & Administration › Setup › Currencies & Rates, authorised by a second user
A7: Source | B7: BDOI currency list
A8: Depends on | B8: Nothing: this template can be filled in first
A9: Progress | B9: Rows entered | C9: =SUMPRODUCT(((ROW($B$17:$B$317)>17)+($B$17<>"USD")>0)*(LEN($B$17:$B$317&$C$17:$C$317&$D$17:$D$317&$E$17:$E$317&$F$17:$F$317)>0)) | D9: Mandatory cells missing | E9: =SUMPRODUCT(((ROW($B$17:$B$317)>17)+($B$17<>"USD")>0)*(LEN($B$17:$B$317&$C$17:$C$317&$D$17:$D$317&$E$17:$E$317&$F$17:$F$317)>0)*(($B$17:$B$317="")+($C$17:$C$317="")+($E$17:$E$317="")+($F$17:$F$317="")))
A10: Confirmed by (BDOI owner) | D10: Date
A12: Mandatory | B12: Yes | C12: Yes | D12: No | E12: Yes | F12: Yes
A13: Format | B13: ISO 4217, 3 capitals | C13: Text, up to 60 | D13: Up to 5 characters | E13: Whole number 0 to 4 | F13: Y or N
A14: Allowed values | B14: Free entry, up to 3 characters | C14: Free entry, up to 60 characters | D14: Free entry, up to 5 characters | E14: A whole number from 0 to 4 | F14: Y or N
A15: What to enter | B15: Code of the currency | C15: Name of the currency | D15: Symbol printed on documents | E15: Decimals of the amounts in the currency | F15: Y when the currency may be used
A16: Row | B16: Currency code * | C16: Name * | D16: Symbol | E16: Decimal places * | F16: Active *
A17: Example – overwrite or delete | B17: USD | C17: US dollar | D17: $ | E17: 2 | F17: Y

Sheet PM-09 Lists and parameters
A1: PM-09 Lists of values and parameters | G1: Step 5 of 52
A2: ← Back to Start here | B2: Step 5 of 52. Fill in one row per record below the column headers; the guide above each column says what to enter. | G2: Ask a question →
A3: Purpose | B3: The values of the Product Maintenance lists (request reasons, response outcomes, advisory groups, not-proceeded reasons, incentive types, coverage kinds, clause kinds, document types, market segments) and the parameters (numbering, reply days, expiry notice, advisory groups, service levels)
A4: Provided by | B4: Product Owner, MBS; System Administrator (entry)
A5: Due | B5: 16-Jul-2027 – Values for UAT
A6: How it is loaded | B6: Upload on the configuration screen Setup & Administration › Broking Setup › Lists of Values or Setup & Administration › Administration › System Parameters, approved by a second user
A7: Source | B7: Upload template of the configuration screen (the same columns, headers, mandatory flags and allowed values)
A8: Depends on | B8: Nothing: this template can be filled in first
A9: Progress | B9: Rows entered | C9: =SUMPRODUCT(((ROW($B$17:$B$517)>17)+($B$17<>"PKG_REQUEST_REASON")>0)*(LEN($B$17:$B$517&$C$17:$C$517&$D$17:$D$517&$E$17:$E$517&$F$17:$F$517)>0)) | D9: Mandatory cells missing | E9: =SUMPRODUCT(((ROW($B$17:$B$517)>17)+($B$17<>"PKG_REQUEST_REASON")>0)*(LEN($B$17:$B$517&$C$17:$C$517&$D$17:$D$517&$E$17:$E$517&$F$17:$F$517)>0)*(($B$17:$B$517="")+($D$17:$D$517="")))
A10: Confirmed by (BDOI owner) | D10: Date
A12: Mandatory | B12: Yes | C12: Conditional: list | D12: Yes | E12: Conditional: list | F12: Conditional: list
A13: Format | B13: Code from the drop-down | C13: Up to 40 capitals | D13: Text | E13: Text | F13: dd-MMM-yyyy
A14: Allowed values | B14: List List or parameter (PM-09): 23 values, see Reference lists | C14: Free entry | D14: Free entry | E14: Free entry | F14: Free entry
A15: What to enter | B15: List or parameter | C15: Code of the value of a list | D15: Label of the value, or value of the parameter | E15: Order; active Y or N | F15: First day of use of the value
A16: Row | B16: List or parameter * | C16: Value code | D16: Label or value * | E16: Order / Active | F16: Effective from
A17: Example – overwrite or delete | B17: PKG_REQUEST_REASON | C17: LOSS_EXPERIENCE | D17: Loss experience | E17: 50; Y

Sheet R01 Lists of values and MIS val
A1: R01 Lists of values and MIS values | I1: Step 6 of 52
A2: ← Back to Start here | B2: Step 6 of 52. Fill in one row per record below the column headers; the guide above each column says what to enter. | I2: Ask a question →
A3: Purpose | B3: One row per record of Lists of values and MIS values as extracted from QPS, EBIX. Key list_type, code. Sent as the file R01_template.csv (CSV, header row as below) with its control file (row count, count of distinct keys).
A4: Provided by | B4: MBS data steward (to name); approved by Product Owner, Marketing Business System (MBS); extracted by BDOI IT
A5: Due | B5: M3 (29 Jan 2027)
A6: How it is loaded | B6: Migration Console: the file R01_template.csv (the header row as below) and its control file are received on Data Migration › Data Migration › Extracts and loaded by a batch of object R01; lands in: Lists of Values (maker-checker); MIS field catalogue
A7: Source | B7: QPS, EBIX
A8: Depends on | B8: Nothing: this template can be filled in first
A9: Progress | B9: Rows entered | C9: =SUMPRODUCT(((ROW($B$18:$B$218)>18)+($B$18<>"MARKET_SEGMENT")>0)*(LEN($B$18:$B$218&$C$18:$C$218&$D$18:$D$218&$E$18:$E$218&$F$18:$F$218&$G$18:$G$218&$H$18:$H$218&$I$18:$I$218)>0)) | D9: Mandatory cells missing | E9: =SUMPRODUCT(((ROW($B$18:$B$218)>18)+($B$18<>"MARKET_SEGMENT")>0)*(LEN($B$18:$B$218&$C$18:$C$218&$D$18:$D$218&$E$18:$E$218&$F$18:$F$218&$G$18:$G$218&$H$18:$H$218&$I$18:$I$218)>0)*(($B$18:$B$218="")+($C$18:$C$218="")+($D$18:$D$218="")+($F$18:$F$218="")))
A10: Confirmed by (BDOI owner) | D10: Date
A12: Check when loaded | B12: Known list name | C12: Unique per list_type | D12: Not blank | E12: Parent exists in the file | F12: Y or N | G12: Valid date | H12: Not before effective_from | I12: 0 or more
A13: Mandatory | B13: Yes | C13: Yes | D13: Yes | E13: No | F13: Yes | G13: No | H13: No | I13: No
A14: Format | B14: Code, up to 40; Upper case | C14: Code, up to 40; As stored in legacy | D14: Text, up to 200; Free text | E14: Code, up to 40 | F14: Flag, up to 1; Y or N | G14: Date, up to 10; yyyy-MM-dd | H14: Date, up to 10; yyyy-MM-dd | I14: Integer, up to 9; Digits
A15: Allowed values | B15: Legacy list names; one code map set LOV:<list> or MIS:<field> per list | C15: Free entry, up to 40 characters | D15: Free entry, up to 200 characters | E15: Codes of the same file | F15: Y or N | G15: Free entry | H15: Free entry | I15: A whole number
A16: What to enter | B16: Legacy name of the list (for example MARKET_SEGMENT, BUSINESS_ORIGIN, CUSTOMER_SEGMENT, REGION, AREA, DEPARTMENT, ACCOUNT_TYPE, ID_TYPE, NATIONALITY) | C16: Legacy value code | D16: Legacy value description | E16: Code of the parent value for hierarchical lists (area under region) | F16: Value in use in legacy | G16: First day the value is valid | H16: Last day the value is valid | I16: Number of legacy records that use the value (helps the mapping)
A17: Row | B17: list_type * | C17: code * | D17: description * | E17: parent_code | F17: active_flag * | G17: effective_from | H17: effective_to | I17: used_count
A18: Example – overwrite or delete | B18: MARKET_SEGMENT | C18: CBG | D18: Consumer Banking Group | E18: NCR | F18: Y | G18: 2020-01-01 | I18: 1520

Sheet R04 Insurers
A1: R04 Insurers | K1: Step 7 of 52
A2: ← Back to Start here | B2: Step 7 of 52. Fill in one row per record below the column headers; the guide above each column says what to enter. | K2: Ask a question →
A3: Purpose | B3: One row per record of Insurers and insurer branches as extracted from QPS, EBIX. Key insurer_code. Sent as the file R04_template.csv (CSV, header row as below) with its control file (row count, count of distinct keys).
A4: Provided by | B4: Operations data steward (to name); approved by Head, Operations; extracted by BDOI IT
A5: Due | B5: M3 (29 Jan 2027)
A6: How it is loaded | B6: Migration Console: the file R04_template.csv (the header row as below) and its control file are received on Data Migration › Data Migration › Extracts and loaded by a batch of object R04; lands in: Insurers and insurer branches (insurer and party records)
A7: Source | B7: QPS, EBIX
A8: Depends on | B8: Nothing: this template can be filled in first
A9: Tax profile | B9: The insurer's registered TIN, VAT treatment and the ATC it withholds on BDOI's commission are kept in the party tax profile (template TX-01)
A10: Tax status | B10: VAT-registered (VAT on premium) or not VAT-registered (premium tax) is not a column of this layout: it is entered on the insurer screen (Client & Policy › Product Maintenance › Insurers, field Tax status); blank keeps the tax of the product line
A11: Progress | B11: Rows entered | C11: =SUMPRODUCT(((ROW($B$20:$B$220)>20)+($B$20<>"MAL")>0)*(LEN($B$20:$B$220&$C$20:$C$220&$D$20:$D$220&$E$20:$E$220&$F$20:$F$220&$G$20:$G$220&$H$20:$H$220&$I$20:$I$220&$J$20:$J$220&$K$20:$K$220)>0)) | D11: Mandatory cells missing | E11: =SUMPRODUCT(((ROW($B$20:$B$220)>20)+($B$20<>"MAL")>0)*(LEN($B$20:$B$220&$C$20:$C$220&$D$20:$D$220&$E$20:$E$220&$F$20:$F$220&$G$20:$G$220&$H$20:$H$220&$I$20:$I$220&$J$20:$J$220&$K$20:$K$220)>0)*(($B$20:$B$220="")+($C$20:$C$220="")+($K$20:$K$220="")))
A12: Confirmed by (BDOI owner) | D12: Date
A14: Check when loaded | B14: Unique | C14: Not blank | D14: - | E14: 9 to 12 digits | F14: - | G14: - | H14: Valid date | I14: Valid e-mail addresses | J14: 0 to 365 | K14: Mapped
A15: Mandatory | B15: Yes | C15: Yes | D15: No | E15: No | F15: No | G15: No | H15: No | I15: No | J15: No | K15: Yes
A16: Format | B16: Code, up to 30; As stored in legacy | C16: Text, up to 200; Free text | D16: Text, up to 40; Free text | E16: Text, up to 20; 000-000-000-000 | F16: Text, up to 300; Free text | G16: Text, up to 40; Free text | H16: Date, up to 10; yyyy-MM-dd | I16: Text, up to 500; name@domain;name@domain | J16: Integer, up to 3; Digits | K16: Code, up to 20; As stored in legacy
A17: Allowed values | B17: Free entry, up to 30 characters | C17: Free entry, up to 200 characters | D17: Free entry, up to 40 characters | E17: Free entry, up to 20 characters | F17: Free entry, up to 300 characters | G17: Free entry, up to 40 characters | H17: Free entry | I17: Free entry, up to 500 characters | J17: A whole number | K17: The legacy code; mapped by the code map STATUS:INSURER (Code Maps screen of the Data Migration Console; maps prepared in the Migration Workbook of BRD-13)
A18: What to enter | B18: Legacy insurer code | C18: Registered name | D18: Short name | E18: Tax identification number | F18: Registered address | G18: Insurance Commission accreditation number | H18: End of accreditation | I18: E-mail address(es) for placement, separated by semicolons | J18: Credit term in days | K18: Insurer status in legacy
A19: Row | B19: insurer_code * | C19: insurer_name * | D19: short_name | E19: tin | F19: address | G19: accreditation_no | H19: accredited_until | I19: placement_email | J19: default_credit_days | K19: status *
A20: Example – overwrite or delete | B20: MAL | C20: Malayan Insurance Co., Inc. | D20: Malayan | E20: 000-123-456-000 | F20: 500 Quintin Paredes St., Manila | G20: IC-2025-0123 | H20: 2028-06-30 | I20: placement@insurer.example | J20: 60 | K20: ACTIVE

Sheet UA-02 Role matrix
A1: UA-02 Role-to-permission matrix | I1: Step 8 of 52
A2: ← Back to Start here | B2: Step 8 of 52. Fill in one row per record below the column headers; the guide above each column says what to enter. | I2: Ask a question →
A3: Purpose | B3: The group profiles BDOI keeps, their privilege level and the permissions of each, starting from the User Access Matrix as delivered
A4: Provided by | B4: Business Administration with the unit heads; reviewed and signed by BDOI Information Security
A5: Due | B5: 9-Apr-2027 – Reference data for Trial migration 1 (M4)
A6: How it is loaded | B6: Upload on the configuration screen Setup & Administration › Administration › Roles & Permissions, approved by a second user
A7: Source | B7: Upload template of the configuration screen (the same columns, headers, mandatory flags and allowed values)
A8: Depends on | B8: Nothing: this template can be filled in first
A9: Progress | B9: Rows entered | C9: =SUMPRODUCT(((ROW($B$17:$B$517)>17)+($B$17<>"MKT_AO")>0)*(LEN($B$17:$B$517&$C$17:$C$517&$D$17:$D$517&$E$17:$E$517&$F$17:$F$517&$G$17:$G$517&$H$17:$H$517&$I$17:$I$517)>0)) | D9: Mandatory cells missing | E9: =SUMPRODUCT(((ROW($B$17:$B$517)>17)+($B$17<>"MKT_AO")>0)*(LEN($B$17:$B$517&$C$17:$C$517&$D$17:$D$517&$E$17:$E$517&$F$17:$F$517&$G$17:$G$517&$H$17:$H$517&$I$17:$I$517)>0)*(($B$17:$B$517="")+($C$17:$C$517="")+($E$17:$E$517="")+($F$17:$F$517="")+($H$17:$H$517="")+($I$17:$I$517="")))
A10: Confirmed by (BDOI owner) | D10: Date
A12: Mandatory | B12: Yes | C12: Yes | D12: No | E12: Yes | F12: Yes | G12: No | H12: Yes | I12: Yes
A13: Format | B13: Up to 40 capital letters, digits or _ | C13: Text | D13: Text | E13: Code from the drop-down | F13: Text | G13: Text | H13: Code from the drop-down | I13: Text
A14: Allowed values | B14: Free entry | C14: Free entry | D14: Free entry | E14: Low, Standard, High, Admin (list Privilege level (UA-02)) | F14: Permission code of the User Access Matrix | G14: Free entry | H14: KEEP, ADD, REMOVE (list Keep / Add / Remove (UA-02)) | I14: Free entry
A15: What to enter | B15: Code of the profile; an existing code changes the profile | C15: Name shown on screens | D15: What the profile is for | E15: Low, Standard, High or Admin | F15: One row per permission of the profile | G15: As shown by the matrix, for the review | H15: Change against the matrix as delivered | I15: Unit head who confirms the row
A16: Row | B16: Group profile code * | C16: Name * | D16: Description | E16: Privilege level * | F16: Permission * | G16: Action class | H16: Keep / Add / Remove * | I16: Approved by unit head *
A17: Example – overwrite or delete | B17: MKT_AO | C17: Marketing Account Officer | D17: Marketing account officers | E17: Standard | F17: QUOTE_MAINTAIN | G17: Create, Amend | H17: KEEP | I17: Carla Reyes

Sheet UA-06 Lists of values
A1: UA-06 Lists of values | G1: Step 9 of 52
A2: ← Back to Start here | B2: Step 9 of 52. Fill in one row per record below the column headers; the guide above each column says what to enter. | G2: Ask a question →
A3: Purpose | B3: The values of the lists of user access (business unit groups and user levels, empty as delivered; deactivation reasons, to confirm with BDOI; the reason No sign-in for the dormancy period is used by the dormant-user job and stays)
A4: Provided by | B4: Business Administration
A5: Due | B5: 1-Nov-2027 – before the templates that use its codes
A6: How it is loaded | B6: Upload on the configuration screen Setup & Administration › Broking Setup › Lists of Values, approved by a second user
A7: Source | B7: Upload template of the configuration screen (the same columns, headers, mandatory flags and allowed values)
A8: Depends on | B8: Nothing: this template can be filled in first
A9: Progress | B9: Rows entered | C9: =SUMPRODUCT(((ROW($B$17:$B$517)>17)+($B$17<>"UAM_BUSINESS_UNIT")>0)*(LEN($B$17:$B$517&$C$17:$C$517&$D$17:$D$517&$E$17:$E$517&$F$17:$F$517)>0)) | D9: Mandatory cells missing | E9: =SUMPRODUCT(((ROW($B$17:$B$517)>17)+($B$17<>"UAM_BUSINESS_UNIT")>0)*(LEN($B$17:$B$517&$C$17:$C$517&$D$17:$D$517&$E$17:$E$517&$F$17:$F$517)>0)*(($B$17:$B$517="")+($C$17:$C$517="")+($D$17:$D$517="")+($F$17:$F$517="")))
A10: Confirmed by (BDOI owner) | D10: Date
A12: Mandatory | B12: Yes | C12: Yes | D12: Yes | E12: No | F12: Yes
A13: Format | B13: Code from the drop-down | C13: Up to 30 capitals, digits or _ | D13: Up to 120 characters | E13: Number without thousands separators, e.g. 1500000.50 | F13: Date dd-MMM-yyyy, e.g. 15-Jan-2026
A14: Allowed values | B14: UAM_BUSINESS_UNIT, UAM_USER_LEVEL, UAM_DEACTIVATION_REASON (list List (UA-06)) | C14: Free entry | D14: Free entry | E14: A number | F14: A date, for example 15-Jan-2028
A15: What to enter | B15: The list | C15: Code of the value | D15: Label shown on screens | E15: Order in the drop-down | F15: Date the value may be used
A16: Row | B16: List * | C16: Code * | D16: Label * | E16: Sort order | F16: Effective from *
A17: Example – overwrite or delete | B17: UAM_BUSINESS_UNIT | C17: COMBANK_MKT | D17: Combank Marketing | E17: 10 | F17: 46391

Sheet D0-05 Employees
A1: D0-05 Employees | H1: Step 10 of 52
A2: ← Back to Start here | B2: Step 10 of 52. Fill in one row per record below the column headers; the guide above each column says what to enter. | H2: Ask a question →
A3: Purpose | B3: Employees used by the cost-centre rules, petty cash and staff advances
A4: Provided by | B4: Human Resources; Head, Comptrollership
A5: Due | B5: 16-Jul-2027 – Values for UAT
A6: How it is loaded | B6: Upload on the configuration screen Setup & Administration › Setup › Employees, approved by a second user
A7: Source | B7: Upload template of the configuration screen (the same columns, headers, mandatory flags and allowed values)
A8: Depends on | B8: D0-02 Branches → | D8: D0-04 Cost centres and business lines →
A9: Progress | B9: Rows entered | C9: =SUMPRODUCT(((ROW($B$17:$B$517)>17)+($B$17<>"1203344")>0)*(LEN($B$17:$B$517&$C$17:$C$517&$D$17:$D$517&$E$17:$E$517&$F$17:$F$517&$G$17:$G$517&$H$17:$H$517)>0)) | D9: Mandatory cells missing | E9: =SUMPRODUCT(((ROW($B$17:$B$517)>17)+($B$17<>"1203344")>0)*(LEN($B$17:$B$517&$C$17:$C$517&$D$17:$D$517&$E$17:$E$517&$F$17:$F$517&$G$17:$G$517&$H$17:$H$517)>0)*(($B$17:$B$517="")+($C$17:$C$517="")+($D$17:$D$517="")+($E$17:$E$517="")))
A10: Confirmed by (BDOI owner) | D10: Date
A12: Mandatory | B12: Yes | C12: Yes | D12: Yes | E12: Yes | F12: No | G12: No | H12: No
A13: Format | B13: HR number | C13: Text | D13: Text | E13: Text | F13: Text | G13: Text | H13: Date dd-MMM-yyyy, e.g. 15-Jan-2026
A14: Allowed values | B14: Free entry | C14: Free entry | D14: Code of an existing branch | E14: Code of an existing cost centre | F14: Free entry | G14: Free entry | H14: A date, for example 15-Jan-2028
A15: What to enter | B15: Employee number; unique | C15: Name of the employee | D15: Home branch | E15: Cost centre of the employee | F15: Position title | G15: For advices and statements | H15: Date of hire
A16: Row | B16: Employee number * | C16: Full name * | D16: Branch code * | E16: Cost centre * | F16: Position | G16: E-mail | H16: Hired on
A17: Example – overwrite or delete | B17: 1203344 | C17: Andrea Mercado | D17: HO | E17: FIN | F17: Accounting Officer | G17: andrea.mercado@company.example.ph | H17: 43527

Sheet D0-06 Chart of accounts
A1: D0-06 Chart of accounts | Q1: Step 11 of 52
A2: ← Back to Start here | B2: Step 11 of 52. Fill in one row per record below the column headers; the guide above each column says what to enter. | Q2: Ask a question →
A3: Purpose | B3: The production chart of accounts, in the columns of the chart upload. List every parent before its children. Accounts are created pending authorization.
A4: Provided by | B4: Head, Comptrollership
A5: Due | B5: 4-Jan-2027 – Platform set-up for Drop 1 SIT
A6: How it is loaded | B6: Chart Upload (General Ledger): the file is checked row by row and every account is created pending authorisation by Comptrollership
A7: Source | B7: The BDOI chart of accounts in use, completed with the legacy control accounts (D0-09)
A8: Depends on | B8: D0-07 Account categories and numbering →
A9: Progress | B9: Rows entered | C9: =SUMPRODUCT(((ROW($C$17:$C$517)>17)+($C$17<>"1210.07")>0)*(LEN($B$17:$B$517&$C$17:$C$517&$D$17:$D$517&$E$17:$E$517&$F$17:$F$517&$G$17:$G$517&$H$17:$H$517&$I$17:$I$517&$J$17:$J$517&$K$17:$K$517&$L$17:$L$517&$M$17:$M$517&$N$17:$N$517&$O$17:$O$517&$P$17:$P$517&$Q$17:$Q$517)>0)) | D9: Mandatory cells missing | E9: =SUMPRODUCT(((ROW($C$17:$C$517)>17)+($C$17<>"1210.07")>0)*(LEN($B$17:$B$517&$C$17:$C$517&$D$17:$D$517&$E$17:$E$517&$F$17:$F$517&$G$17:$G$517&$H$17:$H$517&$I$17:$I$517&$J$17:$J$517&$K$17:$K$517&$L$17:$L$517&$M$17:$M$517&$N$17:$N$517&$O$17:$O$517&$P$17:$P$517&$Q$17:$Q$517)>0)*(($D$17:$D$517="")+($F$17:$F$517="")+($G$17:$G$517="")))
A10: Confirmed by (BDOI owner) | D10: Date
A12: Mandatory | B12: No | C12: No | D12: Yes | E12: No | F12: Yes | G12: Yes | H12: No | I12: No | J12: No | K12: No | L12: No | M12: No | N12: No | O12: No | P12: No | Q12: No
A13: Format | B13: Text | C13: Text | D13: Text | E13: Text | F13: Text | G13: Text | H13: Text | I13: Y or N | J13: Text | K13: Text | L13: Y or N | M13: Y or N | N13: Y or N | O13: Text | P13: yyyy-MM-dd | Q13: Text
A14: Allowed values | B14: A code of D0-06 Chart of accounts, column Account Code | C14: Free entry | D14: Free entry | E14: Free entry | F14: ASSET, LIABILITY, EQUITY, INCOME, EXPENSE, MEMORANDUM (list Account class of the chart) | G14: GROUP, MAIN, SUB, MICRO (list Account level) | H14: A code of D0-07 Account categories and numbering, column Category code | I14: Y or N | J14: Free entry | K14: Free entry | L14: Y or N | M14: Y or N | N14: Y or N | O14: Free entry | P14: Free entry | Q14: ALLOW, WARN, BLOCK (list Negative balance)
A15: What to enter | B15: Code of the parent account; blank for a top-level group | C15: Account code; blank for the next number of the parent's scheme | D15: Account name | E15: Unique short code used on journal lines | F15: Class of the account | G15: Level of the account, one tier below the parent | H15: GL category | I15: Control account | J15: Sub-ledger the account controls; blank for none | K15: Currencies allowed on the account; blank for all | L15: Manual journals allowed; blank for Y | M15: Cost centre mandatory on journal lines | N15: Revalued at month end | O15: Financial statement line | P15: Opening date; blank for today | Q15: What a negative balance does; blank for ALLOW
A16: Row | B16: Parent Code | C16: Account Code | D16: Account Name * | E16: Short Code | F16: Class * | G16: Level * | H16: Category | I16: Control Account | J16: Sub-ledger Type | K16: Currencies | L16: Manual Posting | M16: Cost Centre Required | N16: Revaluation Required | O16: Report Group | P16: Opened On | Q16: Negative Balance
A17: Example – overwrite or delete | C17: 1210.07 | D17: Premium Receivable - Motor | E17: PRMOTOR | F17: ASSET | G17: SUB | I17: N | J17: POLICYHOLDER | K17: PHP | L17: Y | M17: N | N17: N | O17: Premium Receivable | P17: 2026-01-01 | Q17: WARN

Sheet MD-01 Business partners
A1: MD-01 Business partners (reinsurers, intermediaries, suppliers) | O1: Step 12 of 52
A2: ← Back to Start here | B2: Step 12 of 52. Fill in one row per record below the column headers; the guide above each column says what to enter. | O2: Ask a question →
A3: Purpose | B3: One row per business partner other than an insurer or a client: agents and brokers (intermediaries), reinsurers and reinsurance brokers, co-insurers, suppliers, garages, surveyors and banks. Insurers come from R04; clients from C01 and the client upload.
A4: Provided by | B4: Head, Comptrollership; Head, Operations for the reinsurers and intermediaries
A5: Due | B5: 9-Apr-2027 – Reference data for Trial migration 1 (M4)
A6: How it is loaded | B6: Upload on the configuration screen Setup & Administration › Setup › Business Partners, approved by a second user
A7: Source | B7: Upload template of the configuration screen (the same columns, headers, mandatory flags and allowed values)
A8: Depends on | B8: D0-02 Branches →
A9: Progress | B9: Rows entered | C9: =SUMPRODUCT(((ROW($B$17:$B$317)>17)+($B$17<>"RI-0001")>0)*(LEN($B$17:$B$317&$C$17:$C$317&$D$17:$D$317&$E$17:$E$317&$F$17:$F$317&$G$17:$G$317&$H$17:$H$317&$I$17:$I$317&$J$17:$J$317&$K$17:$K$317&$L$17:$L$317&$M$17:$M$317&$N$17:$N$317&$O$17:$O$317)>0)) | D9: Mandatory cells missing | E9: =SUMPRODUCT(((ROW($B$17:$B$317)>17)+($B$17<>"RI-0001")>0)*(LEN($B$17:$B$317&$C$17:$C$317&$D$17:$D$317&$E$17:$E$317&$F$17:$F$317&$G$17:$G$317&$H$17:$H$317&$I$17:$I$317&$J$17:$J$317&$K$17:$K$317&$L$17:$L$317&$M$17:$M$317&$N$17:$N$317&$O$17:$O$317)>0)*(($B$17:$B$317="")+($C$17:$C$317="")+($D$17:$D$317="")+($I$17:$I$317="")))
A10: Confirmed by (BDOI owner) | D10: Date
A12: Mandatory | B12: Yes | C12: Yes | D12: Yes | E12: No | F12: No | G12: No | H12: No | I12: Yes | J12: No | K12: No | L12: Conditional: agent, broker, reinsurance broker | M12: No | N12: No | O12: No
A13: Format | B13: Up to 30; capitals, digits, - and . | C13: Code from the drop-down | D13: Text | E13: 000-000-000-000 | F13: Text | G13: Text | H13: Text | I13: Text | J13: Text | K13: Text | L13: Text | M13: Number without thousands separators, e.g. 1500000.50 | N13: Number without thousands separators, e.g. 1500000.50 | O13: Number without thousands separators, e.g. 1500000.50
A14: Allowed values | B14: Free entry | C14: List Party type (MD-01): 12 values, see Reference lists | D14: Free entry | E14: Free entry | F14: Free entry | G14: Free entry | H14: Free entry | I14: Free entry | J14: Free entry | K14: Free entry | L14: Free entry | M14: A number | N14: A number | O14: A number
A15: What to enter | B15: Code of the partner, unique | C15: Kind of partner | D15: Registered name | E15: Tax identification number | F15: Registered address | G15: E-mail for advices and statements | H15: Phone number | I15: Currency of the partner's transactions | J15: Bank of the partner's account | K15: Account number for payments | L15: Insurance Commission licence number | M15: Credit days of the partner's items | N15: Commission rate of an intermediary | O15: Withholding tax rate applied to the partner
A16: Row | B16: Party code * | C16: Party type * | D16: Name * | E16: TIN / tax id | F16: Address | G16: E-mail | H16: Phone | I16: Default currency * | J16: Bank name | K16: Bank account no. | L16: Licence no. | M16: Credit days | N16: Commission rate % | O16: Withholding tax rate %
A17: Example – overwrite or delete | B17: RI-0001 | C17: REINSURER | D17: Asia Pacific Reinsurance Corp. | E17: 123-456-789-000 | F17: Makati City | G17: treaty@apre.example.ph | H17: +63 2 8888 0000 | I17: PHP | J17: Metropolitan Commercial Bank | K17: 001234567890 | L17: IC-RB-2026-015 | M17: 30 | O17: 2

Sheet R03 Sales organisation (units a
A1: R03 Sales organisation (units and account officers) | L1: Step 13 of 52
A2: ← Back to Start here | B2: Step 13 of 52. Fill in one row per record below the column headers; the guide above each column says what to enter. | L2: Ask a question →
A3: Purpose | B3: One row per record of Sales organisation (regions, departments, teams, unit heads, account officers) as extracted from QPS, EBIX. Key record_type, unit_code, ao_user_id. Sent as the file R03_template.csv (CSV, header row as below) with its control file (row count, row count).
A4: Provided by | B4: Marketing data steward (to name); approved by Heads, Retail and Corporate Marketing; extracted by BDOI IT
A5: Due | B5: M3 (29 Jan 2027)
A6: How it is loaded | B6: Migration Console: the file R03_template.csv (the header row as below) and its control file are received on Data Migration › Data Migration › Extracts and loaded by a batch of object R03; lands in: Sales organisation: sales units and account officers
A7: Source | B7: QPS, EBIX
A8: Depends on | B8: D0-02 Branches → | D8: D0-04 Cost centres and business lines →
A9: Progress | B9: Rows entered | C9: =SUMPRODUCT(((ROW($B$18:$B$218)>18)+($B$18<>"TEAM")>0)*(LEN($B$18:$B$218&$C$18:$C$218&$D$18:$D$218&$E$18:$E$218&$F$18:$F$218&$G$18:$G$218&$H$18:$H$218&$I$18:$I$218&$J$18:$J$218&$K$18:$K$218&$L$18:$L$218)>0)) | D9: Mandatory cells missing | E9: =SUMPRODUCT(((ROW($B$18:$B$218)>18)+($B$18<>"TEAM")>0)*(LEN($B$18:$B$218&$C$18:$C$218&$D$18:$D$218&$E$18:$E$218&$F$18:$F$218&$G$18:$G$218&$H$18:$H$218&$I$18:$I$218&$J$18:$J$218&$K$18:$K$218&$L$18:$L$218)>0)*(($B$18:$B$218="")+($C$18:$C$218="")+($L$18:$L$218="")))
A10: Confirmed by (BDOI owner) | D10: Date
A12: Check when loaded | B12: In the list | C12: Exists as a TEAM row for AO rows | D12: Mandatory for REGION, DEPARTMENT, TEAM | E12: Mandatory for DEPARTMENT and TEAM; parent exists | F12: Mapped in USER | G12: Mapped | H12: Mandatory for AO rows; mapped in USER | I12: Unique | J12: Mandatory for AO rows | K12: Mapped | L12: Y or N
A13: Mandatory | B13: Yes | C13: Yes | D13: Conditional: Mandatory for REGION, DEPARTMENT, TEAM | E13: Conditional: Mandatory for DEPARTMENT and TEAM; parent exists | F13: No | G13: No | H13: Conditional: Mandatory for AO rows; mapped in USER | I13: No | J13: Conditional: Mandatory for AO rows | K13: No | L13: Yes
A14: Format | B14: Code, up to 12; Upper case | C14: Code, up to 20; As stored in legacy | D14: Text, up to 120; Free text | E14: Code, up to 20; As stored in legacy | F14: Code, up to 50; As stored in legacy | G14: Code, up to 20; As stored in legacy | H14: Code, up to 50; As stored in legacy | I14: Code, up to 20; As stored in legacy | J14: Text, up to 120; Free text | K14: Code, up to 20; As stored in legacy | L14: Flag, up to 1; Y or N
A15: Allowed values | B15: REGION, DEPARTMENT, TEAM, AO (list R03 record_type) | C15: Free entry, up to 20 characters | D15: Free entry, up to 120 characters | E15: unit_code values of the file | F15: The legacy code; mapped by the code map USER (Code Maps screen of the Data Migration Console; maps prepared in the Migration Workbook of BRD-13) | G15: The legacy code; mapped by the code map COST_CENTER (Code Maps screen of the Data Migration Console; maps prepared in the Migration Workbook of BRD-13) | H15: The legacy code; mapped by the code map USER (Code Maps screen of the Data Migration Console; maps prepared in the Migration Workbook of BRD-13) | I15: The legacy code; mapped by the code map AO (Code Maps screen of the Data Migration Console; maps prepared in the Migration Workbook of BRD-13) | J15: Free entry, up to 120 characters | K15: The legacy code; mapped by the code map BRANCH (Code Maps screen of the Data Migration Console; maps prepared in the Migration Workbook of BRD-13) | L15: Y or N
A16: What to enter | B16: Kind of row | C16: Legacy code of the unit (for an AO row, the team of the AO) | D16: Unit name | E16: Code of the parent unit (department of a team, region of a department) | F16: Legacy user ID of the unit head | G16: Cost centre of the unit | H16: Legacy user ID of the account officer | I16: Legacy AO code if different from the user ID | J16: AO full name | K16: Branch of the unit or AO | L16: Unit or AO active
A17: Row | B17: record_type * | C17: unit_code * | D17: unit_name | E17: parent_unit_code | F17: unit_head_user_id | G17: cost_center | H17: ao_user_id | I17: ao_code | J17: ao_name | K17: branch_code | L17: active_flag *
A18: Example – overwrite or delete | B18: TEAM | C18: T-RET-07 | D18: Retail Team 7 | E18: D-RET | F18: jdelacruz | G18: 4100 | H18: mreyes | I18: AO0457 | J18: Maria Reyes | K18: MKT01 | L18: Y

Sheet R05 Product lines, cover types,
A1: R05 Product lines, cover types, products and risk codes | J1: Step 14 of 52
A2: ← Back to Start here | B2: Step 14 of 52. Fill in one row per record below the column headers; the guide above each column says what to enter. | J2: Ask a question →
A3: Purpose | B3: One row per record of Product lines, cover types, products and risk codes as extracted from QPS, EBIX. Key risk_code. Sent as the file R05_template.csv (CSV, header row as below) with its control file (row count, count of distinct keys).
A4: Provided by | B4: MBS data steward (to name); approved by Product Owner, MBS; extracted by BDOI IT
A5: Due | B5: M3 (29 Jan 2027)
A6: How it is loaded | B6: Migration Console: the file R05_template.csv (the header row as below) and its control file are received on Data Migration › Data Migration › Extracts and loaded by a batch of object R05; lands in: Product catalogue: product lines, cover types and products
A7: Source | B7: QPS, EBIX
A8: Depends on | B8: PM-09 Lists of values and parameters →
A9: Progress | B9: Rows entered | C9: =SUMPRODUCT(((ROW($B$18:$B$218)>18)+($B$18<>"MOTOR")>0)*(LEN($B$18:$B$218&$C$18:$C$218&$D$18:$D$218&$E$18:$E$218&$F$18:$F$218&$G$18:$G$218&$H$18:$H$218&$I$18:$I$218&$J$18:$J$218)>0)) | D9: Mandatory cells missing | E9: =SUMPRODUCT(((ROW($B$18:$B$218)>18)+($B$18<>"MOTOR")>0)*(LEN($B$18:$B$218&$C$18:$C$218&$D$18:$D$218&$E$18:$E$218&$F$18:$F$218&$G$18:$G$218&$H$18:$H$218&$I$18:$I$218&$J$18:$J$218)>0)*(($B$18:$B$218="")+($E$18:$E$218="")+($F$18:$F$218="")+($I$18:$I$218="")))
A10: Confirmed by (BDOI owner) | D10: Date
A12: Check when loaded | B12: Mapped | C12: - | D12: Mapped | E12: Unique | F12: Not blank | G12: Y or N | H12: Each mapped | I12: Mapped | J12: 0 or more
A13: Mandatory | B13: Yes | C13: No | D13: No | E13: Yes | F13: Yes | G13: No | H13: No | I13: Yes | J13: No
A14: Format | B14: Code, up to 30; As stored in legacy | C14: Text, up to 120; Free text | D14: Code, up to 30; As stored in legacy | E14: Code, up to 20; As stored in legacy | F14: Text, up to 200; Free text | G14: Flag, up to 1; Y or N | H14: Text, up to 300; CODE;CODE | I14: Code, up to 20; As stored in legacy | J14: Integer, up to 9; Digits
A15: Allowed values | B15: The legacy code; mapped by the code map LINE (Code Maps screen of the Data Migration Console; maps prepared in the Migration Workbook of BRD-13) | C15: Free entry, up to 120 characters | D15: The legacy code; mapped by the code map COVER_TYPE (Code Maps screen of the Data Migration Console; maps prepared in the Migration Workbook of BRD-13) | E15: Free entry, up to 20 characters | F15: Free entry, up to 200 characters | G15: Y or N | H15: The legacy code; mapped by the code map LOV:MARKET_SEGMENT (Code Maps screen of the Data Migration Console; maps prepared in the Migration Workbook of BRD-13) | I15: The legacy code; mapped by the code map STATUS:PRODUCT (Code Maps screen of the Data Migration Console; maps prepared in the Migration Workbook of BRD-13) | J15: A whole number
A16: What to enter | B16: Legacy line of business | C16: Line name | D16: Legacy cover type | E16: Legacy risk code / product code | F16: Product / risk name | G16: Sold as a package | H16: Segments that may use the product, separated by semicolons | I16: Status in legacy | J16: Open invoices and in-force policies using the code (helps the mapping)
A17: Row | B17: line_code * | C17: line_name | D17: cover_type_code | E17: risk_code * | F17: risk_name * | G17: packaged_flag | H17: market_segments | I17: status * | J17: open_item_count
A18: Example – overwrite or delete | B18: MOTOR | C18: Motor Car | D18: COMP | E18: MC-PC-COMP | F18: Private Car Own Damage and Theft | G18: N | H18: CBG;RETAIL | I18: ACTIVE | J18: 4211

Sheet UA-01 Users and roles
