Workbook

Sheet Cover
B6: PRODUCT BIBLE
B7: BDOI Product Bible - LOB Library
B8: BDOI products by line of business: OOTB vs BIBS catalogue, migration mapping and library
B9: BIBS – BDOI Broker System
B11: Client | C11: BDO Insurance and Reinsurance Brokers, Inc.
B12: BRD | C12: BRD-00 / BRD-03 / BRD-13
B13: Version | C13: 1.0
B14: Date | C14: 12-Oct-2026
B15: Classification | C15: Confidential
B16: Prepared by | C16: iorta TechNXT
B18: Sheets
B19: Sheet | C19: Content | D19: Rows
B20: README | C20: What each column of each sheet means, with the allowed values
B21: OOTB product set | C21: iNXT BrokerVerse OOTB platform product set by BDOI LOB (configuration codes, read-only reference) | D21: 81
B22: BIBS product set | C22: BIBS New Business catalogue by BDOI LOB: lines, cover types, products, coverages / perils, packages, clauses (configuration codes) | D22: 201
B23: LOB status | C23: Summary of the Comparison: BDOI's 15 LOBs, Covered / Partial / Missing in OOTB and in BIBS, counts per status | D23: 16
B24: Comparison | C24: One row per BDOI LOB and product: OOTB vs BIBS; gaps are flagged for BDOI confirmation, not as certain gaps | D24: 86
B25: Migration mapping | C25: Template for BDOI: legacy product codes (left, to fill) against the BIBS target product (right, pre-filled). Blank legacy cells are for BDOI input. | D25: 120
B26: Migration checks | C26: Validation rules for product reference data, aligned with the Data Migration BRD reconciliation requirements | D26: 16
B27: LOB summary | C27: One row per BDOI line of business (library) | D27: 15
B28: Product library | C28: One row per sub-product / plan per LOB; market rows to confirm with BDOI | D28: 83
B29: Covers & perils | C29: LOB x peril / cover: Standard, Optional or n/a (market practice; BDOI packages may differ) | D29: 37
B30: Clauses | C30: Endorsements and clauses library per LOB | D30: 43
B31: Rating & charges | C31: Rating basis, minimum premium, short period, taxes and commission per LOB; amounts not in BDOI documents are flagged 'confirm' | D31: 15
B32: Data dictionary | C32: Underwriting fields BIBS captures per LOB at quotation / placement | D32: 62
... B35: Sources & questions | C35: Every source used, every market-practice assumption and the open questions for BDOI | D35: 37
B37: Legend
B38: In both | C38: Product in the OOTB set and in the BIBS catalogue
B39: OOTB only | C39: Only in the OOTB platform set
B40: BIBS only | C40: Only in the BIBS catalogue
B41: Neither - market product to confirm | C41: Market or BDOI-listed product with no code yet
B42: Covered | C42: LOB has a line and its main products
B43: Partial | C43: LOB present, products missing
B44: Missing | C44: No product line for the LOB
B46: Purpose: data-migration validation - every product BDOI uses today must have a home in the BIBS New Business product catalogue (Data Migration BRD BRID_MIG 3.1).
B47: The BIBS and OOTB product sets list configuration codes (catalogue reference data); they do not describe system behaviour.
B48: Source legend: 'BDOI document' rows come from BDOI's BRDs / FRS; 'Market practice (to confirm with BDOI)' rows are Philippine non-life market practice and need BDOI confirmation. No BDOI-specific fact is assumed.
B50: Prepared by iorta TechNXT for BDOI. Confidential – BDOI.

Sheet README
A1: README – columns of each sheet
A2: BDOI Product Bible - LOB Library, version 1.0. Drop-down columns accept only the listed values.
A4: Sheet | B4: Column | C4: Meaning | D4: Allowed values
A5: OOTB product set | B5: BDOI LOB | C5: One of BDOI's 15 lines of business | D5: Property, Bond, Personal Accident, Motor, Health Insurance, Liability, Engineering, Electronic Equipment, Others / Miscellaneous, Marine (Cargo), Crime, Marine Hull, Property / Equipment Floater, Aviation, Casualty, All lines
A6: OOTB product set | B6: Level | C6: Line of business, product category, product, policy type, product template, cover, risk section or tax / charge
A7: OOTB product set | B7: OOTB code | C7: Code in the OOTB platform reference data
A8: OOTB product set | B8: Name | C8: Name in the OOTB platform
A9: OOTB product set | B9: Parent | C9: Line, product or template it belongs to
A10: OOTB product set | B10: Detail | C10: Classification (package / non-package, segment), status, rates as seeded
A11: OOTB product set | B11: Source | C11: iNXT BrokerVerse OOTB platform, branch brokerverse-platform
A12: BIBS product set | B12: BDOI LOB | C12: One of BDOI's 15 lines of business | D12: Property, Bond, Personal Accident, Motor, Health Insurance, Liability, Engineering, Electronic Equipment, Others / Miscellaneous, Marine (Cargo), Crime, Marine Hull, Property / Equipment Floater, Aviation, Casualty, All lines
A13: BIBS product set | B13: Level | C13: Product line, cover type, product (risk code), coverage / peril, package coverage term, clause or business-line lookup
A14: BIBS product set | B14: BIBS code | C14: Code in the BIBS catalogue
A15: BIBS product set | B15: Name | C15: Name in the BIBS catalogue
A16: BIBS product set | B16: Parent | C16: Product line / cover type the row belongs to
A17: BIBS product set | B17: Packaged | C17: Package product (Yes / No); n/a for other levels
A18: BIBS product set | B18: Default rate % | C18: Default premium rate (%), defaults until BDOI's product matrix is loaded
A19: BIBS product set | B19: Commission % | C19: Default commission rate (%)
A20: BIBS product set | B20: Min. premium (PHP) | C20: Default minimum premium
A21: BIBS product set | B21: Detail | C21: Attributes: payment gate, multi-year, coverage kind, wording
A22: BIBS product set | B22: Source | C22: BIBS New Business catalogue configuration
A23: LOB status | B23: LOB code (proposed) | C23: Proposed BDOI LOB code, to confirm against legacy codes
A24: LOB status | B24: BDOI LOB | C24: BDOI line of business
A25: LOB status | B25: IC class | C25: Insurance Commission class / statement line (to confirm)
A26: LOB status | B26: OOTB status | C26: Covered / Partial / Missing in the OOTB product set | D26: Covered, Partial, Missing
A27: LOB status | B27: OOTB evidence | C27: What the OOTB set holds for the LOB
A28: LOB status | B28: BIBS status | C28: Covered / Partial / Missing in the BIBS catalogue | D28: Covered, Partial, Missing
A29: LOB status | B29: BIBS evidence | C29: What the BIBS catalogue holds for the LOB
A30: LOB status | B30: Products compared | C30: Rows of the Comparison sheet for the LOB (formula)
A31: LOB status | B31: In both | C31: Count with status In both (formula)
A32: LOB status | B32: OOTB only | C32: Count with status OOTB only (formula)
A33: LOB status | B33: BIBS only | C33: Count with status BIBS only (formula)
A34: LOB status | B34: Neither | C34: Count with status Neither - market product to confirm (formula)
A35: Comparison | B35: BDOI LOB | C35: One of BDOI's 15 lines of business | D35: Property, Bond, Personal Accident, Motor, Health Insurance, Liability, Engineering, Electronic Equipment, Others / Miscellaneous, Marine (Cargo), Crime, Marine Hull, Property / Equipment Floater, Aviation, Casualty, All lines
A36: Comparison | B36: Product | C36: Product BDOI lists (FRS) or the market normally has under the LOB
A37: Comparison | B37: In OOTB (code) | C37: OOTB code(s); '-' when absent
A38: Comparison | B38: In BIBS (code) | C38: BIBS line / cover type (risk products) or coverage codes; '-' when absent
A39: Comparison | B39: Status | C39: In both / OOTB only / BIBS only / Neither - market product to confirm | D39: In both, OOTB only, BIBS only, Neither - market product to confirm
A40: Comparison | B40: Product source | C40: Where the product comes from: BDOI document, BIBS configuration or market practice
A41: Comparison | B41: Source type | C41: Source legend | D41: BDOI document, BIBS configuration, OOTB reference, Market practice (to confirm with BDOI)
...

Sheet OOTB product set
A1: OOTB product set
A2: iNXT BrokerVerse OOTB platform product set by BDOI LOB (configuration codes, read-only reference)
A4: BDOI LOB | B4: Level | C4: OOTB code | D4: Name | E4: Parent | F4: Detail | G4: Source
A5: Property | B5: Line of business | C5: FIRE | D5: Fire | E5: - | F5: Line of business master | G5: OOTB reference data (read 12-Oct-2026)
A6: Property | B6: Product | C6: FIRE | D6: Fire and Allied Perils | E6: FIRE | F6: Non-package, corporate | G6: OOTB reference data (read 12-Oct-2026)
A7: Property | B7: Product | C7: IAR | D7: Industrial All Risks | E7: FIRE | F7: Non-package, corporate | G7: OOTB reference data (read 12-Oct-2026)
A8: Property | B8: Product | C8: HOME | D8: Householder Insurance | E8: FIRE | F8: Package, retail | G8: OOTB reference data (read 12-Oct-2026)
A9: Property | B9: Policy type | C9: FIRE-RES | D9: Residential | E9: FIRE | F9: Policy type of product FIRE | G9: OOTB reference data (read 12-Oct-2026)
A10: Property | B10: Policy type | C10: FIRE-COM | D10: Commercial | E10: FIRE | F10: Policy type of product FIRE | G10: OOTB reference data (read 12-Oct-2026)
A11: Property | B11: Product template | C11: PROP-FIRE-2026 | D11: Property Fire Insurance | E11: FIRE | F11: Active, v3.0; construction type rating factor | G11: OOTB reference data (read 12-Oct-2026)
A12: Property | B12: Cover | C12: FLEXA | D12: Fire and Lightning | E12: FIRE | F12: Cover master | G12: OOTB reference data (read 12-Oct-2026)
A13: Property | B13: Cover | C13: EQ | D13: Earthquake Shock | E13: FIRE | F13: Cover master | G13: OOTB reference data (read 12-Oct-2026)
A14: Property | B14: Cover | C14: RSMD | D14: Riot, Strike, Malicious Damage | E14: FIRE | F14: Cover master | G14: OOTB reference data (read 12-Oct-2026)
A15: Property | B15: Risk section | C15: FIRE | D15: Fire Material Damage | E15: IAR | F15: IAR risk section; default rate 0.15% | G15: OOTB reference data (read 12-Oct-2026)
... A85: All lines | B85: Tax / charge | C85: EWT | D85: Expanded Withholding Tax on Commission | E85: - | F85: 5% of commission | G85: OOTB reference data (read 12-Oct-2026)

Sheet BIBS product set
A1: BIBS product set
A2: BIBS New Business catalogue by BDOI LOB: lines, cover types, products, coverages / perils, packages, clauses (configuration codes)
A4: BDOI LOB | B4: Level | C4: BIBS code | D4: Name | E4: Parent | F4: Packaged | G4: Default rate % | H4: Commission % | I4: Min. premium (PHP) | J4: Detail | K4: Source
A5: Property | B5: Product line | C5: PROPERTY | D5: Property | E5: - | F5: n/a | G5: n/a | H5: n/a | I5: n/a | J5: Risk item kind PROPERTY_LOCATION; rating method PROPERTY | K5: BIBS catalogue configuration
A6: Property | B6: Cover type | C6: FIRE_LIGHTNING | D6: Fire and Lightning only | E6: PROPERTY | F6: n/a | G6: n/a | H6: n/a | I6: n/a | J6: Sub-line / type under the product line | K6: BIBS catalogue configuration
A7: Property | B7: Cover type | C7: ALL_RISK | D7: All-Risk | E7: PROPERTY | F7: n/a | G7: n/a | H7: n/a | I7: n/a | J7: Sub-line / type under the product line | K7: BIBS catalogue configuration
A8: Property | B8: Cover type | C8: BROAD_NAMED_PERILS | D8: Broad-Named Perils | E8: PROPERTY | F8: n/a | G8: n/a | H8: n/a | I8: n/a | J8: Sub-line / type under the product line | K8: BIBS catalogue configuration
A9: Property | B9: Product (risk code) | C9: PAR01 | D9: Property package PAR01 (product matrix to be loaded) | E9: PROPERTY / FIRE_LIGHTNING | F9: Yes | G9: 0.25 | H9: 20 | I9: 1000 | J9: Payment gate PAID; multi-year Yes (max 5 yr); defaults to confirm with BDOI (Q01) | K9: BIBS catalogue configuration
A10: Property | B10: Product (risk code) | C10: PAR08 | D10: Property package PAR08 (product matrix to be loaded) | E10: PROPERTY / FIRE_LIGHTNING | F10: Yes | G10: 0.25 | H10: 20 | I10: 1000 | J10: Payment gate PAID; multi-year Yes (max 5 yr); defaults to confirm with BDOI (Q01) | K10: BIBS catalogue configuration
A11: Property | B11: Product (risk code) | C11: PAR09 | D11: Property package PAR09 (product matrix to be loaded) | E11: PROPERTY / ALL_RISK | F11: Yes | G11: 0.30 | H11: 20 | I11: 1000 | J11: Payment gate PAID; multi-year Yes (max 5 yr); defaults to confirm with BDOI (Q01) | K11: BIBS catalogue configuration
A12: Property | B12: Product (risk code) | C12: PAR13 | D12: Property package PAR13 (product matrix to be loaded) | E12: PROPERTY / FIRE_LIGHTNING | F12: Yes | G12: 0.25 | H12: 20 | I12: 1000 | J12: Payment gate PAID; multi-year Yes (max 5 yr); defaults to confirm with BDOI (Q01) | K12: BIBS catalogue configuration
A13: Property | B13: Product (risk code) | C13: PAR19 | D13: Property package PAR19 (product matrix to be loaded) | E13: PROPERTY / BROAD_NAMED_PERILS | F13: Yes | G13: 0.28 | H13: 20 | I13: 1000 | J13: Payment gate PAID; multi-year Yes (max 5 yr); defaults to confirm with BDOI (Q01) | K13: BIBS catalogue configuration
A14: Property | B14: Product (risk code) | C14: PAR25 | D14: Property package PAR25 (product matrix to be loaded) | E14: PROPERTY / FIRE_LIGHTNING | F14: Yes | G14: 0.25 | H14: 20 | I14: 1000 | J14: Payment gate PAID; multi-year Yes (max 5 yr); defaults to confirm with BDOI (Q01) | K14: BIBS catalogue configuration
A15: Property | B15: Coverage / peril (Peril) | C15: FIRE_LIGHTNING | D15: Fire and Lightning | E15: PROPERTY | F15: n/a | G15: n/a | H15: n/a | I15: n/a | J15: Basic cover | K15: BIBS catalogue configuration
... A205: All lines | B205: Clause (Exclusion) | C205: GEN_SANCTIONS | D205: Sanctions Limitation and Exclusion Clause | E205: All lines | F205: n/a | G205: n/a | H205: n/a | I205: n/a | J205: No insurer is deemed to provide cover or pay a claim to the extent that doing so would expose it to any sanction. | K205: BIBS catalogue configuration

Sheet LOB status
A1: LOB status
A2: Summary of the Comparison: BDOI's 15 LOBs, Covered / Partial / Missing in OOTB and in BIBS, counts per status
A4: LOB code (proposed) | B4: BDOI LOB | C4: IC class | D4: OOTB status | E4: OOTB evidence | F4: BIBS status | G4: BIBS evidence | H4: Products compared | I4: In both | J4: OOTB only | K4: BIBS only | L4: Neither
A5: PRO | B5: Property | C5: Fire (IC line: Fire and allied perils) | D5: Partial | E5: Fire, IAR, home; no all-risk or broad named perils as products | F5: Partial | G5: Three cover types and five perils; no BI or householder product | H5: =COUNTIF(Comparison!$A$5:$A$90,B5) | I5: =COUNTIFS(Comparison!$A$5:$A$90,B5,Comparison!$E$5:$E$90,"In both") | J5: =COUNTIFS(Comparison!$A$5:$A$90,B5,Comparison!$E$5:$E$90,"OOTB only") | K5: =COUNTIFS(Comparison!$A$5:$A$90,B5,Comparison!$E$5:$E$90,"BIBS only") | L5: =COUNTIFS(Comparison!$A$5:$A$90,B5,Comparison!$E$5:$E$90,"Neither - market product to confirm")
A6: BND | B6: Bond | C6: Suretyship (IC line: Surety) | D6: Partial | E6: One product BOND with policy type Performance | F6: Missing | G6: Business-line lookup 'BONDS - Surety Bonds' only; no product line or product | H6: =COUNTIF(Comparison!$A$5:$A$90,B6) | I6: =COUNTIFS(Comparison!$A$5:$A$90,B6,Comparison!$E$5:$E$90,"In both") | J6: =COUNTIFS(Comparison!$A$5:$A$90,B6,Comparison!$E$5:$E$90,"OOTB only") | K6: =COUNTIFS(Comparison!$A$5:$A$90,B6,Comparison!$E$5:$E$90,"BIBS only") | L6: =COUNTIFS(Comparison!$A$5:$A$90,B6,Comparison!$E$5:$E$90,"Neither - market product to confirm")
A7: PAC | B7: Personal Accident | C7: Casualty (Accident) | D7: Covered | E7: PA, GPA, travel, micro | F7: Covered | G7: Four cover types plus Employee Benefits GPA | H7: =COUNTIF(Comparison!$A$5:$A$90,B7) | I7: =COUNTIFS(Comparison!$A$5:$A$90,B7,Comparison!$E$5:$E$90,"In both") | J7: =COUNTIFS(Comparison!$A$5:$A$90,B7,Comparison!$E$5:$E$90,"OOTB only") | K7: =COUNTIFS(Comparison!$A$5:$A$90,B7,Comparison!$E$5:$E$90,"BIBS only") | L7: =COUNTIFS(Comparison!$A$5:$A$90,B7,Comparison!$E$5:$E$90,"Neither - market product to confirm")
A8: MTR | B8: Motor | C8: Motor Car | D8: Covered | E8: Comprehensive, TPL, OD/theft, CTPL and all motor covers | F8: Partial | G8: TPL only and Comprehensive; OD, AON, VTPL, auto PA as coverages, not standalone | H8: =COUNTIF(Comparison!$A$5:$A$90,B8) | I8: =COUNTIFS(Comparison!$A$5:$A$90,B8,Comparison!$E$5:$E$90,"In both") | J8: =COUNTIFS(Comparison!$A$5:$A$90,B8,Comparison!$E$5:$E$90,"OOTB only") | K8: =COUNTIFS(Comparison!$A$5:$A$90,B8,Comparison!$E$5:$E$90,"BIBS only") | L8: =COUNTIFS(Comparison!$A$5:$A$90,B8,Comparison!$E$5:$E$90,"Neither - market product to confirm")
A9: HLT | B9: Health Insurance | C9: Casualty (Health) / HMO (regulated by IC under RA 11223) | D9: Partial | E9: Group health templates; no individual health | F9: Partial | G9: Employee Benefits line HMO (EBHMO01); no individual health | H9: =COUNTIF(Comparison!$A$5:$A$90,B9) | I9: =COUNTIFS(Comparison!$A$5:$A$90,B9,Comparison!$E$5:$E$90,"In both") | J9: =COUNTIFS(Comparison!$A$5:$A$90,B9,Comparison!$E$5:$E$90,"OOTB only") | K9: =COUNTIFS(Comparison!$A$5:$A$90,B9,Comparison!$E$5:$E$90,"BIBS only") | L9: =COUNTIFS(Comparison!$A$5:$A$90,B9,Comparison!$E$5:$E$90,"Neither - market product to confirm")
A10: LIA | B10: Liability | C10: Casualty (Liability) | D10: Partial | E10: CGL only (plus CGL risk section) | F10: Covered | G10: 11 cover types, 7 CGL risk products; medical malpractice, marine and excess auto liability missing | H10: =COUNTIF(Comparison!$A$5:$A$90,B10) | I10: =COUNTIFS(Comparison!$A$5:$A$90,B10,Comparison!$E$5:$E$90,"In both") | J10: =COUNTIFS(Comparison!$A$5:$A$90,B10,Comparison!$E$5:$E$90,"OOTB only") | K10: =COUNTIFS(Comparison!$A$5:$A$90,B10,Comparison!$E$5:$E$90,"BIBS only") | L10: =COUNTIFS(Comparison!$A$5:$A$90,B10,Comparison!$E$5:$E$90,"Neither - market product to confirm")
A11: ENG | B11: Engineering | C11: Casualty (Engineering) | D11: Partial | E11: CAR, EAR, machinery breakdown | F11: Partial | G11: CAR and EAR only; no MBD, CPM, boiler, DSU | H11: =COUNTIF(Comparison!$A$5:$A$90,B11) | I11: =COUNTIFS(Comparison!$A$5:$A$90,B11,Comparison!$E$5:$E$90,"In both") | J11: =COUNTIFS(Comparison!$A$5:$A$90,B11,Comparison!$E$5:$E$90,"OOTB only") | K11: =COUNTIFS(Comparison!$A$5:$A$90,B11,Comparison!$E$5:$E$90,"BIBS only") | L11: =COUNTIFS(Comparison!$A$5:$A$90,B11,Comparison!$E$5:$E$90,"Neither - market product to confirm")
A12: EEI | B12: Electronic Equipment | C12: Casualty (Engineering) | D12: Partial | E12: EEI as a risk section of IAR only | F12: Covered | G12: Line and cover type EEI with three products | H12: =COUNTIF(Comparison!$A$5:$A$90,B12) | I12: =COUNTIFS(Comparison!$A$5:$A$90,B12,Comparison!$E$5:$E$90,"In both") | J12: =COUNTIFS(Comparison!$A$5:$A$90,B12,Comparison!$E$5:$E$90,"OOTB only") | K12: =COUNTIFS(Comparison!$A$5:$A$90,B12,Comparison!$E$5:$E$90,"BIBS only") | L12: =COUNTIFS(Comparison!$A$5:$A$90,B12,Comparison!$E$5:$E$90,"Neither - market product to confirm")
A13: MSC | B13: Others / Miscellaneous | C13: Casualty (Miscellaneous) | D13: Missing | E13: No product | F13: Covered | G13: Seven cover types, one product (GIP01) | H13: =COUNTIF(Comparison!$A$5:$A$90,B13) | I13: =COUNTIFS(Comparison!$A$5:$A$90,B13,Comparison!$E$5:$E$90,"In both") | J13: =COUNTIFS(Comparison!$A$5:$A$90,B13,Comparison!$E$5:$E$90,"OOTB only") | K13: =COUNTIFS(Comparison!$A$5:$A$90,B13,Comparison!$E$5:$E$90,"BIBS only") | L13: =COUNTIFS(Comparison!$A$5:$A$90,B13,Comparison!$E$5:$E$90,"Neither - market product to confirm")
A14: MAR | B14: Marine (Cargo) | C14: Marine (Cargo) | D14: Partial | E14: Marine cargo import / domestic | F14: Covered | G14: 11 cover types, 21 risk products | H14: =COUNTIF(Comparison!$A$5:$A$90,B14) | I14: =COUNTIFS(Comparison!$A$5:$A$90,B14,Comparison!$E$5:$E$90,"In both") | J14: =COUNTIFS(Comparison!$A$5:$A$90,B14,Comparison!$E$5:$E$90,"OOTB only") | K14: =COUNTIFS(Comparison!$A$5:$A$90,B14,Comparison!$E$5:$E$90,"BIBS only") | L14: =COUNTIFS(Comparison!$A$5:$A$90,B14,Comparison!$E$5:$E$90,"Neither - market product to confirm")
A15: CRM | B15: Crime | C15: Casualty (Crime / Fidelity) | D15: Partial | E15: Money and securities only | F15: Covered | G15: Five cover types, no risk product yet; kidnap and ransom missing | H15: =COUNTIF(Comparison!$A$5:$A$90,B15) | I15: =COUNTIFS(Comparison!$A$5:$A$90,B15,Comparison!$E$5:$E$90,"In both") | J15: =COUNTIFS(Comparison!$A$5:$A$90,B15,Comparison!$E$5:$E$90,"OOTB only") | K15: =COUNTIFS(Comparison!$A$5:$A$90,B15,Comparison!$E$5:$E$90,"BIBS only") | L15: =COUNTIFS(Comparison!$A$5:$A$90,B15,Comparison!$E$5:$E$90,"Neither - market product to confirm")
A16: HUL | B16: Marine Hull | C16: Marine (Hull) | D16: Partial | E16: One product HULL | F16: Covered | G16: Four cover types, no risk product yet | H16: =COUNTIF(Comparison!$A$5:$A$90,B16) | I16: =COUNTIFS(Comparison!$A$5:$A$90,B16,Comparison!$E$5:$E$90,"In both") | J16: =COUNTIFS(Comparison!$A$5:$A$90,B16,Comparison!$E$5:$E$90,"OOTB only") | K16: =COUNTIFS(Comparison!$A$5:$A$90,B16,Comparison!$E$5:$E$90,"BIBS only") | L16: =COUNTIFS(Comparison!$A$5:$A$90,B16,Comparison!$E$5:$E$90,"Neither - market product to confirm")
... A19: CAS | B19: Casualty | C19: Casualty (Miscellaneous casualty) | D19: Partial | E19: Burglary and robbery | F19: Missing | G19: Business-line lookup 'CASUALTY - Casualty and Liability' only | H19: =COUNTIF(Comparison!$A$5:$A$90,B19) | I19: =COUNTIFS(Comparison!$A$5:$A$90,B19,Comparison!$E$5:$E$90,"In both") | J19: =COUNTIFS(Comparison!$A$5:$A$90,B19,Comparison!$E$5:$E$90,"OOTB only") | K19: =COUNTIFS(Comparison!$A$5:$A$90,B19,Comparison!$E$5:$E$90,"BIBS only") | L19: =COUNTIFS(Comparison!$A$5:$A$90,B19,Comparison!$E$5:$E$90,"Neither - market product to confirm")
A20: Total | B20: All 15 LOBs | C20: - | D20: =COUNTIF(D5:D19,"Covered")&" covered" | E20: Covered LOBs in OOTB | F20: =COUNTIF(F5:F19,"Covered")&" covered" | G20: Covered LOBs in BIBS | H20: =SUM(H5:H19) | I20: =SUM(I5:I19) | J20: =SUM(J5:J19) | K20: =SUM(K5:K19) | L20: =SUM(L5:L19)

Sheet Comparison
A1: Comparison
A2: One row per BDOI LOB and product: OOTB vs BIBS; gaps are flagged for BDOI confirmation, not as certain gaps
A4: BDOI LOB | B4: Product | C4: In OOTB (code) | D4: In BIBS (code) | E4: Status | F4: Product source | G4: Source type | H4: Remarks / action for BDOI
A5: Property | B5: Fire and lightning (standard fire policy) | C5: FIRE, FLEXA | D5: PROPERTY / FIRE_LIGHTNING (PAR01, PAR08, PAR13, PAR25) | E5: In both | F5: BDOI FRS Product Maintenance v1.0 (19-Aug-2026) | G5: BDOI document | H5: Map legacy Fire risk codes; load PAR product matrix (Q01)
A6: Property | B6: Fire and allied perils / broad named perils | C6: FIRE, EQ, RSMD | D6: PROPERTY / BROAD_NAMED_PERILS (PAR19); perils EARTHQUAKE, TYPHOON_FLOOD, EXTENDED_COVERAGE, RSMD | E6: In both | F6: BDOI FRS Product Maintenance v1.0 (19-Aug-2026) | G6: BDOI document | H6: Map legacy allied-peril codes to BIBS perils
A7: Property | B7: Property all risks | C7: - | D7: PROPERTY / ALL_RISK (PAR09) | E7: BIBS only | F7: BDOI FRS Product Maintenance v1.0 (19-Aug-2026) | G7: BDOI document | H7: Confirm legacy all-risk products
A8: Property | B8: Industrial all risks (IAR) | C8: IAR | D8: - | E8: OOTB only | F8: Market practice (to confirm with BDOI) | G8: Market practice (to confirm with BDOI) | H8: Confirm whether BDOI places IAR separately or as Property all risk
A9: Property | B9: Business interruption / consequential loss | C9: BI (IAR risk section) | D9: - | E9: OOTB only | F9: Market practice (to confirm with BDOI) | G9: Market practice (to confirm with BDOI) | H9: Confirm if written; add as peril or cover type if yes
A10: Property | B10: Householders / homeowners package | C10: HOME | D10: - | E10: OOTB only | F10: Market practice (to confirm with BDOI) | G10: Market practice (to confirm with BDOI) | H10: Confirm retail home package; else map to PROPERTY
A11: Bond | B11: Surety bond (general) | C11: BOND | D11: - | E11: OOTB only | F11: BDOI FRS Product Maintenance v1.0 (19-Aug-2026) | G11: BDOI document | H11: Add product line BOND (only a business-line lookup today)
A12: Bond | B12: Performance bond | C12: BOND-PERF | D12: - | E12: OOTB only | F12: BDOI FRS Product Maintenance v1.0 (19-Aug-2026) | G12: BDOI document | H12: Add product
A13: Bond | B13: Bidder's bond | C13: - | D13: - | E13: Neither - market product to confirm | F13: BDOI FRS Product Maintenance v1.0 (19-Aug-2026) | G13: BDOI document | H13: Add product
A14: Bond | B14: Warranty bond | C14: - | D14: - | E14: Neither - market product to confirm | F14: BDOI FRS Product Maintenance v1.0 (19-Aug-2026) | G14: BDOI document | H14: Add product
A15: Bond | B15: Judicial bond (court bonds) | C15: - | D15: - | E15: Neither - market product to confirm | F15: BDOI FRS Product Maintenance v1.0 (19-Aug-2026) | G15: BDOI document | H15: Add product
... A90: Casualty | B90: All risks on personal property (gadgets, jewellery) | C90: - | D90: - | E90: Neither - market product to confirm | F90: Market practice (to confirm with BDOI) | G90: Market practice (to confirm with BDOI) | H90: Confirm

Sheet Migration mapping
A1: Migration mapping
A2: Template for BDOI: legacy product codes (left, to fill) against the BIBS target product (right, pre-filled). Blank legacy cells are for BDOI input.
A4: Legacy system | B4: Legacy LOB code | C4: Legacy product code | D4: Legacy product name | E4: Legacy package / plan code | F4: Legacy risk / coverage codes | G4: Insurer | H4: Active policies count | I4: BDOI LOB | J4: BIBS line code | K4: BIBS product code | L4: BIBS product name | M4: BIBS package (cover type) | N4: BIBS coverage / peril codes | O4: Mapping status | P4: Remarks
I5: Property | J5: PROPERTY | K5: PAR01 | L5: Property package PAR01 (product matrix to be loaded) | M5: FIRE_LIGHTNING (packaged: Yes) | N5: FIRE_LIGHTNING, EARTHQUAKE, TYPHOON_FLOOD, EXTENDED_COVERAGE, RSMD | O5: Needs confirmation | P5: BDOI to enter the legacy codes that map to this product
I6: Property | J6: PROPERTY | K6: PAR08 | L6: Property package PAR08 (product matrix to be loaded) | M6: FIRE_LIGHTNING (packaged: Yes) | N6: FIRE_LIGHTNING, EARTHQUAKE, TYPHOON_FLOOD, EXTENDED_COVERAGE, RSMD | O6: Needs confirmation | P6: BDOI to enter the legacy codes that map to this product
I7: Property | J7: PROPERTY | K7: PAR09 | L7: Property package PAR09 (product matrix to be loaded) | M7: ALL_RISK (packaged: Yes) | N7: FIRE_LIGHTNING, EARTHQUAKE, TYPHOON_FLOOD, EXTENDED_COVERAGE, RSMD | O7: Needs confirmation | P7: BDOI to enter the legacy codes that map to this product
I8: Property | J8: PROPERTY | K8: PAR13 | L8: Property package PAR13 (product matrix to be loaded) | M8: FIRE_LIGHTNING (packaged: Yes) | N8: FIRE_LIGHTNING, EARTHQUAKE, TYPHOON_FLOOD, EXTENDED_COVERAGE, RSMD | O8: Needs confirmation | P8: BDOI to enter the legacy codes that map to this product
I9: Property | J9: PROPERTY | K9: PAR19 | L9: Property package PAR19 (product matrix to be loaded) | M9: BROAD_NAMED_PERILS (packaged: Yes) | N9: FIRE_LIGHTNING, EARTHQUAKE, TYPHOON_FLOOD, EXTENDED_COVERAGE, RSMD | O9: Needs confirmation | P9: BDOI to enter the legacy codes that map to this product
I10: Property | J10: PROPERTY | K10: PAR25 | L10: Property package PAR25 (product matrix to be loaded) | M10: FIRE_LIGHTNING (packaged: Yes) | N10: FIRE_LIGHTNING, EARTHQUAKE, TYPHOON_FLOOD, EXTENDED_COVERAGE, RSMD | O10: Needs confirmation | P10: BDOI to enter the legacy codes that map to this product
I11: Property | J11: (none) | K11: (none) | L11: Industrial all risks (IAR) | M11: (none) | N11: (none) | O11: Needs new product | P11: No BIBS product yet: Confirm whether BDOI places IAR separately or as Property all risk
I12: Property | J12: (none) | K12: (none) | L12: Business interruption / consequential loss | M12: (none) | N12: (none) | O12: Needs new product | P12: No BIBS product yet: Confirm if written; add as peril or cover type if yes
I13: Property | J13: (none) | K13: (none) | L13: Householders / homeowners package | M13: (none) | N13: (none) | O13: Needs new product | P13: No BIBS product yet: Confirm retail home package; else map to PROPERTY
I14: Bond | J14: (none) | K14: (none) | L14: Surety bond (general) | M14: (none) | N14: (none) | O14: Needs new product | P14: No BIBS product yet: Add product line BOND (only a business-line lookup today)
I15: Bond | J15: (none) | K15: (none) | L15: Performance bond | M15: (none) | N15: (none) | O15: Needs new product | P15: No BIBS product yet: Add product
I16: Bond | J16: (none) | K16: (none) | L16: Bidder's bond | M16: (none) | N16: (none) | O16: Needs new product | P16: No BIBS product yet: Add product
... I124: Casualty | J124: (none) | K124: (none) | L124: All risks on personal property (gadgets, jewellery) | M124: (none) | N124: (none) | O124: Needs new product | P124: No BIBS product yet: Confirm

Sheet Migration checks
A1: Migration checks
A2: Validation rules for product reference data, aligned with the Data Migration BRD reconciliation requirements
A4: Check ID | B4: Check | C4: Rule | D4: BRD reference | E4: Severity | F4: How verified
A5: MC-01 | B5: Mapping completeness | C5: Every legacy LOB, product, package / plan and risk / coverage code in use maps to exactly one BIBS code (or is marked Retire) | D5: BRID_MIG 3.1 | E5: Blocking | F5: Count of distinct legacy codes = count of mapping rows with status Mapped or Retire
A6: MC-02 | B6: No one-to-many conflicts | C6: A legacy code is not mapped to two BIBS codes; many legacy codes to one BIBS code are allowed only with a remark | D6: BRID_MIG 3.1 | E6: Blocking | F6: Group mapping rows by legacy system + legacy code
A7: MC-03 | B7: Target codes exist and are active | C7: Every BIBS line / product / cover type / coverage code in the mapping exists in the BIBS catalogue with status Active (authorised) | D7: BRID_MIG 3.1 | E7: Blocking | F7: Look up each target code on the Products and Coverages screens
A8: MC-04 | B8: No orphan policies | C8: Every migrated in-force policy header carries a line of business and product that resolve through the mapping | D8: BRID_MIG 4.1 | E8: Blocking | F8: Policies without a mapped product = 0
A9: MC-05 | B9: Inactive / retired products | C9: Legacy products without in-force policies are marked Retire or migrated as inactive (history only); none can be sold after cutover | D9: BRID_MIG 1.1 | E9: High | F9: Active policies count = 0 for every Retire row
A10: MC-06 | B10: Mapping version control and sign-off | C10: The mapping list is versioned and signed off by the data steward and the product owner before the load | D10: BRID_MIG 3.1 | E10: Blocking | F10: Signed mapping version referenced in the load log
A11: MC-07 | B11: Unmapped / invalid codes reported | C11: Any code found in the data but not in the mapping is reported as fall-out, not loaded | D11: BRID_MIG 3.1, 1.4 | E11: High | F11: Fall-out report with zero unmapped product codes after remigration
A12: MC-08 | B12: Reconciliation counts | C12: Policy counts and premium totals per LOB and product reconcile between legacy and BIBS | D12: BRID_MIG 1.2 | E12: Blocking | F12: Migration reconciliation report per LOB / product
A13: MC-09 | B13: Insurer x product validity | C13: Each mapped product has its insurer(s) on the package panel with commission rate effective on the policy dates | D13: BRID_MIG 3.1 | E13: High | F13: Insurer-product commission rows exist for all policies
A14: MC-10 | B14: Rating and tax attributes | C14: Each product carries rate, minimum premium, commission rate, VAT / non-VAT regime and FST applicability (Property) before the load | D14: NB BRD Appendix A | E14: High | F14: No product with missing rate / tax regime
A15: MC-11 | B15: Mandatory fields per LOB | C15: Migrated in-force risks hold the mandatory underwriting fields of their LOB (see Data Dictionary) or are flagged for completion at first endorsement / renewal | D15: BRID_MIG 4.1, FRS PM v1.0 | E15: Medium | F15: Exception list per LOB
... A20: MC-16 | B20: Renewal readiness | C20: Products with policies expiring in the first renewal cycle after cutover are Mapped (not Needs confirmation) | D20: Renewal BRD | E20: High | F20: Renewal list by product vs mapping status

Sheet LOB summary
A1: LOB summary
A2: One row per BDOI line of business (library)
A4: LOB code (proposed) | B4: BDOI LOB | C4: IC class | D4: Description | E4: Typical clients / segments | F4: Sub-products | G4: Compulsory? | H4: Key insurers note | I4: Name in BDOI FRS | J4: BRD / FRS references
A5: PRO | B5: Property | C5: Fire (IC line: Fire and allied perils) | D5: Buildings, contents, machinery, stocks and improvements against fire and allied perils, or all risks; includes industrial all risks, householders and business interruption extensions. | E5: Corporate and SME premises; retail homeowners; bank-related mortgage redemption fire on real-estate loans (BDOI Fire packages PAR01-PAR25 are mortgaged-risk packages per NB BRD Appendix B). | F5: =COUNTIF('Product library'!$A$5:$A$87,B5) | G5: No by law; required by the bank as loan collateral cover (mortgagee clause) | H5: Placed with IC-licensed non-life insurers (or HMOs for health); panel per package - see product matrix | I5: Property | J5: NB BRD 2.3.1 and Appendix A (Fire), Appendix B (PAR packages); FRS PM v1.0 FRPM.003.02; BRD-03 FRS v1.3
A6: BND | B6: Bond | C6: Suretyship (IC line: Surety) | D6: Surety bonds guaranteeing the principal's performance of an obligation to an obligee: contract (bid, performance, payment, warranty), judicial, heirs, customs and government bonds. | E6: Contractors and suppliers of BDO corporate / SME clients; litigants (judicial); estates (heirs bond). | F6: =COUNTIF('Product library'!$A$5:$A$87,B6) | G6: Required by the obligee (e.g. government procurement, courts); not compulsory by law | H6: Placed with IC-licensed non-life insurers (or HMOs for health); panel per package - see product matrix | I6: Bonds | J6: FRS PM v1.0 product line 'Bonds' (Heirs, Performance, Surety, Bidder's, Judicial, Warranty); transaction types NB / Endorsement only
A7: PAC | B7: Personal Accident | C7: Casualty (Accident) | D7: Accidental death, disablement and medical reimbursement for individuals and groups, including travel and marine PA. | E7: Retail bank clients (PA programme for BDOI clients), employees (group PA), students, travellers. | F7: =COUNTIF('Product library'!$A$5:$A$87,B7) | G7: No (travel PA may be required for some visas; confirm) | H7: Placed with IC-licensed non-life insurers (or HMOs for health); panel per package - see product matrix | I7: Personal Accident | J7: FRS PM v1.0 sub-line values Personal Accident, Travel; BIBS PA001
A8: MTR | B8: Motor | C8: Motor Car | D8: Private and commercial vehicles: Compulsory Third Party Liability (CTPL), own damage and theft, excess bodily injury / property damage, acts of nature, auto PA. | E8: Retail car owners; bank auto-loan clients (BDOI Motor packages MTR08-MTR38); corporate fleets. | F8: =COUNTIF('Product library'!$A$5:$A$87,B8) | G8: Yes - CTPL is compulsory for LTO registration (Insurance Code ch. VI) | H8: Placed with IC-licensed non-life insurers (or HMOs for health); panel per package - see product matrix | I8: Motor | J8: NB BRD Appendix A (Motor computation), Appendix B (MTR packages); FRS PM v1.0 vehicle fields
A9: HLT | B9: Health Insurance | C9: Casualty (Health) / HMO (regulated by IC under RA 11223) | D9: Group and individual health and HMO programmes: hospitalisation, out-patient, emergency, dental; for a broker usually corporate employee benefit programmes. | E9: Corporate employee benefits; SME groups; individual clients (confirm whether BDOI places them). | F9: =COUNTIF('Product library'!$A$5:$A$87,B9) | G9: No | H9: Placed with IC-licensed non-life insurers (or HMOs for health); panel per package - see product matrix | I9: (not in FRS line list; Employee Benefits BRD) | J9: Employee Benefits.pdf; BIBS Employee Benefits lines HMO / GLI / GPA
A10: LIA | B10: Liability | C10: Casualty (Liability) | D10: Legal liability to third parties: general, products, professional, D&O, employer's, cyber, pollution and marine / excess auto liability. | E10: Corporate and SME clients, mall tenants and service contractors (BDOI CGL programmes). | F10: =COUNTIF('Product library'!$A$5:$A$87,B10) | G10: No by law; often required by lessors, malls, LGU business permits and contracts | H10: Placed with IC-licensed non-life insurers (or HMOs for health); panel per package - see product matrix | I10: Liability | J10: FRS PM v1.0 sub-line values (11 liability products); BIBS CGL01-CGL09
A11: ENG | B11: Engineering | C11: Casualty (Engineering) | D11: Construction and erection risks and operational machinery: CAR, EAR, machinery breakdown, contractor's plant, boiler and pressure vessel, delay in start-up. | E11: Contractors and project owners financed by BDO; manufacturing and utilities. | F11: =COUNTIF('Product library'!$A$5:$A$87,B11) | G11: No; often a loan / contract condition | H11: Placed with IC-licensed non-life insurers (or HMOs for health); panel per package - see product matrix | I11: Engineering | J11: FRS PM v1.0 sub-line values CARI, EAR; BIBS CAR00-CAR29, CARI; NB / Endorsement only
A12: EEI | B12: Electronic Equipment | C12: Casualty (Engineering) | D12: All-risks cover on electronic equipment (computers, medical, telecom), external data media and increased cost of working. | E12: Hospitals and clinics, BPOs, banks and offices, leasing companies. | F12: =COUNTIF('Product library'!$A$5:$A$87,B12) | G12: No | H12: Placed with IC-licensed non-life insurers (or HMOs for health); panel per package - see product matrix | I12: EEI | J12: FRS PM v1.0 line EEI; BIBS EEI01, EEI03, EEI04
A13: MSC | B13: Others / Miscellaneous | C13: Casualty (Miscellaneous) | D13: Specialty covers not in another line: golfer's / hole-in-one, sabotage and terrorism, political violence, trade credit, parametric, fine arts, jewellers block, event and cyber (if placed here). | E13: Corporate specialty risks; golf clubs and members; collectors. | F13: =COUNTIF('Product library'!$A$5:$A$87,B13) | G13: No | H13: Placed with IC-licensed non-life insurers (or HMOs for health); panel per package - see product matrix | I13: Miscellaneous | J13: FRS PM v1.0 sub-line values (Golfer's, S&T, PV, Trade Credit, Parametric, Fine Arts)
A14: MAR | B14: Marine (Cargo) | C14: Marine (Cargo) | D14: Goods in transit by sea, air and land: import, export, inter-island and inland transit, open covers, trust receipt programmes, stock throughput and logistics liabilities. | E14: Importers / exporters with BDO trade finance (trust receipts, letters of credit); distributors. | F14: =COUNTIF('Product library'!$A$5:$A$87,B14) | G14: No; required under L/C and trust receipt terms | H14: Placed with IC-licensed non-life insurers (or HMOs for health); panel per package - see product matrix | I14: Marine Cargo (and Stock Throughput) | J14: FRS PM v1.0 lines Marine Cargo, Stock Throughput; BIBS INL / MOP / MON / TRP products
A15: CRM | B15: Crime | C15: Casualty (Crime / Fidelity) | D15: Money, securities and payroll; fidelity guarantee; comprehensive crime (3D); bankers blanket bond; kidnap and ransom. | E15: Corporate and SME clients handling cash; financial institutions. | F15: =COUNTIF('Product library'!$A$5:$A$87,B15) | G15: No | H15: Placed with IC-licensed non-life insurers (or HMOs for health); panel per package - see product matrix | I15: Crime | J15: FRS PM v1.0 sub-line values (FG, MSP, K&R, BBB, FG+MSP, 3D)
A16: HUL | B16: Marine Hull | C16: Marine (Hull) | D16: Vessels: hull and machinery, protection and indemnity, builder's risk, ship repairer's liability. | E16: Shipping lines, inter-island operators, fishing fleets, shipyards. | F16: =COUNTIF('Product library'!$A$5:$A$87,B16) | G16: No by law for hull; P&I / passenger liability may be required by MARINA (confirm) | H16: Placed with IC-licensed non-life insurers (or HMOs for health); panel per package - see product matrix | I16: Marine Hull | J16: FRS PM v1.0 vessel fields; BIBS cover types H&M, Ship repairers, Builder's risk, P&I
... A19: CAS | B19: Casualty | C19: Casualty (Miscellaneous casualty) | D19: Other casualty covers: burglary and robbery, plate glass, all risks on personal items, comprehensive personal liability (where BDOI files it here) and similar. | E19: SME shops and offices; retail households. | F19: =COUNTIF('Product library'!$A$5:$A$87,B19) | G19: No | H19: Placed with IC-licensed non-life insurers (or HMOs for health); panel per package - see product matrix | I19: (not in FRS line list) | J19: BDOI LOB list only; no BDOI product list found - confirm scope with BDOI

Sheet Product library
A1: Product library
A2: One row per sub-product / plan per LOB; market rows to confirm with BDOI
A4: BDOI LOB | B4: Product code (proposed) | C4: Product | D4: Description | E4: Insured interest | F4: Standard covers / perils | G4: Common extensions / endorsements | H4: Key exclusions | I4: Sum insured basis | J4: Rating basis | K4: Deductible / excess | L4: Policy term | M4: Underwriting information required | N4: Documents required | O4: Taxes / charges | P4: Renewal considerations | Q4: Typical claims documents | R4: Source | S4: Source type
A5: Property | B5: PRO-FL | C5: Fire and Lightning (BIBS FIRE_LIGHTNING) | D5: Standard fire policy on buildings, contents and stocks | E5: Owner, mortgagee (bank) as loss payee | F5: Fire, lightning | G5: Allied perils, RSMD, earthquake, typhoon and flood, extended coverage | H5: War, nuclear, consequential loss unless endorsed, wear and tear | I5: Replacement or actual cash value per item | J5: Rate x TSI; minimum premium per package | K5: Typically none for fire; per package | L5: Annual or multi-year (bank packages) | M5: Location, occupancy, construction class, items and SI | N5: Proposal / application form; client KYC (ID, TIN, SEC / DTI registration for entities); property photos; title / loan details for mortgaged risks | O5: DST 12.5% of net premium; VAT 12% of net premium (NB BRD labels it PTX for Fire); FST 2% of net premium; LGT = net premium x LGT rate of the insurer branch | P5: Re-valuation of sums insured; mortgagee endorsement carried forward; multi-year allowed up to 5 years for bank packages (BIBS catalogue) | Q5: Notice of loss, fire bureau certificate (BFP), photos, sworn statement of loss, inventory, repair estimates, police report (RSMD) | R5: BDOI FRS (Type of Cover: F/L Only); BIBS PAR packages | S5: BDOI document
A6: Property | B6: PRO-NP | C6: Fire and Allied Perils / Broad Named Perils (BIBS BROAD_NAMED_PERILS) | D6: Fire policy extended to named allied perils | E6: Owner, mortgagee | F6: Fire, lightning, earthquake fire and shock, typhoon, flood, extended coverage, RSMD | G6: Debris removal, professional fees, temporary removal | H6: Unnamed perils, basement flood (clause), war | I6: Replacement or actual cash value | J6: Rate x TSI per peril; minimum premium | K6: EQ 2% of value at risk; typhoon / flood 1% of loss min PHP 20,000 (BIBS PAR08 v2) | L6: Annual or multi-year | M6: As Fire plus flood zone and elevation | N6: Proposal / application form; client KYC (ID, TIN, SEC / DTI registration for entities); inspection for large risks | O6: DST 12.5% of net premium; VAT 12% of net premium (NB BRD labels it PTX for Fire); FST 2% of net premium; LGT = net premium x LGT rate of the insurer branch | P6: Re-valuation of sums insured; mortgagee endorsement carried forward; multi-year allowed up to 5 years for bank packages (BIBS catalogue) | Q6: Notice of loss, fire bureau certificate (BFP), photos, sworn statement of loss, inventory, repair estimates, police report (RSMD) | R6: BDOI FRS (Named Perils) | S6: BDOI document
A7: Property | B7: PRO-AR | C7: Property All Risks (BIBS ALL_RISK) | D7: All risks of physical loss or damage unless excluded | E7: Owner, mortgagee | F7: All risks of physical loss or damage | G7: BI, machinery breakdown, money | H7: Wear and tear, gradual deterioration, mysterious disappearance, war, cyber | I7: Replacement value | J7: Rate x TSI; minimum premium | K7: Per occurrence deductible | L7: Annual | M7: Statement of values, risk survey | N7: Proposal / application form; client KYC (ID, TIN, SEC / DTI registration for entities); risk survey report; statement of values | O7: DST 12.5% of net premium; VAT 12% of net premium (NB BRD labels it PTX for Fire); FST 2% of net premium; LGT = net premium x LGT rate of the insurer branch | P7: Re-valuation of sums insured; mortgagee endorsement carried forward; multi-year allowed up to 5 years for bank packages (BIBS catalogue) | Q7: Notice of loss, fire bureau certificate (BFP), photos, sworn statement of loss, inventory, repair estimates, police report (RSMD) | R7: BDOI FRS (All-Risk) | S7: BDOI document
A8: Property | B8: PRO-IAR | C8: Industrial All Risks | D8: All risks on industrial / commercial plants | E8: Corporate owner, lenders | F8: Material damage all risks | G8: Business interruption, machinery breakdown, EEI sections | H8: As all risks plus process failure | I8: Replacement value; BI on gross profit | J8: Rate x TSI by section; minimum premium | K8: Per section deductibles | L8: Annual | M8: Plant survey, loss history, BI worksheet | N8: Proposal / application form; client KYC (ID, TIN, SEC / DTI registration for entities); risk engineering survey; BI worksheet | O8: DST 12.5% of net premium; VAT 12% of net premium (NB BRD labels it PTX for Fire); FST 2% of net premium; LGT = net premium x LGT rate of the insurer branch | P8: Re-valuation of sums insured; mortgagee endorsement carried forward; multi-year allowed up to 5 years for bank packages (BIBS catalogue) | Q8: Notice of loss, fire bureau certificate (BFP), photos, sworn statement of loss, inventory, repair estimates, police report (RSMD) | R8: Market practice (to confirm with BDOI) | S8: Market practice (to confirm with BDOI)
A9: Property | B9: PRO-BI | C9: Business Interruption / Consequential Loss | D9: Loss of gross profit following insured damage | E9: Business owner | F9: Loss of gross profit, increased cost of working | G9: Suppliers / customers extension, public utilities | H9: Losses without insured material damage | I9: Annual gross profit x indemnity period | J9: Rate x gross profit SI | K9: Time excess (e.g. 3-7 days) | L9: Annual | M9: Financial statements, indemnity period | N9: Proposal / application form; client KYC (ID, TIN, SEC / DTI registration for entities); audited financial statements | O9: DST 12.5% of net premium; VAT 12% of net premium (NB BRD labels it PTX for Fire); FST 2% of net premium; LGT = net premium x LGT rate of the insurer branch | P9: Re-valuation of sums insured; mortgagee endorsement carried forward; multi-year allowed up to 5 years for bank packages (BIBS catalogue) | Q9: Notice of loss, fire bureau certificate (BFP), photos, sworn statement of loss, inventory, repair estimates, police report (RSMD) | R9: Market practice (to confirm with BDOI) | S9: Market practice (to confirm with BDOI)
A10: Property | B10: PRO-HH | C10: Householders / Homeowners | D10: Package for dwelling and contents | E10: Homeowner | F10: Fire and allied perils, burglary, personal liability | G10: Earthquake, typhoon and flood | H10: Unoccupancy beyond limit, valuables over limit | I10: Replacement value | J10: Package premium or rate x SI | K10: Fixed deductible | L10: Annual | M10: Address, construction, contents values | N10: Proposal / application form; client KYC (ID, TIN, SEC / DTI registration for entities) | O10: DST 12.5% of net premium; VAT 12% of net premium (NB BRD labels it PTX for Fire); FST 2% of net premium; LGT = net premium x LGT rate of the insurer branch | P10: Re-valuation of sums insured; mortgagee endorsement carried forward; multi-year allowed up to 5 years for bank packages (BIBS catalogue) | Q10: Notice of loss, fire bureau certificate (BFP), photos, sworn statement of loss, inventory, repair estimates, police report (RSMD) | R10: Market practice (to confirm with BDOI) | S10: Market practice (to confirm with BDOI)
A11: Bond | B11: BND-SUR | C11: Surety Bond (general) | D11: Guarantee of an obligation of the principal to the obligee | E11: Obligee (beneficiary); principal (client) | F11: Bond amount payable on principal's default | G11: Extension of term, increase of amount (endorsement) | H11: Obligations outside the bond wording; after expiry | I11: Bond amount (often % of contract price) | J11: Rate x bond amount; minimum premium | K11: n/a | L11: Obligation period (not annual) | M11: Principal's financial statements, contract / tender documents, indemnity agreement, collateral | N11: Proposal / application form; client KYC (ID, TIN, SEC / DTI registration for entities); indemnity agreement; contract or court order | O11: DST on bonds (12.5% of premium - confirm legal basis and rate); VAT 12%; LGT per insurer branch; no FST | P11: Bonds are issued for the obligation period; extension by endorsement; BDOI FRS: NB and endorsement only, no renewal | Q11: Obligee's demand letter, proof of principal's default, contract and bond copy, statement of account | R11: BDOI FRS (Surety Bond) | S11: BDOI document
A12: Bond | B12: BND-BID | C12: Bidder's Bond | D12: Guarantees the bidder enters into the contract if awarded | E12: Obligee (beneficiary); principal (client) | F12: Bond amount payable on principal's default | G12: Extension of term, increase of amount (endorsement) | H12: Obligations outside the bond wording; after expiry | I12: Bond amount (often % of contract price) | J12: Rate x bond amount; minimum premium | K12: n/a | L12: Obligation period (not annual) | M12: Principal's financial statements, contract / tender documents, indemnity agreement, collateral | N12: Proposal / application form; client KYC (ID, TIN, SEC / DTI registration for entities); indemnity agreement; contract or court order | O12: DST on bonds (12.5% of premium - confirm legal basis and rate); VAT 12%; LGT per insurer branch; no FST | P12: Bonds are issued for the obligation period; extension by endorsement; BDOI FRS: NB and endorsement only, no renewal | Q12: Obligee's demand letter, proof of principal's default, contract and bond copy, statement of account | R12: BDOI FRS (Bidder's Bond) | S12: BDOI document
A13: Bond | B13: BND-PER | C13: Performance Bond | D13: Guarantees full performance of a contract | E13: Obligee (beneficiary); principal (client) | F13: Bond amount payable on principal's default | G13: Extension of term, increase of amount (endorsement) | H13: Obligations outside the bond wording; after expiry | I13: Bond amount (often % of contract price) | J13: Rate x bond amount; minimum premium | K13: n/a | L13: Obligation period (not annual) | M13: Principal's financial statements, contract / tender documents, indemnity agreement, collateral | N13: Proposal / application form; client KYC (ID, TIN, SEC / DTI registration for entities); indemnity agreement; contract or court order | O13: DST on bonds (12.5% of premium - confirm legal basis and rate); VAT 12%; LGT per insurer branch; no FST | P13: Bonds are issued for the obligation period; extension by endorsement; BDOI FRS: NB and endorsement only, no renewal | Q13: Obligee's demand letter, proof of principal's default, contract and bond copy, statement of account | R13: BDOI FRS (Performance Bond) | S13: BDOI document
A14: Bond | B14: BND-WAR | C14: Warranty Bond | D14: Guarantees correction of faulty work during the warranty period | E14: Obligee (beneficiary); principal (client) | F14: Bond amount payable on principal's default | G14: Extension of term, increase of amount (endorsement) | H14: Obligations outside the bond wording; after expiry | I14: Bond amount (often % of contract price) | J14: Rate x bond amount; minimum premium | K14: n/a | L14: Obligation period (not annual) | M14: Principal's financial statements, contract / tender documents, indemnity agreement, collateral | N14: Proposal / application form; client KYC (ID, TIN, SEC / DTI registration for entities); indemnity agreement; contract or court order | O14: DST on bonds (12.5% of premium - confirm legal basis and rate); VAT 12%; LGT per insurer branch; no FST | P14: Bonds are issued for the obligation period; extension by endorsement; BDOI FRS: NB and endorsement only, no renewal | Q14: Obligee's demand letter, proof of principal's default, contract and bond copy, statement of account | R14: BDOI FRS (Warranty Bond) | S14: BDOI document
A15: Bond | B15: BND-JUD | C15: Judicial / Court Bond | D15: Bonds required in court proceedings (replevin, attachment, counter-bond) | E15: Obligee (beneficiary); principal (client) | F15: Bond amount payable on principal's default | G15: Extension of term, increase of amount (endorsement) | H15: Obligations outside the bond wording; after expiry | I15: Bond amount (often % of contract price) | J15: Rate x bond amount; minimum premium | K15: n/a | L15: Obligation period (not annual) | M15: Principal's financial statements, contract / tender documents, indemnity agreement, collateral | N15: Proposal / application form; client KYC (ID, TIN, SEC / DTI registration for entities); indemnity agreement; contract or court order | O15: DST on bonds (12.5% of premium - confirm legal basis and rate); VAT 12%; LGT per insurer branch; no FST | P15: Bonds are issued for the obligation period; extension by endorsement; BDOI FRS: NB and endorsement only, no renewal | Q15: Obligee's demand letter, proof of principal's default, contract and bond copy, statement of account | R15: BDOI FRS (Judicial Bond) | S15: BDOI document
... A87: Casualty | B87: CAS-ARP | C87: All Risks on Personal Property | D87: Gadgets, jewellery, personal items | E87: Owner | F87: Gadgets, jewellery, personal items | G87: Per product | H87: Theft without forcible entry, employee theft | I87: Replacement or actual cash value | J87: Rate x SI; minimum premium | K87: Per loss deductible | L87: Annual | M87: Location, security measures, values | N87: Proposal / application form; client KYC (ID, TIN, SEC / DTI registration for entities) | O87: DST 12.5% of premium; VAT 12% of premium (or premium tax / exempt per insurer - confirm); LGT = premium x LGT rate of the insurer branch; no FST | P87: Updated values and security measures | Q87: Police report, inventory of items lost, proof of ownership | R87: Market practice (to confirm with BDOI) | S87: Market practice (to confirm with BDOI)

Sheet Covers & perils
A1: Covers & perils
A2: LOB x peril / cover: Standard, Optional or n/a (market practice; BDOI packages may differ)
A4: Peril / cover | B4: Property | C4: Bond | D4: Personal Accident | E4: Motor | F4: Health Insurance | G4: Liability | H4: Engineering | I4: Electronic Equipment | J4: Others / Miscellaneous | K4: Marine (Cargo) | L4: Crime | M4: Marine Hull | N4: Property / Equipment Floater | O4: Aviation | P4: Casualty
A5: Fire and lightning | B5: Standard | C5: n/a | D5: n/a | E5: Standard | F5: n/a | G5: n/a | H5: Standard | I5: Standard | J5: Optional | K5: Standard | L5: n/a | M5: Standard | N5: Standard | O5: Standard | P5: n/a
A6: Earthquake fire and shock | B6: Optional | C6: n/a | D6: n/a | E6: Optional | F6: n/a | G6: n/a | H6: Optional | I6: Optional | J6: n/a | K6: n/a | L6: n/a | M6: n/a | N6: Optional | O6: n/a | P6: n/a
A7: Typhoon and flood | B7: Optional | C7: n/a | D7: n/a | E7: Optional | F7: n/a | G7: n/a | H7: Optional | I7: Optional | J7: n/a | K7: n/a | L7: n/a | M7: n/a | N7: Optional | O7: n/a | P7: n/a
A8: Extended coverage (windstorm, explosion, aircraft, vehicle impact, smoke) | B8: Optional | C8: n/a | D8: n/a | E8: n/a | F8: n/a | G8: n/a | H8: n/a | I8: n/a | J8: n/a | K8: n/a | L8: n/a | M8: n/a | N8: n/a | O8: n/a | P8: n/a
A9: Riot, strike, malicious damage / civil commotion | B9: Optional | C9: n/a | D9: n/a | E9: Optional | F9: n/a | G9: n/a | H9: Optional | I9: n/a | J9: n/a | K9: Optional | L9: n/a | M9: n/a | N9: Optional | O9: n/a | P9: n/a
A10: Political violence / sabotage and terrorism | B10: Optional | C10: n/a | D10: n/a | E10: Optional | F10: n/a | G10: n/a | H10: n/a | I10: n/a | J10: Standard | K10: n/a | L10: n/a | M10: n/a | N10: Optional | O10: n/a | P10: n/a
A11: All risks of physical loss or damage | B11: Optional | C11: n/a | D11: n/a | E11: n/a | F11: n/a | G11: n/a | H11: Standard | I11: Standard | J11: Optional | K11: Optional | L11: n/a | M11: n/a | N11: Standard | O11: n/a | P11: Optional
A12: Business interruption / loss of profit | B12: Optional | C12: n/a | D12: n/a | E12: n/a | F12: n/a | G12: n/a | H12: Optional | I12: Optional | J12: n/a | K12: n/a | L12: n/a | M12: n/a | N12: n/a | O12: n/a | P12: n/a
A13: Machinery / electrical breakdown | B13: Optional | C13: n/a | D13: n/a | E13: n/a | F13: n/a | G13: n/a | H13: Standard | I13: Standard | J13: n/a | K13: n/a | L13: n/a | M13: n/a | N13: n/a | O13: n/a | P13: n/a
A14: Own damage and theft (vehicle) | B14: n/a | C14: n/a | D14: n/a | E14: Standard | F14: n/a | G14: n/a | H14: n/a | I14: n/a | J14: n/a | K14: n/a | L14: n/a | M14: n/a | N14: n/a | O14: n/a | P14: n/a
A15: Acts of nature (vehicle) | B15: n/a | C15: n/a | D15: n/a | E15: Optional | F15: n/a | G15: n/a | H15: n/a | I15: n/a | J15: n/a | K15: n/a | L15: n/a | M15: n/a | N15: n/a | O15: n/a | P15: n/a
... A41: Hole-in-one / golfer's liability | B41: n/a | C41: n/a | D41: n/a | E41: n/a | F41: n/a | G41: n/a | H41: n/a | I41: n/a | J41: Optional | K41: n/a | L41: n/a | M41: n/a | N41: n/a | O41: n/a | P41: n/a

Sheet Clauses
A1: Clauses
A2: Endorsements and clauses library per LOB
A4: LOB | B4: Clause / endorsement | C4: Type | D4: Purpose | E4: Source | F4: Source type
A5: Property | B5: Mortgagee / loss payee clause | C5: Clause | D5: Bank as mortgagee receives claim proceeds; required for BDO-financed collateral | E5: Market practice (to confirm with BDOI) | F5: Market practice (to confirm with BDOI)
A6: Property | B6: Fire extinguishing appliances warranty | C6: Warranty | D6: Appliances kept in working order (BIBS clause PAR_WARRANTY_EXT) | E6: BIBS catalogue | F6: BIBS configuration
A7: Property | B7: Flood exclusion (basement) | C7: Exclusion | D7: Excludes flood loss to basement property (BIBS clause PAR_FLOOD_EXCL) | E7: BIBS catalogue | F7: BIBS configuration
A8: Property | B8: 72-hour clause | C8: Clause | D8: Typhoon / flood / earthquake losses within 72 hours are one occurrence | E8: Market practice (to confirm with BDOI) | F8: Market practice (to confirm with BDOI)
A9: Property | B9: Earthquake fire and shock endorsement | C9: Endorsement | D9: Adds earthquake perils | E9: Market practice (to confirm with BDOI) | F9: Market practice (to confirm with BDOI)
A10: Property | B10: Typhoon and flood endorsement | C10: Endorsement | D10: Adds typhoon and flood perils | E10: Market practice (to confirm with BDOI) | F10: Market practice (to confirm with BDOI)
A11: Property | B11: Riot, strike and malicious damage (RSMD) | C11: Endorsement | D11: Adds RSMD perils | E11: Market practice (to confirm with BDOI) | F11: Market practice (to confirm with BDOI)
A12: Property | B12: Average / under-insurance (co-insurance) clause | C12: Condition | D12: Pro-rata claim if under-insured | E12: Market practice (to confirm with BDOI) | F12: Market practice (to confirm with BDOI)
A13: Property | B13: Debris removal, professional fees, temporary removal | C13: Extension | D13: Additional costs after a loss | E13: Market practice (to confirm with BDOI) | F13: Market practice (to confirm with BDOI)
A14: Property | B14: Reinstatement value clause | C14: Clause | D14: Claims on new-for-old basis | E14: Market practice (to confirm with BDOI) | F14: Market practice (to confirm with BDOI)
A15: Property | B15: Automatic reinstatement of sum insured | C15: Clause | D15: SI restored after a loss (additional premium) | E15: Market practice (to confirm with BDOI) | F15: Market practice (to confirm with BDOI)
... A47: Health Insurance | B47: Pre-existing condition waiver | C47: Endorsement | D47: Waives waiting period for groups above a size | E47: Market practice (to confirm with BDOI) | F47: Market practice (to confirm with BDOI)

Sheet Rating & charges
A1: Rating & charges
