Workbook
Name CODES_D0_02_BRANCH_CODE: 'D0-02 Branches'!$B$17:$B$517
Name CODES_D0_04_CODE: 'D0-04 Dimensions'!$C$17:$C$517
Name CODES_D0_06_ACCOUNT_CODE: 'D0-06 Chart of accounts'!$C$17:$C$517
Name CODES_D0_07_CATEGORY_CODE: 'D0-07 Categories and numbering'!$C$17:$C$517
Name CODES_PM_01_COVER_TYPE_CODE: 'PM-01 Product catalogue'!$E$17:$E$517
Name CODES_PM_01_LINE_CODE: 'PM-01 Product catalogue'!$B$17:$B$517
Name CODES_UA_02_GROUP_PROFILE_CODE: 'UA-02 Role matrix'!$B$17:$B$517
Name CODES_UA_01_USER_ID: 'UA-01 Users and roles'!$C$17:$C$517
Name CODES_PM_01_RISK_CODE: 'PM-01 Product catalogue'!$H$17:$H$517
Name CODES_D0_11_BANK_ACCOUNT_CODE: 'D0-11 Bank accounts'!$B$17:$B$517
Name CODES_D0_05_EMPLOYEE_NUMBER: 'D0-05 Employees'!$B$17:$B$517
Name CODES_PM_05_PARTNER_CODE: 'PM-05 Insurers'!$B$17:$B$517
Name LIST_YES_NO: 'Reference lists'!$C$5:$C$6
Name LIST_MARKET_SEGMENT: 'Reference lists'!$C$7:$C$11
Name LIST_PLACEMENT_GATE: 'Reference lists'!$C$12:$C$13
Name LIST_TSU_REVIEW: 'Reference lists'!$C$14:$C$16
Name LIST_CI02_RECORD: 'Reference lists'!$C$17:$C$19
Name LIST_DOCUMENT_TYPE: 'Reference lists'!$C$20:$C$82
Name LIST_CLAUSE_KIND: 'Reference lists'!$C$83:$C$86
Name LIST_RATE_TABLE: 'Reference lists'!$C$87:$C$89
Name LIST_MAP_ACTION: 'Reference lists'!$C$90:$C$91
Name LIST_PKG_DOCUMENT: 'Reference lists'!$C$92:$C$97
Name LIST_PM_LIST_OR_PARAMETER: 'Reference lists'!$C$98:$C$137
Name LIST_INCENTIVE_TYPE: 'Reference lists'!$C$138:$C$139
Name LIST_UA_ACTION: 'Reference lists'!$C$140:$C$143
Name LIST_PRIVILEGE_LEVEL: 'Reference lists'!$C$144:$C$147
Name LIST_KEEP_ADD_REMOVE: 'Reference lists'!$C$148:$C$150
Name LIST_UA_ROLE: 'Reference lists'!$C$151:$C$155
Name LIST_SOD_STATUS: 'Reference lists'!$C$156:$C$158
Name LIST_SOD_CONTROL: 'Reference lists'!$C$159:$C$161
Name LIST_REVIEW_FREQUENCY: 'Reference lists'!$C$162:$C$163
Name LIST_UA_PARAMETER: 'Reference lists'!$C$164:$C$180
Name LIST_UA_LIST: 'Reference lists'!$C$181:$C$183
Name LIST_DIMENSION: 'Reference lists'!$C$184:$C$185
Name LIST_ACCOUNT_CLASS: 'Reference lists'!$C$186:$C$190
Name LIST_ACCOUNT_CLASS_CHART: 'Reference lists'!$C$191:$C$196
Name LIST_ACCOUNT_LEVEL: 'Reference lists'!$C$197:$C$200
Name LIST_NEGATIVE_BALANCE: 'Reference lists'!$C$201:$C$203
Name LIST_CATEGORY_ROW: 'Reference lists'!$C$204:$C$205
Name LIST_ACCOUNTING_EVENT: 'Reference lists'!$C$206:$C$295
Name LIST_DEBIT_CREDIT: 'Reference lists'!$C$296:$C$297
Name LIST_LEGACY_ACCOUNT: 'Reference lists'!$C$298:$C$305
Name LIST_TAX_TYPE: 'Reference lists'!$C$306:$C$309
Name LIST_PAYEE_CLASS: 'Reference lists'!$C$310:$C$315
Name LIST_APPROVAL_MODULE: 'Reference lists'!$C$316:$C$319
Name LIST_ROUTE: 'Reference lists'!$C$320:$C$322
Name LIST_STATUS: 'Reference lists'!$C$323:$C$327
Name LIST_TEMPLATES: 'Reference lists'!$C$328:$C$359
Name LIST_QUESTION_STATUS: 'Reference lists'!$C$360:$C$362

Sheet Start here
A3: Drop 0 Configuration Inputs
A4: Every configuration input BDOI provides before go-live for Drop 0 and the platform set-up Drop 1 depends on
A6: Client | C6: BDO Insurance and Reinsurance Brokers, Inc.
A7: Scope | C7: Drop 0 (BRD-03, BRD-11, BRD-13) and the platform set-up Drop 1 depends on
A8: Version and date | C8: Version 2.1, 8 October 2026
A9: Go-live | C9: Go-live is proposed for Monday 3 January 2028 (T), at the year-end boundary (option A of the Data Migration set, for Comptrollership to confirm).
A10: Owner | C10: Program Manager, Business Project Services, with the BDOI owner of each item
A11: Prepared by | C11: iorta TechNXT
A12: Classification | C12: Confidential
A14: How to fill in this workbook
A15: 1 | B15: The index below lists every configuration input of Drop 0 and of the platform set-up that Drop 1 depends on, one row per item, by due date; within a due date the templates come in the order they are filled in, a template whose codes others use first.
A16: 2 | B16: Each item has one route. Template: fill in the template sheet (Open →); its rows are then entered or uploaded on the named screen and authorised by a second user. Screen: enter the item on the named BIBS screen and record the decision in BDOI comments. Migration object: the item comes from the legacy systems through the named object of the Migration Workbook (BRD-13); it is not typed here.
A17: 3 | B17: On a template sheet, read the header block and the guide above each column (Mandatory, Format, Allowed values, What to enter; * marks a mandatory column), overwrite or delete the grey example row and enter one row per record. Drop-downs offer the allowed values (sheet Reference lists) and the codes of the templates filled in before; a mandatory cell left empty turns red.
A18: 4 | B18: The sheets starting with Ref list every list of values, system parameter, numbering prefix, notification event, document template and accounting event of BIBS, and the migration cross-reference; set the value wanted, the decision or the comment on each row you own.
A19: 5 | B19: Set the Status of each item, follow Rows entered and Mandatory cells missing, raise questions on the sheet Questions and comments, and return the workbook to the iorta TechNXT project team by each due date. The status is reviewed at the weekly programme meeting. Codes must be the codes of the other sheets: branch codes of D0-02, accounts of D0-06, cost centres of D0-04, bank accounts of D0-11, group profiles of UA-02 and users of UA-01.
A21: Configuration inputs by due date, templates in the order they are filled in
A22: Step | B22: ID | C22: Configuration item | D22: What BDOI provides | E22: Owner (BDOI unit) | F22: Due | G22: Route | H22: Entered or loaded on | I22: Prepared in | J22: Depends on | K22: Rows entered | L22: Mandatory cells missing | M22: Status | N22: BDOI comments | O22: Provided on | P22: Open
A23: 1 | B23: CFG-023 | C23: Legacy control accounts and Migration Clearing | D23: The account codes of the legacy control accounts and of Migration Clearing in the production chart (proposed rule PR-DM-02) | E23: Head, Comptrollership | F23: 1-Dec-2026 – Drafts with the Drop 0 sign-off | G23: Template | H23: Finance › General Ledger › Chart of Accounts | I23: Drop 0 template D0-09, sheet D0-09 Legacy accounts | J23: D0-06 | K23: ='D0-09 Legacy accounts'!$C$9 | L23: ='D0-09 Legacy accounts'!$E$9 | M23: Not started | P23: D0-09 →
A24: 2 | B24: CFG-075 | C24: Directory sign-in and provisioning (EIAM, UIDM-ISC) | D24: The sign-in mode, the EIAM tenant and claims, and the UIDM-ISC option (clarifications CLR-UA-01 and CLR-UA-03) | E24: BDOI IT | F24: 1-Dec-2026 – Drafts with the Drop 0 sign-off | G24: Screen | H24: Setup & Administration › Administration › System Parameters | I24: This index row (decision and values in BDOI comments) | J24: - | M24: Not started
A25: 3 | B25: CFG-002 | C25: Branches and invoicing branches | D25: Every BDOI branch with its region, address, opening date, head-office flag, contact and weekly rest days; the legacy branch codes are mapped to them by the migration (R02, check only) | E25: Head, Comptrollership | F25: 4-Jan-2027 – Platform set-up for Drop 1 SIT | G25: Template | H25: Setup & Administration › Setup › Branches | I25: Drop 0 template D0-02, sheet D0-02 Branches | J25: - | K25: ='D0-02 Branches'!$C$9 | L25: ='D0-02 Branches'!$E$9 | M25: Not started | P25: D0-02 →
A26: 4 | B26: CFG-004 | C26: Cost centres and business lines | D26: The cost centres and business lines used on journal lines and in the cost-centre rules; the legacy cost centres are mapped by code map COST_CENTER | E26: Head, Comptrollership | F26: 4-Jan-2027 – Platform set-up for Drop 1 SIT | G26: Template | H26: Setup & Administration › Setup › Dimensions | I26: Drop 0 template D0-04, sheet D0-04 Dimensions | J26: - | K26: ='D0-04 Dimensions'!$C$9 | L26: ='D0-04 Dimensions'!$E$9 | M26: Not started | P26: D0-04 →
A27: 5 | B27: CFG-021 | C27: Account categories and numbering scheme | D27: The GL categories (with the bank categories) and the numbering scheme under each parent (separator and width) | E27: Head, Comptrollership | F27: 4-Jan-2027 – Platform set-up for Drop 1 SIT | G27: Template | H27: Finance › General Ledger › Chart of Accounts | I27: Drop 0 template D0-07, sheet D0-07 Categories and numbering | J27: - | K27: ='D0-07 Categories and numbering'!$C$9 | L27: ='D0-07 Categories and numbering'!$E$9 | M27: Not started | P27: D0-07 →
A28: 6 | B28: CFG-052 | C28: Account numbering scheme | D28: Covered by CFG-021: the separator and width of the account codes under each parent | E28: Head, Comptrollership | F28: 4-Jan-2027 – Platform set-up for Drop 1 SIT | G28: Template | I28: Drop 0 template D0-07, sheet D0-07 Categories and numbering | J28: - | K28: ='D0-07 Categories and numbering'!$C$9 | L28: ='D0-07 Categories and numbering'!$E$9 | M28: Not started | P28: D0-07 →
A29: 7 | B29: CFG-020 | C29: Chart of accounts | D29: The production chart of accounts of BDOI in the chart upload template: every account with its parent, class, level, control and sub-ledger flags, currencies and report group | E29: Head, Comptrollership | F29: 4-Jan-2027 – Platform set-up for Drop 1 SIT | G29: Template | H29: Finance › General Ledger › Chart Upload | I29: Drop 0 template D0-06, sheet D0-06 Chart of accounts | J29: D0-07 | K29: ='D0-06 Chart of accounts'!$C$9 | L29: ='D0-06 Chart of accounts'!$E$9 | M29: Not started | P29: D0-06 →
A30: 8 | B30: CFG-003 | C30: Holiday calendar | D30: Public and company holidays of 2027 and 2028, company-wide or per branch; they drive the working days of service levels, value dates and jobs | E30: Head, Comptrollership; Human Resources | F30: 4-Jan-2027 – Platform set-up for Drop 1 SIT | G30: Template | H30: Setup & Administration › Setup › Holiday Calendar | I30: Drop 0 template D0-03, sheet D0-03 Holiday calendar | J30: D0-02 | K30: ='D0-03 Holiday calendar'!$C$9 | L30: ='D0-03 Holiday calendar'!$E$9 | M30: Not started | P30: D0-03 →
A31: 9 | B31: CFG-040 | C31: Company bank accounts | D31: Every BDOI bank account used for collections and disbursements: bank, account number, currency, branch, GL account and PDC clearing account | E31: Head, Comptrollership; Treasury | F31: 4-Jan-2027 – Platform set-up for Drop 1 SIT | G31: Template | H31: Finance › Disbursement › Bank Accounts and Checks | I31: Drop 0 template D0-11, sheet D0-11 Bank accounts | J31: D0-06, D0-02 | K31: ='D0-11 Bank accounts'!$C$9 | L31: ='D0-11 Bank accounts'!$E$9 | M31: Not started | P31: D0-11 →
A32: 10 | B32: CFG-001 | C32: Company | D32: The BDOI company record: code, registered name, TIN, address, base currency, fiscal year start and the value-date window of postings | E32: Head, Comptrollership | F32: 4-Jan-2027 – Platform set-up for Drop 1 SIT | G32: Template | H32: Setup & Administration › Setup › Companies | I32: Drop 0 template D0-01, sheet D0-01 Company | J32: D0-06 | K32: ='D0-01 Company'!$C$9 | L32: ='D0-01 Company'!$E$9 | M32: Not started | P32: D0-01 →
A33: 11 | B33: CFG-022 | C33: Accounting rules per event | D33: For each accounting event of the platform, the debit and credit accounts per amount component, business line and currency | E33: Head, Comptrollership | F33: 4-Jan-2027 – Platform set-up for Drop 1 SIT | G33: Template | H33: Finance › Accounting Engine › Accounting Rules | I33: Drop 0 template D0-08, sheet D0-08 Accounting rules | J33: D0-04, D0-06 | K33: ='D0-08 Accounting rules'!$C$9 | L33: ='D0-08 Accounting rules'!$E$9 | M33: Not started | P33: D0-08 →
A34: 12 | B34: CFG-111 | C34: Role-to-permission matrix | D34: BRD-11 template CI-02 | E34: Business Administration with the unit heads; reviewed and signed by BDOI Information Security | F34: 9-Apr-2027 – Reference data for Trial migration 1 (M4) | G34: Template | H34: Setup & Administration › User Access › Group Profile Requests | I34: BRD-11 template CI-02, sheet UA-02 Role matrix | J34: - | K34: ='UA-02 Role matrix'!$C$9 | L34: ='UA-02 Role matrix'!$E$9 | M34: Not started | P34: UA-02 →
A35: 13 | B35: CFG-045 | C35: Bank list (mortgagee banks) | D35: The banks named as mortgagee or payout bank; the legacy bank codes are mapped to this list by code map BANK | E35: Product Owner, BDOI (New Business) | F35: 9-Apr-2027 – Reference data for Trial migration 1 (M4) | G35: Template | H35: Setup & Administration › Broking Setup › Lists of Values | I35: This workbook, sheet Ref Lists of values | J35: - | M35: Not started | P35: Open →
A36: 14 | B36: CFG-060 | C36: Lists of values (every list of the platform) | D36: For every list: its owner, and the values BDOI keeps, adds or retires. The lists whose values come from the legacy systems are loaded by R01; the others are entered on Lists of Values under maker-checker (see the sheet Ref Lists of values for the route of each list) | E36: BDOI IT | F36: 9-Apr-2027 – Reference data for Trial migration 1 (M4) | G36: Template | H36: Setup & Administration › Broking Setup › Lists of Values | I36: This workbook, sheet Ref Lists of values | J36: - | M36: Not started | P36: Open →
A37: 15 | B37: CFG-090 | C37: Product catalogue | D37: Product lines, cover types and products (risk codes) with their features, prepared in BRD-03 template CI-01 | E37: Product Owner, Marketing Business System (MBS) | F37: 9-Apr-2027 – Reference data for Trial migration 1 (M4) | G37: Migration object | H37: Data migration object R05 Product lines, cover types, products and risk codes; after go-live: Client & Policy › Product Maintenance › Products | I37: BRD-03 template CI-01, sheet PM-01 Product catalogue; delivered in the layout of R05 | J37: PM-09 | K37: ='PM-01 Product catalogue'!$C$9 | L37: ='PM-01 Product catalogue'!$E$9 | M37: Not started | P37: PM-01 →
A38: 16 | B38: CFG-100 | C38: Insurers and insurer branches | D38: The insurer panel with accreditation, placement e-mails and credit days, and the insurer branches with their LGT rate (BRD-03 template CI-05) | E38: Head, Operations Services | F38: 9-Apr-2027 – Reference data for Trial migration 1 (M4) | G38: Migration object | H38: Data migration object R04 Insurers and insurer branches; after go-live: Client & Policy › Product Maintenance › Insurers | I38: BRD-03 template CI-05, sheet PM-05 Insurers; delivered in the layout of R04 | J38: PM-01 | K38: ='PM-05 Insurers'!$C$9 | L38: ='PM-05 Insurers'!$E$9 | M38: Not started | P38: PM-05 →
A39: 17 | B39: CFG-101 | C39: Commission rates by insurer and product | D39: The commission rates in force at cut-over and later (commission rows of BRD-03 template CI-05) | E39: Head, Operations Services | F39: 9-Apr-2027 – Reference data for Trial migration 1 (M4) | G39: Migration object | H39: Data migration object R07 Commission rates by insurer and product; after go-live: Client & Policy › Product Maintenance › Insurers | I39: BRD-03 template CI-05, sheet PM-05 Insurers; delivered in the layout of R07 | J39: PM-01 | K39: ='PM-05 Insurers'!$C$9 | L39: ='PM-05 Insurers'!$E$9 | M39: Not started | P39: PM-05 →
A40: 18 | B40: CFG-007 | C40: Sales organisation (regions, departments, teams, unit heads, account officers) | D40: The sales units and account officers in force, and the inactive officers of open items; after go-live maintained on Sales Organisation | E40: Product Owner, BDOI (New Business) | F40: 9-Apr-2027 – Reference data for Trial migration 1 (M4) | G40: Migration object | H40: Data migration object R03 Sales organisation (regions, departments, teams, unit heads, account officers); after go-live: Client & Policy › Product Maintenance › Sales Organisation | I40: Migration Workbook, layout R03 | J40: - | M40: Not started | P40: R03 →
A41: 19 | B41: CFG-103 | C41: Payees | D41: Active payees of EBIX, loaded by the payee registration of Disbursement if BDOI brings R09 into scope (conditional object, DMQ30); otherwise registered on Payees | E41: Head, Comptrollership | F41: 9-Apr-2027 – Reference data for Trial migration 1 (M4) | G41: Migration object | H41: Data migration object R09 Payees; after go-live: Finance › Disbursement › Payees | I41: Migration Workbook, layout R09 | J41: - | M41: Not started | P41: R09 →
A42: 20 | B42: CFG-095 | C42: Package map (legacy package to BIBS package version) | D42: BRD-03 template CI-07, loaded as reference data for the package check of the Renewal sanitation | E42: Product Owner, Marketing Business System (MBS) | F42: 18-Jun-2027 – Code maps approved (M5) | G42: Migration object | H42: Data migration object R06 Package code map (legacy package and version to BIBS package version); after go-live: Data Migration › Data Migration › Code Maps | I42: BRD-03 template CI-07, sheet PM-07 Package map; delivered in the layout of R06 | J42: PM-01, PM-05, PM-06 | K42: ='PM-07 Package map'!$C$9 | L42: ='PM-07 Package map'!$E$9 | M42: Not started | P42: PM-07 →
A43: 21 | B43: CFG-024 | C43: Chart of accounts mapping (legacy GL account to BIBS account) | D43: The map of every legacy GL account of EBIX and ISYS to a BIBS account; control accounts to Migration Clearing | E43: Program Manager, Business Project Services (Data Migration) | F43: 18-Jun-2027 – Code maps approved (M5) | G43: Migration object | H43: Data migration object R08 Chart of accounts mapping (legacy GL account to BIBS account); after go-live: Data Migration › Data Migration › Code Maps | I43: Migration Workbook, layout R08 | J43: - | M43: Not started | P43: R08 →
A44: 22 | B44: CFG-061 | C44: Values of the lists used by migrated records | D44: The legacy values of the lists mapped by the code maps LOV and MIS, and the BIBS value of each | E44: Program Manager, Business Project Services (Data Migration) | F44: 18-Jun-2027 – Code maps approved (M5) | G44: Migration object | H44: Data migration object R01 Lists of values and MIS values; after go-live: Data Migration › Data Migration › Code Maps | I44: Migration Workbook, layout R01 | J44: - | M44: Not started | P44: R01 →
A45: 23 | B45: CFG-140 | C45: Code maps of the reference data | D45: The approved versions of the code maps (branches, sales units, officers, users, cost centres, banks, currencies, dispositions, statuses) that turn legacy codes into BIBS codes | E45: Program Manager, Business Project Services (Data Migration) | F45: 18-Jun-2027 – Code maps approved (M5) | G45: Migration object | H45: Data migration object R01 Lists of values and MIS values; after go-live: Data Migration › Data Migration › Code Maps | I45: Migration Workbook, layout R01 | J45: - | M45: Not started | P45: R01 →
...

Sheet D0-02 Branches
A1: D0-02 Branches | M1: Step 1 of 31
A2: ← Back to Start here | B2: Step 1 of 31. Fill in one row per record below the column headers; the guide above each column says what to enter. | M2: Ask a question →
A3: Purpose | B3: Every BDOI branch and invoicing branch
A4: Provided by | B4: Head, Comptrollership
A5: Due | B5: 4-Jan-2027 – Platform set-up for Drop 1 SIT
A6: How it is loaded | B6: Branches (Setup & Administration), before the first migration mock; the legacy branches are mapped to them by the code map BRANCH (object R02)
A7: Source | B7: BDOI branch list; EBIX branch codes for the code map BRANCH
A8: Depends on | B8: Nothing: this template can be filled in first
A9: Progress | B9: Rows entered | C9: =SUMPRODUCT(((ROW($B$17:$B$517)>17)+($B$17<>"HO")>0)*(LEN($B$17:$B$517&$C$17:$C$517&$D$17:$D$517&$E$17:$E$517&$F$17:$F$517&$G$17:$G$517&$H$17:$H$517&$I$17:$I$517&$J$17:$J$517&$K$17:$K$517&$L$17:$L$517&$M$17:$M$517)>0)) | D9: Mandatory cells missing | E9: =SUMPRODUCT(((ROW($B$17:$B$517)>17)+($B$17<>"HO")>0)*(LEN($B$17:$B$517&$C$17:$C$517&$D$17:$D$517&$E$17:$E$517&$F$17:$F$517&$G$17:$G$517&$H$17:$H$517&$I$17:$I$517&$J$17:$J$517&$K$17:$K$517&$L$17:$L$517&$M$17:$M$517)>0)*(($B$17:$B$517="")+($C$17:$C$517="")+($F$17:$F$517="")+($G$17:$G$517="")+($H$17:$H$517="")))
A10: Confirmed by (BDOI owner) | D10: Date
A12: Mandatory | B12: Yes | C12: Yes | D12: No | E12: No | F12: Yes | G12: Yes | H12: Yes | I12: No | J12: No | K12: No | L12: No | M12: No
A13: Format | B13: Up to 10 capitals | C13: Up to 120 characters | D13: Text | E13: Text | F13: dd-MMM-yyyy | G13: Y or N | H13: Y or N | I13: Text | J13: E-mail address | K13: Name | L13: SAT, SUN | M13: EBIX codes separated by commas
A14: Allowed values | B14: Free entry, up to 10 characters | C14: Free entry, up to 120 characters | D14: Free entry | E14: Free entry | F14: A date, for example 15-Jan-2028 | G14: Y or N | H14: Y or N | I14: Free entry | J14: Free entry | K14: Free entry | L14: Free entry | M14: Free entry
A15: What to enter | B15: Code of the branch; unique | C15: Name shown on screens and documents | D15: Region of the branch | E15: Address printed on documents | F15: Date the branch opened | G15: Y for one branch only | H15: May receive and pay in foreign currency | I15: Branch telephone | J15: Branch mailbox | K15: Head of the branch | L15: Days the branch is closed each week | M15: For the code map BRANCH (R02)
A16: Row | B16: Branch code * | C16: Branch name * | D16: Region | E16: Address | F16: Opening date * | G16: Head office * | H16: Foreign currency authorised * | I16: Contact phone | J16: Contact e-mail | K16: Branch manager | L16: Weekly rest days | M16: Legacy branch codes
A17: Example – overwrite or delete | B17: HO | C17: Head Office | D17: NCR | E17: 7899 Makati Avenue, Makati City | F17: 40179 | G17: Y | H17: Y | I17: (02) 8888-0000 | J17: ho@bdoi.example.ph | L17: SAT,SUN | M17: 001

Sheet D0-04 Dimensions
A1: D0-04 Cost centres and business lines | G1: Step 2 of 31
A2: ← Back to Start here | B2: Step 2 of 31. Fill in one row per record below the column headers; the guide above each column says what to enter. | G2: Ask a question →
A3: Purpose | B3: The values of the dimensions of journal lines
A4: Provided by | B4: Head, Comptrollership
A5: Due | B5: 4-Jan-2027 – Platform set-up for Drop 1 SIT
A6: How it is loaded | B6: Dimensions (Setup & Administration); the legacy cost centres are mapped by the code map COST_CENTER
A7: Source | B7: Current cost centre list of Comptrollership; the product lines for the business lines
A8: Depends on | B8: Nothing: this template can be filled in first
A9: Progress | B9: Rows entered | C9: =SUMPRODUCT(((ROW($B$17:$B$517)>17)+($B$17<>"COST_CENTER")>0)*(LEN($B$17:$B$517&$C$17:$C$517&$D$17:$D$517&$E$17:$E$517)>0)) | D9: Mandatory cells missing | E9: =SUMPRODUCT(((ROW($B$17:$B$517)>17)+($B$17<>"COST_CENTER")>0)*(LEN($B$17:$B$517&$C$17:$C$517&$D$17:$D$517&$E$17:$E$517)>0)*(($B$17:$B$517="")+($C$17:$C$517="")+($D$17:$D$517="")+($E$17:$E$517="")))
A10: Confirmed by (BDOI owner) | D10: Date
A12: Mandatory | B12: Yes | C12: Yes | D12: Yes | E12: Yes
A13: Format | B13: COST_CENTER or BUSINESS_LINE | C13: Up to 20 capitals or digits | D13: Up to 120 characters | E13: Y or N
A14: Allowed values | B14: COST_CENTER, BUSINESS_LINE (list Dimension) | C14: Free entry, up to 20 characters | D14: Free entry, up to 120 characters | E14: Y or N
A15: What to enter | B15: Dimension of the value | C15: Code of the value | D15: Name shown on screens and reports | E15: N keeps the value for history only
A16: Row | B16: Dimension * | C16: Code * | D16: Name * | E16: Active *
A17: Example – overwrite or delete | B17: COST_CENTER | C17: FIN | D17: Finance and Accounting | E17: Y

Sheet D0-07 Categories and numbering
A1: D0-07 Account categories and numbering | I1: Step 3 of 31
A2: ← Back to Start here | B2: Step 3 of 31. Fill in one row per record below the column headers; the guide above each column says what to enter. | I2: Ask a question →
A3: Purpose | B3: The GL categories and the numbering scheme under each parent account
A4: Provided by | B4: Head, Comptrollership
A5: Due | B5: 4-Jan-2027 – Platform set-up for Drop 1 SIT
A6: How it is loaded | B6: Chart of Accounts (General Ledger)
A7: Source | B7: The BDOI chart of accounts
A8: Depends on | B8: Nothing: this template can be filled in first
A9: Progress | B9: Rows entered | C9: =SUMPRODUCT(((ROW($B$17:$B$517)>17)+($B$17<>"CATEGORY")>0)*(LEN($B$17:$B$517&$C$17:$C$517&$D$17:$D$517&$E$17:$E$517&$F$17:$F$517&$G$17:$G$517&$H$17:$H$517&$I$17:$I$517)>0)) | D9: Mandatory cells missing | E9: =SUMPRODUCT(((ROW($B$17:$B$517)>17)+($B$17<>"CATEGORY")>0)*(LEN($B$17:$B$517&$C$17:$C$517&$D$17:$D$517&$E$17:$E$517&$F$17:$F$517&$G$17:$G$517&$H$17:$H$517&$I$17:$I$517)>0)*(($B$17:$B$517="")))
A10: Confirmed by (BDOI owner) | D10: Date
A12: Mandatory | B12: Yes | C12: Conditional: CATEGORY | D12: Conditional: CATEGORY | E12: Conditional: CATEGORY | F12: Conditional: CATEGORY | G12: Conditional: NUMBERING | H12: Conditional: NUMBERING | I12: Conditional: NUMBERING
A13: Format | B13: CATEGORY or NUMBERING | C13: Up to 20 capitals | D13: Text | E13: ASSET, LIABILITY, EQUITY, INCOME, EXPENSE | F13: Y or N | G13: Account code of D0-06 | H13: . or - or none | I13: 1 to 6
A14: Allowed values | B14: CATEGORY, NUMBERING (list Category or numbering row) | C14: Free entry, up to 20 characters | D14: Free entry | E14: ASSET, LIABILITY, EQUITY, INCOME, EXPENSE (list Account class) | F14: Y or N | G14: Free entry | H14: Free entry | I14: A whole number from 1 to 6
A15: What to enter | B15: What the row defines | C15: GL category | D15: Name of the category | E15: Class of the accounts of the category | F15: Y for the accounts of bank accounts (D0-11) | G15: Parent whose children are numbered | H15: Between the parent code and the running number | I15: Digits of the running number
A16: Row | B16: Row * | C16: Category code | D16: Category name | E16: Account class | F16: Bank category | G16: Parent account | H16: Separator | I16: Width
A17: Example – overwrite or delete | B17: CATEGORY | C17: CASH_IN_BANK | D17: Cash in bank | E17: ASSET | F17: Y | G17: 1110 | H17: . | I17: 2

Sheet PM-09 Lists and parameters
A1: PM-09 Lists of values and parameters | G1: Step 4 of 31
A2: ← Back to Start here | B2: Step 4 of 31. Fill in one row per record below the column headers; the guide above each column says what to enter. | G2: Ask a question →
A3: Purpose | B3: The values of the Product Maintenance lists (request reasons, response outcomes, advisory groups, not-proceeded reasons, incentive types, coverage kinds, clause kinds, document types, market segments) and the parameters (numbering, reply days, expiry notice, advisory groups, service levels)
A4: Provided by | B4: Product Owner, MBS; System Administrator (entry)
A5: Due | B5: 16-Jul-2027 – Values for UAT
A6: How it is loaded | B6: Data migration object R01 for the values used by migrated records; the other values on Lists of Values and System Parameters
A7: Source | B7: Delivered values (FRS chapter 9) confirmed or changed by BDOI
A8: Depends on | B8: Nothing: this template can be filled in first
A9: Progress | B9: Rows entered | C9: =SUMPRODUCT(((ROW($B$17:$B$517)>17)+($B$17<>"PKG_REQUEST_REASON")>0)*(LEN($B$17:$B$517&$C$17:$C$517&$D$17:$D$517&$E$17:$E$517&$F$17:$F$517)>0)) | D9: Mandatory cells missing | E9: =SUMPRODUCT(((ROW($B$17:$B$517)>17)+($B$17<>"PKG_REQUEST_REASON")>0)*(LEN($B$17:$B$517&$C$17:$C$517&$D$17:$D$517&$E$17:$E$517&$F$17:$F$517)>0)*(($B$17:$B$517="")+($D$17:$D$517="")))
A10: Confirmed by (BDOI owner) | D10: Date
A12: Mandatory | B12: Yes | C12: Conditional: list | D12: Yes | E12: No | F12: No
A13: Format | B13: Code of the list or parameter | C13: Up to 40 capitals | D13: Text; number for a parameter | E13: Number; Y or N | F13: dd-MMM-yyyy
A14: Allowed values | B14: List Product Maintenance list or parameter: 40 values, see Reference lists | C14: Free entry, up to 40 characters | D14: Free entry | E14: Free entry | F14: A date, for example 15-Jan-2028
A15: What to enter | B15: For example PKG_REQUEST_REASON, PKG_SLA_NEGOTIATION | C15: Code of the value | D15: Label shown to users, or the parameter value | E15: Display order and status | F15: From when the value applies
A16: Row | B16: List or parameter * | C16: Value code | D16: Label or value * | E16: Order / Active | F16: Effective from
A17: Example – overwrite or delete | B17: PKG_REQUEST_REASON | C17: LOSS_EXPERIENCE | D17: Loss experience | E17: 50; Y | F17: 46327

Sheet UA-02 Role matrix
A1: UA-02 Role-to-permission matrix | I1: Step 5 of 31
A2: ← Back to Start here | B2: Step 5 of 31. Fill in one row per record below the column headers; the guide above each column says what to enter. | I2: Ask a question →
A3: Purpose | B3: The group profiles BDOI keeps, their privilege level and the permissions of each, starting from the User Access Matrix as delivered
A4: Provided by | B4: Business Administration with the unit heads; reviewed and signed by BDOI Information Security
A5: Due | B5: 9-Apr-2027 – Reference data for Trial migration 1 (M4)
A6: How it is loaded | B6: Group-profile requests (SCR-UA-12): one request per new or changed profile, approved in order and implemented by the System Administrator; checked with the User Group Profile Report
A7: Source | B7: The User Access Matrix export of this set (DO-06) and the menus by persona of FRS chapter 12
A8: Depends on | B8: Nothing: this template can be filled in first
A9: Progress | B9: Rows entered | C9: =SUMPRODUCT(((ROW($B$17:$B$517)>17)+($B$17<>"MKT_AO")>0)*(LEN($B$17:$B$517&$C$17:$C$517&$D$17:$D$517&$E$17:$E$517&$F$17:$F$517&$G$17:$G$517&$H$17:$H$517&$I$17:$I$517)>0)) | D9: Mandatory cells missing | E9: =SUMPRODUCT(((ROW($B$17:$B$517)>17)+($B$17<>"MKT_AO")>0)*(LEN($B$17:$B$517&$C$17:$C$517&$D$17:$D$517&$E$17:$E$517&$F$17:$F$517&$G$17:$G$517&$H$17:$H$517&$I$17:$I$517)>0)*(($B$17:$B$517="")+($C$17:$C$517="")+($E$17:$E$517="")+($F$17:$F$517="")+($H$17:$H$517="")+($I$17:$I$517="")))
A10: Confirmed by (BDOI owner) | D10: Date
A12: Mandatory | B12: Yes | C12: Yes | D12: No | E12: Yes | F12: Yes | G12: No | H12: Yes | I12: Yes
A13: Format | B13: Up to 40 capital letters, digits or _ | C13: Up to 120 characters | D13: Up to 500 characters | E13: Low, Standard, High or Admin | F13: Permission code of the User Access Matrix | G13: View only, Create, Amend, Approve / Validate | H13: KEEP, ADD or REMOVE | I13: Name
A14: Allowed values | B14: Free entry, up to 40 characters | C14: Free entry, up to 120 characters | D14: Free entry, up to 500 characters | E14: Low, Standard, High, Admin (list Privilege level) | F14: Free entry | G14: Free entry | H14: KEEP, ADD, REMOVE (list Change against the matrix) | I14: Free entry
A15: What to enter | B15: Code of the profile; an existing code changes the profile | C15: Name shown on screens | D15: What the profile is for | E15: High and Admin need a second approval when given or raised | F15: One row per permission of the profile | G15: As shown by the matrix, for the review | H15: Change against the matrix as delivered | I15: Unit head who confirms the row
A16: Row | B16: Group profile code * | C16: Name * | D16: Description | E16: Privilege level * | F16: Permission * | G16: Action class | H16: Keep / Add / Remove * | I16: Approved by unit head *
A17: Example – overwrite or delete | B17: MKT_AO | C17: Marketing Account Officer | D17: Marketing account officers of the Combank and Corbank units | E17: Standard | F17: QUOTE_MAINTAIN | G17: Create, Amend | H17: KEEP | I17: Carla Reyes

Sheet UA-06 Lists of values
A1: UA-06 Lists of values | G1: Step 6 of 31
A2: ← Back to Start here | B2: Step 6 of 31. Fill in one row per record below the column headers; the guide above each column says what to enter. | G2: Ask a question →
A3: Purpose | B3: The values of the lists of user access (business unit groups and user levels, empty as delivered; deactivation reasons, to confirm with BDOI; the reason No sign-in for the dormancy period is used by the dormant-user job and stays)
A4: Provided by | B4: Business Administration
A5: Due | B5: 1-Nov-2027 – before the templates that use its codes
A6: How it is loaded | B6: Lists of Values (New Business set) under maker-checker; before the users of CI-01 are loaded
A7: Source | B7: BDOI organisation (UQ05)
A8: Depends on | B8: Nothing: this template can be filled in first
A9: Progress | B9: Rows entered | C9: =SUMPRODUCT(((ROW($B$17:$B$517)>17)+($B$17<>"UAM_BUSINESS_UNIT")>0)*(LEN($B$17:$B$517&$C$17:$C$517&$D$17:$D$517&$E$17:$E$517&$F$17:$F$517)>0)) | D9: Mandatory cells missing | E9: =SUMPRODUCT(((ROW($B$17:$B$517)>17)+($B$17<>"UAM_BUSINESS_UNIT")>0)*(LEN($B$17:$B$517&$C$17:$C$517&$D$17:$D$517&$E$17:$E$517&$F$17:$F$517)>0)*(($B$17:$B$517="")+($C$17:$C$517="")+($D$17:$D$517="")+($F$17:$F$517="")))
A10: Confirmed by (BDOI owner) | D10: Date
A12: Mandatory | B12: Yes | C12: Yes | D12: Yes | E12: No | F12: Yes
A13: Format | B13: UAM_BUSINESS_UNIT, UAM_USER_LEVEL or UAM_DEACTIVATION_REASON | C13: Up to 30 capitals, digits or _ | D13: Up to 120 characters | E13: Whole number | F13: dd-MMM-yyyy
A14: Allowed values | B14: UAM_BUSINESS_UNIT, UAM_USER_LEVEL, UAM_DEACTIVATION_REASON (list User access list) | C14: Free entry, up to 30 characters | D14: Free entry, up to 120 characters | E14: A whole number | F14: A date, for example 15-Jan-2028
A15: What to enter | B15: The list | C15: Code of the value | D15: Label shown on screens | E15: Order in the drop-down | F15: Date the value may be used
A16: Row | B16: List * | C16: Code * | D16: Label * | E16: Sort order | F16: Effective from *
A17: Example – overwrite or delete | B17: UAM_BUSINESS_UNIT | C17: COMBANK_MKT | D17: Combank Marketing | E17: 10 | F17: 46391

Sheet D0-05 Employees
A1: D0-05 Employees | H1: Step 7 of 31
A2: ← Back to Start here | B2: Step 7 of 31. Fill in one row per record below the column headers; the guide above each column says what to enter. | H2: Ask a question →
A3: Purpose | B3: Employees used by the cost-centre rules, petty cash and staff advances
A4: Provided by | B4: Human Resources; Head, Comptrollership
A5: Due | B5: 16-Jul-2027 – Values for UAT
A6: How it is loaded | B6: Employees (Setup & Administration)
A7: Source | B7: HR employee list
A8: Depends on | B8: D0-02 Branches → | D8: D0-04 Cost centres and business lines →
A9: Progress | B9: Rows entered | C9: =SUMPRODUCT(((ROW($B$17:$B$517)>17)+($B$17<>"1203344")>0)*(LEN($B$17:$B$517&$C$17:$C$517&$D$17:$D$517&$E$17:$E$517&$F$17:$F$517&$G$17:$G$517&$H$17:$H$517)>0)) | D9: Mandatory cells missing | E9: =SUMPRODUCT(((ROW($B$17:$B$517)>17)+($B$17<>"1203344")>0)*(LEN($B$17:$B$517&$C$17:$C$517&$D$17:$D$517&$E$17:$E$517&$F$17:$F$517&$G$17:$G$517&$H$17:$H$517)>0)*(($B$17:$B$517="")+($C$17:$C$517="")+($D$17:$D$517="")+($E$17:$E$517="")))
A10: Confirmed by (BDOI owner) | D10: Date
A12: Mandatory | B12: Yes | C12: Yes | D12: Yes | E12: Yes | F12: No | G12: No | H12: No
A13: Format | B13: HR number | C13: Up to 120 characters | D13: Code of D0-02 | E13: Cost centre of D0-04 | F13: Text | G13: Company e-mail | H13: dd-MMM-yyyy
A14: Allowed values | B14: Free entry | C14: Free entry, up to 120 characters | D14: A code of D0-02 Branches, column Branch code | E14: A code of D0-04 Cost centres and business lines, column Code | F14: Free entry | G14: Free entry | H14: A date, for example 15-Jan-2028
A15: What to enter | B15: Unique | C15: Name of the employee | D15: Home branch | E15: Cost centre of the employee | F15: Position title | G15: For advices and statements | H15: Date of hire
A16: Row | B16: Employee number * | C16: Full name * | D16: Branch code * | E16: Cost centre * | F16: Position | G16: E-mail | H16: Hired on
A17: Example – overwrite or delete | B17: 1203344 | C17: Andrea Mercado | D17: HO | E17: FIN | F17: Accounting Officer | G17: andrea.mercado@bdoi.example.ph | H17: 43527

Sheet D0-06 Chart of accounts
A1: D0-06 Chart of accounts | Q1: Step 8 of 31
A2: ← Back to Start here | B2: Step 8 of 31. Fill in one row per record below the column headers; the guide above each column says what to enter. | Q2: Ask a question →
A3: Purpose | B3: The production chart of accounts, in the columns of the chart upload. List every parent before its children. Accounts are created pending authorization.
A4: Provided by | B4: Head, Comptrollership
A5: Due | B5: 4-Jan-2027 – Platform set-up for Drop 1 SIT
A6: How it is loaded | B6: Chart Upload (General Ledger): the file is checked row by row and every account is created pending authorisation by Comptrollership
A7: Source | B7: The BDOI chart of accounts in use, completed with the legacy control accounts (D0-09)
A8: Depends on | B8: D0-07 Account categories and numbering →
A9: Progress | B9: Rows entered | C9: =SUMPRODUCT(((ROW($C$17:$C$517)>17)+($C$17<>"1210.07")>0)*(LEN($B$17:$B$517&$C$17:$C$517&$D$17:$D$517&$E$17:$E$517&$F$17:$F$517&$G$17:$G$517&$H$17:$H$517&$I$17:$I$517&$J$17:$J$517&$K$17:$K$517&$L$17:$L$517&$M$17:$M$517&$N$17:$N$517&$O$17:$O$517&$P$17:$P$517&$Q$17:$Q$517)>0)) | D9: Mandatory cells missing | E9: =SUMPRODUCT(((ROW($C$17:$C$517)>17)+($C$17<>"1210.07")>0)*(LEN($B$17:$B$517&$C$17:$C$517&$D$17:$D$517&$E$17:$E$517&$F$17:$F$517&$G$17:$G$517&$H$17:$H$517&$I$17:$I$517&$J$17:$J$517&$K$17:$K$517&$L$17:$L$517&$M$17:$M$517&$N$17:$N$517&$O$17:$O$517&$P$17:$P$517&$Q$17:$Q$517)>0)*(($D$17:$D$517="")+($F$17:$F$517="")+($G$17:$G$517="")))
A10: Confirmed by (BDOI owner) | D10: Date
A12: Mandatory | B12: No | C12: No | D12: Yes | E12: No | F12: Yes | G12: Yes | H12: No | I12: No | J12: No | K12: No | L12: No | M12: No | N12: No | O12: No | P12: No | Q12: No
A13: Format | B13: Text | C13: Text | D13: Text | E13: Text | F13: Text | G13: Text | H13: Text | I13: Y or N | J13: Text | K13: Text | L13: Y or N | M13: Y or N | N13: Y or N | O13: Text | P13: yyyy-MM-dd | Q13: Text
A14: Allowed values | B14: A code of D0-06 Chart of accounts, column Account Code | C14: Free entry | D14: Free entry | E14: Free entry | F14: ASSET, LIABILITY, EQUITY, INCOME, EXPENSE, MEMORANDUM (list Account class of the chart) | G14: GROUP, MAIN, SUB, MICRO (list Account level) | H14: A code of D0-07 Account categories and numbering, column Category code | I14: Y or N | J14: Free entry | K14: Free entry | L14: Y or N | M14: Y or N | N14: Y or N | O14: Free entry | P14: Free entry | Q14: ALLOW, WARN, BLOCK (list Negative balance)
A15: What to enter | B15: Code of the parent account; blank for a top-level group | C15: Account code; blank for the next number of the parent's scheme | D15: Account name | E15: Unique short code used on journal lines | F15: Class of the account | G15: Level of the account, one tier below the parent | H15: GL category | I15: Control account | J15: Sub-ledger the account controls; blank for none | K15: Currencies allowed on the account; blank for all | L15: Manual journals allowed; blank for Y | M15: Cost centre mandatory on journal lines | N15: Revalued at month end | O15: Financial statement line | P15: Opening date; blank for today | Q15: What a negative balance does; blank for ALLOW
A16: Row | B16: Parent Code | C16: Account Code | D16: Account Name * | E16: Short Code | F16: Class * | G16: Level * | H16: Category | I16: Control Account | J16: Sub-ledger Type | K16: Currencies | L16: Manual Posting | M16: Cost Centre Required | N16: Revaluation Required | O16: Report Group | P16: Opened On | Q16: Negative Balance
A17: Example – overwrite or delete | C17: 1210.07 | D17: Premium Receivable - Motor | E17: PRMOTOR | F17: ASSET | G17: SUB | I17: N | J17: POLICYHOLDER | K17: {baseCurrency} | L17: Y | M17: N | N17: N | O17: Premium Receivable | P17: 2026-01-01 | Q17: WARN

Sheet PM-01 Product catalogue
A1: PM-01 Product catalogue | W1: Step 9 of 31
A2: ← Back to Start here | B2: Step 9 of 31. Fill in one row per record below the column headers; the guide above each column says what to enter. | W2: Ask a question →
A3: Purpose | B3: Product lines, cover types and subtypes, and every product (risk code) with its features
A4: Provided by | B4: Product Owner, Marketing Business System (MBS)
A5: Due | B5: 9-Apr-2027 – Reference data for Trial migration 1 (M4)
A6: How it is loaded | B6: Data migration object R05 (product lines, cover types, products) through the catalogue services, pending authorisation; after go-live on Products (SCR-PM-11)
A7: Source | B7: Legacy QPS and EBIX product lists, completed by MBS
A8: Depends on | B8: PM-09 Lists of values and parameters →
A9: Progress | B9: Rows entered | C9: =SUMPRODUCT(((ROW($B$17:$B$517)>17)+($B$17<>"MOTOR")>0)*(LEN($B$17:$B$517&$C$17:$C$517&$D$17:$D$517&$E$17:$E$517&$F$17:$F$517&$G$17:$G$517&$H$17:$H$517&$I$17:$I$517&$J$17:$J$517&$K$17:$K$517&$L$17:$L$517&$M$17:$M$517&$N$17:$N$517&$O$17:$O$517&$P$17:$P$517&$Q$17:$Q$517&$R$17:$R$517&$S$17:$S$517&$T$17:$T$517&$U$17:$U$517&$V$17:$V$517&$W$17:$W$517)>0)) | D9: Mandatory cells missing | E9: =SUMPRODUCT(((ROW($B$17:$B$517)>17)+($B$17<>"MOTOR")>0)*(LEN($B$17:$B$517&$C$17:$C$517&$D$17:$D$517&$E$17:$E$517&$F$17:$F$517&$G$17:$G$517&$H$17:$H$517&$I$17:$I$517&$J$17:$J$517&$K$17:$K$517&$L$17:$L$517&$M$17:$M$517&$N$17:$N$517&$O$17:$O$517&$P$17:$P$517&$Q$17:$Q$517&$R$17:$R$517&$S$17:$S$517&$T$17:$T$517&$U$17:$U$517&$V$17:$V$517&$W$17:$W$517)>0)*(($B$17:$B$517="")+($C$17:$C$517="")+($H$17:$H$517="")+($I$17:$I$517="")+($K$17:$K$517="")+($M$17:$M$517="")+($P$17:$P$517="")+($Q$17:$Q$517="")))
A10: Confirmed by (BDOI owner) | D10: Date
A12: Mandatory | B12: Yes | C12: Yes | D12: No | E12: Conditional: package products | F12: Conditional: with the code | G12: No | H12: Yes | I12: Yes | J12: No | K12: Yes | L12: No | M12: Yes | N12: No | O12: No | P12: Yes | Q12: Yes | R12: No | S12: No | T12: No | U12: No | V12: No | W12: No
A13: Format | B13: Up to 30 capitals | C13: Text | D13: Regular expression | E13: Up to 30 capitals | F13: Text | G13: Cover type code | H13: 1 to 20 capitals or digits | I13: Up to 200 characters | J13: Text | K13: Y or N | L13: Codes separated by commas; blank = all | M13: PAID or CLIENT_CONFIRMATION | N13: BY_RULES, ALWAYS or NEVER | O13: Up to four decimals | P13: Percentage | Q13: Amount in PHP | R13: Amount in PHP | S13: Y or N | T13: Y or N | U13: Y or N | V13: Y or N; 2 to 10 years | W13: Y or N
A14: Allowed values | B14: Free entry, up to 30 characters | C14: Free entry | D14: Free entry | E14: Free entry, up to 30 characters | F14: Free entry | G14: A code of PM-01 Product catalogue, column Cover type code | H14: Free entry, up to 20 characters | I14: Free entry, up to 200 characters | J14: Free entry | K14: Y or N | L14: One or more codes of the list Market segment (Reference lists), separated by commas | M14: PAID, CLIENT_CONFIRMATION (list Placement after) | N14: BY_RULES, ALWAYS, NEVER (list TSU review) | O14: A number from 0 to 100 | P14: A number from 0 to 100 | Q14: A number | R14: A number | S14: Y or N | T14: Y or N | U14: Y or N | V14: Free entry | W14: Y or N
A15: What to enter | B15: Product line (level 1), for example MOTOR, PROPERTY | C15: Name shown in the drop-downs | D15: Naming convention of the risk codes of the line, when BDOI states one | E15: Cover type (level 2) of the line | F15: Name of the cover type | G15: Only for a subtype (one level below a cover type) | H15: Product code (level 3); unique | I15: Name shown to users | J15: Code of the product in QPS or EBIX, for the migration map | K15: Y for a package product (terms change through versions) | L15: Segments the product is offered to (list MARKET_SEGMENT) | M15: Payment gate before placement | N15: When TSU reviews an account of the product | O15: Rate of a non-package product; for a package, of version 1 | P15: Commission when no insurer rate applies | Q15: Minimum premium of the product | R15: Above it the account goes to TSU | S15: Several vehicles on one account | T15: Mortgage or loan related | U15: Premium may be paid directly to the insurer | V15: Multi-year term and its maximum | W15: Free First Year eligible
A16: Row | B16: Line code * | C16: Line name * | D16: Risk-code pattern | E16: Cover type code | F16: Cover type name | G16: Parent cover type | H16: Risk code * | I16: Product name * | J16: Legacy code | K16: Package * | L16: Market segments | M16: Placement after * | N16: TSU review | O16: Default rate % | P16: Default commission % * | Q16: Minimum premium * | R16: Package TSI limit | S16: Fleet | T16: Mortgage related | U16: Direct payment allowed | V16: Multi-year / Maximum term | W16: Free First Year
A17: Example – overwrite or delete | B17: MOTOR | C17: Motor | D17: MTR[0-9]{2} | E17: COMPREHENSIVE | F17: Comprehensive | H17: MTR30 | I17: Motor Fleet Plus | J17: QPS-MFP | K17: Y | L17: COMBANK | M17: PAID | N17: BY_RULES | O17: 1.2 | P17: 15 | Q17: 5000 | R17: 5000000 | S17: Y | T17: N | U17: N | V17: N | W17: N

Sheet UA-01 Users and roles
A1: UA-01 Users and roles load | L1: Step 10 of 31
A2: ← Back to Start here | B2: Step 10 of 31. Fill in one row per record below the column headers; the guide above each column says what to enter. | L2: Ask a question →
A3: Purpose | B3: Every BIBS user at go-live with the user data and the group profiles, in the columns of the Bulk Request template
A4: Provided by | B4: Business Administration, with the unit heads who name their users
A5: Due | B5: 1-Nov-2027 – Production values before the dress rehearsal
A6: How it is loaded | B6: Bulk Request (SCR-UA-09): the file of this template is uploaded as a bulk batch, checked row by row and approved by an approver like single requests; users are out of the data migration scope (DMQ30)
A7: Source | B7: The users of the legacy systems and the unit rosters; the HR list of employees for the full names and e-mails
A8: Depends on | B8: UA-06 Lists of values → | D8: UA-02 Role-to-permission matrix →
A9: Progress | B9: Rows entered | C9: =SUMPRODUCT(((ROW($B$17:$B$517)>17)+($B$17<>"ENROL")>0)*(LEN($B$17:$B$517&$C$17:$C$517&$D$17:$D$517&$E$17:$E$517&$F$17:$F$517&$G$17:$G$517&$H$17:$H$517&$I$17:$I$517&$J$17:$J$517&$K$17:$K$517&$L$17:$L$517)>0)) | D9: Mandatory cells missing | E9: =SUMPRODUCT(((ROW($B$17:$B$517)>17)+($B$17<>"ENROL")>0)*(LEN($B$17:$B$517&$C$17:$C$517&$D$17:$D$517&$E$17:$E$517&$F$17:$F$517&$G$17:$G$517&$H$17:$H$517&$I$17:$I$517&$J$17:$J$517&$K$17:$K$517&$L$17:$L$517)>0)*(($B$17:$B$517="")+($C$17:$C$517="")+($L$17:$L$517="")))
A10: Confirmed by (BDOI owner) | D10: Date
A12: Mandatory | B12: Yes | C12: Yes | D12: Conditional: ENROL | E12: No | F12: No | G12: No | H12: No | I12: No | J12: Conditional: ENROL | K12: No | L12: Yes
A13: Format | B13: ENROL, MODIFY, DEACTIVATE or REACTIVATE | C13: A letter and nine digits (BDOI format a999999999) | D13: Up to 120 characters | E13: Company e-mail address | F13: Windows log-on name; unique | G13: Branch code | H13: Code of the list Business unit group (CI-06) | I13: Code of the list User level (CI-06) | J13: Profile codes of CI-02 separated by ';' | K13: yyyy-MM-dd; blank = on approval | L13: Up to 1,000 characters
A14: Allowed values | B14: ENROL, MODIFY, DEACTIVATE, REACTIVATE (list Bulk request action) | C14: Free entry, up to 10 characters | D14: Free entry, up to 120 characters | E14: Free entry | F14: Free entry | G14: Free entry | H14: Codes of UA-06 Lists of values, column Code (one or more) | I14: Codes of UA-06 Lists of values, column Code (one or more) | J14: Codes of UA-02 Role-to-permission matrix, column Group profile code (one or more) | K14: Free entry | L14: Free entry, up to 1000 characters
A15: What to enter | B15: ENROL for the go-live load | C15: The BIBS user ID; unique | D15: Name shown on screens and reports | E15: Receives the access-changed notices and the reset links | F15: Used for the BDO directory sign-in when it is enabled | G15: Home branch of the user | H15: Business unit group | I15: User level | J15: The group profiles of the user | K15: Date the change applies | L15: Justification of the line
A16: Row | B16: Action * | C16: User ID * | D16: Full Name | E16: E-mail | F16: Windows ID | G16: Home Branch Code | H16: Business Unit | I16: User Level | J16: Group Profiles | K16: Effective Date | L16: Remarks *
A17: Example – overwrite or delete | B17: ENROL | C17: a013000201 | D17: Andrea Mercado | E17: andrea.mercado@brokerverse-seed.ph | F17: AMERCADO | G17: HO | J17: MKT_AO | L17: Joined Marketing

Sheet D0-03 Holiday calendar
A1: D0-03 Holiday calendar | G1: Step 11 of 31
A2: ← Back to Start here | B2: Step 11 of 31. Fill in one row per record below the column headers; the guide above each column says what to enter. | G2: Ask a question →
A3: Purpose | B3: Public and company holidays of 2027 and 2028
A4: Provided by | B4: Head, Comptrollership; Human Resources
A5: Due | B5: 4-Jan-2027 – Platform set-up for Drop 1 SIT
A6: How it is loaded | B6: Holiday Calendar (Setup & Administration); 2028 before the dress rehearsal, later years each December
A7: Source | B7: Proclamations of the national holidays; BDOI company holidays
A8: Depends on | B8: D0-02 Branches →
A9: Progress | B9: Rows entered | C9: =SUMPRODUCT(((ROW($D$17:$D$517)>17)+($D$17<>"New Year's Day")>0)*(LEN($B$17:$B$517&$C$17:$C$517&$D$17:$D$517)>0)) | D9: Mandatory cells missing | E9: =SUMPRODUCT(((ROW($D$17:$D$517)>17)+($D$17<>"New Year's Day")>0)*(LEN($B$17:$B$517&$C$17:$C$517&$D$17:$D$517)>0)*(($C$17:$C$517="")+($D$17:$D$517="")))
A10: Confirmed by (BDOI owner) | D10: Date
A12: Mandatory | B12: No | C12: Yes | D12: Yes
A13: Format | B13: Code of D0-02; blank = every branch | C13: dd-MMM-yyyy | D13: Up to 120 characters
A14: Allowed values | B14: A code of D0-02 Branches, column Branch code | C14: A date, for example 15-Jan-2028 | D14: Free entry, up to 120 characters
A15: What to enter | B15: Branch the holiday applies to | C15: Date of the holiday | D15: Name of the holiday
A16: Row | B16: Branch code | C16: Date * | D16: Description *
A17: Example – overwrite or delete | C17: 46753 | D17: New Year's Day

Sheet UA-04 SoD rules
A1: UA-04 Separation-of-duties rules | H1: Step 12 of 31
A2: ← Back to Start here | B2: Step 12 of 31. Fill in one row per record below the column headers; the guide above each column says what to enter. | H2: Ask a question →
A3: Purpose | B3: The rules BIBS enforces, for confirmation, and the combinations of profiles or permissions that BDOI Information Security does not allow one user to hold
A4: Provided by | B4: BDOI Information Security
A5: Due | B5: 16-Jul-2027 – Values for UAT
A6: How it is loaded | B6: The rules marked Enforced are fixed in BIBS; the privileged profiles are set by the privilege level of CI-02. Each combination of two profiles is entered on Separation of Duties (SCR-UA-19) by the Business Administrator and authorised by Information Security; BIBS then refuses every request and bulk line that breaks it. A combination of permissions is reviewed with the reports
A7: Source | B7: BDOI information security policy; the separation-of-duties rules of FRS chapter 13
A8: Depends on | B8: UA-02 Role-to-permission matrix →
A9: Progress | B9: Rows entered | C9: =SUMPRODUCT(((ROW($B$17:$B$517)>17)+($B$17<>"SOD-01")>0)*(LEN($B$17:$B$517&$C$17:$C$517&$D$17:$D$517&$E$17:$E$517&$F$17:$F$517&$G$17:$G$517&$H$17:$H$517)>0)) | D9: Mandatory cells missing | E9: =SUMPRODUCT(((ROW($B$17:$B$517)>17)+($B$17<>"SOD-01")>0)*(LEN($B$17:$B$517&$C$17:$C$517&$D$17:$D$517&$E$17:$E$517&$F$17:$F$517&$G$17:$G$517&$H$17:$H$517)>0)*(($B$17:$B$517="")+($C$17:$C$517="")+($D$17:$D$517="")+($G$17:$G$517="")))
A10: Confirmed by (BDOI owner) | D10: Date
A12: Mandatory | B12: Yes | C12: Yes | D12: Yes | E12: Conditional: combination rule | F12: Conditional: combination rule | G12: Yes | H12: Conditional: Detect by review
A13: Format | B13: SOD-nn | C13: Text | D13: Enforced, To confirm, New | E13: Profile or permission of CI-02 | F13: Profile or permission of CI-02 | G13: Prevent (a rule of Separation of Duties, for two profiles), Detect by review, Second approval | H13: Monthly, Quarterly
A14: Allowed values | B14: Free entry | C14: Free entry | D14: Enforced, To confirm, New (list Separation-of-duties rule status) | E14: Codes of UA-02 Role-to-permission matrix, column Group profile code (one or more) | F14: Codes of UA-02 Role-to-permission matrix, column Group profile code (one or more) | G14: Prevent, Detect by review, Second approval (list Separation-of-duties control) | H14: Monthly, Quarterly (list Review frequency)
A15: What to enter | B15: Identifier of the rule | C15: The rule | D15: Enforced = a fixed rule of BIBS | E15: First profile or permission of a combination | F15: Profile or permission that may not be held with A | G15: How the rule is controlled | H15: How often the reports are reviewed
A16: Row | B16: Rule ID * | C16: Rule * | D16: Status * | E16: Profile or permission A | F16: Profile or permission B | G16: Control * | H16: Review frequency
A17: Example – overwrite or delete | B17: SOD-01 | C17: The requester never decides his own request | D17: Enforced | E17: User Access Requestor | F17: User Access Approver | G17: Prevent | H17: Quarterly

Sheet D0-11 Bank accounts
A1: D0-11 Company bank accounts | J1: Step 13 of 31
A2: ← Back to Start here | B2: Step 13 of 31. Fill in one row per record below the column headers; the guide above each column says what to enter. | J2: Ask a question →
A3: Purpose | B3: The bank accounts of BDOI used for collections and disbursements
A4: Provided by | B4: Head, Comptrollership; Treasury
A5: Due | B5: 4-Jan-2027 – Platform set-up for Drop 1 SIT
A6: How it is loaded | B6: Bank Accounts and Checks (Disbursement), authorised by Comptrollership
A7: Source | B7: BDOI bank account list
A8: Depends on | B8: D0-06 Chart of accounts → | D8: D0-02 Branches →
A9: Progress | B9: Rows entered | C9: =SUMPRODUCT(((ROW($B$17:$B$517)>17)+($B$17<>"BDO-CA-001")>0)*(LEN($B$17:$B$517&$C$17:$C$517&$D$17:$D$517&$E$17:$E$517&$F$17:$F$517&$G$17:$G$517&$H$17:$H$517&$I$17:$I$517&$J$17:$J$517)>0)) | D9: Mandatory cells missing | E9: =SUMPRODUCT(((ROW($B$17:$B$517)>17)+($B$17<>"BDO-CA-001")>0)*(LEN($B$17:$B$517&$C$17:$C$517&$D$17:$D$517&$E$17:$E$517&$F$17:$F$517&$G$17:$G$517&$H$17:$H$517&$I$17:$I$517&$J$17:$J$517)>0)*(($B$17:$B$517="")+($C$17:$C$517="")+($D$17:$D$517="")+($E$17:$E$517="")+($F$17:$F$517="")+($G$17:$G$517="")+($J$17:$J$517="")))
A10: Confirmed by (BDOI owner) | D10: Date
A12: Mandatory | B12: Yes | C12: Yes | D12: Yes | E12: Yes | F12: Yes | G12: Yes | H12: No | I12: No | J12: Yes
A13: Format | B13: Up to 20 capitals | C13: Text | D13: Bank name | E13: As printed by the bank | F13: ISO 4217 | G13: Account of D0-06 with a bank category | H13: Account of D0-06 | I13: Code of D0-02 | J13: Format of the bank advice
A14: Allowed values | B14: Free entry, up to 20 characters | C14: Free entry | D14: Free entry | E14: Free entry | F14: Free entry, up to 3 characters | G14: A code of D0-06 Chart of accounts, column Account Code | H14: A code of D0-06 Chart of accounts, column Account Code | I14: A code of D0-02 Branches, column Branch code | J14: Free entry
A15: What to enter | B15: Code of the account in BIBS | C15: Name shown on screens | D15: Bank of the account | E15: Account number | F15: Currency of the account | G15: Cash-in-bank account | H15: Account of issued post-dated checks | I15: Branch that uses the account | J15: Format of the notification to the payee
A16: Row | B16: Bank account code * | C16: Name * | D16: Bank * | E16: Account number * | F16: Currency * | G16: GL account * | H16: PDC clearing account | I16: Branch code | J16: Payment notification format *
A17: Example – overwrite or delete | B17: BDO-CA-001 | C17: BDO Makati current account | D17: BDO Unibank, Inc. | E17: 000123456789 | F17: PHP | G17: 1110.01 | H17: 2241 | I17: HO | J17: EMAIL

Sheet PM-02 Coverages and rules
A1: PM-02 Coverages, perils and field rules | J1: Step 14 of 31
A2: ← Back to Start here | B2: Step 14 of 31. Fill in one row per record below the column headers; the guide above each column says what to enter. | J2: Ask a question →
A3: Purpose | B3: The coverage and peril level of each line, and the fields and documents each product needs on an account
A4: Provided by | B4: MBS
A5: Due | B5: 16-Jul-2027 – Values for UAT
A6: How it is loaded | B6: Entered on Coverages & Clauses (SCR-PM-15) and on the rule tabs of Products (SCR-PM-11, SCR-PM-12) before UAT; not migrated
A7: Source | B7: MBS and TSU (product matrix, PQ02)
A8: Depends on | B8: PM-09 Lists of values and parameters → | D8: PM-01 Product catalogue →
A9: Progress | B9: Rows entered | C9: =SUMPRODUCT(((ROW($B$17:$B$517)>17)+($B$17<>"COVERAGE")>0)*(LEN($B$17:$B$517&$C$17:$C$517&$D$17:$D$517&$E$17:$E$517&$F$17:$F$517&$G$17:$G$517&$H$17:$H$517&$I$17:$I$517&$J$17:$J$517)>0)) | D9: Mandatory cells missing | E9: =SUMPRODUCT(((ROW($B$17:$B$517)>17)+($B$17<>"COVERAGE")>0)*(LEN($B$17:$B$517&$C$17:$C$517&$D$17:$D$517&$E$17:$E$517&$F$17:$F$517&$G$17:$G$517&$H$17:$H$517&$I$17:$I$517&$J$17:$J$517)>0)*(($B$17:$B$517="")+($C$17:$C$517="")+($D$17:$D$517="")+($E$17:$E$517="")+($F$17:$F$517="")+($J$17:$J$517="")))
A10: Confirmed by (BDOI owner) | D10: Date
A12: Mandatory | B12: Yes | C12: Yes | D12: Yes | E12: Yes | F12: Yes | G12: Conditional: coverage | H12: Conditional: list, range or format rules | I12: Conditional: document rule | J12: Yes
A13: Format | B13: COVERAGE, FIELD_RULE or DOCUMENT_RULE | C13: Line or product the row applies to; * = every product | D13: A-Z, 0-9 and _ (coverage); field key (rule) | E13: Text | F13: Coverage kind (Section, Coverage, Peril, Extension); check (Presence, List of values, Number range, Format) | G13: Y or N | H13: List code; minimum and maximum; pattern | I13: List DOCUMENT_TYPE | J13: Y or N
A14: Allowed values | B14: COVERAGE, FIELD_RULE, DOCUMENT_RULE (list Coverage and rule record) | C14: Codes of PM-01 Product catalogue, column Risk code (one or more) | D14: Free entry | E14: Free entry | F14: Free entry | G14: Y or N | H14: Free entry | I14: List Document type: 63 values, see Reference lists | J14: Y or N
A15: What to enter | B15: What the row defines | C15: Scope of the row | D15: Coverage code or the account field checked | E15: Coverage name or field label | F15: Coverage kind or rule check | G15: A package needs at least one basic coverage | H15: Parameters of the check | I15: Document an account needs before submission | J15: Required or optional
A16: Row | B16: Record * | C16: Line code / Risk code * | D16: Code or field key * | E16: Name or label * | F16: Kind or check * | G16: Basic | H16: Parameters | I16: Document type | J16: Mandatory *
A17: Example – overwrite or delete | B17: COVERAGE | C17: MOTOR | D17: OD_THEFT | E17: Own damage and theft | F17: Coverage | G17: Y | J17: Y

Sheet PM-03 Clause library
A1: PM-03 Clause library | G1: Step 15 of 31
A2: ← Back to Start here | B2: Step 15 of 31. Fill in one row per record below the column headers; the guide above each column says what to enter. | G2: Ask a question →
A3: Purpose | B3: Warranties, clauses, exclusions and deductible wordings used in the insurer terms of package versions
A4: Provided by | B4: TSU (wordings); MBS (maintenance)
A5: Due | B5: 16-Jul-2027 – Values for UAT
A6: How it is loaded | B6: Entered on Coverages & Clauses › Clause Library (SCR-PM-15); not migrated
A7: Source | B7: Current package slips and insurer wordings
A8: Depends on | B8: PM-09 Lists of values and parameters → | D8: PM-01 Product catalogue →
A9: Progress | B9: Rows entered | C9: =SUMPRODUCT(((ROW($B$17:$B$517)>17)+($B$17<>"FLEET_REPAIR")>0)*(LEN($B$17:$B$517&$C$17:$C$517&$D$17:$D$517&$E$17:$E$517&$F$17:$F$517&$G$17:$G$517)>0)) | D9: Mandatory cells missing | E9: =SUMPRODUCT(((ROW($B$17:$B$517)>17)+($B$17<>"FLEET_REPAIR")>0)*(LEN($B$17:$B$517&$C$17:$C$517&$D$17:$D$517&$E$17:$E$517&$F$17:$F$517&$G$17:$G$517)>0)*(($B$17:$B$517="")+($C$17:$C$517="")+($E$17:$E$517="")+($F$17:$F$517="")+($G$17:$G$517="")))
A10: Confirmed by (BDOI owner) | D10: Date
A12: Mandatory | B12: Yes | C12: Yes | D12: No | E12: Yes | F12: Yes | G12: Yes (from)
A13: Format | B13: A-Z, 0-9 and _ | C13: WARRANTY, CLAUSE, EXCLUSION or DEDUCTIBLE_WORDING | D13: Line code; blank = every line | E13: Text | F13: Full text | G13: dd-MMM-yyyy
A14: Allowed values | B14: Free entry | C14: WARRANTY, CLAUSE, EXCLUSION, DEDUCTIBLE_WORDING (list Clause kind) | D14: A code of PM-01 Product catalogue, column Line code | E14: Free entry | F14: Free entry | G14: Free entry
