Workbook
Name DayRate: Assumptions!$B$7
Name Accuracy: Assumptions!$B$6

Sheet Cover
B6: CHANGE REQUESTS - EFFORT
B7: CR Effort Estimate
B8: BRD-11 User Access Maintenance - change requests of the FRS v1.4 with their effort
B9: BIBS – BDOI Broker System
B11: Client | C11: BDO Insurance and Reinsurance Brokers, Inc.
B12: BRD | C12: BRD-11
B13: Version | C13: 1.0
B14: Date | C14: 11 October 2026
B15: Classification | C15: Confidential
B16: Prepared by | C16: iorta TechNXT
B18: Sheets
B19: Sheet | C19: Content | D19: Rows
B20: README | C20: What each column of each sheet means, with the allowed values
B21: Summary | C21: Totals of the change requests of BRD-11 (FRS v1.4, Annex AA.2); figures by formula | D21: 13
B22: CR Effort | C22: One row per change request (orange point of the FRS v1.4); man-days of 8 hours, +-20% | D22: 9
B23: Beyond the BRD - OOTB | C23: Points of the FRS v1.4 that no BRD asks for and the iNXT BrokerVerse OOTB platform offers (green): no cost | D23: 5
B24: BRD items to deliver | C24: BRD requirements not (fully) in the iNXT BrokerVerse OOTB platform (FRS Annex X.2, AA.4): in-scope delivery work, for planning | D24: 15
B25: Integration & Data Migration | C25: Covered by the Integration and Data Migration scope (grey label in the FRS, Annex AA.5): no change request, no cost here | D25: 6
B26: Best practice (blue) | C26: Insurance-broking best practices in no BRD, not in the FRS and not in OOTB (blue, FRS Annex AA.6): recommendations, not commitments | D26: 7
B27: Assumptions | C27: Assumptions of the estimate; enter the day rate in the yellow cell | D27: 8
B29: Legend
B30: Change request | C30: In no BRD and not (or only partly) in the iNXT BrokerVerse OOTB platform (orange in the FRS); also when already available in BIBS
B31: Offered by OOTB | C31: Not in the BRD; offered by the iNXT BrokerVerse OOTB platform (brokerverse-platform), no cost (green in the FRS)
B32: Integration / Data Migration scope | C32: Interfaces and data migration: covered by those workstreams, not a change request (grey label)
B33: Best practice | C33: In no BRD, FRS or OOTB: recommendation with indicative effort, excluded from the CR total (blue)
B34: BRD requirement | C34: In scope; delivered without a change request (black in the FRS)
B37: Prepared by iorta TechNXT for BDOI. Confidential – BDOI.

Sheet README
A1: README – columns of each sheet
A2: CR Effort Estimate, version 1.0. Drop-down columns accept only the listed values.
A4: Sheet | B4: Column | C4: Meaning | D4: Allowed values
A5: Summary | B5: Item | C5: Change request or group
A6: Summary | B6: Man-days | C6: Total effort (8-hour days)
A7: Summary | B7: Low (-20%) | C7: Lower end of the range
A8: Summary | B8: High (+20%) | C8: Upper end of the range
A9: Summary | B9: Cost | C9: Man-days x day rate (sheet Assumptions)
A10: Summary | B10: Note
A11: CR Effort | B11: CR No. | C11: Change request number (Change Request Register)
A12: CR Effort | B12: Title
A13: CR Effort | B13: FRS reference | C13: FR item or annex of the FRS v1.4
A14: CR Effort | B14: BRD reference | C14: 'Not in BRD' for every change request
A15: CR Effort | B15: Source | C15: BDOI FRS / best practice / iorta TechNXT
A16: CR Effort | B16: Why needed
A17: CR Effort | B17: OOTB status | C17: What the iNXT BrokerVerse OOTB platform offers (brokerverse-platform)
A18: CR Effort | B18: Scope of the change
A19: CR Effort | B19: Analysis and design | C19: Man-days
A20: CR Effort | B20: Backend | C20: Man-days
A21: CR Effort | B21: Frontend | C21: Man-days
A22: CR Effort | B22: Testing | C22: Man-days
A23: CR Effort | B23: Documentation and UAT support | C23: Man-days
A24: CR Effort | B24: Total man-days | C24: Formula
A25: CR Effort | B25: Low (-20%) | C25: Formula
A26: CR Effort | B26: High (+20%) | C26: Formula
A27: CR Effort | B27: Complexity | D27: Low, Medium, High
A28: CR Effort | B28: Priority | D28: High, Medium, Low
A29: CR Effort | B29: Dependencies
A30: CR Effort | B30: Assumptions
A31: CR Effort | B31: Cost | C31: Total man-days x day rate
A32: CR Effort | B32: Feature List ID / OOTB status | C32: Row of the Feature List vs OOTB workbook (column OOTB platform)
A33: CR Effort | B33: OOTB evidence | C33: Screen or function of the OOTB platform, or not found
A34: CR Effort | B34: Already in BIBS? | C34: Already available for BDOI in the BIBS system; the effort is still the CR value
A35: Beyond the BRD - OOTB | B35: No. | C35: OB-UA-nn
A36: Beyond the BRD - OOTB | B36: Point
A37: Beyond the BRD - OOTB | B37: FRS reference
A38: Beyond the BRD - OOTB | B38: BRD reference
A39: Beyond the BRD - OOTB | B39: What BDOI gets
A40: Beyond the BRD - OOTB | B40: OOTB status
A41: Beyond the BRD - OOTB | B41: Cost (man-days) | C41: No change request
...

Sheet Summary
A1: Summary
A2: Totals of the change requests of BRD-11 (FRS v1.4, Annex AA.2); figures by formula
A4: Item | B4: Man-days | C4: Low (-20%) | D4: High (+20%) | E4: Cost | F4: Note
A5: CR-UA-003 Break-glass administrators | B5: ='CR Effort'!N5 | C5: ='CR Effort'!O5 | D5: ='CR Effort'!P5 | E5: ='CR Effort'!U5 | F5: High priority; Medium complexity
A6: CR-UA-007 Supervisory and record-ownership access | B6: ='CR Effort'!N6 | C6: ='CR Effort'!O6 | D6: ='CR Effort'!P6 | E6: ='CR Effort'!U6 | F6: Medium priority; High complexity
A7: CR-UA-008 No conflicting permissions inside a group profile | B7: ='CR Effort'!N7 | C7: ='CR Effort'!O7 | D7: ='CR Effort'!P7 | E7: ='CR Effort'!U7 | F7: Medium priority; Low complexity
A8: CR-UA-009 Export file names | B8: ='CR Effort'!N8 | C8: ='CR Effort'!O8 | D8: ='CR Effort'!P8 | E8: ='CR Effort'!U8 | F8: Low priority; Low complexity
A9: CR-UA-011 Approval times, reminders and escalation | B9: ='CR Effort'!N9 | C9: ='CR Effort'!O9 | D9: ='CR Effort'!P9 | E9: ='CR Effort'!U9 | F9: Medium priority; Medium complexity
A10: CR-UA-013 E-mail copy of the request notices | B10: ='CR Effort'!N10 | C10: ='CR Effort'!O10 | D10: ='CR Effort'!P10 | E10: ='CR Effort'!U10 | F10: Medium priority; Low complexity
A11: CR-UA-014 Temporary access with an end date | B11: ='CR Effort'!N11 | C11: ='CR Effort'!O11 | D11: ='CR Effort'!P11 | E11: ='CR Effort'!U11 | F11: Low priority; Medium complexity
A12: CR-UA-016 Emergency role edit | B12: ='CR Effort'!N12 | C12: ='CR Effort'!O12 | D12: ='CR Effort'!P12 | E12: ='CR Effort'!U12 | F12: Medium priority; Medium complexity
A13: Total of the 8 change requests | B13: =SUM(B5:B12) | C13: =SUM(C5:C12) | D13: =SUM(D5:D12) | E13: =IF(DayRate="","",SUM(E5:E12)) | F13: Cost appears when the day rate is entered on the sheet Assumptions
A14: Points beyond the BRD offered by iNXT BrokerVerse OOTB (5) | B14: 0 | C14: 0 | D14: 0 | E14: 0 | F14: No change request, no cost (sheet Beyond the BRD - OOTB)
A15: BRD requirements to deliver (15, in scope) | B15: =SUM('BRD items to deliver'!I5:I19) | E15: Not charged | F15: For planning only (FRS Annex AA.4)
A16: Integration and Data Migration scope (6) | E16: Not here | F16: Covered by the Integration and Data Migration workstreams (FRS Annex AA.5)
A17: Best-practice recommendations (6, blue) | B17: =SUM('Best practice (blue)'!E5:E10) | E17: Indicative | F17: Excluded from the CR total (FRS Annex AA.6)

Sheet CR Effort
A1: CR Effort
A2: One row per change request (orange point of the FRS v1.4); man-days of 8 hours, +-20%
A4: CR No. | B4: Title | C4: FRS reference | D4: BRD reference | E4: Source | F4: Why needed | G4: OOTB status | H4: Scope of the change | I4: Analysis and design | J4: Backend | K4: Frontend | L4: Testing | M4: Documentation and UAT support | N4: Total man-days | O4: Low (-20%) | P4: High (+20%) | Q4: Complexity | R4: Priority | S4: Dependencies | T4: Assumptions | U4: Cost | V4: Feature List ID / OOTB status | W4: OOTB evidence | X4: Already in BIBS?
A5: CR-UA-003 | B5: Break-glass administrators | C5: FRUM.001.06; Annex N.4, Annex Q.5 | D5: Not in BRD | E5: Best practice (iorta TechNXT) | F5: BDOI's FRS signs every user in through EIAM; two named administrator accounts must still get in when EIAM is down, with each such sign-in alerted to Information Security. The OOTB platform has local accounts only and no break-glass accounts or alert. | G5: Not offered: no feature row; the OOTB platform has local accounts with a second factor (UAM-007) but no break-glass accounts kept beside the Enterprise SSO and no sign-in alert. | H5: Two named System Administrator accounts with a local password and second factor while every other user signs in through EIAM; the sign-in method recorded; a notice and e-mail to Information Security at each break-glass sign-in; the setting of the alert addresses. | I5: 1 | J5: 2 | K5: 1 | L5: 1.5 | M5: 0.5 | N5: =SUM(I5:M5) | O5: =ROUND(N5*(1-Accuracy),1) | P5: =ROUND(N5*(1+Accuracy),1) | Q5: Medium | R5: High | S5: Sign-in through EIAM (IS-UA-03, Integration scope). | T5: Uses the second factor of the OOTB platform (UAM-007). | U5: =IF(DayRate="","",N5*DayRate) | V5: No feature row (related UAM-007 two-factor authentication: Available) | W5: Not found: no break-glass account or break-glass sign-in alert in the OOTB sign-in | X5: Yes
A6: CR-UA-007 | B6: Supervisory and record-ownership access | C6: FRUM.001.02 (b), FRUM.005.01; Annex Q (C15) | D6: Not in BRD | E6: BDOI FRS v1.1 | F6: BDOI's FRS asks that a user with a supervisory role sees and manages the records of the personnel assigned to him or her, with record-ownership rules per role. The OOTB platform limits scoped roles to their own records and clients (UAM-017 Partial); it has no scope by branch or unit, no supervisor-to-personnel link and no record-owner rule per role. | G6: Partial (UAM-017): scoped roles see only their own records and clients. Missing, and estimated here: scope by company, branch and unit, the supervisor link and the record-owner rule per role. | H6: Data scope by company, branch and unit on the user and the group profile; supervisor (reports-to) on the user record and in the access requests; data scope "own records", "own and assigned personnel" and "unit" per group profile; the rule applied to the lists, records, documents and reports of every module; audit of the scope changes; screens of the user and the group profile. | I6: 3.5 | J6: 12 | K6: 4 | L6: 6 | M6: 2 | N6: =SUM(I6:M6) | O6: =ROUND(N6*(1-Accuracy),1) | P6: =ROUND(N6*(1+Accuracy),1) | Q6: High | R6: Medium | S6: BDOI to name the supervisory roles and the record owner of each module (User Access Matrix, Annex C); module FRS of each BRD for the records concerned. | T6: Effort for the missing part only (the own-records scope of the OOTB platform is reused); the personnel of a supervisor come from the user record (or UIDM-ISC), not from a separate organisation chart. | U6: =IF(DayRate="","",N6*DayRate) | V6: UAM-017 Data-scope restriction: Partial | W6: Partial: own-records scope of scoped roles and the reporting line on the user; no branch or unit scope, no supervisor rule | X6: Partly (data scope by company and branch; no supervisor link)
A7: CR-UA-008 | B7: No conflicting permissions inside a group profile | C7: FRUM.006.03 | D7: Not in BRD | E7: BDOI FRS v1.1 | F7: BDOI's FRS asks that a group profile cannot hold two permissions that conflict. The OOTB platform checks pairs of roles held by one user (separation-of-duties rules); it has no rule on pairs of permissions inside a role. | G7: Partial: rules on pairs of roles (checked at role assignment). Missing, and estimated here: rules on pairs of permissions, checked when a group profile is changed and when a user is given access. | H7: Rules on pairs of permissions kept by the Business Administrator; check on every group profile change and access request; message naming the conflict; audit. | I7: 0.5 | J7: 2 | K7: 1 | L7: 1 | M7: 0.25 | N7: =SUM(I7:M7) | O7: =ROUND(N7*(1-Accuracy),1) | P7: =ROUND(N7*(1+Accuracy),1) | Q7: Low | R7: Medium | S7: BRD items BRD-UA-07 and BRD-UA-09 (rights by function, group profile requests). | T7: Effort for the permission pairs only; the role-pair rules of the OOTB platform are reused. | U7: =IF(DayRate="","",N7*DayRate) | V7: UAM-018 Segregation of duties rules: Available (pairs of roles only) | W7: Partial: Access Control > Separation-of-duties rules on pairs of roles; no rule on pairs of permissions | X7: Yes
A8: CR-UA-009 | B8: Export file names | C8: FRUM.007.02; Annex V | D8: Not in BRD | E8: BDOI FRS v1.1 | F8: BDOI's FRS names the exports <Report name>_MMDDYYYY and Audit Logs_MMDDYYYY. In the OOTB platform the file names are fixed per report (RPT-009 Not available). | G8: Not offered: RPT-009 Not available (file names fixed per report). | H8: File names of the User Access reports and of the audit log export by BDOI's convention, as a setting; test of every export. | I8: 0.25 | J8: 1 | K8: 0.25 | L8: 0.5 | M8: 0.25 | N8: =SUM(I8:M8) | O8: =ROUND(N8*(1-Accuracy),1) | P8: =ROUND(N8*(1+Accuracy),1) | Q8: Low | R8: Low | S8: - | T8: The convention of the access reports only; the naming of the other modules' reports is in their own FRS. | U8: =IF(DayRate="","",N8*DayRate) | V8: RPT-009 Report file naming conventions: Not available | W8: Not found: export file names fixed per report (Reports) | X8: Yes
A9: CR-UA-011 | B9: Approval times, reminders and escalation | C9: Annex S (time rules), Annex Q.5, Annex Z | D9: Not in BRD | E9: Best practice (iorta TechNXT) | F9: The BRD sets no service level for the approval of access requests. A reminder and an escalation after a number of working days keep requests from waiting unseen. The OOTB platform has deadlines and escalation for claims, complaints, leads and collections only, and no access requests (WFL-007 Partial). | G9: Partial (WFL-007): deadlines and escalation exist in other modules, not for access requests. Missing, and estimated here: the time rules, reminder and escalation of access requests. | H9: Settings for the working days per stage, the reminder day and the escalation role; a daily run that sends the reminder notice and escalates overdue requests to the Business Administrator; the overdue marker on the lists; audit of each reminder and escalation. | I9: 1 | J9: 3 | K9: 1 | L9: 2 | M9: 1 | N9: =SUM(I9:M9) | O9: =ROUND(N9*(1-Accuracy),1) | P9: =ROUND(N9*(1+Accuracy),1) | Q9: Medium | R9: Medium | S9: BRD item BRD-UA-08 (access requests); working-day calendar of the OOTB platform (ADM-008). | T9: Reminders use the notices and e-mails of Annex T; one escalation level. | U9: =IF(DayRate="","",N9*DayRate) | V9: WFL-007 Turnaround-time tracking and escalation: Partial (UAM-019 access requests: Not available) | W9: Not found for access requests: escalation only in the AML and user screens; no access request flow | X9: No
A10: CR-UA-013 | B10: E-mail copy of the request notices | C10: FRUM.013.01; Annex T | D10: Not in BRD | E10: Best practice (iorta TechNXT) | F10: BDOI's FRS asks that the notices to approve, returned and decided are also e-mailed, by the user's preference. The OOTB platform sends in-system notices for access-control events (UAM-027 Partial); it has e-mail templates (WFL-011) but no e-mail copy of the access notices. | G10: Partial (UAM-027): in-system notices only. Missing, and estimated here: the e-mail copy and the user's preference. | H10: E-mail copy of the request notices (to approve, returned, decided) from templates, by the user's preference (setting); the outbox status; tests. | I10: 0.5 | J10: 1.5 | K10: 0.5 | L10: 1 | M10: 0.25 | N10: =SUM(I10:M10) | O10: =ROUND(N10*(1-Accuracy),1) | P10: =ROUND(N10*(1+Accuracy),1) | Q10: Low | R10: Medium | S10: BRD item BRD-UA-14 (notices of the access requests). | T10: Effort for the e-mail copy only; uses the e-mail templates and outbox of the OOTB platform (WFL-011). | U10: =IF(DayRate="","",N10*DayRate) | V10: UAM-027 Notices of access changes: Partial | W10: Partial: in-system access-control notices and the e-mail outbox; no e-mail copy of access notices | X10: Yes
A11: CR-UA-014 | B11: Temporary access with an end date | C11: Annex Z (CLR-UA-06, CLR-UA-13); FRUM.009.10 | D11: Not in BRD (BRD NFR 1.k asks for an effective date only) | E11: Best practice (iorta TechNXT) | F11: Access given for a project or a leave cover should end by itself. The OOTB platform applies changes at once, with no effective or end date (UAM-024 Not available); the effective date is a BRD requirement (Annex AA.4). | G11: Not offered: UAM-024 Not available (no effective or end date). The effective date is in scope as BRD item BRD-UA-11; this CR is the end date only. | H11: End date on the user requests and the bulk template; validation (after the effective date); the end date on the user's group profiles and in the reports; the daily run removes the access on the end date with a notice a number of days before; audit of each removal. | I11: 1.5 | J11: 4 | K11: 2.5 | L11: 2.5 | M11: 1 | N11: =SUM(I11:M11) | O11: =ROUND(N11*(1-Accuracy),1) | P11: =ROUND(N11*(1+Accuracy),1) | Q11: Medium | R11: Low | S11: BRD item BRD-UA-11 (effective dates); answers to CLR-UA-06 and CLR-UA-13 (Annex Z). | T11: The removal is a scheduled change of the daily run of BRD-UA-11, checked again as the other scheduled changes. | U11: =IF(DayRate="","",N11*DayRate) | V11: UAM-024 Effective-dated access changes: Not available | W11: Not found: no effective or end date on role assignment | X11: No
A12: CR-UA-016 | B12: Emergency role edit | C12: FRUM.005.01; Annex J | D12: Not in BRD | E12: Best practice (iorta TechNXT) | F12: With group profiles changed only by approved requests, an emergency path lets the System Administrator edit users and group profiles directly, when Information Security opens it, with every edit audited and alerted. The OOTB platform has no request flow and no emergency edit; the feature list has no row for it. | G12: Not offered: no feature row; in the OOTB platform roles are edited directly with no request, so no controlled emergency path exists. | H12: The emergency role edit setting, opened by Information Security; the direct edit of users and group profiles by the System Administrator while it is open, closed as delivered; every edit audited and alerted to Information Security; the marker on the screens. | I12: 1 | J12: 2.5 | K12: 1 | L12: 1.5 | M12: 0.5 | N12: =SUM(I12:M12) | O12: =ROUND(N12*(1-Accuracy),1) | P12: =ROUND(N12*(1+Accuracy),1) | Q12: Medium | R12: Medium | S12: BRD items BRD-UA-09 and BRD-UA-13 (group profile requests, second approval of security settings). | T12: Alerts use the notices and e-mails of Annex T. | U12: =IF(DayRate="","",N12*DayRate) | V12: No feature row (UAM-022 group profile requests: Not available) | W12: Not found: roles edited directly, no emergency path | X12: Yes
A13: Total | B13: 8 change requests | I13: =SUM(I5:I12) | J13: =SUM(J5:J12) | K13: =SUM(K5:K12) | L13: =SUM(L5:L12) | M13: =SUM(M5:M12) | N13: =SUM(N5:N12) | O13: =SUM(O5:O12) | P13: =SUM(P5:P12) | U13: =IF(DayRate="","",SUM(U5:U12))

Sheet Beyond the BRD - OOTB
A1: Beyond the BRD - OOTB
A2: Points of the FRS v1.4 that no BRD asks for and the iNXT BrokerVerse OOTB platform offers (green): no cost
A4: No. | B4: Point | C4: FRS reference | D4: BRD reference | E4: What BDOI gets | F4: OOTB status | G4: Cost (man-days) | H4: Note | I4: Feature List ID / OOTB status | J4: OOTB evidence
A5: OB-UA-01 | B5: Separation-of-duties rules | C5: FRUM.012.01; Annex M.6 | D5: Not in BRD | E5: Pairs of group profiles one user may not hold (block or warn), kept by the Business Administrator; checked on every assignment. | F5: Offered by OOTB | G5: 0 | H5: Extends the segregation-of-duties principle of the Operations addendum; was CR-UA-001 | I5: UAM-018 Segregation of duties rules: Available | J5: Access Control > Separation-of-duties rules (pairs of roles, block or warn, checked at assignment)
A6: OB-UA-02 | B6: Dormant-user deactivation | C6: FRUM.003.04; Annex V | D6: Not in BRD | E6: Users without a sign-in for 90 days deactivated by the daily run (setting Dormant days). | F6: Offered by OOTB | G6: 0 | H6: Was CR-UA-002; the notice 7 days before is a detail BDOI confirms | I6: UAM-028 Dormant account deactivation: Available | J6: Daily run Dormant accounts (setting Dormant days, 90)
A7: OB-UA-03 | B7: Second factor of the local accounts | C7: FRUM-004; Annex M.4 | D7: Not in BRD | E7: Authenticator code at sign-in, compulsory per role, and reset of a lost authenticator by an administrator. | F7: Offered by OOTB | G7: 0 | H7: - | I7: UAM-007 Two-factor authentication: Available | J7: Sign-in with authenticator code; two-factor per role on the user screen
A8: OB-UA-04 | B8: Business settings without a release | C8: Annex M.10 | D8: Not in BRD | E8: Parameters applied at once and audited, so a point where BDOI's FRS and the BRD differ is chosen by a setting without a release. | F8: Offered by OOTB | G8: 0 | H8: The options themselves follow the colour of their own point | I8: ADM-011 Business parameters without a release: Available | J8: Settings screen: parameters applied at once and audited
A9: OB-UA-05 | B9: Periodic access review and scheduled reports | C9: Annex V, Annex Q.5 (UA-Q51) | D9: Not in BRD | E9: Recertification campaigns over every active user (revoke deactivates the account) and report schedules with recipients, so the monthly access review reaches Information Security. | F9: Offered by OOTB | G9: 0 | H9: Was CR-UA-012 | I9: UAM-030 Periodic access entitlement review: Available; RPT-007 User-scheduled reports: Available | J9: Access Control > Access Reviews; Reports > Schedules (recipients, format, timing)

Sheet BRD items to deliver
A1: BRD items to deliver
A2: BRD requirements not (fully) in the iNXT BrokerVerse OOTB platform (FRS Annex X.2, AA.4): in-scope delivery work, for planning
A4: No. | B4: Item | C4: BRD reference | D4: FRS reference | E4: What is delivered | F4: Analysis and design | G4: Backend and frontend | H4: Testing and UAT support | I4: Total man-days | J4: Cost | K4: Feature List ID / OOTB status | L4: OOTB evidence | M4: Already in BIBS?
A5: BRD-UA-01 | B5: One session per device | C5: Collections addendum NFR 10.07 | D5: FRUM.001.01; Annex M.5 | E5: A sign-in on another device ends the user's earlier session, with the reason in the session log and a message on the earlier device. | F5: 0.5 | G5: 3 | H5: 1.5 | I5: =SUM(F5:H5) | J5: Not charged | K5: UAM-005: Not available | L5: Not found (several sessions per user) | M5: No
A6: BRD-UA-02 | B6: Administrator passwords of 12 characters | C6: Collections addendum NFR 2.04 | D6: FRUM-004; Annex M.4 | E6: Minimum length 12 for the accounts with administrator privileges, 8 or more for any other local account; as a setting. | F6: 0.25 | G6: 0.75 | H6: 0.5 | I6: =SUM(F6:H6) | J6: Not charged | K6: UAM-008: Available (one minimum length only) | L6: Password policy: one minimum length | M6: No
A7: BRD-UA-03 | B7: Inactivity warning at 15 minutes | C7: UAM BRD x.001.1.2, x.001.1.3; Collections addendum NFR 10.01 | D7: FRUM.001.03, FRUM.001.04; Annex M.5 | E7: A warning after 15 minutes of inactivity with Stay Logged In and Log Out, besides the sign-out after 30 minutes; both times settings (BDOI confirms 15 or 30 minutes). | F7: 0.25 | G7: 1.5 | H7: 0.75 | I7: =SUM(F7:H7) | J7: Not charged | K7: UAM-003: Partial | L7: Partial: idle sign-out with one-minute warning | M7: Yes
A8: BRD-UA-05 | B8: Windows ID, business unit group, user level and user ID rule on the user record | C8: UAM BRD NFR 13, 15; Collections addendum NFR 2.09 | D8: FRUM.002.03; Annex M | E8: The fields of the BRD on the user record, screens and reports; the user ID pattern as a setting. | F8: 0.5 | G8: 3.5 | H8: 1.5 | I8: =SUM(F8:H8) | J8: Not charged | K8: UAM-012: Partial | L8: Partial: users table without Windows ID, BU group, user level | M8: Yes
A9: BRD-UA-07 | B9: Add, amend, delete and task-level rights per group profile | C9: UAM BRD 4.002.2 to 4.002.2.10; report sample B | D9: FRUM.006; Annex C | E9: Rights by function (view, add, amend, delete, approve and the tasks of the BRD) per module and group profile, in the screens, the checks and the Group Profile Access Report. | F9: 1 | G9: 6 | H9: 2.5 | I9: =SUM(F9:H9) | J9: Not charged | K9: UAM-015: Partial | L9: Partial: read / write / approve per module | M9: Yes
A10: BRD-UA-08 | B10: Access request lifecycle with approval and automatic provisioning | C10: UAM BRD 1.002 to 1.008, 2.002 (approver chosen by the requester; approve, reject or return) | D10: FRUM.002, FRUM.003, FRUM.009, FRUM.010 | E10: Requests to enrol, modify, deactivate and reactivate with draft, cancel and submit; the approver chosen by the requester; approve, reject or return with remarks; the access applied on approval; request history and lists. | F10: 4 | G10: 24 | H10: 11 | I10: =SUM(F10:H10) | J10: Not charged | K10: UAM-019, UAM-020, UAM-021: Not available | L10: Not found (no access requests) | M10: Yes
A11: BRD-UA-09 | B11: Group profile requests approved in sequence and implemented | C11: UAM BRD 3.002.1 to 3.002.4 | D11: FRUM.005, FRUM.011 | E11: Requests to create or change a group profile approved by the approvers in order and implemented by the System Administrator. | F11: 2 | G11: 10 | H11: 5 | I11: =SUM(F11:H11) | J11: Not charged | K11: UAM-022: Not available | L11: Not found (roles edited directly) | M11: Yes
A12: BRD-UA-10 | B12: Bulk access requests with approval | C12: UAM BRD 1.009; NFR 38 | D12: FRUM.002.04; Annex M | E12: The bulk template raised as a request, checked row by row with an error file and decided by the approver as a whole (the bulk load of the OOTB platform is reused). | F12: 0.5 | G12: 5 | H12: 2 | I12: =SUM(F12:H12) | J12: Not charged | K12: UAM-023: Partial | L12: Partial: bulk user load by the System Administrator | M12: Yes
A13: BRD-UA-11 | B13: Effective-dated access changes | C13: UAM BRD NFR 14 (1.k) | D13: FRUM.009.10; Annex Z | E13: An effective date on the requests; a daily run applies the scheduled changes, checked again on the day. | F13: 1 | G13: 4.5 | H13: 2.5 | I13: =SUM(F13:H13) | J13: Not charged | K13: UAM-024: Not available | L13: Not found | M13: Yes
A14: BRD-UA-12 | B14: Escalation of privileged or out-of-hours changes | C14: UAM BRD NFR 40 (Other BU NFR 11) | D14: FRUM.010.02; Annex S | E14: Privilege level on the group profiles and the working-hours rule; a second approval of the privileged or out-of-hours changes. | F14: 1 | G14: 4 | H14: 2.5 | I14: =SUM(F14:H14) | J14: Not charged | K14: UAM-025: Not available | L14: Not found | M14: Yes
A15: BRD-UA-13 | B15: Second approval of security settings | C15: UAM BRD NFR 16, NFR 40 | D15: FRUM.012.02; Annex M | E15: A change of a sign-in, password, session or access setting applies only after the approval of Information Security (in the OOTB platform these settings apply at once). | F15: 0.5 | G15: 4 | H15: 2 | I15: =SUM(F15:H15) | J15: Not charged | K15: UAM-026: Partial | L15: Partial: settings apply at once (audited) | M15: Yes
A16: BRD-UA-14 | B16: Notices of the access requests to the requester and the user | C16: UAM BRD 1.006.1.1, 1.008.1.4, 2.002.1; NFR 39 | D16: FRUM.013; Annex T | E16: In-system notices of each request step (to approve, returned, decided, implemented) to the requester, the approver and the affected user. | F16: 0.5 | G16: 2.5 | H16: 1.5 | I16: =SUM(F16:H16) | J16: Not charged | K16: UAM-027: Partial | L16: Partial: in-app access-control notices | M16: Yes
... A19: BRD-UA-17 | B19: Access from BDO devices only | C19: UAM BRD 1.001.1, 2.001.1, 3.001.1, 4.001.1 | D19: FRUM.001.01; Technical Specification | E19: Access limited to BDO's network and devices: network zone and IP rules of the OOTB platform, plus the device check BDOI IT chooses. | F19: 0.5 | G19: 2.5 | H19: 1.5 | I19: =SUM(F19:H19) | J19: Not charged | K19: UAM-033: Partial | L19: Partial: network / IP rules outside the application | M19: Partly (network and IP rules)

Sheet Integration & Data Migration
A1: Integration & Data Migration
A2: Covered by the Integration and Data Migration scope (grey label in the FRS, Annex AA.5): no change request, no cost here
A4: No. | B4: Point | C4: FRS reference | D4: Scope | E4: Workstream | F4: Feature List ID / OOTB status | G4: Note | H4: Cost
A5: IS-UA-01 | B5: Synchronisation with UIDM-ISC and EIAM (joiner, mover, leaver, rehire; Synchronise Now) | C5: FRUM.002.02, FRUM.003.03; Annex N.3 | D5: Events approved in UIDM-ISC applied with the UIDM request number; refused events queued and alerted. | E5: Integration | F5: UAM-011: Not available | G5: Was CR-UA-005 | H5: Not a CR
A6: IS-UA-02 | B6: Revocation on an SSO status change | C6: FRUM.003.02.01; Annex N | D6: A leaver, or an SSO account inactive, locked or disabled, deactivates the user and ends the open sessions. | E6: Integration | F6: UAM-011: Not available | G6: Was CR-UA-006 | H6: Not a CR
A7: IS-UA-03 | B7: Sign-in through Microsoft Entra ID / EIAM with the Windows ID | C7: FRUM.001.02; Annex N | D7: Single sign-on of every user (BRD UAM-NFR 11, 17, 33; CLXN NFR 1.01): a BRD requirement delivered by the Integration workstream. | E7: Integration | F7: UAM-011: Not available | G7: Was BRD item to deliver | H7: Not a CR
A8: IS-UA-04 | B8: External access-control list interface | C8: Annex W | D8: Interface with the access-control list of the system BDOI names (BRD UAM-NFR 12; UQ14). | E8: Integration | F8: UAM-013: Not available | G8: BRD requirement | H8: Not a CR
A9: IS-UA-05 | B9: EIAM and UIDM-ISC simulator for SIT and UAT | C9: Annex N | D9: Sign-in and identity events simulated in the test environments until BDOI IT connects the real services. | E9: Integration | F9: No feature row | G9: - | H9: Not a CR
A10: DM-UA-01 | B10: Users and group profiles at go-live | C10: Annex W (BRD-13 Data Migration) | D10: Users and their group profiles loaded before go-live and at the dress rehearsal (users are not migrated from the legacy systems; loaded by bulk request). | E10: Data Migration (BRD-13) | F10: MIG-014 Users migration: Available | G10: - | H10: Not a CR

Sheet Best practice (blue)
A1: Best practice (blue)
A2: Insurance-broking best practices in no BRD, not in the FRS and not in OOTB (blue, FRS Annex AA.6): recommendations, not commitments
A4: ID | B4: Practice | C4: Why it matters for a broker | D4: Suggested priority | E4: Indicative man-days
A5: BP-UA-01 | B5: Monitoring of privileged sessions | C5: System Administrator and break-glass sessions logged in detail (screens opened, data exported) and reviewed by Information Security; expected by the IC and by the BDO group's IT risk rules for privileged access to client and policy data. | D5: High | E5: 8
A6: BP-UA-02 | B6: Alert on unusual sign-in | C6: Sign-in at an unusual hour, from a new device or network, or many failures across users raised to Information Security; early sign of account takeover of client personal data (Data Privacy Act, NPC breach rules). | D6: Medium | E6: 6
A7: BP-UA-03 | B7: Log of views of sensitive records | C7: Who viewed (not only changed) the records of PEP, high-risk and claims clients; supports AMLA confidentiality and Data Privacy Act accountability. | D7: Medium | E7: 6
A8: BP-UA-04 | B8: Joiner-mover-leaver timeliness report | C8: Time from the UIDM-ISC approval to access given or removed, and leavers still active; evidence for internal audit that leavers lose access the same day. | D8: Medium | E8: 4
A9: BP-UA-05 | B9: Separation-of-duties what-if check | C9: Before a request is submitted the requester sees which separation-of-duties rules the new access would break, so conflicts are fixed before approval. | D9: Low | E9: 4
A10: BP-UA-06 | B10: Generic and shared account register | C10: Every non-personal account (service, interface, training) with an owner, purpose and review date; a common audit finding in Philippine financial institutions. | D10: Low | E10: 3
A11: Total | B11: 6 recommendations (indicative, excluded from the CR total) | E11: =SUM(E5:E10)

Sheet Assumptions
A1: Assumptions
A2: Assumptions of the estimate; enter the day rate in the yellow cell
A4: Assumption | B4: Value | C4: Note
A5: Man-day | B5: 8 | C5: Hours of work in one man-day
A6: Accuracy of the estimates | B6: 0.2 | C6: Plus or minus; the Low and High columns use it
A7: Day rate | C7: Enter the rate of one man-day (currency below); the costs are computed from it
A8: Currency | C8: For example PHP
A9: Basis | C9: Sized against the iNXT BrokerVerse OOTB platform (repo BDOI-OOTB, branch brokerverse-platform, checked in its code with the Feature List vs OOTB as a cross-check), not against the BIBS system configured for BDOI: a point OOTB offers is not a change request; for a partial point only the missing part is estimated; a change request already available in BIBS (column Already in BIBS?) keeps its effort as the CR value; interfaces and data migration are not change requests (sheet Integration & Data Migration); best practice is indicative and excluded (sheet Best practice (blue)) (sheet Beyond the BRD - OOTB).
A10: Activities | C10: Analysis and design (FRS update, rules), backend, frontend (screens), testing (test cases of the RTM, regression of the access functions), documentation and UAT support.
A11: Not included | C11: Work of BDOI and BDOI IT (decisions, identity systems, infrastructure), data migration, training beyond the UAT support.
A12: Validity | C12: Until the sign-off of the FRS v1.4; re-estimated when the decision of BDOI changes the scope of a change request.

Sheet Lists
A1: Complexity | B1: Priority
A2: Low | B2: High
A3: Medium | B3: Medium
A4: High | B4: Low
