Workbook
Name CODES_CI_01_COVER_TYPE_CODE: 'CI-01 Product catalogue'!$E$17:$E$517
Name CODES_CI_01_LINE_CODE: 'CI-01 Product catalogue'!$B$17:$B$517
Name CODES_CI_01_RISK_CODE: 'CI-01 Product catalogue'!$H$17:$H$517
Name CODES_CI_05_PARTNER_CODE: 'CI-05 Insurers'!$B$17:$B$517
Name LIST_YES_NO: 'Reference lists'!$C$5:$C$6
Name LIST_MARKET_SEGMENT: 'Reference lists'!$C$7:$C$11
Name LIST_PLACEMENT_GATE: 'Reference lists'!$C$12:$C$13
Name LIST_TSU_REVIEW: 'Reference lists'!$C$14:$C$16
Name LIST_CI02_RECORD: 'Reference lists'!$C$17:$C$19
Name LIST_DOCUMENT_TYPE: 'Reference lists'!$C$20:$C$80
Name LIST_CLAUSE_KIND: 'Reference lists'!$C$81:$C$84
Name LIST_RATE_TABLE: 'Reference lists'!$C$85:$C$87
Name LIST_MAP_ACTION: 'Reference lists'!$C$88:$C$89
Name LIST_PKG_DOCUMENT: 'Reference lists'!$C$90:$C$95
Name LIST_PM_LIST_OR_PARAMETER: 'Reference lists'!$C$96:$C$118
Name LIST_INCENTIVE_TYPE: 'Reference lists'!$C$119:$C$120
Name LIST_TEMPLATES: 'Reference lists'!$C$121:$C$131
Name LIST_QUESTION_STATUS: 'Reference lists'!$C$132:$C$134
Name LIST_STATUS: 'Reference lists'!$C$135:$C$138

Sheet Start here
A3: Configuration Input Templates BRD-3 Product Maintenance
A4: What the business provides to set up Product Maintenance and to load it at go-live
A6: Client | C6: BDO Insurance and Reinsurance Brokers, Inc.
A7: Release set | C7: BRD-3 Product Maintenance (Drop 0, Setup and Data Migration)
A8: Version and date | C8: Version 2.0, 27 September 2026
A9: Owner | C9: Product Owner, Marketing Business System (MBS)
A10: Due | C10: Drafts with the sign-off of this set; final content at the data migration map freeze (T-7)
A11: Prepared by | C11: iorta TechNXT
A12: Classification | C12: Confidential
A14: How to fill in this workbook
A15: 1 | B15: Follow the steps of the index below in their order: a template whose codes other templates use comes first, so that the drop-downs of the later templates offer the codes already entered.
A16: 2 | B16: On each template sheet, read the header block (purpose, who provides it, due date, how it is loaded, what it depends on) and the guide above each column: Mandatory, Format, Allowed values and What to enter. Columns marked * are mandatory; point at a column header for its full description.
A17: 3 | B17: Overwrite or delete the grey example row, then enter one row per record under it. Drop-downs offer the allowed values (sheet Reference lists) and the codes of the templates filled in before; a mandatory cell left empty in a row turns red.
A18: 4 | B18: Follow Rows entered and Mandatory cells missing in the index, set the Status of each template and record on the template sheet who confirmed it and when. Raise questions on the sheet Questions and comments.
A19: 5 | B19: Return the workbook to the iorta TechNXT project team by the due dates. Templates loaded by the data migration follow its mocks and the map freeze; the others are entered on the screens and authorised by a second user.
A21: Templates in the order they are filled in
A22: Step | B22: ID | C22: Template | D22: What it holds | E22: Provided by | F22: Due | G22: How it is loaded | H22: Depends on | I22: Rows entered | J22: Mandatory cells missing | K22: Status | L22: Open
A23: 1 | B23: CI-09 | C23: Lists of values and parameters | D23: The values of the Product Maintenance lists (request reasons, response outcomes, advisory groups, not-proceeded reasons, incentive types, coverage kinds, clause kinds, document types, market segments) and the parameters (numbering, reply days, expiry notice, advisory groups, service levels) | E23: Product Owner, MBS; System Administrator (entry) | F23: 16-Jul-2027 – Values for UAT | G23: Data migration object R01 for the values used by migrated records; the other values on Lists of Values and System Parameters | H23: - | I23: ='CI-09 Lists and parameters'!$C$9 | J23: ='CI-09 Lists and parameters'!$E$9 | K23: Not started | L23: Open →
A24: 2 | B24: CI-01 | C24: Product catalogue | D24: Product lines, cover types and subtypes, and every product (risk code) with its features | E24: Product Owner, Marketing Business System (MBS) | F24: 9-Apr-2027 – Reference data for Trial migration 1 (M4) | G24: Data migration object R05 (product lines, cover types, products) through the catalogue services, pending authorisation; after go-live on Products (SCR-PM-11) | H24: CI-09 | I24: ='CI-01 Product catalogue'!$C$9 | J24: ='CI-01 Product catalogue'!$E$9 | K24: Not started | L24: Open →
A25: 3 | B25: CI-02 | C25: Coverages, perils and field rules | D25: The coverage and peril level of each line, and the fields and documents each product needs on an account | E25: MBS | F25: 16-Jul-2027 – Values for UAT | G25: Entered on Coverages & Clauses (SCR-PM-15) and on the rule tabs of Products (SCR-PM-11, SCR-PM-12) before UAT; not migrated | H25: CI-09, CI-01 | I25: ='CI-02 Coverages and rules'!$C$9 | J25: ='CI-02 Coverages and rules'!$E$9 | K25: Not started | L25: Open →
A26: 4 | B26: CI-03 | C26: Clause library | D26: Warranties, clauses, exclusions and deductible wordings used in the insurer terms of package versions | E26: TSU (wordings); MBS (maintenance) | F26: 16-Jul-2027 – Values for UAT | G26: Entered on Coverages & Clauses › Clause Library (SCR-PM-15); not migrated | H26: CI-09, CI-01 | I26: ='CI-03 Clause library'!$C$9 | J26: ='CI-03 Clause library'!$E$9 | K26: Not started | L26: Open →
A27: 5 | B27: CI-05 | C27: Insurers, branches and commission rates | D27: The insurer panel with accreditation and placement e-mails, the branches with their LGT rate, and the commission rates per product | E27: Head of Operations; MBS (commission per package) | F27: 9-Apr-2027 – Reference data for Trial migration 1 (M4) | G27: Data migration objects R04 (insurers, branches, business partners) and R07 (commission rates); after go-live on Insurers (SCR-PM-17, SCR-PM-18) | H27: CI-01 | I27: ='CI-05 Insurers'!$C$9 | J27: ='CI-05 Insurers'!$E$9 | K27: Not started | L27: Open →
A28: 6 | B28: CI-04 | C28: Rate tables | D28: Statutory charges and rating factors, the short-period table and the motor BI / PD limit premiums | E28: Product Owner, MBS; Comptrollership (taxes) | F28: 16-Jul-2027 – Values for UAT | G28: Entered on Rates & Taxes (SCR-PM-19), pending authorisation; not migrated (effective-dated from go-live) | H28: CI-01 | I28: ='CI-04 Rate tables'!$C$9 | J28: ='CI-04 Rate tables'!$E$9 | K28: Not started | L28: Open →
A29: 7 | B29: CI-10 | C29: Incentive criteria | D29: The incentive criteria (for example CPC2) with their value, the products matrix and the effective dates | E29: Incentive Maintenance user (MBS); Comptrollership (CPC2 definition, PQ04) | F29: 16-Jul-2027 – Values for UAT | G29: Entered on Incentive Criteria (SCR-PM-16), pending authorisation; the copied booking rules are reviewed there | H29: CI-09, CI-01 | I29: ='CI-10 Incentive criteria'!$C$9 | J29: ='CI-10 Incentive criteria'!$E$9 | K29: Not started | L29: Open →
A30: 8 | B30: CI-06 | C30: Packages in force at go-live | D30: For every package sold at go-live: its terms as they will be set up in BIBS through a package request (TSU) and a package version (MBS): rate scheme, dates, coverages, panel insurers and their terms | E30: TSU (prepares); Product Owner, MBS (approves) | F30: 1-Nov-2027 – Production values before the dress rehearsal | G30: Not migrated: TSU raises a package request per package (type New package, or Update for an existing risk code) and MBS sets up and validates the version before the map freeze; the Package Request Form accepts the same fields | H30: CI-01, CI-02, CI-05, CI-03 | I30: ='CI-06 Packages'!$C$9 | J30: ='CI-06 Packages'!$E$9 | K30: Not started | L30: Open →
A31: 9 | B31: CI-07 | C31: Package map (legacy package to BIBS package version) | D31: Entries from each legacy package and version to the BIBS package version that renews it, with qualifiers where one legacy package splits; read at Renewal sanitation (check PACKAGE_REMAP) | E31: TSU (prepares); Product Owner, MBS (approves each map version) | F31: 18-Jun-2027 – Code maps approved (M5) | G31: Data migration object R06 (loaded as reference data and handed to the Renewal package map); new map versions until the map freeze (T-7), then maintained in Renewal | H31: CI-01, CI-05, CI-06 | I31: ='CI-07 Package map'!$C$9 | J31: ='CI-07 Package map'!$E$9 | K31: Not started | L31: Open →
A32: 10 | B32: CI-08 | C32: Document templates | D32: The texts of the package documents: Package Request Form, quotation slip, comparative table, package slip, package advisory and package renewal advisory, with the merge fields each may use | E32: TSU and MBS (texts); Business Administrator (maintenance) | F32: 16-Jul-2027 – Values for UAT | G32: Entered on Document Templates (New Business set, SCR-NB-44) as a new template version effective from a date; not migrated | H32: - | I32: ='CI-08 Document templates'!$C$9 | J32: ='CI-08 Document templates'!$E$9 | K32: Not started | L32: Open →
A34: Other sheets
A35: Sheet | D35: What it holds
A36: Reference lists | D36: Every list of allowed values of the drop-downs, with code and label
A37: Questions and comments | D37: Questions and comments per template and column, with the answer
A39: Prepared by iorta TechNXT for BDOI. Confidential – BDOI.

Sheet CI-09 Lists and parameters
A1: CI-09 Lists of values and parameters | G1: Step 1 of 10
A2: ← Back to Start here | B2: Step 1 of 10. Fill in one row per record below the column headers; the guide above each column says what to enter. | G2: Ask a question →
A3: Purpose | B3: The values of the Product Maintenance lists (request reasons, response outcomes, advisory groups, not-proceeded reasons, incentive types, coverage kinds, clause kinds, document types, market segments) and the parameters (numbering, reply days, expiry notice, advisory groups, service levels)
A4: Provided by | B4: Product Owner, MBS; System Administrator (entry)
A5: Due | B5: 16-Jul-2027 – Values for UAT
A6: How it is loaded | B6: Data migration object R01 for the values used by migrated records; the other values on Lists of Values and System Parameters
A7: Source | B7: Delivered values (FRS chapter 9) confirmed or changed by BDOI
A8: Depends on | B8: Nothing: this template can be filled in first
A9: Progress | B9: Rows entered | C9: =SUMPRODUCT(((ROW($B$17:$B$517)>17)+($B$17<>"PKG_REQUEST_REASON")>0)*(LEN($B$17:$B$517&$C$17:$C$517&$D$17:$D$517&$E$17:$E$517&$F$17:$F$517)>0)) | D9: Mandatory cells missing | E9: =SUMPRODUCT(((ROW($B$17:$B$517)>17)+($B$17<>"PKG_REQUEST_REASON")>0)*(LEN($B$17:$B$517&$C$17:$C$517&$D$17:$D$517&$E$17:$E$517&$F$17:$F$517)>0)*(($B$17:$B$517="")+($D$17:$D$517="")))
A10: Confirmed by (BDOI owner) | D10: Date
A12: Mandatory | B12: Yes | C12: Conditional: list | D12: Yes | E12: No | F12: No
A13: Format | B13: Code of the list or parameter | C13: Up to 40 capitals | D13: Text; number for a parameter | E13: Number; Y or N | F13: dd-MMM-yyyy
A14: Allowed values | B14: List Product Maintenance list or parameter: 23 values, see Reference lists | C14: Free entry, up to 40 characters | D14: Free entry | E14: Free entry | F14: A date, for example 15-Jan-2028
A15: What to enter | B15: For example PKG_REQUEST_REASON, PKG_SLA_NEGOTIATION | C15: Code of the value | D15: Label shown to users, or the parameter value | E15: Display order and status | F15: From when the value applies
A16: Row | B16: List or parameter * | C16: Value code | D16: Label or value * | E16: Order / Active | F16: Effective from
A17: Example – overwrite or delete | B17: PKG_REQUEST_REASON | C17: LOSS_EXPERIENCE | D17: Loss experience | E17: 50; Y | F17: 46327

Sheet CI-01 Product catalogue
A1: CI-01 Product catalogue | W1: Step 2 of 10
A2: ← Back to Start here | B2: Step 2 of 10. Fill in one row per record below the column headers; the guide above each column says what to enter. | W2: Ask a question →
A3: Purpose | B3: Product lines, cover types and subtypes, and every product (risk code) with its features
A4: Provided by | B4: Product Owner, Marketing Business System (MBS)
A5: Due | B5: 9-Apr-2027 – Reference data for Trial migration 1 (M4)
A6: How it is loaded | B6: Data migration object R05 (product lines, cover types, products) through the catalogue services, pending authorisation; after go-live on Products (SCR-PM-11)
A7: Source | B7: Legacy QPS and EBIX product lists, completed by MBS
A8: Depends on | B8: CI-09 Lists of values and parameters →
A9: Progress | B9: Rows entered | C9: =SUMPRODUCT(((ROW($B$17:$B$517)>17)+($B$17<>"MOTOR")>0)*(LEN($B$17:$B$517&$C$17:$C$517&$D$17:$D$517&$E$17:$E$517&$F$17:$F$517&$G$17:$G$517&$H$17:$H$517&$I$17:$I$517&$J$17:$J$517&$K$17:$K$517&$L$17:$L$517&$M$17:$M$517&$N$17:$N$517&$O$17:$O$517&$P$17:$P$517&$Q$17:$Q$517&$R$17:$R$517&$S$17:$S$517&$T$17:$T$517&$U$17:$U$517&$V$17:$V$517&$W$17:$W$517)>0)) | D9: Mandatory cells missing | E9: =SUMPRODUCT(((ROW($B$17:$B$517)>17)+($B$17<>"MOTOR")>0)*(LEN($B$17:$B$517&$C$17:$C$517&$D$17:$D$517&$E$17:$E$517&$F$17:$F$517&$G$17:$G$517&$H$17:$H$517&$I$17:$I$517&$J$17:$J$517&$K$17:$K$517&$L$17:$L$517&$M$17:$M$517&$N$17:$N$517&$O$17:$O$517&$P$17:$P$517&$Q$17:$Q$517&$R$17:$R$517&$S$17:$S$517&$T$17:$T$517&$U$17:$U$517&$V$17:$V$517&$W$17:$W$517)>0)*(($B$17:$B$517="")+($C$17:$C$517="")+($H$17:$H$517="")+($I$17:$I$517="")+($K$17:$K$517="")+($M$17:$M$517="")+($P$17:$P$517="")+($Q$17:$Q$517="")))
A10: Confirmed by (BDOI owner) | D10: Date
A12: Mandatory | B12: Yes | C12: Yes | D12: No | E12: Conditional: package products | F12: Conditional: with the code | G12: No | H12: Yes | I12: Yes | J12: No | K12: Yes | L12: No | M12: Yes | N12: No | O12: No | P12: Yes | Q12: Yes | R12: No | S12: No | T12: No | U12: No | V12: No | W12: No
A13: Format | B13: Up to 30 capitals | C13: Text | D13: Regular expression | E13: Up to 30 capitals | F13: Text | G13: Cover type code | H13: 1 to 20 capitals or digits | I13: Up to 200 characters | J13: Text | K13: Y or N | L13: Codes separated by commas; blank = all | M13: PAID or CLIENT_CONFIRMATION | N13: BY_RULES, ALWAYS or NEVER | O13: Up to four decimals | P13: Percentage | Q13: Amount in PHP | R13: Amount in PHP | S13: Y or N | T13: Y or N | U13: Y or N | V13: Y or N; 2 to 10 years | W13: Y or N
A14: Allowed values | B14: Free entry, up to 30 characters | C14: Free entry | D14: Free entry | E14: Free entry, up to 30 characters | F14: Free entry | G14: A code of CI-01 Product catalogue, column Cover type code | H14: Free entry, up to 20 characters | I14: Free entry, up to 200 characters | J14: Free entry | K14: Y or N | L14: One or more codes of the list Market segment (Reference lists), separated by commas | M14: PAID, CLIENT_CONFIRMATION (list Placement after) | N14: BY_RULES, ALWAYS, NEVER (list TSU review) | O14: A number from 0 to 100 | P14: A number from 0 to 100 | Q14: A number | R14: A number | S14: Y or N | T14: Y or N | U14: Y or N | V14: Free entry | W14: Y or N
A15: What to enter | B15: Product line (level 1), for example MOTOR, PROPERTY | C15: Name shown in the drop-downs | D15: Naming convention of the risk codes of the line, when BDOI states one | E15: Cover type (level 2) of the line | F15: Name of the cover type | G15: Only for a subtype (one level below a cover type) | H15: Product code (level 3); unique | I15: Name shown to users | J15: Code of the product in QPS or EBIX, for the migration map | K15: Y for a package product (terms change through versions) | L15: Segments the product is offered to (list MARKET_SEGMENT) | M15: Payment gate before placement | N15: When TSU reviews an account of the product | O15: Rate of a non-package product; for a package, of version 1 | P15: Commission when no insurer rate applies | Q15: Minimum premium of the product | R15: Above it the account goes to TSU | S15: Several vehicles on one account | T15: Mortgage or loan related | U15: Premium may be paid directly to the insurer | V15: Multi-year term and its maximum | W15: Free First Year eligible
A16: Row | B16: Line code * | C16: Line name * | D16: Risk-code pattern | E16: Cover type code | F16: Cover type name | G16: Parent cover type | H16: Risk code * | I16: Product name * | J16: Legacy code | K16: Package * | L16: Market segments | M16: Placement after * | N16: TSU review | O16: Default rate % | P16: Default commission % * | Q16: Minimum premium * | R16: Package TSI limit | S16: Fleet | T16: Mortgage related | U16: Direct payment allowed | V16: Multi-year / Maximum term | W16: Free First Year
A17: Example – overwrite or delete | B17: MOTOR | C17: Motor | D17: MTR[0-9]{2} | E17: COMPREHENSIVE | F17: Comprehensive | H17: MTR30 | I17: Motor Fleet Plus | J17: QPS-MFP | K17: Y | L17: COMBANK | M17: PAID | N17: BY_RULES | O17: 1.2 | P17: 15 | Q17: 5000 | R17: 5000000 | S17: Y | T17: N | U17: N | V17: N | W17: N

Sheet CI-02 Coverages and rules
A1: CI-02 Coverages, perils and field rules | J1: Step 3 of 10
A2: ← Back to Start here | B2: Step 3 of 10. Fill in one row per record below the column headers; the guide above each column says what to enter. | J2: Ask a question →
A3: Purpose | B3: The coverage and peril level of each line, and the fields and documents each product needs on an account
A4: Provided by | B4: MBS
A5: Due | B5: 16-Jul-2027 – Values for UAT
A6: How it is loaded | B6: Entered on Coverages & Clauses (SCR-PM-15) and on the rule tabs of Products (SCR-PM-11, SCR-PM-12) before UAT; not migrated
A7: Source | B7: MBS and TSU (product matrix, PQ02)
A8: Depends on | B8: CI-09 Lists of values and parameters → | D8: CI-01 Product catalogue →
A9: Progress | B9: Rows entered | C9: =SUMPRODUCT(((ROW($B$17:$B$517)>17)+($B$17<>"COVERAGE")>0)*(LEN($B$17:$B$517&$C$17:$C$517&$D$17:$D$517&$E$17:$E$517&$F$17:$F$517&$G$17:$G$517&$H$17:$H$517&$I$17:$I$517&$J$17:$J$517)>0)) | D9: Mandatory cells missing | E9: =SUMPRODUCT(((ROW($B$17:$B$517)>17)+($B$17<>"COVERAGE")>0)*(LEN($B$17:$B$517&$C$17:$C$517&$D$17:$D$517&$E$17:$E$517&$F$17:$F$517&$G$17:$G$517&$H$17:$H$517&$I$17:$I$517&$J$17:$J$517)>0)*(($B$17:$B$517="")+($C$17:$C$517="")+($D$17:$D$517="")+($E$17:$E$517="")+($F$17:$F$517="")+($J$17:$J$517="")))
A10: Confirmed by (BDOI owner) | D10: Date
A12: Mandatory | B12: Yes | C12: Yes | D12: Yes | E12: Yes | F12: Yes | G12: Conditional: coverage | H12: Conditional: list, range or format rules | I12: Conditional: document rule | J12: Yes
A13: Format | B13: COVERAGE, FIELD_RULE or DOCUMENT_RULE | C13: Line or product the row applies to; * = every product | D13: A-Z, 0-9 and _ (coverage); field key (rule) | E13: Text | F13: Coverage kind (Section, Coverage, Peril, Extension); check (Presence, List of values, Number range, Format) | G13: Y or N | H13: List code; minimum and maximum; pattern | I13: List DOCUMENT_TYPE | J13: Y or N
A14: Allowed values | B14: COVERAGE, FIELD_RULE, DOCUMENT_RULE (list Coverage and rule record) | C14: Codes of CI-01 Product catalogue, column Risk code (one or more) | D14: Free entry | E14: Free entry | F14: Free entry | G14: Y or N | H14: Free entry | I14: List Document type: 61 values, see Reference lists | J14: Y or N
A15: What to enter | B15: What the row defines | C15: Scope of the row | D15: Coverage code or the account field checked | E15: Coverage name or field label | F15: Coverage kind or rule check | G15: A package needs at least one basic coverage | H15: Parameters of the check | I15: Document an account needs before submission | J15: Required or optional
A16: Row | B16: Record * | C16: Line code / Risk code * | D16: Code or field key * | E16: Name or label * | F16: Kind or check * | G16: Basic | H16: Parameters | I16: Document type | J16: Mandatory *
A17: Example – overwrite or delete | B17: COVERAGE | C17: MOTOR | D17: OD_THEFT | E17: Own damage and theft | F17: Coverage | G17: Y | J17: Y

Sheet CI-03 Clause library
A1: CI-03 Clause library | G1: Step 4 of 10
A2: ← Back to Start here | B2: Step 4 of 10. Fill in one row per record below the column headers; the guide above each column says what to enter. | G2: Ask a question →
A3: Purpose | B3: Warranties, clauses, exclusions and deductible wordings used in the insurer terms of package versions
A4: Provided by | B4: TSU (wordings); MBS (maintenance)
A5: Due | B5: 16-Jul-2027 – Values for UAT
A6: How it is loaded | B6: Entered on Coverages & Clauses › Clause Library (SCR-PM-15); not migrated
A7: Source | B7: Current package slips and insurer wordings
A8: Depends on | B8: CI-09 Lists of values and parameters → | D8: CI-01 Product catalogue →
A9: Progress | B9: Rows entered | C9: =SUMPRODUCT(((ROW($B$17:$B$517)>17)+($B$17<>"FLEET_REPAIR")>0)*(LEN($B$17:$B$517&$C$17:$C$517&$D$17:$D$517&$E$17:$E$517&$F$17:$F$517&$G$17:$G$517)>0)) | D9: Mandatory cells missing | E9: =SUMPRODUCT(((ROW($B$17:$B$517)>17)+($B$17<>"FLEET_REPAIR")>0)*(LEN($B$17:$B$517&$C$17:$C$517&$D$17:$D$517&$E$17:$E$517&$F$17:$F$517&$G$17:$G$517)>0)*(($B$17:$B$517="")+($C$17:$C$517="")+($E$17:$E$517="")+($F$17:$F$517="")+($G$17:$G$517="")))
A10: Confirmed by (BDOI owner) | D10: Date
A12: Mandatory | B12: Yes | C12: Yes | D12: No | E12: Yes | F12: Yes | G12: Yes (from)
A13: Format | B13: A-Z, 0-9 and _ | C13: WARRANTY, CLAUSE, EXCLUSION or DEDUCTIBLE_WORDING | D13: Line code; blank = every line | E13: Text | F13: Full text | G13: dd-MMM-yyyy
A14: Allowed values | B14: Free entry | C14: WARRANTY, CLAUSE, EXCLUSION, DEDUCTIBLE_WORDING (list Clause kind) | D14: A code of CI-01 Product catalogue, column Line code | E14: Free entry | F14: Free entry | G14: Free entry
A15: What to enter | B15: Unique code | C15: Code of the list CLAUSE_KIND | D15: Lines the clause is offered for | E15: Title shown in the pickers | F15: Wording printed on the package documents | G15: Validity of the wording
A16: Row | B16: Clause code * | C16: Kind * | D16: Line code | E16: Title * | F16: Wording * | G16: Effective from / to *
A17: Example – overwrite or delete | B17: FLEET_REPAIR | C17: CLAUSE | D17: MOTOR | E17: Accredited repair shops for fleets | F17: Repairs are made at the accredited shops of the insurer... | G17: 01-Jan-2027

Sheet CI-05 Insurers
A1: CI-05 Insurers, branches and commission rates | J1: Step 5 of 10
A2: ← Back to Start here | B2: Step 5 of 10. Fill in one row per record below the column headers; the guide above each column says what to enter. | J2: Ask a question →
A3: Purpose | B3: The insurer panel with accreditation and placement e-mails, the branches with their LGT rate, and the commission rates per product
A4: Provided by | B4: Head of Operations; MBS (commission per package)
A5: Due | B5: 9-Apr-2027 – Reference data for Trial migration 1 (M4)
A6: How it is loaded | B6: Data migration objects R04 (insurers, branches, business partners) and R07 (commission rates); after go-live on Insurers (SCR-PM-17, SCR-PM-18)
A7: Source | B7: Legacy QPS and EBIX insurer masters
A8: Depends on | B8: CI-01 Product catalogue →
A9: Progress | B9: Rows entered | C9: =SUMPRODUCT(((ROW($B$17:$B$517)>17)+($B$17<>"INS-MGIC")>0)*(LEN($B$17:$B$517&$C$17:$C$517&$D$17:$D$517&$E$17:$E$517&$F$17:$F$517&$G$17:$G$517&$H$17:$H$517&$I$17:$I$517&$J$17:$J$517)>0)) | D9: Mandatory cells missing | E9: =SUMPRODUCT(((ROW($B$17:$B$517)>17)+($B$17<>"INS-MGIC")>0)*(LEN($B$17:$B$517&$C$17:$C$517&$D$17:$D$517&$E$17:$E$517&$F$17:$F$517&$G$17:$G$517&$H$17:$H$517&$I$17:$I$517&$J$17:$J$517)>0)*(($B$17:$B$517="")+($C$17:$C$517="")))
A10: Confirmed by (BDOI owner) | D10: Date
A12: Mandatory | B12: Yes | C12: Yes (name) | D12: No | E12: No | F12: Conditional: for package insurers | G12: No | H12: Conditional: branch rows | I12: Conditional: branch rows | J12: Conditional: commission rows
A13: Format | B13: INS- followed by capitals | C13: Text | D13: 000-000-000-000; text | E13: Text; dd-MMM-yyyy | F13: Addresses separated by commas | G13: 0 to 365 | H13: Text | I13: 0 to 100 | J13: Risk code or blank for all; percentage; dd-MMM-yyyy
A14: Allowed values | B14: Free entry | C14: Free entry | D14: Free entry | E14: Free entry | F14: Free entry | G14: A whole number from 0 to 365 | H14: Free entry | I14: A number from 0 to 100 | J14: Codes of CI-01 Product catalogue, column Risk code (one or more)
A15: What to enter | B15: Insurer code; unique | C15: Registered and short name | D15: Business partner details | E15: Insurance Commission accreditation | F15: Where quotation and placement slips are sent | G15: Default credit days | H15: Branch of the insurer | I15: Local government tax on premium | J15: Commission rate of the insurer
A16: Row | B16: Partner code * | C16: Name / Short name * | D16: TIN / Address | E16: IC accreditation no. / Accredited until | F16: Placement e-mails | G16: Credit days | H16: Branch code / Branch name / City | I16: LGT % | J16: Commission product / Commission % / From / To
A17: Example – overwrite or delete | B17: INS-MGIC | C17: Mabuhay General Insurance Corp. | D17: 123-456-789-000 | E17: IC-2026-001; 31-Dec-2027 | F17: placement@insurer.example | G17: 30 | H17: MKT; Makati; Makati City | I17: 0.5 | J17: MTR30; 15; 01-Jan-2028; -

Sheet CI-04 Rate tables
A1: CI-04 Rate tables | H1: Step 6 of 10
A2: ← Back to Start here | B2: Step 6 of 10. Fill in one row per record below the column headers; the guide above each column says what to enter. | H2: Ask a question →
A3: Purpose | B3: Statutory charges and rating factors, the short-period table and the motor BI / PD limit premiums
A4: Provided by | B4: Product Owner, MBS; Comptrollership (taxes)
A5: Due | B5: 16-Jul-2027 – Values for UAT
A6: How it is loaded | B6: Entered on Rates & Taxes (SCR-PM-19), pending authorisation; not migrated (effective-dated from go-live)
A7: Source | B7: BIR and LGU rates; current rating tables
A8: Depends on | B8: CI-01 Product catalogue →
A9: Progress | B9: Rows entered | C9: =SUMPRODUCT(((ROW($B$17:$B$517)>17)+($B$17<>"TAX")>0)*(LEN($B$17:$B$517&$C$17:$C$517&$D$17:$D$517&$E$17:$E$517&$F$17:$F$517&$G$17:$G$517&$H$17:$H$517)>0)) | D9: Mandatory cells missing | E9: =SUMPRODUCT(((ROW($B$17:$B$517)>17)+($B$17<>"TAX")>0)*(LEN($B$17:$B$517&$C$17:$C$517&$D$17:$D$517&$E$17:$E$517&$F$17:$F$517&$G$17:$G$517&$H$17:$H$517)>0)*(($B$17:$B$517="")+($H$17:$H$517="")))
A10: Confirmed by (BDOI owner) | D10: Date
A12: Mandatory | B12: Yes | C12: Conditional: TAX | D12: No | E12: Conditional: TAX, SHORT_PERIOD | F12: Conditional: SHORT_PERIOD | G12: Conditional: MOTOR_LIMIT | H12: Yes (from)
A13: Format | B13: TAX, SHORT_PERIOD or MOTOR_LIMIT | C13: DST, premium tax, VAT, fire service tax, motor factors | D13: Line; blank = every line | E13: Up to four decimals, 0 to 100 | F13: 1 to 12 | G13: BI or PD; amounts in PHP | H13: dd-MMM-yyyy
A14: Allowed values | B14: TAX, SHORT_PERIOD, MOTOR_LIMIT (list Rate table) | C14: Free entry | D14: A code of CI-01 Product catalogue, column Line code | E14: A number from 0 to 100 | F14: A whole number from 1 to 12 | G14: Free entry | H14: Free entry
A15: What to enter | B15: Table of the row | C15: Charge or factor | D15: Line the rate applies to | E15: Rate, or % of the annual premium | F15: Months covered, up to | G15: Limit and its premium | H15: Validity of the row
A16: Row | B16: Table * | C16: Rate | D16: Line code | E16: Rate % | F16: Months covered | G16: Coverage / Limit / Premium | H16: Effective from / to *
A17: Example – overwrite or delete | B17: TAX | C17: DST | E17: 12.5 | F17: 6 | G17: BI; 100000.00; 350.00 | H17: 01-Jan-2028

Sheet CI-10 Incentive criteria
A1: CI-10 Incentive criteria | G1: Step 7 of 10
A2: ← Back to Start here | B2: Step 7 of 10. Fill in one row per record below the column headers; the guide above each column says what to enter. | G2: Ask a question →
A3: Purpose | B3: The incentive criteria (for example CPC2) with their value, the products matrix and the effective dates
A4: Provided by | B4: Incentive Maintenance user (MBS); Comptrollership (CPC2 definition, PQ04)
A5: Due | B5: 16-Jul-2027 – Values for UAT
A6: How it is loaded | B6: Entered on Incentive Criteria (SCR-PM-16), pending authorisation; the copied booking rules are reviewed there
A7: Source | B7: Current incentive programmes; the booking incentive rules copied into the catalogue
A8: Depends on | B8: CI-09 Lists of values and parameters → | C8: CI-01 Product catalogue →
A9: Progress | B9: Rows entered | C9: =SUMPRODUCT(((ROW($B$17:$B$517)>17)+($B$17<>"CPC2; CPC2 campaign 2028")>0)*(LEN($B$17:$B$517&$C$17:$C$517&$D$17:$D$517&$E$17:$E$517&$F$17:$F$517&$G$17:$G$517)>0)) | D9: Mandatory cells missing | E9: =SUMPRODUCT(((ROW($B$17:$B$517)>17)+($B$17<>"CPC2; CPC2 campaign 2028")>0)*(LEN($B$17:$B$517&$C$17:$C$517&$D$17:$D$517&$E$17:$E$517&$F$17:$F$517&$G$17:$G$517)>0)*(($B$17:$B$517="")+($C$17:$C$517="")+($D$17:$D$517="")+($F$17:$F$517="")+($G$17:$G$517="")))
A10: Confirmed by (BDOI owner) | D10: Date
A12: Mandatory | B12: Yes | C12: Yes | D12: Yes (basis) | E12: No | F12: Yes (one product) | G12: Yes (from)
A13: Format | B13: A-Z, 0-9, _ and -; text | C13: List INCENTIVE_TYPE | D13: Rate (%), Fixed amount or Rule; number | E13: Parameter and value pairs separated by semicolons | F13: Active risk codes; segment or blank | G13: dd-MMM-yyyy
A14: Allowed values | B14: Free entry | C14: OTHERS, MIGRATED (list Incentive type) | D14: Free entry | E14: Free entry | F14: Codes of CI-01 Product catalogue, column Risk code (one or more) | G14: Free entry
A15: What to enter | B15: Criterion | C15: Type of criterion | D15: Value of the criterion | E15: Parameters of a rule criterion, as agreed with Comptrollership | F15: Products and segments the criterion applies to | G15: Validity; no overlap with another row of the code
A16: Row | B16: Code / Name * | C16: Incentive type * | D16: Value basis / Value * | E16: Rule parameters | F16: Products matrix: risk code / segment * | G16: Effective from / to *
A17: Example – overwrite or delete | B17: CPC2; CPC2 campaign 2028 | C17: CAMPAIGN | D17: Rate (%); 1.00 | E17: Minimum premium 5000 | F17: MTR30; COMBANK | G17: 01-Jan-2028

Sheet CI-06 Packages
A1: CI-06 Packages in force at go-live | J1: Step 8 of 10
A2: ← Back to Start here | B2: Step 8 of 10. Fill in one row per record below the column headers; the guide above each column says what to enter. | J2: Ask a question →
A3: Purpose | B3: For every package sold at go-live: its terms as they will be set up in BIBS through a package request (TSU) and a package version (MBS): rate scheme, dates, coverages, panel insurers and their terms
A4: Provided by | B4: TSU (prepares); Product Owner, MBS (approves)
A5: Due | B5: 1-Nov-2027 – Production values before the dress rehearsal
A6: How it is loaded | B6: Not migrated: TSU raises a package request per package (type New package, or Update for an existing risk code) and MBS sets up and validates the version before the map freeze; the Package Request Form accepts the same fields
A7: Source | B7: Signed package slips and ManCom sign-offs in force
A8: Depends on | B8: CI-01 Product catalogue → | D8: CI-02 Coverages, perils and field rules → | E8: CI-05 Insurers, branches and commission rates → | F8: CI-03 Clause library →
A9: Progress | B9: Rows entered | C9: =SUMPRODUCT(((ROW($B$17:$B$517)>17)+($B$17<>"MTR30")>0)*(LEN($B$17:$B$517&$C$17:$C$517&$D$17:$D$517&$E$17:$E$517&$F$17:$F$517&$G$17:$G$517&$H$17:$H$517&$I$17:$I$517&$J$17:$J$517)>0)) | D9: Mandatory cells missing | E9: =SUMPRODUCT(((ROW($B$17:$B$517)>17)+($B$17<>"MTR30")>0)*(LEN($B$17:$B$517&$C$17:$C$517&$D$17:$D$517&$E$17:$E$517&$F$17:$F$517&$G$17:$G$517&$H$17:$H$517&$I$17:$I$517&$J$17:$J$517)>0)*(($B$17:$B$517="")+($C$17:$C$517="")+($D$17:$D$517="")+($E$17:$E$517="")+($F$17:$F$517="")+($G$17:$G$517="")+($H$17:$H$517="")+($I$17:$I$517="")+($J$17:$J$517="")))
A10: Confirmed by (BDOI owner) | D10: Date
A12: Mandatory | B12: Yes | C12: Yes (name, scope) | D12: Yes (effective from, package end) | E12: Yes (minimum, commission; rate or insurer rates) | F12: Yes | G12: Yes (one basic coverage) | H12: Yes (the panel) | I12: Yes (every insurer and included coverage) | J12: Yes
A13: Format | B13: Code of CI-01 | C13: Text; Generic or Client-specific; client code | D13: dd-MMM-yyyy | E13: Percentages and PHP amounts | F13: Text | G13: Codes of CI-02; Y or N; PHP | H13: Codes of CI-05; Panel, Lead or Participant; shares total 100 | I13: Codes of CI-03 separated by commas | J13: Reference; the signed slip file
A14: Allowed values | B14: A code of CI-01 Product catalogue, column Risk code | C14: Free entry | D14: Free entry | E14: Free entry | F14: Free entry | G14: Codes of CI-02 Coverages, perils and field rules, column Code or field key (one or more) | H14: Codes of CI-05 Insurers, branches and commission rates, column Partner code (one or more) | I14: Codes of CI-03 Clause library, column Clause code (one or more) | J14: Free entry
A15: What to enter | B15: Package product | C15: As on the Package Request Form | D15: Dates of the version | E15: Rate scheme of the version | F15: How the premium is computed | G15: Coverages of the version | H15: Panel insurers | I15: Terms per insurer and coverage | J15: Evidence kept on the request
A16: Row | B16: Risk code * | C16: Package name / Scope / Client code * | D16: Effective from / Package start / Package end / Anniversary * | E16: Package rate % / Minimum premium / Commission % / Package TSI limit * | F16: Computation basis * | G16: Coverage code / Included / Optional / Limit / Deductible * | H16: Insurer code / Role / Share % / Rate % / Minimum premium * | I16: Insurer terms: insurer / coverage / limit / deductible / clauses * | J16: ManCom sign-off reference / Signed package slip *
A17: Example – overwrite or delete | B17: MTR30 | C17: Motor Fleet Plus; Generic | D17: 01-Jan-2028; 01-Jan-2028; 31-Dec-2028; - | E17: 1.2000; 5000.00; 15; 5000000.00 | F17: Comprehensive rate on the vehicle value | G17: OD_THEFT; Y; N; -; 2000.00 | H17: INS-MGIC; Panel; -; 1.2000; - | I17: INS-MGIC; OD_THEFT; -; 2000.00; FLEET_REPAIR | J17: MC-2026-017

Sheet CI-07 Package map
A1: CI-07 Package map (legacy package to BIBS package version) | I1: Step 9 of 10
A2: ← Back to Start here | B2: Step 9 of 10. Fill in one row per record below the column headers; the guide above each column says what to enter. | I2: Ask a question →
A3: Purpose | B3: Entries from each legacy package and version to the BIBS package version that renews it, with qualifiers where one legacy package splits; read at Renewal sanitation (check PACKAGE_REMAP)
A4: Provided by | B4: TSU (prepares); Product Owner, MBS (approves each map version)
A5: Due | B5: 18-Jun-2027 – Code maps approved (M5)
A6: How it is loaded | B6: Data migration object R06 (loaded as reference data and handed to the Renewal package map); new map versions until the map freeze (T-7), then maintained in Renewal
A7: Source | B7: QPS package list of the in-force policies expiring from go-live
A8: Depends on | B8: CI-01 Product catalogue → | C8: CI-05 Insurers, branches and commission rates → | D8: CI-06 Packages in force at go-live →
A9: Progress | B9: Rows entered | C9: =SUMPRODUCT(((ROW($B$17:$B$517)>17)+($B$17<>"PKG-MOTOR-FLEET; 3")>0)*(LEN($B$17:$B$517&$C$17:$C$517&$D$17:$D$517&$E$17:$E$517&$F$17:$F$517&$G$17:$G$517&$H$17:$H$517&$I$17:$I$517)>0)) | D9: Mandatory cells missing | E9: =SUMPRODUCT(((ROW($B$17:$B$517)>17)+($B$17<>"PKG-MOTOR-FLEET; 3")>0)*(LEN($B$17:$B$517&$C$17:$C$517&$D$17:$D$517&$E$17:$E$517&$F$17:$F$517&$G$17:$G$517&$H$17:$H$517&$I$17:$I$517)>0)*(($B$17:$B$517="")+($H$17:$H$517="")))
A10: Confirmed by (BDOI owner) | D10: Date
A12: Mandatory | B12: Yes | C12: No | D12: No | E12: No | F12: No | G12: Conditional: action MAP | H12: Yes | I12: No
A13: Format | B13: As stored in QPS | C13: Text | D13: Risk code of CI-01 | E13: Partner code of CI-05 | F13: PHP amounts | G13: A package version active in Product Maintenance | H13: MAP or REJECT | I13: Text
A14: Allowed values | B14: Free entry | C14: Free entry | D14: A code of CI-01 Product catalogue, column Risk code | E14: A code of CI-05 Insurers, branches and commission rates, column Partner code | F14: Free entry | G14: Codes of CI-06 Packages in force at go-live, column Risk code (one or more) | H14: MAP, REJECT (list Package map action) | I14: Free entry
A15: What to enter | B15: Package of the legacy policy headers | C15: For reading only | D15: When one legacy package maps to several BIBS packages by product | E15: When the split is by insurer | F15: When the split is by sum-insured band | G15: Target of the entry | H15: REJECT sends the candidate to the Renewal Exception bucket | I15: Reason of a REJECT or a split
A16: Row | B16: Legacy package code / Legacy version * | C16: Legacy package name | D16: Qualifier: risk code | E16: Qualifier: insurer | F16: Qualifier: sum insured from / to | G16: BIBS risk code / BIBS version | H16: Action * | I16: Remarks
A17: Example – overwrite or delete | B17: PKG-MOTOR-FLEET; 3 | C17: Motor fleet package 2025 | D17: MTR30 | G17: MTR30; 1 | H17: MAP

Sheet CI-08 Document templates
A1: CI-08 Document templates | G1: Step 10 of 10
A2: ← Back to Start here | B2: Step 10 of 10. Fill in one row per record below the column headers; the guide above each column says what to enter. | G2: Ask a question →
A3: Purpose | B3: The texts of the package documents: Package Request Form, quotation slip, comparative table, package slip, package advisory and package renewal advisory, with the merge fields each may use
A4: Provided by | B4: TSU and MBS (texts); Business Administrator (maintenance)
A5: Due | B5: 16-Jul-2027 – Values for UAT
A6: How it is loaded | B6: Entered on Document Templates (New Business set, SCR-NB-44) as a new template version effective from a date; not migrated
A7: Source | B7: BDOI layouts of the current documents (Q03)
A8: Depends on | B8: Nothing: this template can be filled in first
A9: Progress | B9: Rows entered | C9: =SUMPRODUCT(((ROW($B$17:$B$517)>17)+($B$17<>"PKG_ADVISORY")>0)*(LEN($B$17:$B$517&$C$17:$C$517&$D$17:$D$517&$E$17:$E$517&$F$17:$F$517)>0)) | D9: Mandatory cells missing | E9: =SUMPRODUCT(((ROW($B$17:$B$517)>17)+($B$17<>"PKG_ADVISORY")>0)*(LEN($B$17:$B$517&$C$17:$C$517&$D$17:$D$517&$E$17:$E$517&$F$17:$F$517)>0)*(($B$17:$B$517="")+($C$17:$C$517="")+($D$17:$D$517="")+($F$17:$F$517="")))
A10: Confirmed by (BDOI owner) | D10: Date
A12: Mandatory | B12: Yes | C12: Yes | D12: Yes | E12: No | F12: Yes
A13: Format | B13: PKG_REQUEST_FORM, PKG_QUOTATION_SLIP, PKG_COMPARATIVE, PKG_SLIP, PKG_ADVISORY, PKG_RENEWAL_ADVISORY | C13: Text | D13: Text with merge fields in double braces | E13: PKG_REQUEST_FORM: reference, requestType, title; PKG_QUOTATION_SLIP: reference, roundNo, replyBy; PKG_COMPARATIVE: reference, roundNo, variant; PKG_SLIP: reference, title; advisories: productCode, productName, versionNo, effectiveFrom, reference | F13: dd-MMM-yyyy
A14: Allowed values | B14: List Package document template: 6 values, see Reference lists | C14: Free entry | D14: Free entry | E14: Free entry | F14: A date, for example 15-Jan-2028
A15: What to enter | B15: Template code | C15: Title of the template version | D15: Opening text of the document | E15: Fields filled in by BIBS | F15: Date from which the version is used
A16: Row | B16: Template * | C16: Title * | D16: Text * | E16: Merge fields used | F16: Effective from *
A17: Example – overwrite or delete | B17: PKG_ADVISORY | C17: Package advisory | D17: This is to advise that the package {{productCode}} - {{productName}} ... | E17: productCode, productName, versionNo, effectiveFrom, reference | F17: 46327

Sheet Reference lists
A1: Reference lists
A2: ← Back to Start here | B2: Every list of allowed values used by the drop-downs, with its code and label. A drop-down accepts the codes of its list.
A4: List | B4: Used in | C4: Code | D4: Label | E4: Note
A5: Yes or no (YES_NO) | B5: CI-01 Product catalogue: Package CI-01 Product catalogue: Fleet CI-01 Product catalogue: Mortgage related CI-01 Product catalogue: Direct payment allowed CI-01 Product catalogue: Free First Year CI-02 Coverages and rules: Basic CI-02 Coverages and rules: Mandatory | C5: Y | D5: Yes
C6: N | D6: No
A7: Market segment (MARKET_SEGMENT) | B7: CI-01 Product catalogue: Market segments | C7: CBG | D7: Consumer Banking Group (CBG) | E7: The values of the list MARKET_SEGMENT as delivered with BIBS; a new value is added with its template and may then be used here.
C8: COMBANK | D8: Commercial Banking
C9: CORBANK | D9: Corporate Banking
C10: RETAIL | D10: Retail Marketing
C11: INSTITUTIONAL | D11: Institutional Banking / SM / BDO accounts
A12: Placement after (PLACEMENT_GATE) | B12: CI-01 Product catalogue: Placement after | C12: PAID | D12: Premium paid
C13: CLIENT_CONFIRMATION | D13: Client confirmation
A14: TSU review (TSU_REVIEW) | B14: CI-01 Product catalogue: TSU review | C14: BY_RULES | D14: By the review rules
C15: ALWAYS | D15: Always
C16: NEVER | D16: Never
A17: Coverage and rule record (CI02_RECORD) | B17: CI-02 Coverages and rules: Record | C17: COVERAGE | D17: Coverage or peril of a line
C18: FIELD_RULE | D18: Field an account of the product needs
C19: DOCUMENT_RULE | D19: Document an account of the product needs
A20: Document type (DOCUMENT_TYPE) | B20: CI-02 Coverages and rules: Document type | C20: IDF | D20: Insurance Declaration Form (IDF) | E20: The values of the list DOCUMENT_TYPE as delivered with BIBS; a new value is added with its template and may then be used here.
C21: VALID_ID | D21: Valid ID
C22: BIRTH_CERTIFICATE | D22: Birth certificate
C23: ACCOUNT_LIST | D23: List of account details (Excel)
C24: QUOTATION | D24: Quotation / proposal
C25: CLIENT_ACCEPTANCE | D25: Client acceptance e-mail
C26: EPOLICY | D26: E-policy
C27: OFFICIAL_RECEIPT | D27: Official receipt
C28: POLICY_COPY | D28: Issued policy copy
C29: OTHERS | D29: Others
C30: KYC_FORM | D30: Client information sheet / KYC form
C31: PROOF_OF_ADDRESS | D31: Proof of address
C32: SEC_CERTIFICATE | D32: SEC / DTI certificate of registration
... C80: MIG_EVIDENCE | D80: Migration sign-off evidence
A81: Clause kind (CLAUSE_KIND) | B81: CI-03 Clause library: Kind | C81: WARRANTY | D81: Warranty | E81: The values of the list CLAUSE_KIND as delivered with BIBS; a new value is added with its template and may then be used here.
C82: CLAUSE | D82: Clause
C83: EXCLUSION | D83: Exclusion
C84: DEDUCTIBLE_WORDING | D84: Deductible wording
A85: Rate table (RATE_TABLE) | B85: CI-04 Rate tables: Table | C85: TAX | D85: Statutory charge or rating factor
C86: SHORT_PERIOD | D86: Short-period table
C87: MOTOR_LIMIT | D87: Motor BI / PD limit premium
A88: Package map action (MAP_ACTION) | B88: CI-07 Package map: Action | C88: MAP | D88: Renew with the BIBS package version
...

Sheet Questions and comments
A1: Questions and comments
A2: ← Back to Start here | B2: Raise a question or a comment on a template or a column; the iorta TechNXT project team answers here.
A4: No. | B4: Template | C4: Column | D4: Question / comment | E4: Raised by | F4: Date | G4: Answer | H4: Answered by | I4: Status
A5: 1
A6: 2
A7: 3
A8: 4
A9: 5
A10: 6
A11: 7
A12: 8
A13: 9
A14: 10
A15: 11
A16: 12
... A104: 100
