Workbook

Sheet Cover
B6: CHANGE REGISTER
B7: Change Management Register
B8: For documentation and change control; does not change the platform or the FRS baseline.
B9: BIBS – BDOI Broker System
B11: Client | C11: BDO Insurance and Reinsurance Brokers, Inc.
B12: BRD | C12: BRD-00
B13: Version | C13: 1.0
B14: Date | C14: 26 September 2026
B15: Classification | C15: Confidential
B16: Prepared by | C16: iorta TechNXT
B18: Sheets
B19: Sheet | C19: Content | D19: Rows
B20: How to read | C20: Reading guide, deviation types, statuses, priorities, size classes and column definitions
B21: Document control | C21: Version history, review and approval, distribution; the statement that the register does not change the platform or the FRS
B22: Register | C22: 178 deviations from the BRDs for change control. For documentation and change control; does not change the platform or the FRS baseline. | D22: 178
B23: Summary | C23: Counts and man-days by drop, BRD, deviation type, status and priority. Formulas read the Register sheet, so the figures follow any change to it.
B24: Effort basis | C24: How the man-days are estimated: team roles, the man-day, what is included and excluded, and the size classes.
B25: Change control | C25: Change-control process for deviations and new change requests, with the roles and the proposed Change Control Board (CCB).
B26: CR form | C26: Change request form: one per CR; the Project Manager files the signed form with the register.
B28: Legend
B29: Draft | C29: Raised by the project team. Impact analysis done; the BDOI answer or decision it needs is still open.
B30: For CCB review | C30: Impact analysis complete; ready for the Change Control Board to approve, reject or defer.
B31: Approved | C31: Approved by the CCB; scheduled into a drop or release.
B32: Rejected | C32: Rejected by the CCB; the BRD text stands, or the item is closed without change.
B33: For acceptance | C33: The proposed behaviour is decided and documented and differs from the BRD text; the CCB records the acceptance. No work remains.
B35: Status as of 26 September 2026. Baseline: FRS v1.0 of every BRD (BRD-2, BRD-6, BRD-11 and BRD-13 at v1.1 or later), discrepancy register v1.2, BDOI answers of 26 September 2026.
B37: Prepared by iorta TechNXT for BDOI. Confidential – BDOI.

Sheet Document control
A1: Document control
A3: For documentation and change control; does not change the platform or the FRS baseline.
A5: Document | B5: Change Management Register (BIBS-CMR-BRD-00)
A6: Version | B6: 1.0
A7: Date | B7: 26 September 2026
A8: Status | B8: Issued for BDOI review
A9: Status as of | B9: 26 September 2026
A10: Baseline | B10: FRS v1.0 of every BRD (BRD-2, BRD-6, BRD-11 and BRD-13 at v1.1 or later), discrepancy register v1.2, BDOI answers of 26 September 2026
A11: Word summary | B11: BIBS_Change_Register_BRD-00_Change_Management_Summary_v1.0.docx
A12: Owner of the register | B12: Project Manager (iorta TechNXT) on behalf of the Change Control Board
A14: Version history
A15: Version | B15: Date | C15: Author | D15: Reviewer | E15: Approver | F15: Change
A16: 1.0 | B16: 26 Sep 2026 | C16: iorta TechNXT Business Analyst lead | D16: iorta TechNXT Solution Architect | E16: BIBS Product Owner (pending) | F16: First issue: 178 deviations from BRD-00 to BRD-13 with effort in man-days
A18: Review and approval
A19: Role | B19: Organisation | C19: Name | D19: Signature | E19: Date | F19: Purpose
A20: BIBS Product Owner | B20: BDOI | F20: Chair of the CCB; approves the register
A21: Program Manager, Business Project Services | B21: BDO Unibank ESG | F21: Plan, drops and effort
A22: Head, Comptrollership | B22: BDOI | F22: Posting, GL, tax and BIR items
A23: Chief Compliance Officer | B23: BDOI | F23: Screening, access and retention items
A24: Project Manager | B24: iorta TechNXT | F24: Register owner; CCB secretary
A26: Distribution
A27: Recipient | B27: Organisation | C27: Purpose
A28: Owners of BRD-1 to BRD-13 (department heads and product owners) | B28: BDOI | C28: Review the CRs of their BRD; decision owners
A29: BDOI IT (integration owners) | B29: BDOI | C29: Interface and infrastructure CRs
A30: Project team | B30: iorta TechNXT | C30: Impact analysis, scheduling, FRS revisions

Sheet How to read
A1: How to read this register
A2: For documentation and change control; does not change the platform or the FRS baseline.
A4: Reading guide
A5: • | B5: One row per deviation from a BRD requirement, merged across sources (the clarifications chapters of the FRS, the requirements baselines, the discrepancy register v1.2, the alignment pack, the cross-BRD decisions and the BDOI answers of 26 September 2026). The Source column says where each deviation is recorded.
A6: • | B6: Filter the Register sheet by Drop, BRD, Deviation type, Priority or CR status. The Summary sheet recounts from the Register, so it stays correct when rows are added or a status changes.
A7: • | B7: Effort is in man-days for the work still needed to close the deviation as proposed (Effort basis sheet). It is 0 when no work remains and the behaviour only needs acceptance. 'BRD as written' gives the indicative effort to deliver the BRD text instead, where the CCB may want to compare.
A8: • | B8: A CR moves Draft -> For CCB review -> Approved or Rejected. Rows marked 'For acceptance' describe decided behaviour that differs from the BRD: the CCB records the acceptance; no work remains.
A9: • | B9: The register does not change the FRS. An approved CR reaches the FRS only through the next FRS revision, which cites the CR ID.
A11: Deviation types
A12: Type | B12: Meaning
A13: Scope addition — beyond BRD | B13: BIBS does more than the BRD asks, or the umbrella FRS proposes a requirement that no function BRD owns. BDOI accepts the addition or removes it.
A14: Scope reduction / descoped | B14: A BRD requirement is not delivered, or is delivered with less than the BRD asks, by a BDOI instruction or a proposal. BDOI confirms the descoping.
A15: Behaviour differs from BRD | B15: The requirement is met in a different way from the BRD text. BDOI accepts the proposed behaviour or asks for the BRD text.
A16: Deferred pending BDOI answer | B16: The element runs with a documented default and waits for a BDOI answer (values, layouts, rules, a yes / no on scope).
A17: Deferred to Phase 2 | B17: Out of phase 1 by BDOI decision; kept for phase 2.
A18: BRD conflict resolved by decision | B18: Two BRDs, or two parts of one BRD, conflict. A binding decision (D1-D10) or a proposed resolution settles the conflict; BDOI confirms it.
A19: Integration dependency | B19: The requirement depends on an interface with a BDO or insurer system that is not yet specified. BIBS runs on an upload or a manual step until the interface exists.
A20: NFR / infrastructure change | B20: A non-functional value (hours, availability, recovery, retention, sizing) or an infrastructure choice differs from one or more BRDs, or from the IER workbook.
A21: Data migration | B21: The migration or cut-over treatment differs from what a BRD assumes, or adds work that a BRD does not state.
A23: CR status
A24: Status | B24: Meaning
A25: Draft | B25: Raised by the project team. Impact analysis done; the BDOI answer or decision it needs is still open.
A26: For CCB review | B26: Impact analysis complete; ready for the Change Control Board to approve, reject or defer.
A27: Approved | B27: Approved by the CCB; scheduled into a drop or release.
A28: Rejected | B28: Rejected by the CCB; the BRD text stands, or the item is closed without change.
A29: For acceptance | B29: The proposed behaviour is decided and documented and differs from the BRD text; the CCB records the acceptance. No work remains.
A31: Priority
A32: Priority | B32: Meaning
A33: High | B33: Affects money (premium, commission, GL, remittance), regulatory compliance, security or access, or blocks a drop. Decide before the FRS of the area is signed off.
A34: Medium | B34: Changes a rule, screen, report or interface; a documented default runs until BDOI decides.
A35: Low | B35: Wording, labels or presentation; no effect on money, control or data.
A37: Size classes (effort basis)
A38: Class | B38: Man-days
A39: 0 | B39: Acceptance only
A40: S | B40: 1 to 3
A41: M | B41: 4 to 10
A42: L | B42: 11 to 25
A43: XL | B43: more than 25
A45: Columns of the data sheets
A46: Sheet | B46: Column | C46: Meaning | D46: Allowed values
...

Sheet Register
A1: Register
A2: 178 deviations from the BRDs for change control. For documentation and change control; does not change the platform or the FRS baseline.
A4: CR ID | B4: Drop | C4: BRD | D4: BRD requirement ID(s) and page | E4: FRS FR ID(s) | F4: Deviation type | G4: BRD requirement | H4: Proposed behaviour | I4: Reason | J4: Business impact | K4: Affected departments | L4: Analysis (md) | M4: Dev. (md) | N4: Test (md) | O4: Doc. (md) | P4: Total (md) | Q4: Size basis | R4: BRD as written (md) | S4: Priority | T4: CR status | U4: Decision owner (BDOI) | V4: Register / question refs | W4: Target drop / release | X4: Source of the record
A5: CR-0001 | B5: Phase 2 | C5: BRD-00 | D5: CORE-15.01-15.10; BR-153 to BR-160 (p.10-11); capability matrix (p.28); ReInsurance BRD | E5: FRS BRD-00 section 6 (Reinsurance, phase 2); CLR-CR-01 | F5: Deferred to Phase 2 | G5: Reinsurance placement, slips, SOA, claims reporting and payment, net settlement (capability 15). | H5: Out of phase 1: the ReInsurance BRD is received and is phase 2. Phase 1 keeps open reinsurer party types, template-driven slips and SOAs, report subscriptions, open-item matching and the claim party model. The insurer-side reinsurance module of the platform stays hidden from BDOI roles. | I5: BDOI answer A3 of 26-Sep-2026: the reinsurance module is phase 2. | J5: Reinsurance placement stays outside BIBS until phase 2; only the transactions routed through Remittance (CR-0002) are in phase 1. | K5: Reinsurance; Comptrollership; Operations | L5: 0 | M5: 0 | N5: 0 | O5: 1 | P5: =SUM(L5:O5) | Q5: =IF(P5=0,"0 - acceptance only",IF(P5<=3,"S",IF(P5<=10,"M",IF(P5<=25,"L","XL")))&" ("&P5&")") | S5: Medium | T5: For CCB review | U5: BIBS Product Owner with the Program Manager, Business Project Services | V5: A3; CLR-CR-01; A-CR-04 | W5: Phase 2 | X5: FRS BRD-00 sections 1.2, 5, 6; Programme alignment 1.2
A6: CR-0002 | B6: Drop 1 | C6: BRD-02 | D6: Drop plan item 1.D3 (Operations BRD, Remittance Addendum; Reinsurance BRD); RMTID.001-040 (p.49-70) | E6: FR-OP-030 to FR-OP-041 (Remittance); FRS BRD-2 v1.1 introduction | F6: Scope addition — beyond BRD | G6: The Operations BRD specifies remittance to insurers only. The drop plan names the Reinsurance BRD for Remittance in Drop 1. | H6: Proposed: the named reinsurance transactions run in Remittance as remittance types with reinsurer counterparties and their own accounting rules; treaty and facultative processing stays phase 2. | I6: BDOI answer A3 of 26-Sep-2026: Remittance handles the reinsurance transactions in Drop 1. Which transactions and their accounting are open (IQ20). | J6: Reinsurance premium and recoveries settled through BIBS from go-live; new posting rules for Comptrollership. | K6: Operations (Remittance); Comptrollership; Reinsurance | L6: 4 | M6: 12 | N6: 6 | O6: 2 | P6: =SUM(L6:O6) | Q6: =IF(P6=0,"0 - acceptance only",IF(P6<=3,"S",IF(P6<=10,"M",IF(P6<=25,"L","XL")))&" ("&P6&")") | S6: High | T6: Draft | U6: Head of Operations (Financial Transactions and Processing) | V6: DCR-210; IQ20; A3 | W6: Drop 1, second release (Jan - Feb 2027) | X6: Register DCR-210; Programme alignment 2.2 item 1
A7: CR-0003 | B7: Drop 1 | C7: BRD-02 | D7: Drop plan items 1.D2 and 1.D3: Operations BRD (Cashiering Addendum), (Remittance Addendum) | E7: FRS BRD-2 (Cashiering, Remittance chapters) | F7: Deferred pending BDOI answer | G7: The drop plan names a Cashiering Addendum and a Remittance Addendum to the Operations BRD. | H7: The Operations pack received has only Addendum 1 (RMTID.002, ADJID.014). FRS BRD-2 is written without the two addenda; they are taken into FRS BRD-2 v1.2 when received and their impact is estimated then. | I7: Documents not received (DCR-215, IQ20). | J7: Cashiering and Remittance requirements may change after FRS sign-off. | K7: Operations (Cashiering, Remittance) | L7: 3 | M7: 0 | N7: 0 | O7: 2 | P7: =SUM(L7:O7) | Q7: =IF(P7=0,"0 - acceptance only",IF(P7<=3,"S",IF(P7<=10,"M",IF(P7<=25,"L","XL")))&" ("&P7&")") | S7: Medium | T7: Draft | U7: Head of Operations (Financial Transactions and Processing) | V7: DCR-215; IQ20 | W7: After BDOI answer (slot set by the CCB) | X7: Register DCR-215; Programme alignment 2.2
A8: CR-0004 | B8: Drop 2 | C8: BRD-00 | D8: CORE-14.08-14.10; BR-146 to BR-148 (p.10); BRD-7 (no claim money through BDOI) | E8: FRS BRD-00 CLR-CR-02; FR-CM (none) | F8: Deferred pending BDOI answer | G8: Safekeeping of unclaimed settlement cheques, hand-over to and retrieval from Cashiering. | H8: BRD-7 has no claim money through BDOI (CLQ10) and Claims posts no accounting entry. If BDOI holds cheques: a cheque custody register in Claims using the Cashiering cheque hand-over. | I8: Conflict between the umbrella BRD and BRD-7; CRQ03, CLQ10, XQ13. | J8: Without a register, cheque custody stays manual outside BIBS. | K8: Claims; Operations (Cashiering) | L8: 2 | M8: 5 | N8: 3 | O8: 1 | P8: =SUM(L8:O8) | Q8: =IF(P8=0,"0 - acceptance only",IF(P8<=3,"S",IF(P8<=10,"M",IF(P8<=25,"L","XL")))&" ("&P8&")") | R8: 11 | S8: Medium | T8: For CCB review | U8: BIBS Product Owner with the Program Manager, Business Project Services | V8: DCR-164; CRQ03; CLQ10; XQ13 | W8: Drop 2 (Mar - Apr 2027) | X8: FRS BRD-00 chapter 5 (CLR-CR-02); Cross-BRD decisions XQ13
A9: CR-0005 | B9: Drop 1 | C9: BRD-00 | D9: CORE-16.06; BR-165 (p.11); BRD-9 CSF-EM10 (e-mail of 13-Feb-2026) | E9: FRS BRD-00 CLR-CR-03; FRS BRD-9 chapter 12 | F9: Scope reduction / descoped | G9: CSF case resolution: add and edit case details and status. | H9: Out of phase 1. BRD-9 puts case management out of scope and keeps case logging in SharePoint. If BDOI brings it in: a CSF case record in the CSF module. | I9: BRD-9 e-mail of 13-Feb-2026; CRQ04 open; XQ12. | J9: Contact Center cases stay in SharePoint; no case history in BIBS. | K9: Contact Center Management; Alternative Distribution | L9: 0 | M9: 0 | N9: 0 | O9: 1 | P9: =SUM(L9:O9) | Q9: =IF(P9=0,"0 - acceptance only",IF(P9<=3,"S",IF(P9<=10,"M",IF(P9<=25,"L","XL")))&" ("&P9&")") | R9: 18 | S9: Medium | T9: For CCB review | U9: Product Owner, CSF (Contact Center Management) | V9: DCR-163; CRQ04; XQ12 | W9: FRS sign-off (Nov 2026) | X9: FRS BRD-00 chapter 5 (CLR-CR-03); FRS BRD-9 chapter 12
A10: CR-0006 | B10: Programme | C10: BRD-00 | D10: CORE-18.01; BR-176 (p.11) | E10: FRS BRD-00 CLR-CR-09 | F10: Scope reduction / descoped | G10: Include any other or additional system capabilities (emerging capabilities). | H10: No work until the capabilities are listed: the requirement has no content to deliver or test. BDOI lists the capabilities or withdraws BR-176. | I10: CRQ10 open. | J10: None until BDOI names a capability; a named capability becomes its own CR. | K10: Business Project Services | L10: 0 | M10: 0 | N10: 0 | O10: 0 | P10: =SUM(L10:O10) | Q10: =IF(P10=0,"0 - acceptance only",IF(P10<=3,"S",IF(P10<=10,"M",IF(P10<=25,"L","XL")))&" ("&P10&")") | S10: Low | T10: For CCB review | U10: BIBS Product Owner with the Program Manager, Business Project Services | V10: CRQ10; CLR-CR-09 | W10: FRS sign-off (Nov 2026) | X10: FRS BRD-00 section 5
A11: CR-0007 | B11: Programme | C11: BRD-00 | D11: XC-21 ALeA e-mail address encoding (p.43) | E11: FRS BRD-00 CLR-CR-10 | F11: Deferred pending BDOI answer | G11: ALeA e-mail address encoding, as needed. | H11: Not in scope; the term is not defined in the BRD pack. | I11: CRQ20 open. | J11: None known until BDOI explains ALeA. | K11: BDOI IT | L11: 1 | M11: 0 | N11: 0 | O11: 0 | P11: =SUM(L11:O11) | Q11: =IF(P11=0,"0 - acceptance only",IF(P11<=3,"S",IF(P11<=10,"M",IF(P11<=25,"L","XL")))&" ("&P11&")") | S11: Low | T11: Draft | U11: BIBS Product Owner with the Program Manager, Business Project Services | V11: CRQ20; CLR-CR-10 | W11: After BDOI answer (slot set by the CCB) | X11: FRS BRD-00 section 5
A12: CR-0008 | B12: Programme | C12: BRD-00 | D12: XC-16; BR-183 (p.23) | E12: FRS BRD-00 traceability (OUT); A-CR-05 | F12: Behaviour differs from BRD | G12: The vendor uses Figma for design execution. | H12: Screens follow the BDO UX guidelines and the BIBS design system in code; the vendor-qualification items are met by the alignment pass and persona walkthroughs. BDOI supplies the icon set and design files (CRQ17). | I12: A-CR-05: BR-178 to BR-183 are vendor-qualification items. | J12: None on the business process. | K12: Business Project Services | L12: 0 | M12: 0 | N12: 0 | O12: 0 | P12: =SUM(L12:O12) | Q12: =IF(P12=0,"0 - acceptance only",IF(P12<=3,"S",IF(P12<=10,"M",IF(P12<=25,"L","XL")))&" ("&P12&")") | S12: Low | T12: For acceptance | U12: BIBS Product Owner with the Program Manager, Business Project Services | V12: CRQ17; A-CR-05 | W12: FRS sign-off (Nov 2026) | X12: FRS BRD-00 traceability XC-16
A13: CR-0009 | B13: Drop 0 | C13: BRD-00 | D13: CORE-17.01; BR-170 (p.11) | E13: FR-CR-031 | F13: Scope addition — beyond BRD | G13: Master data change logging for users, products, insurers and LOVs. No function BRD owns it. | H13: BIBS audits each action with a summary. Proposed: a field-level log (old and new values) for the registered master types. | I13: Umbrella requirement without an owning BRD (Drop 0 item 0.4); CRQ07 open on the master types, approver and viewers. | J13: Auditors can see what changed on a master record, field by field. | K13: Business Project Services; Compliance; MBS; Comptrollership | L13: 2 | M13: 6 | N13: 4 | O13: 1 | P13: =SUM(L13:O13) | Q13: =IF(P13=0,"0 - acceptance only",IF(P13<=3,"S",IF(P13<=10,"M",IF(P13<=25,"L","XL")))&" ("&P13&")") | S13: Medium | T13: Draft | U13: BIBS Product Owner with the Program Manager, Business Project Services | V13: DCR-174; CRQ07; CLR-CR-04 | W13: Drop 1, second release (Jan - Feb 2027) | X13: FRS BRD-00 chapter 5 (CLR-CR-04); register DCR-174
A14: CR-0010 | B14: Drop 0 | C14: BRD-00 | D14: CORE-17.02; BR-171 (p.11) | E14: FR-CR-061 | F14: Scope addition — beyond BRD | G14: Insurer management: risk participation, payment terms, remittance schedules on the insurer. | H14: The insurer page has no such attributes. Proposed: add the attributes and LOV INSURER_CONTACT_FUNCTION. | I14: Umbrella requirement without an owning BRD; CRQ08 open on meaning, owners and approval. | J14: One place for insurer terms used by Remittance and Collections. | K14: MBS; Operations (Remittance) | L14: 2 | M14: 4 | N14: 2 | O14: 1 | P14: =SUM(L14:O14) | Q14: =IF(P14=0,"0 - acceptance only",IF(P14<=3,"S",IF(P14<=10,"M",IF(P14<=25,"L","XL")))&" ("&P14&")") | S14: Medium | T14: Draft | U14: BIBS Product Owner with the Program Manager, Business Project Services | V14: CRQ08; CLR-CR-05 | W14: Drop 1, second release (Jan - Feb 2027) | X14: FRS BRD-00 chapter 5 (CLR-CR-05)
A15: CR-0011 | B15: Drop 0 | C15: BRD-00 | D15: CORE-17.04; BR-173, BR-174 (p.11) | E15: FR-CR-062 | F15: Scope addition — beyond BRD | G15: MIS field definition. | H15: Proposed: an MIS field catalogue that names existing data per entity; users do not add database fields (A-CR-06). | I15: Umbrella requirement without an owning BRD; CRQ09 (fixed list or user-defined fields). | J15: Consistent MIS reporting fields across modules and migration. | K15: Business Project Services; MIS; Marketing | L15: 2 | M15: 6 | N15: 3 | O15: 1 | P15: =SUM(L15:O15) | Q15: =IF(P15=0,"0 - acceptance only",IF(P15<=3,"S",IF(P15<=10,"M",IF(P15<=25,"L","XL")))&" ("&P15&")") | R15: 30 | S15: Medium | T15: Draft | U15: BIBS Product Owner with the Program Manager, Business Project Services | V15: CRQ09; CLR-CR-06 | W15: Drop 1, second release (Jan - Feb 2027) | X15: FRS BRD-00 chapter 5 (CLR-CR-06)
A16: CR-0012 | B16: Programme | C16: BRD-00 | D16: CORE-21.04; BR-053 (p.12) | E16: FR-CR-042 | F16: Scope addition — beyond BRD | G16: Dynamic report customisation: data fields, charts and summaries. | H16: BIBS has fixed report columns and saved parameter variants. Proposed: column layout stored in the variant. | I16: Umbrella requirement without an owning BRD; CRQ11 open. | J16: Users choose and order report columns without a change request. | K16: All report users | L16: 2 | M16: 8 | N16: 4 | O16: 1 | P16: =SUM(L16:O16) | Q16: =IF(P16=0,"0 - acceptance only",IF(P16<=3,"S",IF(P16<=10,"M",IF(P16<=25,"L","XL")))&" ("&P16&")") | S16: Medium | T16: Draft | U16: BIBS Product Owner with the Program Manager, Business Project Services | V16: DCR-177; CRQ11; CLR-CR-07 | W16: Drop 1, second release (Jan - Feb 2027) | X16: FRS BRD-00 chapter 5 (CLR-CR-07)
A17: CR-0013 | B17: Programme | C17: BRD-00 | D17: CORE-21.05; BR-054, BR-103 (p.12) | E17: FR-CR-043 | F17: Scope addition — beyond BRD | G17: Scheduled or on-demand report generation for any report. | H17: Only system-scheduled files exist. Proposed: report subscriptions per user (REPORT_SUBSCRIPTIONS_MAX 20; external domains limited). | I17: Umbrella requirement without an owning BRD; CRQ11 open. | J17: Users receive recurring reports by e-mail without manual runs. | K17: All report users | L17: 1 | M17: 6 | N17: 3 | O17: 1 | P17: =SUM(L17:O17) | Q17: =IF(P17=0,"0 - acceptance only",IF(P17<=3,"S",IF(P17<=10,"M",IF(P17<=25,"L","XL")))&" ("&P17&")") | S17: Medium | T17: Draft | U17: BIBS Product Owner with the Program Manager, Business Project Services | V17: DCR-177; CRQ11; CLR-CR-08 | W17: Drop 1, second release (Jan - Feb 2027) | X17: FRS BRD-00 chapter 5 (CLR-CR-08)
A18: CR-0014 | B18: Programme | C18: BRD-00 | D18: XC-02; BR-125, BR-152, BR-160, BR-203 (p.5, p.20-21) | E18: FR-CR-010, FR-CR-011 | F18: Scope addition — beyond BRD | G18: Centralised, real-time dashboards for all roles, with drill-down. | H18: Each module has its home page. Proposed: a role home with configurable widgets per role family (DASHBOARD_REFRESH_MINUTES 5). | I18: Umbrella requirement without an owning BRD; CRQ06 open (figures per role). | J18: Each role sees its work and figures on one page. | K18: All departments | L18: 3 | M18: 8 | N18: 4 | O18: 1 | P18: =SUM(L18:O18) | Q18: =IF(P18=0,"0 - acceptance only",IF(P18<=3,"S",IF(P18<=10,"M",IF(P18<=25,"L","XL")))&" ("&P18&")") | S18: Medium | T18: Draft | U18: BIBS Product Owner with the Program Manager, Business Project Services | V18: CRQ06; CLR-CR-11 | W18: Drop 1, second release (Jan - Feb 2027) | X18: FRS BRD-00 chapter 5 (CLR-CR-11)
A19: CR-0015 | B19: Drop 1 | C19: BRD-00 | D19: XC-13; BR-175 (p.23) | E19: FR-CR-090 | F19: Scope addition — beyond BRD | G19: Invoice Master List across workflows. | H19: Proposed: columns added to the Operations invoice ledger view. | I19: Umbrella requirement without an owning BRD; CRQ13 open. | J19: One list of invoices with their status across NB, Operations and Collections. | K19: Operations; Collections; Comptrollership | L19: 1 | M19: 3 | N19: 2 | O19: 1 | P19: =SUM(L19:O19) | Q19: =IF(P19=0,"0 - acceptance only",IF(P19<=3,"S",IF(P19<=10,"M",IF(P19<=25,"L","XL")))&" ("&P19&")") | S19: Low | T19: Draft | U19: BIBS Product Owner with the Program Manager, Business Project Services | V19: CRQ13; CLR-CR-12 | W19: Drop 1, second release (Jan - Feb 2027) | X19: FRS BRD-00 chapter 5 (CLR-CR-12)
A20: CR-0016 | B20: Drop 1 | C20: BRD-00 | D20: XC-19 (p.43); BRNB.100 related | E20: FR-CR-081; FR-NB-117 | F20: Integration dependency | G20: Invoice batch printing, delivery to insurers by SFTP and a delivery report, daily per insurer. | H20: Service invoices are issued and e-mailed. Proposed: daily batch per insurer at 20:00 PHT with SFTP delivery once the insurer SFTP addresses are given. | I20: CRQ18 open (format, SFTP addresses, replaces e-mail?). | J20: Insurers receive invoices in one daily file instead of single e-mails. | K20: Processing; Operations; BDOI IT | L20: 2 | M20: 6 | N20: 4 | O20: 1 | P20: =SUM(L20:O20) | Q20: =IF(P20=0,"0 - acceptance only",IF(P20<=3,"S",IF(P20<=10,"M",IF(P20<=25,"L","XL")))&" ("&P20&")") | S20: Medium | T20: Draft | U20: BDOI IT (integration owner) with the BIBS Product Owner | V20: CRQ18; CLR-CR-13 | W20: Drop 1, second release (Jan - Feb 2027) | X20: FRS BRD-00 chapter 5 (CLR-CR-13)
A21: CR-0017 | B21: Drop 0 | C21: BRD-00 | D21: XC-20 client migration and daily client batches (p.43); BRD-13 BRID 2.1 (p.7) | E21: FR-CR-082; FR-DM-031, FR-DM-032 | F21: Data migration | G21: Umbrella BRD: one-time client migration 2020 to present plus daily midday and EOD client batches with a modification report. | H21: Selective migration of clean client master data by the Data Migration programme; legacy read-only after cut-over; no daily client batches after go-live. | I21: Conflict between the umbrella and BRD-13, decided in the Data Migration design; CRQ19, DMQ05 open on the client scope. | J21: Legacy client changes stop at the freeze; BIBS is the client master from go-live. | K21: Business Project Services; Marketing; Processing | L21: 0 | M21: 0 | N21: 0 | O21: 1 | P21: =SUM(L21:O21) | Q21: =IF(P21=0,"0 - acceptance only",IF(P21<=3,"S",IF(P21<=10,"M",IF(P21<=25,"L","XL")))&" ("&P21&")") | S21: Medium | T21: For CCB review | U21: Program Manager, Business Project Services, with Comptrollership and Operations | V21: DCR-173; CRQ19; DMQ05; CLR-CR-14 | W21: Migration functions (Nov 2026 - Mar 2027) | X21: FRS BRD-00 chapter 5 (CLR-CR-14); register DCR-173
A22: CR-0018 | B22: Drop 1 | C22: BRD-00 | D22: XC-10; BR-039, BR-043 (p.14-15) | E22: FR-CR-093 | F22: Deferred pending BDOI answer | G22: SOA generated with the placement report and the Insurance Advice; service invoice issued to the insurer with the SOA at booking. | H22: Proposed after BDOI states which SOA is meant. | I22: CRQ12 open. | J22: Insurers and clients receive the SOA from BIBS instead of a manual document. | K22: Processing; Operations | L22: 1 | M22: 3 | N22: 2 | O22: 1 | P22: =SUM(L22:O22) | Q22: =IF(P22=0,"0 - acceptance only",IF(P22<=3,"S",IF(P22<=10,"M",IF(P22<=25,"L","XL")))&" ("&P22&")") | S22: Medium | T22: Draft | U22: BIBS Product Owner with the Program Manager, Business Project Services | V22: CRQ12; CLR-CR-15 | W22: After BDOI answer (slot set by the CCB) | X22: FRS BRD-00 chapter 5 (CLR-CR-15)
A23: CR-0019 | B23: Programme | C23: BRD-00 | D23: NFR sections of every BRD: service hours, availability, maintenance window, BCP (umbrella p.42-46) | E23: FRS BRD-00 section 7 | F23: NFR / infrastructure change | G23: Service hours differ by BRD (07:00-22:00 Mon-Sat NB and RN; 06:00-20:00 Mon-Fri Claims; 08:00-18:00 Mon-Fri SANC; others); availability 99.9% to 100%; maintenance windows 19:00-07:00 (ACCT) to 00:00-04:00 (SANC, SP). | H23: Proposed one BIBS-wide set: service 06:00-22:00 Mon-Sat plus month-end weekends; 99.9% within service hours; maintenance 00:00-04:00; batch after 22:00. | I23: XQ08; OQ44, CQ25, AQ27, PQ18, CLQ24, EBQ25, CSQ11, SP SQ21 / SQ22, RQ28. | J23: One service level for all departments; month-end work covered. | K23: All departments; BDOI IT | L23: 2 | M23: 0 | N23: 0 | O23: 2 | P23: =SUM(L23:O23) | Q23: =IF(P23=0,"0 - acceptance only",IF(P23<=3,"S",IF(P23<=10,"M",IF(P23<=25,"L","XL")))&" ("&P23&")") | S23: High | T23: For CCB review | U23: BIBS Product Owner with the Program Manager, Business Project Services | V23: DCR-133; DCR-134; DCR-138; DCR-057; XQ08 | W23: FRS sign-off (Nov 2026) | X23: Register DCR-133, 134, 138; FRS BRD-00 section 7
A24: CR-0020 | B24: Programme | C24: BRD-00 | D24: NFR recovery objectives: RPO 24 h (OPS, PM, EB), 4 h (CLXN, CLM, CSF); CSF backup every 15 minutes (BRCSF-011.001, p.11) | E24: FRS BRD-00 section 7; FR-CSF-043 | F24: NFR / infrastructure change | G24: Recovery objectives and backup frequency differ by BRD; the DR location is not stated. | H24: RPO 15 minutes (continuous WAL archiving) and RTO 4 hours for the whole platform, as in the IER. Proposed DR: RDS cross-region replica, S3 cross-region replication, EKS standby scaled at failover, DR runbook and a failover test. DR region to be named after the data-residency check. | I24: IER workbook v20 (BDO IT) states RPO 15 minutes, RTO 4 hours; IQ26 open on the DR region. | J24: One recovery target; CSF 15-minute backup met by continuous archiving. | K24: BDOI IT; all departments | L24: 2 | M24: 3 | N24: 4 | O24: 2 | P24: =SUM(L24:O24) | Q24: =IF(P24=0,"0 - acceptance only",IF(P24<=3,"S",IF(P24<=10,"M",IF(P24<=25,"L","XL")))&" ("&P24&")") | S24: High | T24: For CCB review | U24: BDO Cloud and Digital Operations Engineering (IER owner) with BDOI IT | V24: DCR-135; DCR-225; CSQ11; IQ26 | W24: Before go-live (Oct - Dec 2027) | X24: Register DCR-135, DCR-225; Programme alignment 6.2, 6.5
A25: CR-0021 | B25: Programme | C25: BRD-00 | D25: Retention: umbrella 5 years online / 15 offline (p.42-46); BRD-7 10 / 15; BRD-5, 10, 12 5 / 5; BRNB.106 (p.12) | E25: FR-NB-137; FRS BRD-00 section 7 | F25: NFR / infrastructure change | G25: Retain, archive and purge per the BRD values, which differ by BRD. | H25: Retention rules per record type with review counts (default 5 years online, 15 years archive; backup kept 7 years). Archive and purge wait until BDOI gives the retention per record type. | I25: Q39, CRQ22 open. | J25: Legal record keeping; database size and cost over time. | K25: Compliance; Comptrollership; BDOI IT; all record owners | L25: 2 | M25: 8 | N25: 4 | O25: 2 | P25: =SUM(L25:O25) | Q25: =IF(P25=0,"0 - acceptance only",IF(P25<=3,"S",IF(P25<=10,"M",IF(P25<=25,"L","XL")))&" ("&P25&")") | S25: High | T25: Draft | U25: BIBS Product Owner with the Program Manager, Business Project Services | V25: DCR-136; DCR-167; DCR-209; Q39; CRQ22 | W25: After BDOI answer (slot set by the CCB) | X25: FRS BRD-1 chapter 21 (BRNB.106); register DCR-136
A26: CR-0022 | B26: Programme | C26: BRD-00 | D26: Response times: 2 s (SP) to 10 s (NB, RN, UAM); umbrella under 5 s for every role (p.42) | E26: FRS BRD-00 section 7 | F26: NFR / infrastructure change | G26: Response-time targets differ by BRD. | H26: Proposed: screens and single-record actions p95 under 2 seconds; reports and batches run as jobs with progress. Proved in the performance test (deliverable 28). | I26: CRQ21 open. | J26: One testable target for every screen. | K26: All departments | L26: 1 | M26: 0 | N26: 0 | O26: 1 | P26: =SUM(L26:O26) | Q26: =IF(P26=0,"0 - acceptance only",IF(P26<=3,"S",IF(P26<=10,"M",IF(P26<=25,"L","XL")))&" ("&P26&")") | S26: Medium | T26: For CCB review | U26: BIBS Product Owner with the Program Manager, Business Project Services | V26: DCR-137; DCR-165; CRQ21 | W26: FRS sign-off (Nov 2026) | X26: Register DCR-137, DCR-165
A27: CR-0023 | B27: Programme | C27: BRD-00 | D27: Umbrella p.42: 1,344 named / 429 concurrent users; IER: about 1,200 internal users | E27: FRS BRD-00 section 7 | F27: NFR / infrastructure change | G27: User counts differ between the umbrella, BRD-3, BRD-7, BRD-8 and the IER. | H27: Sized and tested for 429 concurrent sessions as the peak case; no external users. | I27: CRQ21, CRQ24, IQ32 open. | J27: Infrastructure cost and the performance test depend on the figure. | K27: BDOI IT | L27: 1 | M27: 0 | N27: 0 | O27: 1 | P27: =SUM(L27:O27) | Q27: =IF(P27=0,"0 - acceptance only",IF(P27<=3,"S",IF(P27<=10,"M",IF(P27<=25,"L","XL")))&" ("&P27&")") | S27: Medium | T27: For CCB review | U27: BDO Cloud and Digital Operations Engineering (IER owner) with BDOI IT | V27: DCR-166; DCR-232; IQ32; CRQ24 | W27: FRS sign-off (Nov 2026) | X27: Register DCR-166, DCR-232
... A32: CR-0028 | B32: Programme | C32: BRD-00 | D32: BDOI answer A4 of 26-Sep-2026 (documents in S3 only); every BRD that stores files | E32: FRS BRD-00 section 4 (document generation, data management) | F32: NFR / infrastructure change | G32: Documents and attachments are stored in an S3 bucket only. | H32: Proposed: every file in S3 with its metadata in PostgreSQL; signed links after the permission check and audit; quarantine until the malware scan passes; retention and legal hold; every module moved to the S3 store and the existing files copied with a checksum check. | I32: Decision D9 (option C of DOCUMENT_STORAGE_DECISION, approved 26-Sep-2026); five design points still to confirm (IQ31). | J32: Smaller database and backups; encryption with BDOI keys; Object Lock for records under legal hold. | K32: BDOI IT; Compliance; all departments that upload or print documents | L32: 3 | M32: 22 | N32: 8 | O32: 3 | P32: =SUM(L32:O32) | Q32: =IF(P32=0,"0 - acceptance only",IF(P32<=3,"S",IF(P32<=10,"M",IF(P32<=25,"L","XL")))&" ("&P32&")") | S32: High | T32: For CCB review | U32: BDOI IT (integration owner) with the BIBS Product Owner | V32: DCR-227; D9; A4; IQ31; DSQ01-DSQ04 | W32: Drop 1, first release (Nov - Dec 2026) | X32: Document storage proposal section 4; Programme alignment 6.3
A33: CR-0029 | B33: Programme | C33: BRD-00 | D33: IER HW and SW sheet: ElastiCache Redis 7 "(cluster)" in Pre-Prod and PROD | E33: FRS BRD-00 section 7 | F33: NFR / infrastructure change | G33: The IER asks for ElastiCache in cluster mode. | H33: BIBS runs Redis 7 with cluster mode disabled (one shard, Multi-AZ replica); the cache clear and the job lock assume one shard. | I33: Technical constraint; IQ34 open. | J33: None if accepted; cluster mode enabled needs a code change. | K33: BDOI IT | L33: 0 | M33: 0 | N33: 0 | O33: 1 | P33: =SUM(L33:O33) | Q33: =IF(P33=0,"0 - acceptance only",IF(P33<=3,"S",IF(P33<=10,"M",IF(P33<=25,"L","XL")))&" ("&P33&")") | R33: 10 | S33: Low | T33: For CCB review | U33: BDO Cloud and Digital Operations Engineering (IER owner) with BDOI IT | V33: DCR-228; IQ34 | W33: Infrastructure before SIT (by Jan 2027) | X33: Register DCR-228; Programme alignment 6.2
A34: CR-0030 | B34: Programme | C34: BRD-00 | D34: IER VDI sheet: OpenJDK 17, Node 20, Angular SPA; RDS rows "RHEL 9.x" | E34: FRS BRD-00 section 7 | F34: NFR / infrastructure change | G34: The IER names JDK 17, Node 20 and an Angular front end. | H34: BIBS runs on Java 21, Spring Boot 3.5, Node 22 and React 19. Proposed IER correction: Temurin 21, Maven 3.9, Node 22, no Angular; RDS rows without an operating system. | I34: Technology baseline of BIBS; IQ28, IQ29. | J34: VDI images and base images follow the real stack. | K34: BDOI IT | L34: 0 | M34: 0 | N34: 0 | O34: 1 | P34: =SUM(L34:O34) | Q34: =IF(P34=0,"0 - acceptance only",IF(P34<=3,"S",IF(P34<=10,"M",IF(P34<=25,"L","XL")))&" ("&P34&")") | S34: Low | T34: For CCB review | U34: BDO Cloud and Digital Operations Engineering (IER owner) with BDOI IT | V34: DCR-224; IQ28; IQ29 | W34: Infrastructure before SIT (by Jan 2027) | X34: Register DCR-224; Programme alignment 6.2
A35: CR-0031 | B35: Programme | C35: BRD-00 | D35: IER assumptions: non-production 12 x 5 hours | E35: FRS BRD-00 section 7 | F35: NFR / infrastructure change | G35: Non-production environments run 12 hours a day, 5 days a week. | H35: Night jobs run from 20:00 to 06:00 PHT and would never fire. Proposed: non-production crons moved into the window by environment variables; extended hours booked for batch, month-end and migration rehearsal cycles. | I35: Technical constraint; IQ27 open. | J35: SIT and UAT can test the batch cycle and month-end. | K35: BDOI IT; QA | L35: 1 | M35: 1 | N35: 1 | O35: 1 | P35: =SUM(L35:O35) | Q35: =IF(P35=0,"0 - acceptance only",IF(P35<=3,"S",IF(P35<=10,"M",IF(P35<=25,"L","XL")))&" ("&P35&")") | S35: Medium | T35: For CCB review | U35: BDO Cloud and Digital Operations Engineering (IER owner) with BDOI IT | V35: DCR-226; IQ27 | W35: Infrastructure before SIT (by Jan 2027) | X35: Register DCR-226; Programme alignment 6.5
A36: CR-0032 | B36: Programme | C36: BRD-00 | D36: IER workbook v20 (HW and SW sheet, infrastructure diagram, architecture diagram): GitLab runner, Jenkins, ArgoCD and Helm | E36: FRS BRD-00 section 7 | F36: NFR / infrastructure change | G36: Three CI / CD toolchains appear in the IER; the BDO standard is not named. | H36: Proposed: a Helm chart or Kustomize overlays per environment and a pipeline on the toolchain BDO IT names (container registry, image base, code-quality server). | I36: IQ29 open. | J36: Releases follow BDO change management and tooling. | K36: BDOI IT | L36: 1 | M36: 5 | N36: 2 | O36: 1 | P36: =SUM(L36:O36) | Q36: =IF(P36=0,"0 - acceptance only",IF(P36<=3,"S",IF(P36<=10,"M",IF(P36<=25,"L","XL")))&" ("&P36&")") | S36: Medium | T36: Draft | U36: BDO Cloud and Digital Operations Engineering (IER owner) with BDOI IT | V36: DCR-224; IQ29 | W36: Infrastructure before SIT (by Jan 2027) | X36: Programme alignment 6.2, 6.6
A37: CR-0033 | B37: Programme | C37: BRD-00 | D37: IER: Dynatrace (VDI, K8s sheets) against CloudWatch, X-Ray, Prometheus, Loki, Grafana (diagram); BRD-11 NFR remote log server (p.14) | E37: FRS BRD-11 interfaces (remote log server, on hold) | F37: NFR / infrastructure change | G37: Two observability stacks named; BRD-11 asks for logs on a remote log server. | H37: Health checks, metrics for Prometheus and structured logs. Proposed: monitoring collectors and log shipping for the stack BDO IT chooses; alert routing per the alert catalogue (deliverable 38). | I37: IQ30 open. | J37: Production support sees BIBS in the BDO monitoring tools. | K37: BDOI IT; production support | L37: 1 | M37: 4 | N37: 2 | O37: 1 | P37: =SUM(L37:O37) | Q37: =IF(P37=0,"0 - acceptance only",IF(P37<=3,"S",IF(P37<=10,"M",IF(P37<=25,"L","XL")))&" ("&P37&")") | S37: Medium | T37: Draft | U37: BDO Cloud and Digital Operations Engineering (IER owner) with BDOI IT | V37: IQ30 | W37: Infrastructure before SIT (by Jan 2027) | X37: Programme alignment 6.2; FRS BRD-11 interfaces
A38: CR-0034 | B38: Programme | C38: BRD-00 | D38: Hosting appendix (access restricted to personnel in the Philippines); IER VDI sheet (15 users) | E38: FRS BRD-00 section 7 | F38: NFR / infrastructure change | G38: Access is restricted to personnel in the Philippines; the IER plans 15 VDI users without saying where they sit. | H38: Proposed: production and UAT reachable only from the Philippines; DEV and SIT with masked data reachable by named vendor staff through VDI. | I38: IQ28 open. | J38: Defines who can support the platform from where. | K38: BDOI IT; Compliance | L38: 1 | M38: 0 | N38: 0 | O38: 1 | P38: =SUM(L38:O38) | Q38: =IF(P38=0,"0 - acceptance only",IF(P38<=3,"S",IF(P38<=10,"M",IF(P38<=25,"L","XL")))&" ("&P38&")") | S38: Medium | T38: For CCB review | U38: BDO Cloud and Digital Operations Engineering (IER owner) with BDOI IT | V38: DCR-231; IQ28 | W38: Infrastructure before SIT (by Jan 2027) | X38: Register DCR-231
A39: CR-0035 | B39: Programme | C39: BRD-00 | D39: Concept paper "Advance Implementation of Renewal Processing" V1.0 (MANCOM, 06-Sep-2026); timeline slide | E39: FRS BRD-6 v1.1 introduction; FRS BRD-13 (FR-DM-120) | F39: BRD conflict resolved by decision | G39: The signed concept paper proposes an early renewal release by 15-Aug-2027 for January to May 2028 expiries, with early migration of client and reference data. | H39: Superseded: every module goes live together in January 2028; no early release and no early migration. Its capabilities stay in scope for January 2028. | I39: BDOI answer A1 of 26-Sep-2026. | J39: One cut-over; renewals of January to May 2028 run in BIBS after go-live (CR-0139). | K39: Marketing; Processing; Business Project Services | L39: 0 | M39: 0 | N39: 0 | O39: 1 | P39: =SUM(L39:O39) | Q39: =IF(P39=0,"0 - acceptance only",IF(P39<=3,"S",IF(P39<=10,"M",IF(P39<=25,"L","XL")))&" ("&P39&")") | S39: High | T39: For CCB review | U39: BIBS Product Owner with the Program Manager, Business Project Services | V39: DCR-218; DCR-240; A1 | W39: FRS sign-off (Nov 2026) | X39: Programme alignment 3; register DCR-218, DCR-240
A40: CR-0036 | B40: Programme | C40: BRD-00 | D40: Drop plan: BRD-10 Sanction Screening and CSF service requests not placed; Drop 0 items 0.1, 0.4, 0.5 without a BRD | E40: FRS BRD-00 section 3; FRS BRD-10; FRS BRD-9 | F40: BRD conflict resolved by decision | G40: The drop plan does not place BRD-10 or the CSF service-request functions, and names Drop 0 items without a governing BRD. | H40: Proposed: BRD-10 in Drop 1 with Client Onboarding; CSF service requests in Drop 2; Drop 0 acceptance on BRD-11 plus EIAM (item 0.1), CORE-17 of the umbrella (item 0.4) and the workflows of each BRD (item 0.5). Documents are filed by this map. | I40: IQ23, IQ24 open. | J40: Test and sign-off windows for the two BRDs. | K40: Compliance; Contact Center Management; Business Project Services | L40: 0 | M40: 0 | N40: 0 | O40: 1 | P40: =SUM(L40:O40) | Q40: =IF(P40=0,"0 - acceptance only",IF(P40<=3,"S",IF(P40<=10,"M",IF(P40<=25,"L","XL")))&" ("&P40&")") | S40: Medium | T40: For CCB review | U40: BIBS Product Owner with the Program Manager, Business Project Services | V40: DCR-213; DCR-214; IQ23; IQ24 | W40: FRS sign-off (Nov 2026) | X40: Programme alignment 2.2 items 5-6
A41: CR-0037 | B41: Programme | C41: BRD-00 | D41: BRD-8 BRID-022.01 (PDF/XLSX/CSV/WORD); other BRDs Excel and PDF; FRBS 3.2.0 (p.63) board schedules in Word | E41: FRS BRD-00 (report generation); FRS BRD-5 Vol.1 chapter 12 | F41: Scope addition — beyond BRD | G41: BRD-8 asks for Word export of reports; BRD-5 asks for board schedules in Word; the other BRDs ask for Excel and PDF. | H41: Word export for every report, Word on documents and schedules (GL-SCHEDULE, GL-BVA, FRBS-MANCOM-MARKET, RI-SOA, FIN-AP-VOUCHER), and a Word copy of each composed business document. | I41: Work item P2; FRS BRD-5 Vol.1 clarification CLR-AC-10. | J41: All departments can export to Word, beyond what their BRD asks. | K41: All report users; Comptrollership | L41: 0 | M41: 0 | N41: 0 | O41: 0 | P41: =SUM(L41:O41) | Q41: =IF(P41=0,"0 - acceptance only",IF(P41<=3,"S",IF(P41<=10,"M",IF(P41<=25,"L","XL")))&" ("&P41&")") | S41: Low | T41: For acceptance | U41: BIBS Product Owner with the Program Manager, Business Project Services | V41: DCR-161; P2; EBQ21 | W41: FRS sign-off (Nov 2026) | X41: Deliverables plan item 17; register DCR-161
A42: CR-0038 | B42: Programme | C42: BRD-00 | D42: BRD-7, BRD-4, BRD-10, BRD-2, BRD-1 shared-drive and FS04 targets; BRNB.110 (p.14); SNSRP-706 (p.19-20) | E42: FR-NB-038; FR-SS-071; FR-CM-064; FR-OP (extracts) | F42: Behaviour differs from BRD | G42: Several BRDs send files or lists to a shared drive or a designated folder. | H42: Files are kept in BIBS with download and notification; a shared-drive or SFTP drop is added only where a downstream system reads the file (for example FS04, CR-0104). | I42: BRD-12 asks for one master database instead of shared-drive files; OQ17, CLQ21. | J42: No uncontrolled copies on shared drives; users download from BIBS. | K42: Claims; Compliance; Operations; Marketing | L42: 0 | M42: 0 | N42: 0 | O42: 0 | P42: =SUM(L42:O42) | Q42: =IF(P42=0,"0 - acceptance only",IF(P42<=3,"S",IF(P42<=10,"M",IF(P42<=25,"L","XL")))&" ("&P42&")") | S42: Low | T42: For acceptance | U42: BIBS Product Owner with the Program Manager, Business Project Services | V42: DCR-152; OQ17; CLQ21 | W42: FRS sign-off (Nov 2026) | X42: Register DCR-152; FRS BRD-1 chapter 21
A43: CR-0039 | B43: Programme | C43: BRD-00 | D43: Ageing buckets: ACSL 2.14.x (p.124); Claims report list; BRCLXN reports; Cashiering reports | E43: FR-CM-060; FR-CL (reports); FR-AS (ACSL reports) | F43: BRD conflict resolved by decision | G43: Ageing buckets differ: ACSL 0-30 to over 730 days; Claims 0-30 to 181+; Collections and Cashiering without buckets. | H43: Proposed: ageing buckets configurable per report family, ACSL buckets as the default, as a shared setting. | I43: Conflict between BRDs; OQ43. | J43: Ageing reports agree across departments. | K43: Comptrollership; Claims; Collections; Operations | L43: 1 | M43: 3 | N43: 2 | O43: 0 | P43: =SUM(L43:O43) | Q43: =IF(P43=0,"0 - acceptance only",IF(P43<=3,"S",IF(P43<=10,"M",IF(P43<=25,"L","XL")))&" ("&P43&")") | S43: Low | T43: Draft | U43: BIBS Product Owner with the Program Manager, Business Project Services | V43: DCR-158; OQ43 | W43: Drop 1, second release (Jan - Feb 2027) | X43: Register DCR-158
A44: CR-0040 | B44: Programme | C44: BRD-00 | D44: BRD-8 (documents restricted by process), BRD-9 BRCSF-006, 009 (p.9-10), BRD-7 claim document types | E44: FR-CSF-030, FR-CSF-033; FR-EB-002 | F44: BRD conflict resolved by decision | G44: Contact Center users view and resend renewal advices and claims reports; EB restricts documents by process; claim documents may be confidential. | H44: Access class per document type; CSF users may view RENEWAL_ADVICE and CLAIM_REPORT; the loss advice and insurer claim reports are stored as CLAIM_REPORT. Final confidentiality matrix to confirm. | I44: XQ04, XQ05; CSQ07, EBQ15, CLQ26. | J44: Contact Center sees only the document types it is cleared for. | K44: Contact Center Management; Claims; Employee Benefits | L44: 0 | M44: 0 | N44: 0 | O44: 0 | P44: =SUM(L44:O44) | Q44: =IF(P44=0,"0 - acceptance only",IF(P44<=3,"S",IF(P44<=10,"M",IF(P44<=25,"L","XL")))&" ("&P44&")") | S44: Medium | T44: For acceptance | U44: BIBS Product Owner with the Program Manager, Business Project Services | V44: DCR-148; XQ04; XQ05; P3 | W44: FRS sign-off (Nov 2026) | X44: Cross-BRD decisions 5, 6.1
A45: CR-0041 | B45: Programme | C45: BRD-00 | D45: Report List as of 27-Apr-2026: #69, #73, #168 (BDOI remarks "DELETE" / "no longer needed") | E45: FRS BRD-00 report generation | F45: Scope reduction / descoped | G45: The Report List carries #69, #73 and #168. | H45: Marked DROPPED and not in scope, per the BDOI remarks in the Report List. | I45: Report List remarks (DCR-130, answered). | J45: None; the data is in the Policy Transmittal and e-policy reports. | K45: Report SMEs named in the Report List | L45: 0 | M45: 0 | N45: 0 | O45: 0 | P45: =SUM(L45:O45) | Q45: =IF(P45=0,"0 - acceptance only",IF(P45<=3,"S",IF(P45<=10,"M",IF(P45<=25,"L","XL")))&" ("&P45&")") | S45: Low | T45: For acceptance | U45: BIBS Product Owner with the Program Manager, Business Project Services | V45: DCR-130 | W45: FRS sign-off (Nov 2026) | X45: Register DCR-130
...

Sheet Summary
A1: Summary
A2: Counts and man-days by drop, BRD, deviation type, status and priority. Formulas read the Register sheet, so the figures follow any change to it.
A4: By drop
A5: Value | B5: Description | C5: CRs | D5: High | E5: Draft | F5: For CCB review | G5: For acceptance | H5: Analysis (md) | I5: Dev. (md) | J5: Test (md) | K5: Doc. (md) | L5: Total (md)
A6: Drop 0 | B6: Drop 0 - Setup and Data Migration | C6: =COUNTIFS(Register!$B$5:$B$682,"Drop 0") | D6: =COUNTIFS(Register!$B$5:$B$682,"Drop 0",Register!$S$5:$S$682,"High") | E6: =COUNTIFS(Register!$B$5:$B$682,"Drop 0",Register!$T$5:$T$682,"Draft") | F6: =COUNTIFS(Register!$B$5:$B$682,"Drop 0",Register!$T$5:$T$682,"For CCB review") | G6: =COUNTIFS(Register!$B$5:$B$682,"Drop 0",Register!$T$5:$T$682,"For acceptance") | H6: =SUMIFS(Register!$L$5:$L$682,Register!$B$5:$B$682,"Drop 0") | I6: =SUMIFS(Register!$M$5:$M$682,Register!$B$5:$B$682,"Drop 0") | J6: =SUMIFS(Register!$N$5:$N$682,Register!$B$5:$B$682,"Drop 0") | K6: =SUMIFS(Register!$O$5:$O$682,Register!$B$5:$B$682,"Drop 0") | L6: =SUMIFS(Register!$P$5:$P$682,Register!$B$5:$B$682,"Drop 0")
A7: Drop 1 | B7: Drop 1 - Transactional (upstream and downstream) | C7: =COUNTIFS(Register!$B$5:$B$682,"Drop 1") | D7: =COUNTIFS(Register!$B$5:$B$682,"Drop 1",Register!$S$5:$S$682,"High") | E7: =COUNTIFS(Register!$B$5:$B$682,"Drop 1",Register!$T$5:$T$682,"Draft") | F7: =COUNTIFS(Register!$B$5:$B$682,"Drop 1",Register!$T$5:$T$682,"For CCB review") | G7: =COUNTIFS(Register!$B$5:$B$682,"Drop 1",Register!$T$5:$T$682,"For acceptance") | H7: =SUMIFS(Register!$L$5:$L$682,Register!$B$5:$B$682,"Drop 1") | I7: =SUMIFS(Register!$M$5:$M$682,Register!$B$5:$B$682,"Drop 1") | J7: =SUMIFS(Register!$N$5:$N$682,Register!$B$5:$B$682,"Drop 1") | K7: =SUMIFS(Register!$O$5:$O$682,Register!$B$5:$B$682,"Drop 1") | L7: =SUMIFS(Register!$P$5:$P$682,Register!$B$5:$B$682,"Drop 1")
A8: Drop 2 | B8: Drop 2 - Independent | C8: =COUNTIFS(Register!$B$5:$B$682,"Drop 2") | D8: =COUNTIFS(Register!$B$5:$B$682,"Drop 2",Register!$S$5:$S$682,"High") | E8: =COUNTIFS(Register!$B$5:$B$682,"Drop 2",Register!$T$5:$T$682,"Draft") | F8: =COUNTIFS(Register!$B$5:$B$682,"Drop 2",Register!$T$5:$T$682,"For CCB review") | G8: =COUNTIFS(Register!$B$5:$B$682,"Drop 2",Register!$T$5:$T$682,"For acceptance") | H8: =SUMIFS(Register!$L$5:$L$682,Register!$B$5:$B$682,"Drop 2") | I8: =SUMIFS(Register!$M$5:$M$682,Register!$B$5:$B$682,"Drop 2") | J8: =SUMIFS(Register!$N$5:$N$682,Register!$B$5:$B$682,"Drop 2") | K8: =SUMIFS(Register!$O$5:$O$682,Register!$B$5:$B$682,"Drop 2") | L8: =SUMIFS(Register!$P$5:$P$682,Register!$B$5:$B$682,"Drop 2")
A9: Programme | B9: Programme (cross-drop) | C9: =COUNTIFS(Register!$B$5:$B$682,"Programme") | D9: =COUNTIFS(Register!$B$5:$B$682,"Programme",Register!$S$5:$S$682,"High") | E9: =COUNTIFS(Register!$B$5:$B$682,"Programme",Register!$T$5:$T$682,"Draft") | F9: =COUNTIFS(Register!$B$5:$B$682,"Programme",Register!$T$5:$T$682,"For CCB review") | G9: =COUNTIFS(Register!$B$5:$B$682,"Programme",Register!$T$5:$T$682,"For acceptance") | H9: =SUMIFS(Register!$L$5:$L$682,Register!$B$5:$B$682,"Programme") | I9: =SUMIFS(Register!$M$5:$M$682,Register!$B$5:$B$682,"Programme") | J9: =SUMIFS(Register!$N$5:$N$682,Register!$B$5:$B$682,"Programme") | K9: =SUMIFS(Register!$O$5:$O$682,Register!$B$5:$B$682,"Programme") | L9: =SUMIFS(Register!$P$5:$P$682,Register!$B$5:$B$682,"Programme")
A10: Phase 2 | B10: Reinsurance module (BDOI answer A3) | C10: =COUNTIFS(Register!$B$5:$B$682,"Phase 2") | D10: =COUNTIFS(Register!$B$5:$B$682,"Phase 2",Register!$S$5:$S$682,"High") | E10: =COUNTIFS(Register!$B$5:$B$682,"Phase 2",Register!$T$5:$T$682,"Draft") | F10: =COUNTIFS(Register!$B$5:$B$682,"Phase 2",Register!$T$5:$T$682,"For CCB review") | G10: =COUNTIFS(Register!$B$5:$B$682,"Phase 2",Register!$T$5:$T$682,"For acceptance") | H10: =SUMIFS(Register!$L$5:$L$682,Register!$B$5:$B$682,"Phase 2") | I10: =SUMIFS(Register!$M$5:$M$682,Register!$B$5:$B$682,"Phase 2") | J10: =SUMIFS(Register!$N$5:$N$682,Register!$B$5:$B$682,"Phase 2") | K10: =SUMIFS(Register!$O$5:$O$682,Register!$B$5:$B$682,"Phase 2") | L10: =SUMIFS(Register!$P$5:$P$682,Register!$B$5:$B$682,"Phase 2")
A11: Total | C11: =SUM(C6:C10) | D11: =SUM(D6:D10) | E11: =SUM(E6:E10) | F11: =SUM(F6:F10) | G11: =SUM(G6:G10) | H11: =SUM(H6:H10) | I11: =SUM(I6:I10) | J11: =SUM(J6:J10) | ... L11: =SUM(L6:L10)
A13: By BRD
A14: Value | B14: Description | C14: CRs | D14: High | E14: Draft | F14: For CCB review | G14: For acceptance | H14: Analysis (md) | I14: Dev. (md) | J14: Test (md) | K14: Doc. (md) | L14: Total (md)
A15: BRD-00 | B15: Core Replacement (umbrella) and programme | C15: =COUNTIFS(Register!$C$5:$C$682,"BRD-00") | D15: =COUNTIFS(Register!$C$5:$C$682,"BRD-00",Register!$S$5:$S$682,"High") | E15: =COUNTIFS(Register!$C$5:$C$682,"BRD-00",Register!$T$5:$T$682,"Draft") | F15: =COUNTIFS(Register!$C$5:$C$682,"BRD-00",Register!$T$5:$T$682,"For CCB review") | G15: =COUNTIFS(Register!$C$5:$C$682,"BRD-00",Register!$T$5:$T$682,"For acceptance") | H15: =SUMIFS(Register!$L$5:$L$682,Register!$C$5:$C$682,"BRD-00") | I15: =SUMIFS(Register!$M$5:$M$682,Register!$C$5:$C$682,"BRD-00") | J15: =SUMIFS(Register!$N$5:$N$682,Register!$C$5:$C$682,"BRD-00") | K15: =SUMIFS(Register!$O$5:$O$682,Register!$C$5:$C$682,"BRD-00") | L15: =SUMIFS(Register!$P$5:$P$682,Register!$C$5:$C$682,"BRD-00")
A16: BRD-01 | B16: New Business | C16: =COUNTIFS(Register!$C$5:$C$682,"BRD-01") | D16: =COUNTIFS(Register!$C$5:$C$682,"BRD-01",Register!$S$5:$S$682,"High") | E16: =COUNTIFS(Register!$C$5:$C$682,"BRD-01",Register!$T$5:$T$682,"Draft") | F16: =COUNTIFS(Register!$C$5:$C$682,"BRD-01",Register!$T$5:$T$682,"For CCB review") | G16: =COUNTIFS(Register!$C$5:$C$682,"BRD-01",Register!$T$5:$T$682,"For acceptance") | H16: =SUMIFS(Register!$L$5:$L$682,Register!$C$5:$C$682,"BRD-01") | I16: =SUMIFS(Register!$M$5:$M$682,Register!$C$5:$C$682,"BRD-01") | J16: =SUMIFS(Register!$N$5:$N$682,Register!$C$5:$C$682,"BRD-01") | K16: =SUMIFS(Register!$O$5:$O$682,Register!$C$5:$C$682,"BRD-01") | L16: =SUMIFS(Register!$P$5:$P$682,Register!$C$5:$C$682,"BRD-01")
A17: BRD-02 | B17: Operations | C17: =COUNTIFS(Register!$C$5:$C$682,"BRD-02") | D17: =COUNTIFS(Register!$C$5:$C$682,"BRD-02",Register!$S$5:$S$682,"High") | E17: =COUNTIFS(Register!$C$5:$C$682,"BRD-02",Register!$T$5:$T$682,"Draft") | F17: =COUNTIFS(Register!$C$5:$C$682,"BRD-02",Register!$T$5:$T$682,"For CCB review") | G17: =COUNTIFS(Register!$C$5:$C$682,"BRD-02",Register!$T$5:$T$682,"For acceptance") | H17: =SUMIFS(Register!$L$5:$L$682,Register!$C$5:$C$682,"BRD-02") | I17: =SUMIFS(Register!$M$5:$M$682,Register!$C$5:$C$682,"BRD-02") | J17: =SUMIFS(Register!$N$5:$N$682,Register!$C$5:$C$682,"BRD-02") | K17: =SUMIFS(Register!$O$5:$O$682,Register!$C$5:$C$682,"BRD-02") | L17: =SUMIFS(Register!$P$5:$P$682,Register!$C$5:$C$682,"BRD-02")
A18: BRD-03 | B18: Product Maintenance | C18: =COUNTIFS(Register!$C$5:$C$682,"BRD-03") | D18: =COUNTIFS(Register!$C$5:$C$682,"BRD-03",Register!$S$5:$S$682,"High") | E18: =COUNTIFS(Register!$C$5:$C$682,"BRD-03",Register!$T$5:$T$682,"Draft") | F18: =COUNTIFS(Register!$C$5:$C$682,"BRD-03",Register!$T$5:$T$682,"For CCB review") | G18: =COUNTIFS(Register!$C$5:$C$682,"BRD-03",Register!$T$5:$T$682,"For acceptance") | H18: =SUMIFS(Register!$L$5:$L$682,Register!$C$5:$C$682,"BRD-03") | I18: =SUMIFS(Register!$M$5:$M$682,Register!$C$5:$C$682,"BRD-03") | J18: =SUMIFS(Register!$N$5:$N$682,Register!$C$5:$C$682,"BRD-03") | K18: =SUMIFS(Register!$O$5:$O$682,Register!$C$5:$C$682,"BRD-03") | L18: =SUMIFS(Register!$P$5:$P$682,Register!$C$5:$C$682,"BRD-03")
A19: BRD-04 | B19: Collections | C19: =COUNTIFS(Register!$C$5:$C$682,"BRD-04") | D19: =COUNTIFS(Register!$C$5:$C$682,"BRD-04",Register!$S$5:$S$682,"High") | E19: =COUNTIFS(Register!$C$5:$C$682,"BRD-04",Register!$T$5:$T$682,"Draft") | F19: =COUNTIFS(Register!$C$5:$C$682,"BRD-04",Register!$T$5:$T$682,"For CCB review") | G19: =COUNTIFS(Register!$C$5:$C$682,"BRD-04",Register!$T$5:$T$682,"For acceptance") | H19: =SUMIFS(Register!$L$5:$L$682,Register!$C$5:$C$682,"BRD-04") | I19: =SUMIFS(Register!$M$5:$M$682,Register!$C$5:$C$682,"BRD-04") | J19: =SUMIFS(Register!$N$5:$N$682,Register!$C$5:$C$682,"BRD-04") | K19: =SUMIFS(Register!$O$5:$O$682,Register!$C$5:$C$682,"BRD-04") | L19: =SUMIFS(Register!$P$5:$P$682,Register!$C$5:$C$682,"BRD-04")
A20: BRD-05 | B20: Accounting, Disbursement and ACSL | C20: =COUNTIFS(Register!$C$5:$C$682,"BRD-05") | D20: =COUNTIFS(Register!$C$5:$C$682,"BRD-05",Register!$S$5:$S$682,"High") | E20: =COUNTIFS(Register!$C$5:$C$682,"BRD-05",Register!$T$5:$T$682,"Draft") | F20: =COUNTIFS(Register!$C$5:$C$682,"BRD-05",Register!$T$5:$T$682,"For CCB review") | G20: =COUNTIFS(Register!$C$5:$C$682,"BRD-05",Register!$T$5:$T$682,"For acceptance") | H20: =SUMIFS(Register!$L$5:$L$682,Register!$C$5:$C$682,"BRD-05") | I20: =SUMIFS(Register!$M$5:$M$682,Register!$C$5:$C$682,"BRD-05") | J20: =SUMIFS(Register!$N$5:$N$682,Register!$C$5:$C$682,"BRD-05") | K20: =SUMIFS(Register!$O$5:$O$682,Register!$C$5:$C$682,"BRD-05") | L20: =SUMIFS(Register!$P$5:$P$682,Register!$C$5:$C$682,"BRD-05")
A21: BRD-06 | B21: Renewal | C21: =COUNTIFS(Register!$C$5:$C$682,"BRD-06") | D21: =COUNTIFS(Register!$C$5:$C$682,"BRD-06",Register!$S$5:$S$682,"High") | E21: =COUNTIFS(Register!$C$5:$C$682,"BRD-06",Register!$T$5:$T$682,"Draft") | F21: =COUNTIFS(Register!$C$5:$C$682,"BRD-06",Register!$T$5:$T$682,"For CCB review") | G21: =COUNTIFS(Register!$C$5:$C$682,"BRD-06",Register!$T$5:$T$682,"For acceptance") | H21: =SUMIFS(Register!$L$5:$L$682,Register!$C$5:$C$682,"BRD-06") | I21: =SUMIFS(Register!$M$5:$M$682,Register!$C$5:$C$682,"BRD-06") | J21: =SUMIFS(Register!$N$5:$N$682,Register!$C$5:$C$682,"BRD-06") | K21: =SUMIFS(Register!$O$5:$O$682,Register!$C$5:$C$682,"BRD-06") | L21: =SUMIFS(Register!$P$5:$P$682,Register!$C$5:$C$682,"BRD-06")
A22: BRD-07 | B22: Claims | C22: =COUNTIFS(Register!$C$5:$C$682,"BRD-07") | D22: =COUNTIFS(Register!$C$5:$C$682,"BRD-07",Register!$S$5:$S$682,"High") | E22: =COUNTIFS(Register!$C$5:$C$682,"BRD-07",Register!$T$5:$T$682,"Draft") | F22: =COUNTIFS(Register!$C$5:$C$682,"BRD-07",Register!$T$5:$T$682,"For CCB review") | G22: =COUNTIFS(Register!$C$5:$C$682,"BRD-07",Register!$T$5:$T$682,"For acceptance") | H22: =SUMIFS(Register!$L$5:$L$682,Register!$C$5:$C$682,"BRD-07") | I22: =SUMIFS(Register!$M$5:$M$682,Register!$C$5:$C$682,"BRD-07") | J22: =SUMIFS(Register!$N$5:$N$682,Register!$C$5:$C$682,"BRD-07") | K22: =SUMIFS(Register!$O$5:$O$682,Register!$C$5:$C$682,"BRD-07") | L22: =SUMIFS(Register!$P$5:$P$682,Register!$C$5:$C$682,"BRD-07")
A23: BRD-08 | B23: Employee Benefits | C23: =COUNTIFS(Register!$C$5:$C$682,"BRD-08") | D23: =COUNTIFS(Register!$C$5:$C$682,"BRD-08",Register!$S$5:$S$682,"High") | E23: =COUNTIFS(Register!$C$5:$C$682,"BRD-08",Register!$T$5:$T$682,"Draft") | F23: =COUNTIFS(Register!$C$5:$C$682,"BRD-08",Register!$T$5:$T$682,"For CCB review") | G23: =COUNTIFS(Register!$C$5:$C$682,"BRD-08",Register!$T$5:$T$682,"For acceptance") | H23: =SUMIFS(Register!$L$5:$L$682,Register!$C$5:$C$682,"BRD-08") | I23: =SUMIFS(Register!$M$5:$M$682,Register!$C$5:$C$682,"BRD-08") | J23: =SUMIFS(Register!$N$5:$N$682,Register!$C$5:$C$682,"BRD-08") | K23: =SUMIFS(Register!$O$5:$O$682,Register!$C$5:$C$682,"BRD-08") | L23: =SUMIFS(Register!$P$5:$P$682,Register!$C$5:$C$682,"BRD-08")
A24: BRD-09 | B24: Customer Servicing Facility | C24: =COUNTIFS(Register!$C$5:$C$682,"BRD-09") | D24: =COUNTIFS(Register!$C$5:$C$682,"BRD-09",Register!$S$5:$S$682,"High") | E24: =COUNTIFS(Register!$C$5:$C$682,"BRD-09",Register!$T$5:$T$682,"Draft") | F24: =COUNTIFS(Register!$C$5:$C$682,"BRD-09",Register!$T$5:$T$682,"For CCB review") | G24: =COUNTIFS(Register!$C$5:$C$682,"BRD-09",Register!$T$5:$T$682,"For acceptance") | H24: =SUMIFS(Register!$L$5:$L$682,Register!$C$5:$C$682,"BRD-09") | I24: =SUMIFS(Register!$M$5:$M$682,Register!$C$5:$C$682,"BRD-09") | J24: =SUMIFS(Register!$N$5:$N$682,Register!$C$5:$C$682,"BRD-09") | K24: =SUMIFS(Register!$O$5:$O$682,Register!$C$5:$C$682,"BRD-09") | L24: =SUMIFS(Register!$P$5:$P$682,Register!$C$5:$C$682,"BRD-09")
A25: BRD-10 | B25: Sanction Screening | C25: =COUNTIFS(Register!$C$5:$C$682,"BRD-10") | D25: =COUNTIFS(Register!$C$5:$C$682,"BRD-10",Register!$S$5:$S$682,"High") | E25: =COUNTIFS(Register!$C$5:$C$682,"BRD-10",Register!$T$5:$T$682,"Draft") | F25: =COUNTIFS(Register!$C$5:$C$682,"BRD-10",Register!$T$5:$T$682,"For CCB review") | G25: =COUNTIFS(Register!$C$5:$C$682,"BRD-10",Register!$T$5:$T$682,"For acceptance") | H25: =SUMIFS(Register!$L$5:$L$682,Register!$C$5:$C$682,"BRD-10") | I25: =SUMIFS(Register!$M$5:$M$682,Register!$C$5:$C$682,"BRD-10") | J25: =SUMIFS(Register!$N$5:$N$682,Register!$C$5:$C$682,"BRD-10") | K25: =SUMIFS(Register!$O$5:$O$682,Register!$C$5:$C$682,"BRD-10") | L25: =SUMIFS(Register!$P$5:$P$682,Register!$C$5:$C$682,"BRD-10")
A26: BRD-11 | B26: User Access Maintenance | C26: =COUNTIFS(Register!$C$5:$C$682,"BRD-11") | D26: =COUNTIFS(Register!$C$5:$C$682,"BRD-11",Register!$S$5:$S$682,"High") | E26: =COUNTIFS(Register!$C$5:$C$682,"BRD-11",Register!$T$5:$T$682,"Draft") | F26: =COUNTIFS(Register!$C$5:$C$682,"BRD-11",Register!$T$5:$T$682,"For CCB review") | G26: =COUNTIFS(Register!$C$5:$C$682,"BRD-11",Register!$T$5:$T$682,"For acceptance") | H26: =SUMIFS(Register!$L$5:$L$682,Register!$C$5:$C$682,"BRD-11") | I26: =SUMIFS(Register!$M$5:$M$682,Register!$C$5:$C$682,"BRD-11") | J26: =SUMIFS(Register!$N$5:$N$682,Register!$C$5:$C$682,"BRD-11") | K26: =SUMIFS(Register!$O$5:$O$682,Register!$C$5:$C$682,"BRD-11") | L26: =SUMIFS(Register!$P$5:$P$682,Register!$C$5:$C$682,"BRD-11")
