Workbook
Name cur_ex: #REF!
Name curex: #REF!
Name ESHardwareDiscount: #REF!
Name ESHardwareDiscount: #REF!
Name ESSoftwareDiscount: #REF!
Name ESSoftwareDiscount: #REF!
Name OnPremDiscount: #REF!
Name OnPremDiscount: #REF!
Name sw_inflation: #REF!

Sheet Document Control
B1: Information Technology Cloud & Digital Operations Engineering | D1: Infrastructure Estimation and Recommendation Workbook | G1: Doc. Ref. No.: | H1: FR-ITC-ENG007
G2: Effective Date: | H2: 44643
G3: Ver. and Rev. No.: | H3: 5
B7: Document Version History
B8: Ver. and Rev. No. | C8: Date | D8: Prepared By | E8: Reviewed By | F8: Approved By | G8: Description
B9: 1 | C9: 43648 | D9: Edlin Resurreccion | E9: Ronna May Dimapilis | F9: Joel Eric Tesoro | G9: Initial Creation
B10: 2 | C10: 43901 | D10: Josephus Carl Gallo | E10: Ronna May Dimapilis | F10: Joel Eric Tesoro | G10: - Updated General Assumptions list with common assumptions, and added "Suggestions to minimize cost" section - General assumptions for Dollar-to-Php, Cost Buffer, and TCO % increase per year conversion has been linked to Summary page - Modified Licenses and One-Time Cost computations from US Dollars to Philippine Peso (PhP) - Modified Environment sheets by adding Monthly EBS Snapshot costs for all environments - Removed 5-year TCO in Environment sheets, adjusted currency fields to 2 decimal digits - Modified Summary page with the costing buffer and TCO values for easier estimations - Modified the Additional Cost % on Summay Page and Grand Total visuals only
B11: 2.1 | C11: 43921 | D11: Ryan Kerwin Macrohon | E11: Ronna May Dimapilis | F11: Joel Eric Tesoro | G11: Added note in HW & SW Requirements regarding technical refresh
B12: 2.2 | C12: 43937 | D12: Ronna May Dimapilis | E12: Ryan Kerwin Macrohon | F12: Joel Eric Tesoro | G12: - Color coded tabs and cells to be filled out by requesting unit (green) and servicing unit (blue) - Updated utilization to 36% in all non-productions environments based on the assumption 12x5 availability per month - Removed Instance Count column - Updated reference to the new AWS calculator - Updated document ownership to Engineering - Renamed from Cost Estimation Workbook to Infrastructure Estimation and Recommendation Workbook - Other formatting updates
B13: 3 | C13: 44046 | D13: Hanna Raissa Sarmiento Ronna May Dimapilis | E13: Ryan Kerwin Macrohon | F13: Joel Eric Tesoro | G13: - Added RTO, RPO requirements, expected % YoY growth, tabs for IT Infrastructure outputs (Architecture Diagram, HW&SW Specifications) - Updated computation for growth rate - Added dropdown for cost buffer
B14: 4 | C14: 44228 | D14: Ronna May Dimapilis | E14: Joel Eric Tesoro | F14: Joel Eric Tesoro | G14: - Added VDI-related requirements, specifications, and costing - Renamed Licenses and One-Time Cost to Software Licenses - Updated variables, computations, and Summary tab
B15: 5 | C15: 44643 | D15: Gian Carlo Adivncula | E15: Ryan Kerwin Macrohon / Augustus Anthony Lim | F15: Augustus Anthony Lim | G15: - Added IER Change Log to keep track of cost changes - Added Max Concurrent Users field in VDI Requirements tab
B16: 6 | C16: 44860 | D16: Joseph Bartolome | E16: Ryan Kerwin Macrohon / Augustus Anthony Lim | F16: Augustus Anthony Lim | G16: Modified formula for IER Change Log sheet to reference the previous change instead of the 1st year total cost
B17: 7 | C17: 44902 | D17: Joseph Bartolome | E17: Ryan Kerwin Macrohon / Augustus Anthony Lim | F17: Augustus Anthony Lim | G17: - Modified utilization from percentage to number of hours - Added Prod Support to VDI User drop down menu
B18: 8 | C18: 44993 | D18: Joy Coronado | E18: Augustus Anthony Lim | F18: Augustus Anthony Lim | G18: - Modified utilization to hours - Automatic compute of number of hours
B19: 9 | C19: 45051 | D19: Alan Villanobles II | E19: Catherine Joy Coronado | F19: Augustus Anthony Lim | G19: - Modified context in the Assumption to automatically get the dollar conversion rate from the Summary worksheet. - Updated drop-down list in the VDI Requirements worksheet to include "Prod Support" to the 2nd and 3rd tables. - added "Estimated Duration of Use" on each profile in the "VDI Requirements" and "HW & SW Requirements" worksheets - added "Prod Support" description to align with the profile added on v7
B20: 10 | C20: 45294 | D20: Benbol Del Pilar | E20: Rhett Lee Martinez | F20: Augustus Anthony Lim | G20: - Modified the cost for VDI - Add additional pre-prod environment
... B32: 19 | C32: 46176 | D32: Catherine Joy Coronado | E32: Rhett Lee Martinez | F32: Augustus Anthony Lim | G32: 1. Update the following: a. K8s Min/Max column b. K8s Ephemeral Storage c. K8s Kube-System and additional pods for autoscaling d. K8s PDB column e. Horizontal Scaling (separating sheets for k8s yearly increase) 2. Added Assumptions and notes for EKS/AKS form applicability

Sheet Assumptions
A1: GENERAL ASSUMPTIONS
A2: No. | B2: Assumption
A3: 1 | B3: Costing found in this workbook represents only the infrastructure costing for the given project. This should not be mistaken to represent costing for the entire project.
A4: 2 | B4: Costing found in this workbook represents the infrastructure costing only for the project components that are declared in this workbook. Any additional components not initially declared may have an impact on costing.
A5: 3 | B5: The Non-Production instances (DEV, SIT, UAT, Pre-Prod) are going to run for 12 hours a day, 5 days a week (12 x 5).
A6: 4 | B6: The Production instances are going to run for 24 hours a day, 7 days a week (24 x 7).
A7: 5 | B7: Snapshot costs are included for all environments (10% change for monthly snapshots).
A8: 6 | B8: VAT is only applicable to our Public Cloud components
A9: 7 | B9: Enterprise discount for Azure component is already part of the monthly cost in their calculator. For AWS the enterprise discount is 10.5%
A10: 8 | B10: Micrsoft Licenses has a minimum of 4 Licenses
A11: 9 | B11: Use K8S sheets to identify container technology requirements. Remove Kube-system namespace if the hosting environment will be on AKS and add the system pool worker nodes group instead
A12: 10 | B12: =CONCATENATE("USD to PHP exchange rate is 1 USD : ", SUMMARY!C22, " Philippine Pesos. This is based on the prevailing exchange rate on the week of this workbook's review and approval.") -> USD to PHP exchange rate is 1 USD : 60 Philippine Pesos. This is based on the prevailing exchange rate on the week of this workbook's review and approval.
A13: 11
A14: 12
A15: 13
A16: 14
A17: 15
A18: 16
A19: 17
A20: 18
A21: 19
A22: 20
A23: 21
A24: No. | B24: Suggestions to minimize cost
A25: 1
A26: 2
A27: 3
A28: 4
A29: 5
A30: 6
A31: 7
A32: 8

Sheet IER Change Log
E2: Initial Cost Estimate / Technical Recommendation Summary
F3: 1st-yr TCO (manual input) | G3: 5-yr TCO (manual input)
F4: 0 | G4: 0
A7: Cost Estimate / Technical Recommendation - Revision History (fill-out as necessary)
A8: Change # | B8: High Level Description of Change | C8: Details/Rationale for the change | D8: Change Driver | E8: Date of Change (MM/DD/YYYY) | F8: Cost Impact 1st yr TCO (manual input) | G8: Cost Impact 5-yr TCO (manual input) | H8: Calculated Compared to Initial 1st yr (auto-fill) | I8: Calculated Compared to Initial 5-yr (auto-fill) | J8: Calculated Compared to Previous Change 1st yr (auto-fill) | K8: Calculated Compared to Previous Change 5-yr (auto-fill)
A9: 1 | F9: 0 | G9: 0 | H9: =IF(F9=0,"₱0",F9-$F$4) -> ₱0 | I9: =IF(G9=0,"₱0",G9-$G$4) -> ₱0 | J9: N/A | K9: N/A
A10: 2 | F10: 0 | G10: 0 | H10: =IF(F10=0,"₱0",F10-$F$4) -> ₱0 | I10: =IF(G10=0,"₱0",G10-$G$4) -> ₱0 | J10: =IF(F10=0,"₱0",F10-$F9) -> ₱0 | K10: =IF(G10=0,"₱0",G10-$G9) -> ₱0
A11: 3 | F11: 0 | G11: 0 | H11: =IF(F11=0,"₱0",F11-$F$4) -> ₱0 | I11: =IF(G11=0,"₱0",G11-$G$4) -> ₱0 | J11: =IF(F11=0,"₱0",F11-$F10) -> ₱0 | K11: =IF(G11=0,"₱0",G11-$G10) -> ₱0
A12: 4 | F12: 0 | G12: 0 | H12: =IF(F12=0,"₱0",F12-$F$4) -> ₱0 | I12: =IF(G12=0,"₱0",G12-$G$4) -> ₱0 | J12: =IF(F12=0,"₱0",F12-$F11) -> ₱0 | K12: =IF(G12=0,"₱0",G12-$G11) -> ₱0
A13: 5 | F13: 0 | G13: 0 | H13: =IF(F13=0,"₱0",F13-$F$4) -> ₱0 | I13: =IF(G13=0,"₱0",G13-$G$4) -> ₱0 | J13: =IF(F13=0,"₱0",F13-$F12) -> ₱0 | K13: =IF(G13=0,"₱0",G13-$G12) -> ₱0
A14: 6 | F14: 0 | G14: 0 | H14: =IF(F14=0,"₱0",F14-$F$4) -> ₱0 | I14: =IF(G14=0,"₱0",G14-$G$4) -> ₱0 | J14: =IF(F14=0,"₱0",F14-$F13) -> ₱0 | K14: =IF(G14=0,"₱0",G14-$G13) -> ₱0
A15: 7 | F15: 0 | G15: 0 | H15: =IF(F15=0,"₱0",F15-$F$4) -> ₱0 | I15: =IF(G15=0,"₱0",G15-$G$4) -> ₱0 | J15: =IF(F15=0,"₱0",F15-$F14) -> ₱0 | K15: =IF(G15=0,"₱0",G15-$G14) -> ₱0
A16: 8 | F16: 0 | G16: 0 | H16: =IF(F16=0,"₱0",F16-$F$4) -> ₱0 | I16: =IF(G16=0,"₱0",G16-$G$4) -> ₱0 | J16: =IF(F16=0,"₱0",F16-$F15) -> ₱0 | K16: =IF(G16=0,"₱0",G16-$G15) -> ₱0
A17: 9 | F17: 0 | G17: 0 | H17: =IF(F17=0,"₱0",F17-$F$4) -> ₱0 | I17: =IF(G17=0,"₱0",G17-$G$4) -> ₱0 | J17: =IF(F17=0,"₱0",F17-$F16) -> ₱0 | K17: =IF(G17=0,"₱0",G17-$G16) -> ₱0
A18: 10 | F18: 0 | G18: 0 | H18: =IF(F18=0,"₱0",F18-$F$4) -> ₱0 | I18: =IF(G18=0,"₱0",G18-$G$4) -> ₱0 | J18: =IF(F18=0,"₱0",F18-$F17) -> ₱0 | K18: =IF(G18=0,"₱0",G18-$G17) -> ₱0

Sheet Architecture Diagram
A2: iNXT BrokerVerse — High-Level Architecture (BDOI Core Modernization)
A4: Recovery Point Objective | B4: 15 minutes | C4: may be in seconds, minutes, hours, days | G4: Recovery Time Objective | H4: 4 hours | I4: may be in seconds, minutes, hours, days
A5: Place high-level architecture diagram below:

Sheet HW & SW Requirements
A1: Hardware and Software Requirements (to be filled out by requesting unit)
A2: Kindly fill in the necessary details below with the requested specs for each environment as discussed and recommended by the vendor or solution developer.
A3: Expected % YoY Growth | B3: 15 | D3: Estimated Duration of Use | E3: 60 | F3: months
A5: Environment | B5: Description | C5: CPU | D5: Memory (GB) | E5: Storage (GB) | F5: Operating System and Software Requirement | G5: Remarks
A6: DEV | B6: Application Database (PostgreSQL) | C6: 4 | D6: 16 | E6: 200 | F6: RHEL 9.x + PostgreSQL 16 (Amazon RDS, Single-AZ) | G6: Primary OLTP DB for iNXT BrokerVerse
A7: DEV | B7: Cache & Event Streaming (Redis + Kafka) | C7: 4 | D7: 16 | E7: 200 | F7: Amazon ElastiCache for Redis 7.x + Amazon MSK (Apache Kafka 3.6) | G7: Session/cache + async eventing
A8: SIT | B8: Application Database (PostgreSQL) | C8: 4 | D8: 16 | E8: 200 | F8: RHEL 9.x + PostgreSQL 16 (Amazon RDS, Single-AZ) | G8: Integration test OLTP DB
A9: SIT | B9: Cache & Event Streaming (Redis + Kafka) | C9: 4 | D9: 16 | E9: 200 | F9: Amazon ElastiCache for Redis 7.x + Amazon MSK (Kafka 3.6) | G9: Cache + eventing
A10: UAT | B10: Application Database (PostgreSQL) | C10: 8 | D10: 32 | E10: 500 | F10: RHEL 9.x + PostgreSQL 16 (Amazon RDS, Single-AZ) | G10: UAT OLTP DB, prod-like data volume
A11: UAT | B11: Cache & Event Streaming (Redis + Kafka) | C11: 4 | D11: 16 | E11: 300 | F11: Amazon ElastiCache for Redis 7.x + Amazon MSK (Kafka 3.6) | G11: Cache + eventing
A12: PRE-PROD | B12: Application Database (PostgreSQL) | C12: 8 | D12: 64 | E12: 1000 | F12: RHEL 9.x + PostgreSQL 16 (Amazon RDS, Multi-AZ) | G12: Prod-mirror DB for performance & cutover rehearsal
A13: PRE-PROD | B13: Cache & Event Streaming (Redis + Kafka) | C13: 8 | D13: 32 | E13: 1000 | F13: ElastiCache for Redis 7.x (cluster) + Amazon MSK (3 brokers) | G13: Cache + eventing
A14: PROD | B14: Application Database (PostgreSQL) | C14: 16 | D14: 128 | E14: 2000 | F14: RHEL 9.x + PostgreSQL 16 (Amazon RDS, Multi-AZ) | G14: Primary OLTP, HA Multi-AZ, automated backups
A15: PROD | B15: Cache & Event Streaming (Redis + Kafka) | C15: 8 | D15: 32 | E15: 1000 | F15: ElastiCache for Redis 7.x (cluster) + Amazon MSK (3 brokers) | G15: Cache + durable eventing
A16: PROD | B16: Bastion / CI-CD Runner | C16: 4 | D16: 16 | E16: 200 | F16: RHEL 9.x + GitLab Runner, AWS SSM, kubectl/helm | G16: Shared deploy & jump host
A17: PROD DR | B17: Application Database (PostgreSQL standby) | C17: 16 | D17: 128 | E17: 2000 | F17: RHEL 9.x + PostgreSQL 16 (cross-region read replica) | G17: DR standby, async replication, RPO target ≤15 min
A18: PROD DR | B18: Cache & Event Streaming (Redis + Kafka) | C18: 8 | D18: 32 | E18: 1000 | F18: ElastiCache for Redis 7.x + Amazon MSK (3 brokers) | G18: DR cache + eventing
A19: PROD | B19: Object & File Storage | F19: Amazon S3 (document store) + Amazon EFS (shared K8s PV) | G19: Managed, consumption-based; lifecycle to S3-IA/Glacier

Sheet VDI Requirements
A1: VDI Requirements (to be filled out by requesting unit)
G3: Total Number of VDI Users | H3: =SUM(B7,B33,B59) -> 15
J5: User Profiles
A6: User Profile | B6: Developer | J6: Basic User : no runtime requirements; only requires productivity tools such
A7: =CONCATENATE("No. of ", $B$6, "s") -> No. of Developers | B7: 8 | J7: as office tools and access to documents, applications/sytems
A8: =CONCATENATE("Max Concurrent No. of ", $B$6, "s") -> Max Concurrent No. of Developers | B8: 6
A9: Estimated Duration of Use | B9: 24 | C9: months | J9: Developer : has runtime requirements; requires developer tools and
A10: Uptime Schedule | B10: 12 | C10: hours | D10: Multi-Session Aware : software/application allows multiple concurrent interactive sessions | J10: productivity tools and access to environments
B11: 5 | C11: days | D11: Information is required as it impacts specification and cost. | J11: Tester : has runtime requirements; requires QA and productivity tools
A12: Total Hours | B12: =((B10*B11*4)/(24*7*4))*730 -> 260.71429 | J12: and access to environments.
A13: Software Name indicate (1) standard software not included in the default list* and (2) other required software/tools | B13: Software Version | C13: Description | D13: Purpose | E13: Multi-Session Aware? (Y/N) | F13: Memory Requirement (GB) if known | G13: Storage Requirement (GB) if known | H13: Remarks | J13: Prod Support : may need runtime requirements and access to production environment (User Role/Profile only) (needs a separate request and approval for accessing the prod system/environment)
A14: Visual Studio Code | B14: 1.9x | C14: Primary IDE | D14: development | E14: N | F14: 2 | G14: 5 | H14: Angular/Java microservice dev
A15: OpenJDK (Temurin) | B15: 17 LTS | C15: Java SDK & runtime | D15: development | E15: N | F15: 1 | G15: 2 | H15: BrokerVerse services build on JDK 17
A16: Node.js + npm | B16: 20 LTS | C16: Front-end build toolchain | D16: development | E16: N | F16: 1 | G16: 3 | H16: Angular SPA build | J16: *List of Standard Software Installed by default
A17: Git client | B17: 2.4x | C17: Source control | D17: development | E17: N | F17: 1 | G17: 1 | H17: Connects to GitLab | J17: Software | K17: Version
A18: DBeaver | B18: 24.x | C18: PostgreSQL DB client | D18: development | E18: N | F18: 1 | G18: 1 | J18: Libre Office tools | K18: 5.4.5
A19: Postman | B19: 11.x | C19: API testing | D19: development | E19: N | F19: 1 | G19: 1 | J19: OpenOffice | K19: 4.1.6
A20: Docker CLI / kubectl / Helm | B20: latest | C20: Container & K8s tooling | D20: development | E20: N | F20: 1 | G20: 2 | H20: EKS deploy from runner | J20: WinSCP | K20: 5.17
J21: 7-Zip | K21: 19
J22: Putty | K22: 0.73
J23: Notepad++ | K23: 7.8.6
J24: Microsoft Edge / Firefox | K24: 83.0 / 68.8.0esr
J25: Adobe Acrobat Reader | K25: 2017 17.011.30113
J26: For the complete list, please refer to:
J27: https://www.ito.bdo.com.ph/references/memoranda/bdo-system-image
F29: =SUM(F14:F28) -> 8 | G29: =SUM(G14:G28) -> 15 | J29: List of Standard Software that can be requested for installation
J30: http://fs01.software.bdo.com.ph/workstation/free-software-and-tools/ITD%20Tools/
A32: User Profile | B32: Tester
A33: =CONCATENATE("No. of ", $B$32, "s") -> No. of Testers | B33: 4
A34: =CONCATENATE("Max Concurrent No. of ", $B$32, "s") -> Max Concurrent No. of Testers | B34: 3
A35: Estimated Duration of Use | B35: 18 | C35: months
A36: Uptime Schedule | B36: 12 | C36: hours | D36: Multi-Session Aware : software/application allows multiple concurrent interactive sessions
B37: 5 | C37: days | D37: Information is required as it impacts specification and cost.
A38: Total Hours | B38: =((B36*B37*4)/(24*7*4))*730 -> 260.71429
A39: Software Name indicate (1) standard software not included in the default list* and (2) other required software/tools | B39: Software Version | C39: Description | D39: Purpose | E39: Multi-Session Aware? (Y/N) | F39: Memory Requirement (GB) if known | G39: Storage Requirement (GB) if known | H39: Remarks
A40: Katalon Studio / Selenium | B40: latest | C40: UI test automation | D40: testing | E40: N | F40: 2 | G40: 4 | H40: Regression automation
A41: Apache JMeter | B41: 5.6 | C41: Performance & load testing | D41: testing | E41: N | F41: 2 | G41: 2 | H41: NFR/TPS validation
A42: Postman / Newman | B42: 11.x | C42: API test execution | D42: testing | E42: N | F42: 1 | G42: 1
A43: DBeaver | B43: 24.x | C43: Test data validation | D43: testing | E43: N | F43: 1 | G43: 1
A44: Xray / TestRail (browser) | B44: SaaS | C44: Test management | D44: testing | E44: N | F44: 1 | G44: 1 | H44: Web client
...

Sheet Architecture Diagram (Infra)
A2: High-Level Architecture ( to be filled out by servicing unit)
A4: Recovery Point Objective | C4: 15 min | G4: Recovery Time Objective | I4: 4 h
A5: Place recommended high-level architecture diagram below:
A142: DB1
A146: DB2
A290: DB1
A294: DB2

Sheet HW & SW Specifications (Infra)
A1: Hardware and Software Specifications (to be filled out by servicing unit)
B2: Estimated Duration of Use | C2: =IF(ISBLANK('HW & SW Requirements'!E3),"",'HW & SW Requirements'!E3) -> 60 | D2: months
A3: Environment | B3: Description | C3: CPU | D3: Memory (GB) | E3: Storage (GB) | F3: Operating System and Software Requirement | G3: Remarks

Sheet VDI Specifications (Infra)
A1: VDI Specifications (to be filled out by servicing unit)
A3: Description | B3: Estimated Duration of Use (months) | C3: Hours | D3: CPU | E3: Memory (GB) | F3: Storage (GB) | G3: Monthly Subscription Cost ($) | H3: Monthly Storage Cost ($) | I3: Total Monthly Cost (VAT Inc $) | J3: Total Annual Cost ($)
A4: =CONCATENATE('VDI Requirements'!$B$6, " VM(s)") -> Developer VM(s)
B5: ='VDI Requirements'!B9 -> 24 | C5: ='VDI Requirements'!B12 -> 260.71429 | F5: Managed disks (128GB) Profile (30GB) | H5: 0 | I5: =SUM(G5:H5) * 1.12 -> 0 | J5: =I5*12 -> 0
C6: ='VDI Requirements'!B12 -> 260.71429 | F6: Managed disks (128GB) Profile (30GB) | I6: =SUM(G6:H6) * 1.12 -> 0 | J6: =I6*12 -> 0
C7: ='VDI Requirements'!B12 -> 260.71429 | F7: Managed disks (128GB) Profile (30GB) | I7: =SUM(G7:H7) * 1.12 -> 0 | J7: =I7*12 -> 0
A8: =CONCATENATE('VDI Requirements'!$B$32, " VM(s)") -> Tester VM(s)
B9: ='VDI Requirements'!B35 -> 18 | C9: ='VDI Requirements'!B38 -> 260.71429 | F9: Managed disks (128GB) Profile (30GB) | I9: =SUM(G9:H9) * 1.12 -> 0 | J9: =I9*12 -> 0
C10: ='VDI Requirements'!B38 -> 260.71429 | F10: Managed disks (128GB) Profile (30GB) | I10: =SUM(G10:H10) * 1.12 -> 0 | J10: =I10*12 -> 0
C11: ='VDI Requirements'!B38 -> 260.71429 | F11: Managed disks (128GB) Profile (30GB) | I11: =SUM(G11:H11) * 1.12 -> 0 | J11: =I11*12 -> 0
A12: =CONCATENATE('VDI Requirements'!$B$58, " VM(s)") -> Prod Support VM(s)
B13: ='VDI Requirements'!B61 -> 60 | C13: ='VDI Requirements'!B64 -> 260.71429 | F13: Managed disks (128GB) Profile (30GB) | I13: =SUM(G13:H13) * 1.12 -> 0 | J13: =I13*12 -> 0
C14: ='VDI Requirements'!B64 -> 260.71429 | F14: Managed disks (128GB) Profile (30GB) | I14: =SUM(G14:H14) * 1.12 -> 0 | J14: =I14*12 -> 0
C15: ='VDI Requirements'!B64 -> 260.71429 | F15: Managed disks (128GB) Profile (30GB) | I15: =SUM(G15:H15) * 1.12 -> 0 | J15: =I15*12 -> 0
A16: TOTAL | I16: =SUM(I5:I15) -> 0 | J16: =SUM(J5:J15) -> 0

Sheet Software Licenses
A1: SOFTWARE / LICENSE COST
A2: Environment | B2: Software/License Name and Version | C2: No. of Cores/CPU/vCPU | D2: License Unit Cost | E2: No. of License Needed | F2: Amount | G2: Recurring Cost
G3: Year 1 | H3: Year 2 | I3: Year 3 | J3: Year 4 | K3: Year 5 | L3: Total
F4: =ROUNDUP(E4*D4,0) -> 0 | G4: =F4 -> 0 | H4: =G4 -> 0 | I4: =H4 -> 0 | J4: =I4 -> 0 | K4: =J4 -> 0 | L4: =SUM(G4:K4) -> 0
F5: =ROUNDUP(E5*D5,0) -> 0 | G5: =F5 -> 0 | H5: =G5 -> 0 | I5: =H5 -> 0 | J5: =I5 -> 0 | K5: =J5 -> 0 | L5: =SUM(G5:K5) -> 0
F6: =ROUNDUP(E6*D6,0) -> 0 | G6: =F6 -> 0 | H6: =G6 -> 0 | I6: =H6 -> 0 | J6: =I6 -> 0 | K6: =J6 -> 0 | L6: =SUM(G6:K6) -> 0
F7: =ROUNDUP(E7*D7,0) -> 0 | G7: =F7 -> 0 | H7: =G7 -> 0 | I7: =H7 -> 0 | J7: =I7 -> 0 | K7: =J7 -> 0 | L7: =SUM(G7:K7) -> 0
F8: =ROUNDUP(E8*D8,0) -> 0 | G8: =F8 -> 0 | H8: =G8 -> 0 | I8: =H8 -> 0 | J8: =I8 -> 0 | K8: =J8 -> 0 | L8: =SUM(G8:K8) -> 0
F9: =ROUNDUP(E9*D9,0) -> 0 | G9: =F9 -> 0 | H9: =G9 -> 0 | I9: =H9 -> 0 | J9: =I9 -> 0 | K9: =J9 -> 0 | L9: =SUM(G9:K9) -> 0
F10: =ROUNDUP(E10*D10,0) -> 0 | G10: =F10 -> 0 | H10: =G10 -> 0 | I10: =H10 -> 0 | J10: =I10 -> 0 | K10: =J10 -> 0 | L10: =SUM(G10:K10) -> 0
F11: =ROUNDUP(E11*D11,0) -> 0 | G11: =F11 -> 0 | H11: =G11 -> 0 | I11: =H11 -> 0 | J11: =I11 -> 0 | K11: =J11 -> 0 | L11: =SUM(G11:K11) -> 0
F12: =ROUNDUP(E12*D12,0) -> 0 | G12: =F12 -> 0 | H12: =G12 -> 0 | I12: =H12 -> 0 | J12: =I12 -> 0 | K12: =J12 -> 0 | L12: =SUM(G12:K12) -> 0
F13: =ROUNDUP(E13*D13,0) -> 0 | G13: =F13 -> 0 | H13: =G13 -> 0 | I13: =H13 -> 0 | J13: =I13 -> 0 | K13: =J13 -> 0 | L13: =SUM(G13:K13) -> 0
F14: =ROUNDUP(E14*D14,0) -> 0 | G14: =F14 -> 0 | H14: =G14 -> 0 | I14: =H14 -> 0 | J14: =I14 -> 0 | K14: =J14 -> 0 | L14: =SUM(G14:K14) -> 0
F15: =ROUNDUP(E15*D15,0) -> 0 | G15: =F15 -> 0 | H15: =G15 -> 0 | I15: =H15 -> 0 | J15: =I15 -> 0 | K15: =J15 -> 0 | L15: =SUM(G15:K15) -> 0
... F18: =ROUNDUP(E18*D18,0) -> 0 | G18: =F18 -> 0 | H18: =G18 -> 0 | I18: =H18 -> 0 | J18: =I18 -> 0 | K18: =J18 -> 0 | L18: =SUM(G18:K18) -> 0
A19: TOTAL COST | F19: =SUM(F4:F18) -> 0 | G19: =SUM(G4:G18) -> 0 | H19: =SUM(H4:H18) -> 0 | I19: =SUM(I4:I18) -> 0 | J19: =SUM(J4:J18) -> 0 | K19: =SUM(K4:K18) -> 0 | L19: =SUM(L4:L18) -> 0
A23: VDI License Cost
A24: Total Number of Users | C24: Monthy License Cost per User | E24: Total Monthly License Cost | G24: Year 1 | H24: Year 2 | I24: Year 3 | J24: Year 4 | K24: Year 5 | L24: Total
A25: ='VDI Requirements'!H3 -> 15 | C25: 13 | E25: =$A$25*$C$25 -> 195 | G25: =($A$25*$C$25)*12 -> 2340 | H25: =($A$25*$C$25)*12 -> 2340 | I25: =($A$25*$C$25)*12 -> 2340 | J25: =($A$25*$C$25)*12 -> 2340 | K25: =($A$25*$C$25)*12 -> 2340 | L25: =SUM(G25:K26) -> 11700

Sheet DEV
A1: DEVELOPMENT ENVIRONMENT (to be filled out by servicing unit)
A2: YEAR 1
A3: Description | B3: Hours | C3: Cloud Platform | D3: Instance Type, Specs | E3: CPU | F3: Memory (GB) | G3: Operating System | H3: Disk Space Description (Size in GB) | J3: Disk Space (GB) | K3: Monthly EBS Volume Cost ($) | L3: Monthly Subscription Cost ($) | M3: VAT | N3: Enterprise Discount | O3: Total Monthly Cost ($) | P3: Total Annual Cost ($)
B4: =((12*5*4)/(24*7*4))*730 -> 260.71429 | C4: AWS | G4: Windows Server | H4: =IF(G4="Windows Server", "C:\", "/") -> C:\ | I4: =IF(G4="Windows Server", 150, 20) -> 150 | J4: =SUM(I4:I7) -> 300 | K4: =J4 *(IF(C4="AZURE", SUMMARY!C$20, SUMMARY!C$21)) -> 28.8 | M4: =IF(C4="ON PREM", 0, SUMMARY!C$25%) -> 0.12 | N4: =IF(C4="AWS",SUMMARY!C$26%, 0) -> 0.13 | O4: =((SUM(K4:L4))-((SUM(K4:L4))*N4))*(1 + M4) -> 28.06272 | P4: =O4*12 -> 336.75264
H5: =IF(G4="Windows Server", "F:\appdir", "/appdir") -> F:\appdir
H6: =IF(G4="Windows Server", "G:\Log", "/var/log") -> G:\Log | I6: =IF(G4="Windows Server", 50, 20) -> 50
H7: =IF(G4="Windows Server", "H:\Backup", "/backup") -> H:\Backup | I7: =IF(G4="Windows Server", 100, 10) -> 100
B8: =((12*5*4)/(24*7*4))*730 -> 260.71429 | C8: AWS | G8: Windows Server | H8: =IF(G8="Windows Server", "C:\", "/") -> C:\ | I8: =IF(G8="Windows Server", 150, 20) -> 150 | J8: =SUM(I8:I11) -> 300 | K8: =J8 *(IF(C8="AZURE", SUMMARY!C$20, SUMMARY!C$21)) -> 28.8 | M8: =IF(C8="ON PREM", 0, SUMMARY!C$25%) -> 0.12 | N8: =IF(C8="AWS",SUMMARY!C$26%, 0) -> 0.13 | O8: =((SUM(K8:L8))-((SUM(K8:L8))*N8))*(1 + M8) -> 28.06272 | P8: =O8*12 -> 336.75264
H9: =IF(G8="Windows Server", "F:\appdir", "/appdir") -> F:\appdir
H10: =IF(G8="Windows Server", "G:\Log", "/var/log") -> G:\Log | I10: =IF(G8="Windows Server", 50, 20) -> 50
H11: =IF(G8="Windows Server", "H:\Backup", "/backup") -> H:\Backup | I11: =IF(G8="Windows Server", 100, 10) -> 100
E12: =SUM(E4:E11) -> 0 | F12: =SUM(F4:F11) -> 0 | J12: =SUM(J4:J11) -> 600 | K12: =SUM(K4:K11) -> 57.6 | L12: =SUM(L4:L11) -> 0 | O12: =SUM(O4:O11) -> 56.12544 | P12: =SUM(P4:P11) -> 673.50528
A13: YEAR 2
B14: =((12*5*4)/(24*7*4))*730 -> 260.71429 | C14: AWS | E14: =$E$4 -> 0 | F14: =$F$4 -> 0 | G14: Windows Server | H14: =IF(G14="Windows Server", "C:\", "/") -> C:\ | I14: =IF(G14="Windows Server", 150, 20) -> 150 | J14: =SUM(I14:I17) -> 300 | K14: =J14 *(IF(C14="AZURE", SUMMARY!C$20, SUMMARY!C$21)) -> 28.8 | M14: =IF(C14="ON PREM", 0, SUMMARY!C$25%) -> 0.12 | N14: =IF(C14="AWS",SUMMARY!C$26%, 0) -> 0.13 | O14: =((SUM(K14:L14))-((SUM(K14:L14))*N14))*(1 + M14) -> 28.06272 | P14: =O14*12 -> 336.75264
H15: =IF(G14="Windows Server", "F:\appdir", "/appdir'") -> F:\appdir | I15: =$I$5 -> 0
H16: =IF(G14="Windows Server", "G:\Log", "/var/log") -> G:\Log | I16: =IF(G14="Windows Server", 50, 20) -> 50
H17: =IF(G14="Windows Server", "H:\Backup", "/backup") -> H:\Backup | I17: =IF(G14="Windows Server", 100, 10) -> 100
B18: =((12*5*4)/(24*7*4))*730 -> 260.71429 | C18: AWS | E18: =$E$8 -> 0 | F18: =$F$8 -> 0 | G18: Windows Server | H18: =IF(G18="Windows Server", "C:\", "/") -> C:\ | I18: =IF(G18="Windows Server", 150, 20) -> 150 | J18: =SUM(I18:I21) -> 300 | K18: =J18 *(IF(C18="AZURE", SUMMARY!C$20, SUMMARY!C$21)) -> 28.8 | M18: =IF(C18="ON PREM", 0, SUMMARY!C$25%) -> 0.12 | N18: =IF(C18="AWS",SUMMARY!C$26%, 0) -> 0.13 | O18: =((SUM(K18:L18))-((SUM(K18:L18))*N18))*(1 + M18) -> 28.06272 | P18: =O18*12 -> 336.75264
H19: =IF(G18="Windows Server", "F:\appdir", "/appdir") -> F:\appdir | I19: =$I$9 -> 0
H20: =IF(G18="Windows Server", "G:\Log", "/var/log") -> G:\Log | I20: =IF(G18="Windows Server", 50, 20) -> 50
H21: =IF(G18="Windows Server", "H:\Backup", "/backup") -> H:\Backup | I21: =IF(G18="Windows Server", 100, 10) -> 100
E22: =SUM(E14:E21) -> 0 | F22: =SUM(F14:F21) -> 0 | J22: =SUM(J14:J21) -> 600 | K22: =SUM(K14:K21) -> 57.6 | L22: =SUM(L14:L21) -> 0 | O22: =SUM(O14:O21) -> 56.12544 | P22: =SUM(P14:P21) -> 673.50528
A23: YEAR 3
B24: =((12*5*4)/(24*7*4))*730 -> 260.71429 | C24: EXACC | E24: =$E$4 -> 0 | F24: =$F$4 -> 0 | G24: RHEL | H24: =IF(G24="Windows Server", "C:\", "/") -> / | I24: =IF(G24="Windows Server", 150, 20) -> 20 | J24: =SUM(I24:I27) -> 50 | K24: =J24 *(IF(C24="AZURE", SUMMARY!C$20, SUMMARY!C$21)) -> 4.8 | M24: =IF(C24="ON PREM", 0, SUMMARY!C$25%) -> 0.12 | N24: =IF(C24="AWS",SUMMARY!C$26%, 0) -> 0 | O24: =((SUM(K24:L24))-((SUM(K24:L24))*N24))*(1 + M24) -> 5.376 | P24: =O24*12 -> 64.512
H25: =IF(G24="Windows Server", "F:\appdir", "/appdir") -> /appdir
H26: =IF(G24="Windows Server", "G:\Log", "/var/log") -> /var/log | I26: =IF(G24="Windows Server", 50, 20) -> 20
H27: =IF(G24="Windows Server", "H:\Backup", "/backup") -> /backup | I27: =IF(G24="Windows Server", 100, 10) -> 10
B28: =((12*5*4)/(24*7*4))*730 -> 260.71429 | C28: ON PREM | E28: =$E$8 -> 0 | F28: =$F$8 -> 0 | G28: RHEL | H28: =IF(G28="Windows Server", "C:\", "/") -> / | I28: =IF(G28="Windows Server", 150, 20) -> 20 | J28: =SUM(I28:I31) -> 50 | K28: =J28 *(IF(C28="AZURE", SUMMARY!C$20, SUMMARY!C$21)) -> 4.8 | M28: =IF(C28="ON PREM", 0, SUMMARY!C$25%) -> 0 | N28: =IF(C28="AWS",SUMMARY!C$26%, 0) -> 0 | O28: =((SUM(K28:L28))-((SUM(K28:L28))*N28))*(1 + M28) -> 4.8 | P28: =O28*12 -> 57.6
H29: =IF(G28="Windows Server", "F:\appdir", "/appdir") -> /appdir
H30: =IF(G28="Windows Server", "G:\Log", "/var/log") -> /var/log | I30: =IF(G28="Windows Server", 50, 20) -> 20
H31: =IF(G28="Windows Server", "H:\Backup", "/backup") -> /backup | I31: =IF(G28="Windows Server", 100, 10) -> 10
E32: =SUM(E24:E31) -> 0 | F32: =SUM(F24:F31) -> 0 | J32: =SUM(J24:J31) -> 100 | K32: =SUM(K24:K31) -> 9.6 | L32: =SUM(L24:L31) -> 0 | O32: =SUM(O24:O31) -> 10.176 | P32: =SUM(P24:P31) -> 122.112
A33: YEAR 4
B34: =((12*5*4)/(24*7*4))*730 -> 260.71429 | C34: AWS | E34: =$E$4 -> 0 | F34: =$F$4 -> 0 | G34: Windows Server | H34: =IF(G34="Windows Server", "C:\", "/") -> C:\ | I34: =IF(G34="Windows Server", 150, 20) -> 150 | J34: =SUM(I34:I37) -> 300 | K34: =J34 *(IF(C34="AZURE", SUMMARY!C$20, SUMMARY!C$21)) -> 28.8 | M34: =IF(C34="ON PREM", 0, SUMMARY!C$25%) -> 0.12 | N34: =IF(C34="AWS",SUMMARY!C$26%, 0) -> 0.13 | O34: =((SUM(K34:L34))-((SUM(K34:L34))*N34))*(1 + M34) -> 28.06272 | P34: =O34*12 -> 336.75264
H35: =IF(G34="Windows Server", "F:\appdir", "/appdir") -> F:\appdir | I35: =$I$5 -> 0
H36: =IF(G34="Windows Server", "G:\Log", "/var/log") -> G:\Log | I36: =IF(G34="Windows Server", 50, 20) -> 50
H37: =IF(G34="Windows Server", "H:\Backup", "/backup") -> H:\Backup | I37: =IF(G34="Windows Server", 100, 10) -> 100
B38: =((12*5*4)/(24*7*4))*730 -> 260.71429 | C38: AWS | E38: =$E$8 -> 0 | F38: =$F$8 -> 0 | G38: RHEL | H38: =IF(G38="Windows Server", "C:\", "/") -> / | I38: =IF(G38="Windows Server", 150, 20) -> 20 | J38: =SUM(I38:I41) -> 50 | K38: =J38 *(IF(C38="AZURE", SUMMARY!C$20, SUMMARY!C$21)) -> 4.8 | M38: =IF(C38="ON PREM", 0, SUMMARY!C$25%) -> 0.12 | N38: =IF(C38="AWS",SUMMARY!C$26%, 0) -> 0.13 | O38: =((SUM(K38:L38))-((SUM(K38:L38))*N38))*(1 + M38) -> 4.67712 | P38: =O38*12 -> 56.12544
H39: =IF(G38="Windows Server", "F:\appdir", "/appdir") -> /appdir | I39: =$I$9 -> 0
H40: =IF(G38="Windows Server", "G:\Log", "/var/log") -> /var/log | I40: =IF(G38="Windows Server", 50, 20) -> 20
...

Sheet SIT
A1: SIT ENVIRONMENT (to be filled out by servicing unit)
A2: YEAR 1
A3: Description | B3: Hours | C3: Cloud Platform | D3: Instance Type, Specs | E3: CPU | F3: Memory (GB) | G3: Operating System | H3: Disk Space Description (Size in GB) | J3: Disk Space (GB) | K3: Monthly EBS Volume Cost ($) | L3: Monthly Subscription Cost ($) | M3: VAT | N3: Enterprise Discount | O3: Total Monthly Cost ($) | P3: Total Annual Cost ($)
B4: =((12*5*4)/(24*7*4))*730 -> 260.71429 | C4: EXACC | G4: Windows Server | H4: =IF(G4="Windows Server", "C:\", "/") -> C:\ | I4: =IF(G4="Windows Server", 150, 20) -> 150 | J4: =SUM(I4:I7) -> 300 | K4: =J4 *(IF(C4="AZURE", SUMMARY!C$20, SUMMARY!C$21)) -> 28.8 | L4: 2 | M4: =IF(C4="ON PREM", 0, SUMMARY!C$25%) -> 0.12 | N4: =IF(C4="AWS",SUMMARY!C$26%, 0) -> 0 | O4: =((SUM(K4:L4))-((SUM(K4:L4))*N4))*(1 + M4) -> 34.496 | P4: =O4*12 -> 413.952
H5: =IF(G4="Windows Server", "F:\appdir", "/appdir") -> F:\appdir
H6: =IF(G4="Windows Server", "G:\Log", "/var/log") -> G:\Log | I6: =IF(G4="Windows Server", 50, 20) -> 50
H7: =IF(G4="Windows Server", "H:\Backup", "/backup") -> H:\Backup | I7: =IF(G4="Windows Server", 100, 10) -> 100
B8: =((12*5*4)/(24*7*4))*730 -> 260.71429 | C8: ON PREM | G8: Windows Server | H8: =IF(G8="Windows Server", "C:\", "/") -> C:\ | I8: =IF(G8="Windows Server", 150, 20) -> 150 | J8: =SUM(I8:I11) -> 300 | K8: =J8 *(IF(C8="AZURE", SUMMARY!C$20, SUMMARY!C$21)) -> 28.8 | L8: 2 | M8: =IF(C8="ON PREM", 0, SUMMARY!C$25%) -> 0 | N8: =IF(C8="AWS",SUMMARY!C$26%, 0) -> 0 | O8: =((SUM(K8:L8))-((SUM(K8:L8))*N8))*(1 + M8) -> 30.8 | P8: =O8*12 -> 369.6
H9: =IF(G8="Windows Server", "F:\appdir", "/appdir") -> F:\appdir
H10: =IF(G8="Windows Server", "G:\Log", "/var/log") -> G:\Log | I10: =IF(G8="Windows Server", 50, 20) -> 50
H11: =IF(G8="Windows Server", "H:\Backup", "/backup") -> H:\Backup | I11: =IF(G8="Windows Server", 100, 10) -> 100
E12: =SUM(E4:E11) -> 0 | F12: =SUM(F4:F11) -> 0 | J12: =SUM(J4:J11) -> 600 | K12: =SUM(K4:K11) -> 57.6 | L12: =SUM(L4:L11) -> 4 | O12: =SUM(O4:O11) -> 65.296 | P12: =SUM(P4:P11) -> 783.552
A13: YEAR 2
B14: =((12*5*4)/(24*7*4))*730 -> 260.71429 | C14: AWS | E14: =$E$4 -> 0 | F14: =$F$4 -> 0 | G14: Windows Server | H14: =IF(G14="Windows Server", "C:\", "/") -> C:\ | I14: =IF(G14="Windows Server", 150, 20) -> 150 | J14: =SUM(I14:I17) -> 300 | K14: =J14 *(IF(C14="AZURE", SUMMARY!C$20, SUMMARY!C$21)) -> 28.8 | M14: =IF(C14="ON PREM", 0, SUMMARY!C$25%) -> 0.12 | N14: =IF(C14="AWS",SUMMARY!C$26%, 0) -> 0.13 | O14: =((SUM(K14:L14))-((SUM(K14:L14))*N14))*(1 + M14) -> 28.06272 | P14: =O14*12 -> 336.75264
H15: =IF(G14="Windows Server", "F:\appdir", "/appdir'") -> F:\appdir | I15: =$I$5 -> 0
H16: =IF(G14="Windows Server", "G:\Log", "/var/log") -> G:\Log | I16: =IF(G14="Windows Server", 50, 20) -> 50
H17: =IF(G14="Windows Server", "H:\Backup", "/backup") -> H:\Backup | I17: =IF(G14="Windows Server", 100, 10) -> 100
B18: =((12*5*4)/(24*7*4))*730 -> 260.71429 | C18: AWS | E18: =$E$8 -> 0 | F18: =$F$8 -> 0 | G18: Windows Server | H18: =IF(G18="Windows Server", "C:\", "/") -> C:\ | I18: =IF(G18="Windows Server", 150, 20) -> 150 | J18: =SUM(I18:I21) -> 300 | K18: =J18 *(IF(C18="AZURE", SUMMARY!C$20, SUMMARY!C$21)) -> 28.8 | M18: =IF(C18="ON PREM", 0, SUMMARY!C$25%) -> 0.12 | N18: =IF(C18="AWS",SUMMARY!C$26%, 0) -> 0.13 | O18: =((SUM(K18:L18))-((SUM(K18:L18))*N18))*(1 + M18) -> 28.06272 | P18: =O18*12 -> 336.75264
H19: =IF(G18="Windows Server", "F:\appdir", "/appdir") -> F:\appdir | I19: =$I$9 -> 0
H20: =IF(G18="Windows Server", "G:\Log", "/var/log") -> G:\Log | I20: =IF(G18="Windows Server", 50, 20) -> 50
H21: =IF(G18="Windows Server", "H:\Backup", "/backup") -> H:\Backup | I21: =IF(G18="Windows Server", 100, 10) -> 100
E22: =SUM(E14:E21) -> 0 | F22: =SUM(F14:F21) -> 0 | J22: =SUM(J14:J21) -> 600 | K22: =SUM(K14:K21) -> 57.6 | L22: =SUM(L14:L21) -> 0 | O22: =SUM(O14:O21) -> 56.12544 | P22: =SUM(P14:P21) -> 673.50528
A23: YEAR 3
B24: =((12*5*4)/(24*7*4))*730 -> 260.71429 | C24: EXACC | E24: =$E$4 -> 0 | F24: =$F$4 -> 0 | G24: RHEL | H24: =IF(G24="Windows Server", "C:\", "/") -> / | I24: =IF(G24="Windows Server", 150, 20) -> 20 | J24: =SUM(I24:I27) -> 50 | K24: =J24 *(IF(C24="AZURE", SUMMARY!C$20, SUMMARY!C$21)) -> 4.8 | M24: =IF(C24="ON PREM", 0, SUMMARY!C$25%) -> 0.12 | N24: =IF(C24="AWS",SUMMARY!C$26%, 0) -> 0 | O24: =((SUM(K24:L24))-((SUM(K24:L24))*N24))*(1 + M24) -> 5.376 | P24: =O24*12 -> 64.512
H25: =IF(G24="Windows Server", "F:\appdir", "/appdir") -> /appdir
H26: =IF(G24="Windows Server", "G:\Log", "/var/log") -> /var/log | I26: =IF(G24="Windows Server", 50, 20) -> 20
H27: =IF(G24="Windows Server", "H:\Backup", "/backup") -> /backup | I27: =IF(G24="Windows Server", 100, 10) -> 10
B28: =((12*5*4)/(24*7*4))*730 -> 260.71429 | C28: ON PREM | E28: =$E$8 -> 0 | F28: =$F$8 -> 0 | G28: RHEL | H28: =IF(G28="Windows Server", "C:\", "/") -> / | I28: =IF(G28="Windows Server", 150, 20) -> 20 | J28: =SUM(I28:I31) -> 50 | K28: =J28 *(IF(C28="AZURE", SUMMARY!C$20, SUMMARY!C$21)) -> 4.8 | M28: =IF(C28="ON PREM", 0, SUMMARY!C$25%) -> 0 | N28: =IF(C28="AWS",SUMMARY!C$26%, 0) -> 0 | O28: =((SUM(K28:L28))-((SUM(K28:L28))*N28))*(1 + M28) -> 4.8 | P28: =O28*12 -> 57.6
H29: =IF(G28="Windows Server", "F:\appdir", "/appdir") -> /appdir
H30: =IF(G28="Windows Server", "G:\Log", "/var/log") -> /var/log | I30: =IF(G28="Windows Server", 50, 20) -> 20
H31: =IF(G28="Windows Server", "H:\Backup", "/backup") -> /backup | I31: =IF(G28="Windows Server", 100, 10) -> 10
E32: =SUM(E24:E31) -> 0 | F32: =SUM(F24:F31) -> 0 | J32: =SUM(J24:J31) -> 100 | K32: =SUM(K24:K31) -> 9.6 | L32: =SUM(L24:L31) -> 0 | O32: =SUM(O24:O31) -> 10.176 | P32: =SUM(P24:P31) -> 122.112
A33: YEAR 4
B34: =((12*5*4)/(24*7*4))*730 -> 260.71429 | C34: AWS | E34: =$E$4 -> 0 | F34: =$F$4 -> 0 | G34: Windows Server | H34: =IF(G34="Windows Server", "C:\", "/") -> C:\ | I34: =IF(G34="Windows Server", 150, 20) -> 150 | J34: =SUM(I34:I37) -> 300 | K34: =J34 *(IF(C34="AZURE", SUMMARY!C$20, SUMMARY!C$21)) -> 28.8 | M34: =IF(C34="ON PREM", 0, SUMMARY!C$25%) -> 0.12 | N34: =IF(C34="AWS",SUMMARY!C$26%, 0) -> 0.13 | O34: =((SUM(K34:L34))-((SUM(K34:L34))*N34))*(1 + M34) -> 28.06272 | P34: =O34*12 -> 336.75264
H35: =IF(G34="Windows Server", "F:\appdir", "/appdir") -> F:\appdir | I35: =$I$5 -> 0
H36: =IF(G34="Windows Server", "G:\Log", "/var/log") -> G:\Log | I36: =IF(G34="Windows Server", 50, 20) -> 50
H37: =IF(G34="Windows Server", "H:\Backup", "/backup") -> H:\Backup | I37: =IF(G34="Windows Server", 100, 10) -> 100
B38: =((12*5*4)/(24*7*4))*730 -> 260.71429 | C38: AWS | E38: =$E$8 -> 0 | F38: =$F$8 -> 0 | G38: RHEL | H38: =IF(G38="Windows Server", "C:\", "/") -> / | I38: =IF(G38="Windows Server", 150, 20) -> 20 | J38: =SUM(I38:I41) -> 50 | K38: =J38 *(IF(C38="AZURE", SUMMARY!C$20, SUMMARY!C$21)) -> 4.8 | M38: =IF(C38="ON PREM", 0, SUMMARY!C$25%) -> 0.12 | N38: =IF(C38="AWS",SUMMARY!C$26%, 0) -> 0.13 | O38: =((SUM(K38:L38))-((SUM(K38:L38))*N38))*(1 + M38) -> 4.67712 | P38: =O38*12 -> 56.12544
H39: =IF(G38="Windows Server", "F:\appdir", "/appdir") -> /appdir | I39: =$I$9 -> 0
H40: =IF(G38="Windows Server", "G:\Log", "/var/log") -> /var/log | I40: =IF(G38="Windows Server", 50, 20) -> 20
...

Sheet UAT
A1: UAT ENVIRONMENT (to be filled out by servicing unit)
A2: YEAR 1
A3: Description | B3: Hours | C3: Cloud Platform | D3: Instance Type, Specs | E3: CPU | F3: Memory (GB) | G3: Operating System | H3: Disk Space Description (Size in GB) | J3: Disk Space (GB) | K3: Monthly EBS Volume Cost ($) | L3: Monthly Subscription Cost ($) | M3: VAT | N3: Enterprise Discount | O3: Total Monthly Cost ($) | P3: Total Annual Cost ($)
B4: =((12*5*4)/(24*7*4))*730 -> 260.71429 | C4: EXACC | G4: Ubuntu | H4: =IF(G4="Windows Server", "C:\", "/") -> / | I4: =IF(G4="Windows Server", 150, 20) -> 20 | J4: =SUM(I4:I7) -> 50 | K4: =J4 *(IF(C4="AZURE", SUMMARY!C$20, SUMMARY!C$21)) -> 4.8 | M4: =IF(C4="ON PREM", 0, SUMMARY!C$25%) -> 0.12 | N4: =IF(C4="AWS",SUMMARY!C$26%, 0) -> 0 | O4: =((SUM(K4:L4))-((SUM(K4:L4))*N4))*(1 + M4) -> 5.376 | P4: =O4*12 -> 64.512
H5: =IF(G4="Windows Server", "F:\appdir", "/appdir") -> /appdir
H6: =IF(G4="Windows Server", "G:\Log", "/var/log") -> /var/log | I6: =IF(G4="Windows Server", 50, 20) -> 20
H7: =IF(G4="Windows Server", "H:\Backup", "/backup") -> /backup | I7: =IF(G4="Windows Server", 100, 10) -> 10
B8: =((12*5*4)/(24*7*4))*730 -> 260.71429 | C8: ON PREM | G8: Ubuntu | H8: =IF(G8="Windows Server", "C:\", "/") -> / | I8: =IF(G8="Windows Server", 150, 20) -> 20 | J8: =SUM(I8:I11) -> 50 | K8: =J8 *(IF(C8="AZURE", SUMMARY!C$20, SUMMARY!C$21)) -> 4.8 | M8: =IF(C8="ON PREM", 0, SUMMARY!C$25%) -> 0 | N8: =IF(C8="AWS",SUMMARY!C$26%, 0) -> 0 | O8: =((SUM(K8:L8))-((SUM(K8:L8))*N8))*(1 + M8) -> 4.8 | P8: =O8*12 -> 57.6
H9: =IF(G8="Windows Server", "F:\appdir", "/appdir") -> /appdir
H10: =IF(G8="Windows Server", "G:\Log", "/var/log") -> /var/log | I10: =IF(G8="Windows Server", 50, 20) -> 20
H11: =IF(G8="Windows Server", "H:\Backup", "/backup") -> /backup | I11: =IF(G8="Windows Server", 100, 10) -> 10
B12: =((12*5*4)/(24*7*4))*730 -> 260.71429 | C12: EXACC | G12: Oracle Linux | H12: =IF(G12="Windows Server", "C:\", "/") -> / | I12: =IF(G12="Windows Server", 150, 20) -> 20 | J12: =SUM(I12:I15) -> 50 | K12: =J12 *(IF(C12="AZURE", SUMMARY!C$20, SUMMARY!C$21)) -> 4.8 | M12: =IF(C12="ON PREM", 0, SUMMARY!C$25%) -> 0.12 | N12: =IF(C12="AWS",SUMMARY!C$26%, 0) -> 0 | O12: =((SUM(K12:L12))-((SUM(K12:L12))*N12))*(1 + M12) -> 5.376 | P12: =O12*12 -> 64.512
H13: =IF(G12="Windows Server", "F:\appdir", "/appdir") -> /appdir
H14: =IF(G12="Windows Server", "G:\Log", "/var/log") -> /var/log | I14: =IF(G12="Windows Server", 50, 20) -> 20
H15: =IF(G12="Windows Server", "H:\Backup", "/backup") -> /backup | I15: =IF(G12="Windows Server", 100, 10) -> 10
B16: =((12*5*4)/(24*7*4))*730 -> 260.71429 | C16: ON PREM | G16: Oracle Linux | H16: =IF(G16="Windows Server", "C:\", "/") -> / | I16: =IF(G16="Windows Server", 150, 20) -> 20 | J16: =SUM(I16:I19) -> 50 | K16: =J16 *(IF(C16="AZURE", SUMMARY!C$20, SUMMARY!C$21)) -> 4.8 | M16: =IF(C16="ON PREM", 0, SUMMARY!C$25%) -> 0 | N16: =IF(C16="AWS",SUMMARY!C$26%, 0) -> 0 | O16: =((SUM(K16:L16))-((SUM(K16:L16))*N16))*(1 + M16) -> 4.8 | P16: =O16*12 -> 57.6
H17: =IF(G16="Windows Server", "F:\appdir", "/appdir") -> /appdir
H18: =IF(G16="Windows Server", "G:\Log", "/var/log") -> /var/log | I18: =IF(G16="Windows Server", 50, 20) -> 20
H19: =IF(G16="Windows Server", "H:\Backup", "/backup") -> /backup | I19: =IF(G16="Windows Server", 100, 10) -> 10
B20: =((12*5*4)/(24*7*4))*730 -> 260.71429 | C20: EXACC | G20: Ubuntu | H20: =IF(G20="Windows Server", "C:\", "/") -> / | I20: =IF(G20="Windows Server", 150, 20) -> 20 | J20: =SUM(I20:I23) -> 50 | K20: =J20 *(IF(C20="AZURE", SUMMARY!C$20, SUMMARY!C$21)) -> 4.8 | M20: =IF(C20="ON PREM", 0, SUMMARY!C$25%) -> 0.12 | N20: =IF(C20="AWS",SUMMARY!C$26%, 0) -> 0 | O20: =((SUM(K20:L20))-((SUM(K20:L20))*N20))*(1 + M20) -> 5.376 | P20: =O20*12 -> 64.512
H21: =IF(G20="Windows Server", "F:\appdir", "/appdir") -> /appdir
H22: =IF(G20="Windows Server", "G:\Log", "/var/log") -> /var/log | I22: =IF(G20="Windows Server", 50, 20) -> 20
H23: =IF(G20="Windows Server", "H:\Backup", "/backup") -> /backup | I23: =IF(G20="Windows Server", 100, 10) -> 10
B24: =((12*5*4)/(24*7*4))*730 -> 260.71429 | C24: EXACC | G24: Oracle Linux | H24: =IF(G24="Windows Server", "C:\", "/") -> / | I24: =IF(G24="Windows Server", 150, 20) -> 20 | J24: =SUM(I24:I27) -> 50 | K24: =J24 *(IF(C24="AZURE", SUMMARY!C$20, SUMMARY!C$21)) -> 4.8 | M24: =IF(C24="ON PREM", 0, SUMMARY!C$25%) -> 0.12 | N24: =IF(C24="AWS",SUMMARY!C$26%, 0) -> 0 | O24: =((SUM(K24:L24))-((SUM(K24:L24))*N24))*(1 + M24) -> 5.376 | P24: =O24*12 -> 64.512
H25: =IF(G24="Windows Server", "F:\appdir", "/appdir") -> /appdir
H26: =IF(G24="Windows Server", "G:\Log", "/var/log") -> /var/log | I26: =IF(G24="Windows Server", 50, 20) -> 20
H27: =IF(G24="Windows Server", "H:\Backup", "/backup") -> /backup | I27: =IF(G24="Windows Server", 100, 10) -> 10
E28: =SUM(E4:E27) -> 0 | F28: =SUM(F4:F27) -> 0 | J28: =SUM(J4:J27) -> 300 | K28: =SUM(K4:K27) -> 28.8 | L28: =SUM(L4:L27) -> 0 | O28: =SUM(O4:O27) -> 31.104 | P28: =SUM(P4:P27) -> 373.248
A29: YEAR 2
B30: =((12*5*4)/(24*7*4))*730 -> 260.71429 | C30: AWS | E30: =CEILING(E4*(100+SUMMARY!$C$24)%,1) -> 0 | F30: =CEILING(F4*(100+SUMMARY!$C$24)%,1) -> 0 | G30: Windows Server | H30: =IF(G30="Windows Server", "C:\", "/") -> C:\ | I30: =IF(G30="Windows Server", 150, 20) -> 150 | J30: =SUM(I30:I33) -> 300 | K30: =J30 *(IF(C30="AZURE", SUMMARY!C$20, SUMMARY!C$21)) -> 28.8 | M30: =IF(C30="ON PREM", 0, SUMMARY!C$25%) -> 0.12 | N30: =IF(C30="AWS",SUMMARY!C$26%, 0) -> 0.13 | O30: =((SUM(K30:L30))-((SUM(K30:L30))*N30))*(1 + M30) -> 28.06272 | P30: =O30*12 -> 336.75264
H31: =IF(G30="Windows Server", "F:\appdir", "/appdir") -> F:\appdir | I31: =CEILING(I5*(100+SUMMARY!$C$24)%,1) -> 0
H32: =IF(G30="Windows Server", "G:\Log", "/var/log") -> G:\Log | I32: =IF(G30="Windows Server", 50, 20) -> 50
H33: =IF(G30="Windows Server", "H:\Backup", "/backup") -> H:\Backup | I33: =IF(G30="Windows Server", 100, 10) -> 100
B34: =((12*5*4)/(24*7*4))*730 -> 260.71429 | C34: AWS | E34: =CEILING(E8*(100+SUMMARY!$C$24)%,1) -> 0 | F34: =CEILING(F8*(100+SUMMARY!$C$24)%,1) -> 0 | G34: RHEL | H34: =IF(G34="Windows Server", "C:\", "/") -> / | I34: =IF(G34="Windows Server", 150, 20) -> 20 | J34: =SUM(I34:I37) -> 50 | K34: =J34 *(IF(C34="AZURE", SUMMARY!C$20, SUMMARY!C$21)) -> 4.8 | M34: =IF(C34="ON PREM", 0, SUMMARY!C$25%) -> 0.12 | N34: =IF(C34="AWS",SUMMARY!C$26%, 0) -> 0.13 | O34: =((SUM(K34:L34))-((SUM(K34:L34))*N34))*(1 + M34) -> 4.67712 | P34: =O34*12 -> 56.12544
H35: =IF(G34="Windows Server", "F:\appdir", "/appdir") -> /appdir | I35: =CEILING(I9*(100+SUMMARY!$C$24)%,1) -> 0
H36: =IF(G34="Windows Server", "G:\Log", "/var/log") -> /var/log | I36: =IF(G34="Windows Server", 50, 20) -> 20
H37: =IF(G34="Windows Server", "H:\Backup", "/backup") -> /backup | I37: =IF(G34="Windows Server", 100, 10) -> 10
B38: =((12*5*4)/(24*7*4))*730 -> 260.71429 | C38: AWS | E38: =CEILING(E12*(100+SUMMARY!$C$24)%,1) -> 0 | F38: =CEILING(F12*(100+SUMMARY!$C$24)%,1) -> 0 | G38: Windows Server | H38: =IF(G38="Windows Server", "C:\", "/") -> C:\ | I38: =IF(G38="Windows Server", 150, 20) -> 150 | J38: =SUM(I38:I41) -> 300 | K38: =J38 *(IF(C38="AZURE", SUMMARY!C$20, SUMMARY!C$21)) -> 28.8 | M38: =IF(C38="ON PREM", 0, SUMMARY!C$25%) -> 0.12 | N38: =IF(C38="AWS",SUMMARY!C$26%, 0) -> 0.13 | O38: =((SUM(K38:L38))-((SUM(K38:L38))*N38))*(1 + M38) -> 28.06272 | P38: =O38*12 -> 336.75264
H39: =IF(G38="Windows Server", "F:\appdir", "/appdir") -> F:\appdir | I39: =CEILING(I13*(100+SUMMARY!$C$24)%,1) -> 0
H40: =IF(G38="Windows Server", "G:\Log", "/var/log") -> G:\Log | I40: =IF(G38="Windows Server", 50, 20) -> 50
...

Sheet Pre-Prod
A1: UAT ENVIRONMENT (to be filled out by servicing unit)
A2: YEAR 1
A3: Description | B3: Hours | C3: Cloud Platform | D3: Instance Type, Specs | E3: CPU | F3: Memory (GB) | G3: Operating System | H3: Disk Space Description (Size in GB) | J3: Disk Space (GB) | K3: Monthly EBS Volume Cost ($) | L3: Monthly Subscription Cost ($) | M3: VAT | N3: Enterprise Discount | O3: Total Monthly Cost ($) | P3: Total Annual Cost ($)
B4: =((12*5*4)/(24*7*4))*730 -> 260.71429 | C4: EXACC | G4: Ubuntu | H4: =IF(G4="Windows Server", "C:\", "/") -> / | I4: =IF(G4="Windows Server", 150, 20) -> 20 | J4: =SUM(I4:I7) -> 50 | K4: =J4 *(IF(C4="AZURE", SUMMARY!C$20, SUMMARY!C$21)) -> 4.8 | M4: =IF(C4="ON PREM", 0, SUMMARY!C$25%) -> 0.12 | N4: =IF(C4="AWS",SUMMARY!C$26%, 0) -> 0 | O4: =((SUM(K4:L4))-((SUM(K4:L4))*N4))*(1 + M4) -> 5.376 | P4: =O4*12 -> 64.512
H5: =IF(G4="Windows Server", "F:\appdir", "/appdir") -> /appdir
H6: =IF(G4="Windows Server", "G:\Log", "/var/log") -> /var/log | I6: =IF(G4="Windows Server", 50, 20) -> 20
H7: =IF(G4="Windows Server", "H:\Backup", "/backup") -> /backup | I7: =IF(G4="Windows Server", 100, 10) -> 10
B8: =((12*5*4)/(24*7*4))*730 -> 260.71429 | C8: ON PREM | G8: RHEL | H8: =IF(G8="Windows Server", "C:\", "/") -> / | I8: =IF(G8="Windows Server", 150, 20) -> 20 | J8: =SUM(I8:I11) -> 50 | K8: =J8 *(IF(C8="AZURE", SUMMARY!C$20, SUMMARY!C$21)) -> 4.8 | M8: =IF(C8="ON PREM", 0, SUMMARY!C$25%) -> 0 | N8: =IF(C8="AWS",SUMMARY!C$26%, 0) -> 0 | O8: =((SUM(K8:L8))-((SUM(K8:L8))*N8))*(1 + M8) -> 4.8 | P8: =O8*12 -> 57.6
H9: =IF(G8="Windows Server", "F:\appdir", "/appdir") -> /appdir
H10: =IF(G8="Windows Server", "G:\Log", "/var/log") -> /var/log | I10: =IF(G8="Windows Server", 50, 20) -> 20
H11: =IF(G8="Windows Server", "H:\Backup", "/backup") -> /backup | I11: =IF(G8="Windows Server", 100, 10) -> 10
B12: =((12*5*4)/(24*7*4))*730 -> 260.71429 | C12: EXACC | G12: Oracle Linux | H12: =IF(G12="Windows Server", "C:\", "/") -> / | I12: =IF(G12="Windows Server", 150, 20) -> 20 | J12: =SUM(I12:I15) -> 50 | K12: =J12 *(IF(C12="AZURE", SUMMARY!C$20, SUMMARY!C$21)) -> 4.8 | M12: =IF(C12="ON PREM", 0, SUMMARY!C$25%) -> 0.12 | N12: =IF(C12="AWS",SUMMARY!C$26%, 0) -> 0 | O12: =((SUM(K12:L12))-((SUM(K12:L12))*N12))*(1 + M12) -> 5.376 | P12: =O12*12 -> 64.512
H13: =IF(G12="Windows Server", "F:\appdir", "/appdir") -> /appdir
H14: =IF(G12="Windows Server", "G:\Log", "/var/log") -> /var/log | I14: =IF(G12="Windows Server", 50, 20) -> 20
H15: =IF(G12="Windows Server", "H:\Backup", "/backup") -> /backup | I15: =IF(G12="Windows Server", 100, 10) -> 10
B16: =((12*5*4)/(24*7*4))*730 -> 260.71429 | C16: EXACC | G16: Oracle Linux | H16: =IF(G16="Windows Server", "C:\", "/") -> / | I16: =IF(G16="Windows Server", 150, 20) -> 20 | J16: =SUM(I16:I19) -> 50 | K16: =J16 *(IF(C16="AZURE", SUMMARY!C$20, SUMMARY!C$21)) -> 4.8 | M16: =IF(C16="ON PREM", 0, SUMMARY!C$25%) -> 0.12 | N16: =IF(C16="AWS",SUMMARY!C$26%, 0) -> 0 | O16: =((SUM(K16:L16))-((SUM(K16:L16))*N16))*(1 + M16) -> 5.376 | P16: =O16*12 -> 64.512
H17: =IF(G16="Windows Server", "F:\appdir", "/appdir") -> /appdir
H18: =IF(G16="Windows Server", "G:\Log", "/var/log") -> /var/log | I18: =IF(G16="Windows Server", 50, 20) -> 20
H19: =IF(G16="Windows Server", "H:\Backup", "/backup") -> /backup | I19: =IF(G16="Windows Server", 100, 10) -> 10
B20: =((12*5*4)/(24*7*4))*730 -> 260.71429 | C20: EXACC | G20: Ubuntu | H20: =IF(G20="Windows Server", "C:\", "/") -> / | I20: =IF(G20="Windows Server", 150, 20) -> 20 | J20: =SUM(I20:I23) -> 50 | K20: =J20 *(IF(C20="AZURE", SUMMARY!C$20, SUMMARY!C$21)) -> 4.8 | M20: =IF(C20="ON PREM", 0, SUMMARY!C$25%) -> 0.12 | N20: =IF(C20="AWS",SUMMARY!C$26%, 0) -> 0 | O20: =((SUM(K20:L20))-((SUM(K20:L20))*N20))*(1 + M20) -> 5.376 | P20: =O20*12 -> 64.512
H21: =IF(G20="Windows Server", "F:\appdir", "/appdir") -> /appdir
H22: =IF(G20="Windows Server", "G:\Log", "/var/log") -> /var/log | I22: =IF(G20="Windows Server", 50, 20) -> 20
H23: =IF(G20="Windows Server", "H:\Backup", "/backup") -> /backup | I23: =IF(G20="Windows Server", 100, 10) -> 10
B24: =((12*5*4)/(24*7*4))*730 -> 260.71429 | C24: EXACC | G24: RHEL | H24: =IF(G24="Windows Server", "C:\", "/") -> / | I24: =IF(G24="Windows Server", 150, 20) -> 20 | J24: =SUM(I24:I27) -> 50 | K24: =J24 *(IF(C24="AZURE", SUMMARY!C$20, SUMMARY!C$21)) -> 4.8 | M24: =IF(C24="ON PREM", 0, SUMMARY!C$25%) -> 0.12 | N24: =IF(C24="AWS",SUMMARY!C$26%, 0) -> 0 | O24: =((SUM(K24:L24))-((SUM(K24:L24))*N24))*(1 + M24) -> 5.376 | P24: =O24*12 -> 64.512
H25: =IF(G24="Windows Server", "F:\appdir", "/appdir") -> /appdir
H26: =IF(G24="Windows Server", "G:\Log", "/var/log") -> /var/log | I26: =IF(G24="Windows Server", 50, 20) -> 20
H27: =IF(G24="Windows Server", "H:\Backup", "/backup") -> /backup | I27: =IF(G24="Windows Server", 100, 10) -> 10
E28: =SUM(E4:E27) -> 0 | F28: =SUM(F4:F27) -> 0 | J28: =SUM(J4:J27) -> 300 | K28: =SUM(K4:K27) -> 28.8 | L28: =SUM(L4:L27) -> 0 | O28: =SUM(O4:O27) -> 31.68 | P28: =SUM(P4:P27) -> 380.16
A29: YEAR 2
B30: =((12*5*4)/(24*7*4))*730 -> 260.71429 | C30: AWS | E30: =CEILING(E4*(100+SUMMARY!$C$24)%,1) -> 0 | F30: =CEILING(F4*(100+SUMMARY!$C$24)%,1) -> 0 | G30: Windows Server | H30: =IF(G30="Windows Server", "C:\", "/") -> C:\ | I30: =IF(G30="Windows Server", 150, 20) -> 150 | J30: =SUM(I30:I33) -> 300 | K30: =J30 *(IF(C30="AZURE", SUMMARY!C$20, SUMMARY!C$21)) -> 28.8 | M30: =IF(C30="ON PREM", 0, SUMMARY!C$25%) -> 0.12 | N30: =IF(C30="AWS",SUMMARY!C$26%, 0) -> 0.13 | O30: =((SUM(K30:L30))-((SUM(K30:L30))*N30))*(1 + M30) -> 28.06272 | P30: =O30*12 -> 336.75264
H31: =IF(G30="Windows Server", "F:\appdir", "/appdir") -> F:\appdir | I31: =CEILING(I5*(100+SUMMARY!$C$24)%,1) -> 0
H32: =IF(G30="Windows Server", "G:\Log", "/var/log") -> G:\Log | I32: =IF(G30="Windows Server", 50, 20) -> 50
H33: =IF(G30="Windows Server", "H:\Backup", "/backup") -> H:\Backup | I33: =IF(G30="Windows Server", 100, 10) -> 100
B34: =((12*5*4)/(24*7*4))*730 -> 260.71429 | C34: AWS | E34: =CEILING(E8*(100+SUMMARY!$C$24)%,1) -> 0 | F34: =CEILING(F8*(100+SUMMARY!$C$24)%,1) -> 0 | G34: RHEL | H34: =IF(G34="Windows Server", "C:\", "/") -> / | I34: =IF(G34="Windows Server", 150, 20) -> 20 | J34: =SUM(I34:I37) -> 50 | K34: =J34 *(IF(C34="AZURE", SUMMARY!C$20, SUMMARY!C$21)) -> 4.8 | M34: =IF(C34="ON PREM", 0, SUMMARY!C$25%) -> 0.12 | N34: =IF(C34="AWS",SUMMARY!C$26%, 0) -> 0.13 | O34: =((SUM(K34:L34))-((SUM(K34:L34))*N34))*(1 + M34) -> 4.67712 | P34: =O34*12 -> 56.12544
H35: =IF(G34="Windows Server", "F:\appdir", "/appdir") -> /appdir | I35: =CEILING(I9*(100+SUMMARY!$C$24)%,1) -> 0
H36: =IF(G34="Windows Server", "G:\Log", "/var/log") -> /var/log | I36: =IF(G34="Windows Server", 50, 20) -> 20
H37: =IF(G34="Windows Server", "H:\Backup", "/backup") -> /backup | I37: =IF(G34="Windows Server", 100, 10) -> 10
B38: =((12*5*4)/(24*7*4))*730 -> 260.71429 | C38: AWS | E38: =CEILING(E12*(100+SUMMARY!$C$24)%,1) -> 0 | F38: =CEILING(F12*(100+SUMMARY!$C$24)%,1) -> 0 | G38: Windows Server | H38: =IF(G38="Windows Server", "C:\", "/") -> C:\ | I38: =IF(G38="Windows Server", 150, 20) -> 150 | J38: =SUM(I38:I41) -> 300 | K38: =J38 *(IF(C38="AZURE", SUMMARY!C$20, SUMMARY!C$21)) -> 28.8 | M38: =IF(C38="ON PREM", 0, SUMMARY!C$25%) -> 0.12 | N38: =IF(C38="AWS",SUMMARY!C$26%, 0) -> 0.13 | O38: =((SUM(K38:L38))-((SUM(K38:L38))*N38))*(1 + M38) -> 28.06272 | P38: =O38*12 -> 336.75264
H39: =IF(G38="Windows Server", "F:\appdir", "/appdir") -> F:\appdir | I39: =CEILING(I13*(100+SUMMARY!$C$24)%,1) -> 0
H40: =IF(G38="Windows Server", "G:\Log", "/var/log") -> G:\Log | I40: =IF(G38="Windows Server", 50, 20) -> 50
...

Sheet PROD
A1: PROD ENVIRONMENT (to be filled out by servicing unit)
A2: YEAR 1
A3: Description | B3: Hours | C3: Cloud Platform | D3: Instance Type, Specs | E3: CPU | F3: Memory (GB) | G3: Operating System | H3: Disk Space Description (Size in GB) | J3: Disk Space (GB) | K3: Monthly EBS Volume Cost ($) | L3: Monthly Subscription Cost ($) | M3: VAT | N3: Enterprise Discount | O3: Total Monthly Cost ($) | P3: Total Annual Cost ($)
A4: App Server | B4: =((24*7*4)/(24*7*4))*730 -> 730 | C4: AWS | E4: 4 | F4: 16 | G4: Windows Server | H4: =IF(G4="Windows Server", "C:\", "/") -> C:\ | I4: =IF(G4="Windows Server", 150, 20) -> 150 | J4: =SUM(I4:I7) -> 300 | K4: =J4 *(IF(C4="AZURE", SUMMARY!C$20, SUMMARY!C$21)) -> 28.8 | M4: =IF(C4="ON PREM", 0, SUMMARY!C$25%) -> 0.12 | N4: =IF(C4="AWS",SUMMARY!C$26%, 0) -> 0.13 | O4: =((SUM(K4:L4))-((SUM(K4:L4))*N4))*(1 + M4) -> 28.06272 | P4: =O4*12 -> 336.75264
H5: =IF(G4="Windows Server", "F:\appdir", "/appdir") -> F:\appdir
H6: =IF(G4="Windows Server", "G:\Log", "/var/log") -> G:\Log | I6: =IF(G4="Windows Server", 50, 20) -> 50
H7: =IF(G4="Windows Server", "H:\Backup", "/backup") -> H:\Backup | I7: =IF(G4="Windows Server", 100, 10) -> 100
B8: =((24*7*4)/(24*7*4))*730 -> 730 | C8: ON PREM | G8: Windows Server | H8: =IF(G8="Windows Server", "C:\", "/") -> C:\ | I8: =IF(G8="Windows Server", 150, 20) -> 150 | J8: =SUM(I8:I11) -> 300 | K8: =J8 *(IF(C8="AZURE", SUMMARY!C$20, SUMMARY!C$21)) -> 28.8 | M8: =IF(C8="ON PREM", 0, SUMMARY!C$25%) -> 0 | N8: =IF(C8="AWS",SUMMARY!C$26%, 0) -> 0 | O8: =((SUM(K8:L8))-((SUM(K8:L8))*N8))*(1 + M8) -> 28.8 | P8: =O8*12 -> 345.6
H9: =IF(G8="Windows Server", "F:\appdir", "/appdir") -> F:\appdir
H10: =IF(G8="Windows Server", "G:\Log", "/var/log") -> G:\Log | I10: =IF(G8="Windows Server", 50, 20) -> 50
H11: =IF(G8="Windows Server", "H:\Backup", "/backup") -> H:\Backup | I11: =IF(G8="Windows Server", 100, 10) -> 100
B12: =((24*7*4)/(24*7*4))*730 -> 730 | C12: EXACC | G12: RHEL | H12: =IF(G12="Windows Server", "C:\", "/") -> / | I12: =IF(G12="Windows Server", 150, 20) -> 20 | J12: =SUM(I12:I15) -> 50 | K12: =J12 *(IF(C12="AZURE", SUMMARY!C$20, SUMMARY!C$21)) -> 4.8 | M12: =IF(C12="ON PREM", 0, SUMMARY!C$25%) -> 0.12 | N12: =IF(C12="AWS",SUMMARY!C$26%, 0) -> 0 | O12: =((SUM(K12:L12))-((SUM(K12:L12))*N12))*(1 + M12) -> 5.376 | P12: =O12*12 -> 64.512
H13: =IF(G12="Windows Server", "F:\appdir", "/appdir") -> /appdir
H14: =IF(G12="Windows Server", "G:\Log", "/var/log") -> /var/log | I14: =IF(G12="Windows Server", 50, 20) -> 20
H15: =IF(G12="Windows Server", "H:\Backup", "/backup") -> /backup | I15: =IF(G12="Windows Server", 100, 10) -> 10
B16: =((24*7*4)/(24*7*4))*730 -> 730 | C16: EXACC | G16: Oracle Linux | H16: =IF(G16="Windows Server", "C:\", "/") -> / | I16: =IF(G16="Windows Server", 150, 20) -> 20 | J16: =SUM(I16:I19) -> 50 | K16: =J16 *(IF(C16="AZURE", SUMMARY!C$20, SUMMARY!C$21)) -> 4.8 | M16: =IF(C16="ON PREM", 0, SUMMARY!C$25%) -> 0.12 | N16: =IF(C16="AWS",SUMMARY!C$26%, 0) -> 0 | O16: =((SUM(K16:L16))-((SUM(K16:L16))*N16))*(1 + M16) -> 5.376 | P16: =O16*12 -> 64.512
H17: =IF(G16="Windows Server", "F:\appdir", "/appdir") -> /appdir
H18: =IF(G16="Windows Server", "G:\Log", "/var/log") -> /var/log | I18: =IF(G16="Windows Server", 50, 20) -> 20
H19: =IF(G16="Windows Server", "H:\Backup", "/backup") -> /backup | I19: =IF(G16="Windows Server", 100, 10) -> 10
B20: =((24*7*4)/(24*7*4))*730 -> 730 | C20: EXACC | G20: Ubuntu | H20: =IF(G20="Windows Server", "C:\", "/") -> / | I20: =IF(G20="Windows Server", 150, 20) -> 20 | J20: =SUM(I20:I23) -> 50 | K20: =J20 *(IF(C20="AZURE", SUMMARY!C$20, SUMMARY!C$21)) -> 4.8 | M20: =IF(C20="ON PREM", 0, SUMMARY!C$25%) -> 0.12 | N20: =IF(C20="AWS",SUMMARY!C$26%, 0) -> 0 | O20: =((SUM(K20:L20))-((SUM(K20:L20))*N20))*(1 + M20) -> 5.376 | P20: =O20*12 -> 64.512
H21: =IF(G20="Windows Server", "F:\appdir", "/appdir") -> /appdir
H22: =IF(G20="Windows Server", "G:\Log", "/var/log") -> /var/log | I22: =IF(G20="Windows Server", 50, 20) -> 20
H23: =IF(G20="Windows Server", "H:\Backup", "/backup") -> /backup | I23: =IF(G20="Windows Server", 100, 10) -> 10
B24: =((24*7*4)/(24*7*4))*730 -> 730 | C24: EXACC | G24: Windows Server | H24: =IF(G24="Windows Server", "C:\", "/") -> C:\ | I24: =IF(G24="Windows Server", 150, 20) -> 150 | J24: =SUM(I24:I27) -> 300 | K24: =J24 *(IF(C24="AZURE", SUMMARY!C$20, SUMMARY!C$21)) -> 28.8 | M24: =IF(C24="ON PREM", 0, SUMMARY!C$25%) -> 0.12 | N24: =IF(C24="AWS",SUMMARY!C$26%, 0) -> 0 | O24: =((SUM(K24:L24))-((SUM(K24:L24))*N24))*(1 + M24) -> 32.256 | P24: =O24*12 -> 387.072
H25: =IF(G24="Windows Server", "F:\appdir", "/appdir") -> F:\appdir
H26: =IF(G24="Windows Server", "G:\Log", "/var/log") -> G:\Log | I26: =IF(G24="Windows Server", 50, 20) -> 50
H27: =IF(G24="Windows Server", "H:\Backup", "/backup") -> H:\Backup | I27: =IF(G24="Windows Server", 100, 10) -> 100
E28: =SUM(E4:E27) -> 4 | F28: =SUM(F4:F27) -> 16 | J28: =SUM(J4:J27) -> 1050 | K28: =SUM(K4:K27) -> 100.8 | L28: =SUM(L4:L27) -> 0 | O28: =SUM(O4:O27) -> 105.24672 | P28: =SUM(P4:P27) -> 1262.9606
A29: YEAR 2
B30: =((24*7*4)/(24*7*4))*730 -> 730 | C30: AWS | E30: =CEILING(E4*(100+SUMMARY!$C$24)%,1) -> 5 | F30: =CEILING(F4*(100+SUMMARY!$C$24)%,1) -> 19 | G30: Windows Server | H30: =IF(G30="Windows Server", "C:\", "/") -> C:\ | I30: =IF(G30="Windows Server", 150, 20) -> 150 | J30: =SUM(I30:I33) -> 300 | K30: =J30 *(IF(C30="AZURE", SUMMARY!C$20, SUMMARY!C$21)) -> 28.8 | M30: =IF(C30="ON PREM", 0, SUMMARY!C$25%) -> 0.12 | N30: =IF(C30="AWS",SUMMARY!C$26%, 0) -> 0.13 | O30: =((SUM(K30:L30))-((SUM(K30:L30))*N30))*(1 + M30) -> 28.06272 | P30: =O30*12 -> 336.75264
H31: =IF(G30="Windows Server", "F:\appdir", "/appdir") -> F:\appdir | I31: =CEILING(I5*(100+SUMMARY!$C$24)%,1) -> 0
H32: =IF(G30="Windows Server", "G:\Log", "/var/log") -> G:\Log | I32: =IF(G30="Windows Server", 50, 20) -> 50
H33: =IF(G30="Windows Server", "H:\Backup", "/backup") -> H:\Backup | I33: =IF(G30="Windows Server", 100, 10) -> 100
B34: =((24*7*4)/(24*7*4))*730 -> 730 | C34: AWS | E34: =CEILING(E8*(100+SUMMARY!$C$24)%,1) -> 0 | F34: =CEILING(F8*(100+SUMMARY!$C$24)%,1) -> 0 | G34: Windows Server | H34: =IF(G34="Windows Server", "C:\", "/") -> C:\ | I34: =IF(G34="Windows Server", 150, 20) -> 150 | J34: =SUM(I34:I37) -> 300 | K34: =J34 *(IF(C34="AZURE", SUMMARY!C$20, SUMMARY!C$21)) -> 28.8 | M34: =IF(C34="ON PREM", 0, SUMMARY!C$25%) -> 0.12 | N34: =IF(C34="AWS",SUMMARY!C$26%, 0) -> 0.13 | O34: =((SUM(K34:L34))-((SUM(K34:L34))*N34))*(1 + M34) -> 28.06272 | P34: =O34*12 -> 336.75264
H35: =IF(G34="Windows Server", "F:\appdir", "/appdir") -> F:\appdir | I35: =CEILING(I9*(100+SUMMARY!$C$24)%,1) -> 0
H36: =IF(G34="Windows Server", "G:\Log", "/var/log") -> G:\Log | I36: =IF(G34="Windows Server", 50, 20) -> 50
H37: =IF(G34="Windows Server", "H:\Backup", "/backup") -> H:\Backup | I37: =IF(G34="Windows Server", 100, 10) -> 100
B38: =((24*7*4)/(24*7*4))*730 -> 730 | C38: AWS | E38: =CEILING(E12*(100+SUMMARY!$C$24)%,1) -> 0 | F38: =CEILING(F12*(100+SUMMARY!$C$24)%,1) -> 0 | G38: Windows Server | H38: =IF(G38="Windows Server", "C:\", "/") -> C:\ | I38: =IF(G38="Windows Server", 150, 20) -> 150 | J38: =SUM(I38:I41) -> 300 | K38: =J38 *(IF(C38="AZURE", SUMMARY!C$20, SUMMARY!C$21)) -> 28.8 | M38: =IF(C38="ON PREM", 0, SUMMARY!C$25%) -> 0.12 | N38: =IF(C38="AWS",SUMMARY!C$26%, 0) -> 0.13 | O38: =((SUM(K38:L38))-((SUM(K38:L38))*N38))*(1 + M38) -> 28.06272 | P38: =O38*12 -> 336.75264
H39: =IF(G38="Windows Server", "F:\appdir", "/appdir") -> F:\appdir | I39: =CEILING(I13*(100+SUMMARY!$C$24)%,1) -> 0
H40: =IF(G38="Windows Server", "G:\Log", "/var/log") -> G:\Log | I40: =IF(G38="Windows Server", 50, 20) -> 50
...

Sheet DR
A1: DR ENVIRONMENT (to be filled out by servicing unit)
A2: YEAR 1
